Workbook

Sheet Main Menu
B2: TORCH & TORCHPlus Second Edition First Edition Scoring Templates
B4: This series of spreadsheets provide the templates required to enter ACER's TORCH & TORCHPlus (Tests of Reading Comprehension) results into the Student Performance Analyser (SPA). Click on the appropriate button (at right) to select the correct Test Booklet proforma to complete. Follow the instructions opposite. | H4: Step 1: Click on the appropriate button (at left) to select the correct Test Booklet proforma to complete. Step 2: For each student, enter the Date (when test was sat), Year Level, Home Group, Name, and Student ID (CASES No. or Student No.). Step 3: For each question, enter their response (their score will be calculated) OR enter their Raw Score OR enter their PAT Score. Step 4: Save and upload into SPA.
B40: Click here to find out more about other tests available from ACER | H40: Click here to find out more about the Student Performance Analyser

Sheet GrassHoppers
A1: TORCH - Grasshoppers
G3: QUESTION No. and ANSWER KEY (Enter the student's response - "Y" if correct, "N" if incorrect)
E4: Question Number | G4: 1 | H4: 2 | I4: 3 | J4: 4 | K4: 5 | L4: 6 | M4: 7 | N4: 8 | O4: 9 | P4: 10 | Q4: 11 | R4: 12 | S4: 13 | T4: 14 | U4: 15 | V4: 16 | W4: 17 | X4: 18 | Y4: 19
E5: Item Difficulty
E6: Skill Assessed
A8: Date (dd/mm/yy) | B8: Yr_Lev | C8: HG | D8: Surname | E8: First_Name | F8: Student_ID | G8: Y | H8: Y | I8: Y | J8: Y | K8: Y | L8: Y | M8: Y | N8: Y | O8: Y | P8: Y | Q8: Y | R8: Y | S8: Y | T8: Y | U8: Y | V8: Y | W8: Y | X8: Y | Y8: Y | Z8: Raw Score | AA8: TORCH Score
A9: 45356 | B9: 3 | C9: 3A | D9: Lname1 | E9: Fname1 | F9: XXXXX1 | Z9: =IF(D9="",0,COUNTIF(G9:Y9,"Y")) -> 0 | AA9: =IF(D9="","",VLOOKUP(Z9,TORCH_Tables!$A$3:$B$29,2,FALSE)) -> 1.6
A10: 45356 | B10: 3 | C10: 3A | D10: Lname2 | E10: Fname2 | F10: XXXXX2 | Z10: =IF(D10="",0,COUNTIF(G10:Y10,"Y")) -> 0 | AA10: =IF(D10="","",VLOOKUP(Z10,TORCH_Tables!$A$3:$B$29,2,FALSE)) -> 1.6
A11: 45356 | B11: 3 | C11: 3A | D11: Lname3 | E11: Fname3 | F11: XXXXX3 | Z11: =IF(D11="",0,COUNTIF(G11:Y11,"Y")) -> 0 | AA11: =IF(D11="","",VLOOKUP(Z11,TORCH_Tables!$A$3:$B$29,2,FALSE)) -> 1.6
A12: 45356 | B12: 3 | C12: 3A | D12: Lname4 | E12: Fname4 | F12: XXXXX4 | Z12: =IF(D12="",0,COUNTIF(G12:Y12,"Y")) -> 0 | AA12: =IF(D12="","",VLOOKUP(Z12,TORCH_Tables!$A$3:$B$29,2,FALSE)) -> 1.6
A13: 45356 | B13: 3 | C13: 3B | D13: ULname13 | E13: UFname13 | F13: UNLISTED | Z13: =IF(D13="",0,COUNTIF(G13:Y13,"Y")) -> 0 | AA13: =IF(D13="","",VLOOKUP(Z13,TORCH_Tables!$A$3:$B$29,2,FALSE)) -> 1.6
A14: 45356 | B14: 3 | C14: 3A | D14: Lname5 | E14: Fname5 | F14: XXXXX5 | Z14: =IF(D14="",0,COUNTIF(G14:Y14,"Y")) -> 0 | AA14: =IF(D14="","",VLOOKUP(Z14,TORCH_Tables!$A$3:$B$29,2,FALSE)) -> 1.6
A15: 45356 | B15: 3 | C15: 3B | D15: Lname6 | E15: Fname6 | F15: XXXXX6 | Z15: =IF(D15="",0,COUNTIF(G15:Y15,"Y")) -> 0 | AA15: =IF(D15="","",VLOOKUP(Z15,TORCH_Tables!$A$3:$B$29,2,FALSE)) -> 1.6
A16: 45356 | B16: 3 | C16: 3B | D16: Lname7 | E16: Fname7 | F16: XXXXX7 | Z16: =IF(D16="",0,COUNTIF(G16:Y16,"Y")) -> 0 | AA16: =IF(D16="","",VLOOKUP(Z16,TORCH_Tables!$A$3:$B$29,2,FALSE)) -> 1.6
A17: 45356 | B17: 3 | C17: 3B | D17: Lname8 | E17: Fname8 | F17: XXXXX8 | Z17: =IF(D17="",0,COUNTIF(G17:Y17,"Y")) -> 0 | AA17: =IF(D17="","",VLOOKUP(Z17,TORCH_Tables!$A$3:$B$29,2,FALSE)) -> 1.6
A18: 45356 | B18: 3 | C18: 3B | D18: Lname9 | E18: Fname9 | F18: XXXXX9 | Z18: =IF(D18="",0,COUNTIF(G18:Y18,"Y")) -> 0 | AA18: =IF(D18="","",VLOOKUP(Z18,TORCH_Tables!$A$3:$B$29,2,FALSE)) -> 1.6
A19: 45356 | B19: 3 | C19: 3B | D19: Lname10 | E19: Fname10 | F19: XXXXX10 | Z19: =IF(D19="",0,COUNTIF(G19:Y19,"Y")) -> 0 | AA19: =IF(D19="","",VLOOKUP(Z19,TORCH_Tables!$A$3:$B$29,2,FALSE)) -> 1.6
Z20: =IF(D20="",0,COUNTIF(G20:Y20,"Y")) -> 0 | AA20: =IF(D20="","",VLOOKUP(Z20,TORCH_Tables!$A$3:$B$29,2,FALSE))
Z21: =IF(D21="",0,COUNTIF(G21:Y21,"Y")) -> 0 | AA21: =IF(D21="","",VLOOKUP(Z21,TORCH_Tables!$A$3:$B$29,2,FALSE))
Z22: =IF(D22="",0,COUNTIF(G22:Y22,"Y")) -> 0 | AA22: =IF(D22="","",VLOOKUP(Z22,TORCH_Tables!$A$3:$B$29,2,FALSE))
Z23: =IF(D23="",0,COUNTIF(G23:Y23,"Y")) -> 0 | AA23: =IF(D23="","",VLOOKUP(Z23,TORCH_Tables!$A$3:$B$29,2,FALSE))
Z24: =IF(D24="",0,COUNTIF(G24:Y24,"Y")) -> 0 | AA24: =IF(D24="","",VLOOKUP(Z24,TORCH_Tables!$A$3:$B$29,2,FALSE))
Z25: =IF(D25="",0,COUNTIF(G25:Y25,"Y")) -> 0 | AA25: =IF(D25="","",VLOOKUP(Z25,TORCH_Tables!$A$3:$B$29,2,FALSE))
Z26: =IF(D26="",0,COUNTIF(G26:Y26,"Y")) -> 0 | AA26: =IF(D26="","",VLOOKUP(Z26,TORCH_Tables!$A$3:$B$29,2,FALSE))
Z27: =IF(D27="",0,COUNTIF(G27:Y27,"Y")) -> 0 | AA27: =IF(D27="","",VLOOKUP(Z27,TORCH_Tables!$A$3:$B$29,2,FALSE))
Z28: =IF(D28="",0,COUNTIF(G28:Y28,"Y")) -> 0 | AA28: =IF(D28="","",VLOOKUP(Z28,TORCH_Tables!$A$3:$B$29,2,FALSE))
Z29: =IF(D29="",0,COUNTIF(G29:Y29,"Y")) -> 0 | AA29: =IF(D29="","",VLOOKUP(Z29,TORCH_Tables!$A$3:$B$29,2,FALSE))
Z30: =IF(D30="",0,COUNTIF(G30:Y30,"Y")) -> 0 | AA30: =IF(D30="","",VLOOKUP(Z30,TORCH_Tables!$A$3:$B$29,2,FALSE))
Z31: =IF(D31="",0,COUNTIF(G31:Y31,"Y")) -> 0 | AA31: =IF(D31="","",VLOOKUP(Z31,TORCH_Tables!$A$3:$B$29,2,FALSE))
... Z503: =IF(D503="",0,COUNTIF(G503:Y503,"Y")) -> 0 | AA503: =IF(D503="","",VLOOKUP(Z503,TORCH_Tables!$A$3:$B$29,2,FALSE))

Sheet Lizards
A1: TORCH - Lizards Love Eggs
G3: QUESTION No. and ANSWER KEY (Enter the student's response - "Y" if correct, "N" if incorrect)
E4: Question Number | G4: 1 | H4: 2 | I4: 3 | J4: 4 | K4: 5 | L4: 6 | M4: 7 | N4: 8 | O4: 9 | P4: 10 | Q4: 11 | R4: 12 | S4: 13 | T4: 14 | U4: 15 | V4: 16 | W4: 17 | X4: 18 | Y4: 19 | Z4: 20
E5: Item Difficulty
E6: Skill Assessed
A8: Date (dd/mm/yy) | B8: Yr_Lev | C8: HG | D8: Surname | E8: First_Name | F8: Student_ID | G8: Y | H8: Y | I8: Y | J8: Y | K8: Y | L8: Y | M8: Y | N8: Y | O8: Y | P8: Y | Q8: Y | R8: Y | S8: Y | T8: Y | U8: Y | V8: Y | W8: Y | X8: Y | Y8: Y | Z8: Y | AA8: Raw Score | AB8: TORCH Score
A9: 45356 | B9: 3 | C9: 3A | D9: Lname1 | E9: Fname1 | F9: XXXXX1 | AA9: =IF(D9="",0,COUNTIF(G9:Z9,"Y")) -> 0 | AB9: =IF(D9="","",VLOOKUP(AA9,TORCH_Tables!$C$3:$D$29,2,FALSE)) -> 1.6
A10: 45356 | B10: 3 | C10: 3A | D10: Lname2 | E10: Fname2 | F10: XXXXX2 | AA10: =IF(D10="",0,COUNTIF(G10:Z10,"Y")) -> 0 | AB10: =IF(D10="","",VLOOKUP(AA10,TORCH_Tables!$C$3:$D$29,2,FALSE)) -> 1.6
A11: 45356 | B11: 3 | C11: 3A | D11: Lname3 | E11: Fname3 | F11: XXXXX3 | AA11: =IF(D11="",0,COUNTIF(G11:Z11,"Y")) -> 0 | AB11: =IF(D11="","",VLOOKUP(AA11,TORCH_Tables!$C$3:$D$29,2,FALSE)) -> 1.6
A12: 45356 | B12: 3 | C12: 3A | D12: Lname4 | E12: Fname4 | F12: XXXXX4 | AA12: =IF(D12="",0,COUNTIF(G12:Z12,"Y")) -> 0 | AB12: =IF(D12="","",VLOOKUP(AA12,TORCH_Tables!$C$3:$D$29,2,FALSE)) -> 1.6
A13: 45356 | B13: 3 | C13: 3B | D13: ULname13 | E13: UFname13 | F13: UNLISTED | AA13: =IF(D13="",0,COUNTIF(G13:Z13,"Y")) -> 0 | AB13: =IF(D13="","",VLOOKUP(AA13,TORCH_Tables!$C$3:$D$29,2,FALSE)) -> 1.6
A14: 45356 | B14: 3 | C14: 3A | D14: Lname5 | E14: Fname5 | F14: XXXXX5 | AA14: =IF(D14="",0,COUNTIF(G14:Z14,"Y")) -> 0 | AB14: =IF(D14="","",VLOOKUP(AA14,TORCH_Tables!$C$3:$D$29,2,FALSE)) -> 1.6
A15: 45356 | B15: 3 | C15: 3B | D15: Lname6 | E15: Fname6 | F15: XXXXX6 | AA15: =IF(D15="",0,COUNTIF(G15:Z15,"Y")) -> 0 | AB15: =IF(D15="","",VLOOKUP(AA15,TORCH_Tables!$C$3:$D$29,2,FALSE)) -> 1.6
A16: 45356 | B16: 3 | C16: 3B | D16: Lname7 | E16: Fname7 | F16: XXXXX7 | AA16: =IF(D16="",0,COUNTIF(G16:Z16,"Y")) -> 0 | AB16: =IF(D16="","",VLOOKUP(AA16,TORCH_Tables!$C$3:$D$29,2,FALSE)) -> 1.6
A17: 45356 | B17: 3 | C17: 3B | D17: Lname8 | E17: Fname8 | F17: XXXXX8 | AA17: =IF(D17="",0,COUNTIF(G17:Z17,"Y")) -> 0 | AB17: =IF(D17="","",VLOOKUP(AA17,TORCH_Tables!$C$3:$D$29,2,FALSE)) -> 1.6
A18: 45356 | B18: 3 | C18: 3B | D18: Lname9 | E18: Fname9 | F18: XXXXX9 | AA18: =IF(D18="",0,COUNTIF(G18:Z18,"Y")) -> 0 | AB18: =IF(D18="","",VLOOKUP(AA18,TORCH_Tables!$C$3:$D$29,2,FALSE)) -> 1.6
A19: 45356 | B19: 3 | C19: 3B | D19: Lname10 | E19: Fname10 | F19: XXXXX10 | AA19: =IF(D19="",0,COUNTIF(G19:Z19,"Y")) -> 0 | AB19: =IF(D19="","",VLOOKUP(AA19,TORCH_Tables!$C$3:$D$29,2,FALSE)) -> 1.6
AA20: =IF(D20="",0,COUNTIF(G20:Z20,"Y")) -> 0 | AB20: =IF(D20="","",VLOOKUP(AA20,TORCH_Tables!$C$3:$D$29,2,FALSE))
AA21: =IF(D21="",0,COUNTIF(G21:Z21,"Y")) -> 0 | AB21: =IF(D21="","",VLOOKUP(AA21,TORCH_Tables!$C$3:$D$29,2,FALSE))
AA22: =IF(D22="",0,COUNTIF(G22:Z22,"Y")) -> 0 | AB22: =IF(D22="","",VLOOKUP(AA22,TORCH_Tables!$C$3:$D$29,2,FALSE))
AA23: =IF(D23="",0,COUNTIF(G23:Z23,"Y")) -> 0 | AB23: =IF(D23="","",VLOOKUP(AA23,TORCH_Tables!$C$3:$D$29,2,FALSE))
AA24: =IF(D24="",0,COUNTIF(G24:Z24,"Y")) -> 0 | AB24: =IF(D24="","",VLOOKUP(AA24,TORCH_Tables!$C$3:$D$29,2,FALSE))
AA25: =IF(D25="",0,COUNTIF(G25:Z25,"Y")) -> 0 | AB25: =IF(D25="","",VLOOKUP(AA25,TORCH_Tables!$C$3:$D$29,2,FALSE))
AA26: =IF(D26="",0,COUNTIF(G26:Z26,"Y")) -> 0 | AB26: =IF(D26="","",VLOOKUP(AA26,TORCH_Tables!$C$3:$D$29,2,FALSE))
AA27: =IF(D27="",0,COUNTIF(G27:Z27,"Y")) -> 0 | AB27: =IF(D27="","",VLOOKUP(AA27,TORCH_Tables!$C$3:$D$29,2,FALSE))
AA28: =IF(D28="",0,COUNTIF(G28:Z28,"Y")) -> 0 | AB28: =IF(D28="","",VLOOKUP(AA28,TORCH_Tables!$C$3:$D$29,2,FALSE))
AA29: =IF(D29="",0,COUNTIF(G29:Z29,"Y")) -> 0 | AB29: =IF(D29="","",VLOOKUP(AA29,TORCH_Tables!$C$3:$D$29,2,FALSE))
AA30: =IF(D30="",0,COUNTIF(G30:Z30,"Y")) -> 0 | AB30: =IF(D30="","",VLOOKUP(AA30,TORCH_Tables!$C$3:$D$29,2,FALSE))
AA31: =IF(D31="",0,COUNTIF(G31:Z31,"Y")) -> 0 | AB31: =IF(D31="","",VLOOKUP(AA31,TORCH_Tables!$C$3:$D$29,2,FALSE))
... AA503: =IF(D503="",0,COUNTIF(G503:Z503,"Y")) -> 0 | AB503: =IF(D503="","",VLOOKUP(AA503,TORCH_Tables!$C$3:$D$29,2,FALSE))

Sheet Dingo
A1: TORCH - Donna Dingo
G3: QUESTION No. and ANSWER KEY (Enter the student's response - "Y" if correct, "N" if incorrect)
E4: Question Number | G4: 1 | H4: 2 | I4: 3 | J4: 4 | K4: 5 | L4: 6 | M4: 7 | N4: 8 | O4: 9 | P4: 10 | Q4: 11 | R4: 12 | S4: 13 | T4: 14 | U4: 15 | V4: 16 | W4: 17 | X4: 18 | Y4: 19 | Z4: 20
E5: Item Difficulty
E6: Skill Assessed
A8: Date (dd/mm/yy) | B8: Yr_Lev | C8: HG | D8: Surname | E8: First_Name | F8: Student_ID | G8: Y | H8: Y | I8: Y | J8: Y | K8: Y | L8: Y | M8: Y | N8: Y | O8: Y | P8: Y | Q8: Y | R8: Y | S8: Y | T8: Y | U8: Y | V8: Y | W8: Y | X8: Y | Y8: Y | Z8: Y | AA8: Raw Score | AB8: TORCH Score
A9: 45356 | B9: 3 | C9: 3A | D9: Lname1 | E9: Fname1 | F9: XXXXX1 | AA9: =IF(D9="",0,COUNTIF(G9:Z9,"Y")) -> 0 | AB9: =IF(D9="","",VLOOKUP(AA9,TORCH_Tables!$I$3:$J$29,2,FALSE)) -> 7.2
A10: 45356 | B10: 3 | C10: 3A | D10: Lname2 | E10: Fname2 | F10: XXXXX2 | AA10: =IF(D10="",0,COUNTIF(G10:Z10,"Y")) -> 0 | AB10: =IF(D10="","",VLOOKUP(AA10,TORCH_Tables!$I$3:$J$29,2,FALSE)) -> 7.2
A11: 45356 | B11: 3 | C11: 3A | D11: Lname3 | E11: Fname3 | F11: XXXXX3 | AA11: =IF(D11="",0,COUNTIF(G11:Z11,"Y")) -> 0 | AB11: =IF(D11="","",VLOOKUP(AA11,TORCH_Tables!$I$3:$J$29,2,FALSE)) -> 7.2
A12: 45356 | B12: 3 | C12: 3A | D12: Lname4 | E12: Fname4 | F12: XXXXX4 | AA12: =IF(D12="",0,COUNTIF(G12:Z12,"Y")) -> 0 | AB12: =IF(D12="","",VLOOKUP(AA12,TORCH_Tables!$I$3:$J$29,2,FALSE)) -> 7.2
A13: 45356 | B13: 3 | C13: 3B | D13: ULname13 | E13: UFname13 | F13: UNLISTED | AA13: =IF(D13="",0,COUNTIF(G13:Z13,"Y")) -> 0 | AB13: =IF(D13="","",VLOOKUP(AA13,TORCH_Tables!$I$3:$J$29,2,FALSE)) -> 7.2
A14: 45356 | B14: 3 | C14: 3A | D14: Lname5 | E14: Fname5 | F14: XXXXX5 | AA14: =IF(D14="",0,COUNTIF(G14:Z14,"Y")) -> 0 | AB14: =IF(D14="","",VLOOKUP(AA14,TORCH_Tables!$I$3:$J$29,2,FALSE)) -> 7.2
A15: 45356 | B15: 3 | C15: 3B | D15: Lname6 | E15: Fname6 | F15: XXXXX6 | AA15: =IF(D15="",0,COUNTIF(G15:Z15,"Y")) -> 0 | AB15: =IF(D15="","",VLOOKUP(AA15,TORCH_Tables!$I$3:$J$29,2,FALSE)) -> 7.2
A16: 45356 | B16: 3 | C16: 3B | D16: Lname7 | E16: Fname7 | F16: XXXXX7 | AA16: =IF(D16="",0,COUNTIF(G16:Z16,"Y")) -> 0 | AB16: =IF(D16="","",VLOOKUP(AA16,TORCH_Tables!$I$3:$J$29,2,FALSE)) -> 7.2
A17: 45356 | B17: 3 | C17: 3B | D17: Lname8 | E17: Fname8 | F17: XXXXX8 | AA17: =IF(D17="",0,COUNTIF(G17:Z17,"Y")) -> 0 | AB17: =IF(D17="","",VLOOKUP(AA17,TORCH_Tables!$I$3:$J$29,2,FALSE)) -> 7.2
A18: 45356 | B18: 3 | C18: 3B | D18: Lname9 | E18: Fname9 | F18: XXXXX9 | AA18: =IF(D18="",0,COUNTIF(G18:Z18,"Y")) -> 0 | AB18: =IF(D18="","",VLOOKUP(AA18,TORCH_Tables!$I$3:$J$29,2,FALSE)) -> 7.2
A19: 45356 | B19: 3 | C19: 3B | D19: Lname10 | E19: Fname10 | F19: XXXXX10 | AA19: =IF(D19="",0,COUNTIF(G19:Z19,"Y")) -> 0 | AB19: =IF(D19="","",VLOOKUP(AA19,TORCH_Tables!$I$3:$J$29,2,FALSE)) -> 7.2
AA20: =IF(D20="",0,COUNTIF(G20:Z20,"Y")) -> 0 | AB20: =IF(D20="","",VLOOKUP(AA20,TORCH_Tables!$I$3:$J$29,2,FALSE))
AA21: =IF(D21="",0,COUNTIF(G21:Z21,"Y")) -> 0 | AB21: =IF(D21="","",VLOOKUP(AA21,TORCH_Tables!$I$3:$J$29,2,FALSE))
AA22: =IF(D22="",0,COUNTIF(G22:Z22,"Y")) -> 0 | AB22: =IF(D22="","",VLOOKUP(AA22,TORCH_Tables!$I$3:$J$29,2,FALSE))
AA23: =IF(D23="",0,COUNTIF(G23:Z23,"Y")) -> 0 | AB23: =IF(D23="","",VLOOKUP(AA23,TORCH_Tables!$I$3:$J$29,2,FALSE))
AA24: =IF(D24="",0,COUNTIF(G24:Z24,"Y")) -> 0 | AB24: =IF(D24="","",VLOOKUP(AA24,TORCH_Tables!$I$3:$J$29,2,FALSE))
AA25: =IF(D25="",0,COUNTIF(G25:Z25,"Y")) -> 0 | AB25: =IF(D25="","",VLOOKUP(AA25,TORCH_Tables!$I$3:$J$29,2,FALSE))
AA26: =IF(D26="",0,COUNTIF(G26:Z26,"Y")) -> 0 | AB26: =IF(D26="","",VLOOKUP(AA26,TORCH_Tables!$I$3:$J$29,2,FALSE))
AA27: =IF(D27="",0,COUNTIF(G27:Z27,"Y")) -> 0 | AB27: =IF(D27="","",VLOOKUP(AA27,TORCH_Tables!$I$3:$J$29,2,FALSE))
AA28: =IF(D28="",0,COUNTIF(G28:Z28,"Y")) -> 0 | AB28: =IF(D28="","",VLOOKUP(AA28,TORCH_Tables!$I$3:$J$29,2,FALSE))
AA29: =IF(D29="",0,COUNTIF(G29:Z29,"Y")) -> 0 | AB29: =IF(D29="","",VLOOKUP(AA29,TORCH_Tables!$I$3:$J$29,2,FALSE))
AA30: =IF(D30="",0,COUNTIF(G30:Z30,"Y")) -> 0 | AB30: =IF(D30="","",VLOOKUP(AA30,TORCH_Tables!$I$3:$J$29,2,FALSE))
AA31: =IF(D31="",0,COUNTIF(G31:Z31,"Y")) -> 0 | AB31: =IF(D31="","",VLOOKUP(AA31,TORCH_Tables!$I$3:$J$29,2,FALSE))
... AA503: =IF(D503="",0,COUNTIF(G503:Z503,"Y")) -> 0 | AB503: =IF(D503="","",VLOOKUP(AA503,TORCH_Tables!$I$3:$J$29,2,FALSE))

Sheet Zoo
A1: TORCH - At the Zoo
G3: QUESTION No. and ANSWER KEY (Enter the student's response - "Y" if correct, "N" if incorrect)
E4: Question Number | G4: 1 | H4: 2 | I4: 3 | J4: 4 | K4: 5 | L4: 6 | M4: 7 | N4: 8 | O4: 9 | P4: 10 | Q4: 11 | R4: 12 | S4: 13 | T4: 14 | U4: 15 | V4: 16 | W4: 17 | X4: 18 | Y4: 19 | Z4: 20
E5: Item Difficulty
E6: Skill Assessed
A8: Date (dd/mm/yy) | B8: Yr_Lev | C8: HG | D8: Surname | E8: First_Name | F8: Student_ID | G8: Y | H8: Y | I8: Y | J8: Y | K8: Y | L8: Y | M8: Y | N8: Y | O8: Y | P8: Y | Q8: Y | R8: Y | S8: Y | T8: Y | U8: Y | V8: Y | W8: Y | X8: Y | Y8: Y | Z8: Y | AA8: Raw Score | AB8: TORCH Score
A9: 45356 | B9: 3 | C9: 3A | D9: Lname1 | E9: Fname1 | F9: XXXXX1 | AA9: =IF(D9="",0,COUNTIF(G9:Z9,"Y")) -> 0 | AB9: =IF(D9="","",VLOOKUP(AA9,TORCH_Tables!$E$3:$F$29,2,FALSE)) -> 5.6
A10: 45356 | B10: 3 | C10: 3A | D10: Lname2 | E10: Fname2 | F10: XXXXX2 | AA10: =IF(D10="",0,COUNTIF(G10:Z10,"Y")) -> 0 | AB10: =IF(D10="","",VLOOKUP(AA10,TORCH_Tables!$E$3:$F$29,2,FALSE)) -> 5.6
A11: 45356 | B11: 3 | C11: 3A | D11: Lname3 | E11: Fname3 | F11: XXXXX3 | AA11: =IF(D11="",0,COUNTIF(G11:Z11,"Y")) -> 0 | AB11: =IF(D11="","",VLOOKUP(AA11,TORCH_Tables!$E$3:$F$29,2,FALSE)) -> 5.6
A12: 45356 | B12: 3 | C12: 3A | D12: Lname4 | E12: Fname4 | F12: XXXXX4 | AA12: =IF(D12="",0,COUNTIF(G12:Z12,"Y")) -> 0 | AB12: =IF(D12="","",VLOOKUP(AA12,TORCH_Tables!$E$3:$F$29,2,FALSE)) -> 5.6
A13: 45356 | B13: 3 | C13: 3B | D13: ULname13 | E13: UFname13 | F13: UNLISTED | AA13: =IF(D13="",0,COUNTIF(G13:Z13,"Y")) -> 0 | AB13: =IF(D13="","",VLOOKUP(AA13,TORCH_Tables!$E$3:$F$29,2,FALSE)) -> 5.6
A14: 45356 | B14: 3 | C14: 3A | D14: Lname5 | E14: Fname5 | F14: XXXXX5 | AA14: =IF(D14="",0,COUNTIF(G14:Z14,"Y")) -> 0 | AB14: =IF(D14="","",VLOOKUP(AA14,TORCH_Tables!$E$3:$F$29,2,FALSE)) -> 5.6
A15: 45356 | B15: 3 | C15: 3B | D15: Lname6 | E15: Fname6 | F15: XXXXX6 | AA15: =IF(D15="",0,COUNTIF(G15:Z15,"Y")) -> 0 | AB15: =IF(D15="","",VLOOKUP(AA15,TORCH_Tables!$E$3:$F$29,2,FALSE)) -> 5.6
A16: 45356 | B16: 3 | C16: 3B | D16: Lname7 | E16: Fname7 | F16: XXXXX7 | AA16: =IF(D16="",0,COUNTIF(G16:Z16,"Y")) -> 0 | AB16: =IF(D16="","",VLOOKUP(AA16,TORCH_Tables!$E$3:$F$29,2,FALSE)) -> 5.6
A17: 45356 | B17: 3 | C17: 3B | D17: Lname8 | E17: Fname8 | F17: XXXXX8 | AA17: =IF(D17="",0,COUNTIF(G17:Z17,"Y")) -> 0 | AB17: =IF(D17="","",VLOOKUP(AA17,TORCH_Tables!$E$3:$F$29,2,FALSE)) -> 5.6
A18: 45356 | B18: 3 | C18: 3B | D18: Lname9 | E18: Fname9 | F18: XXXXX9 | AA18: =IF(D18="",0,COUNTIF(G18:Z18,"Y")) -> 0 | AB18: =IF(D18="","",VLOOKUP(AA18,TORCH_Tables!$E$3:$F$29,2,FALSE)) -> 5.6
A19: 45356 | B19: 3 | C19: 3B | D19: Lname10 | E19: Fname10 | F19: XXXXX10 | AA19: =IF(D19="",0,COUNTIF(G19:Z19,"Y")) -> 0 | AB19: =IF(D19="","",VLOOKUP(AA19,TORCH_Tables!$E$3:$F$29,2,FALSE)) -> 5.6
AA20: =IF(D20="",0,COUNTIF(G20:Z20,"Y")) -> 0 | AB20: =IF(D20="","",VLOOKUP(AA20,TORCH_Tables!$E$3:$F$29,2,FALSE))
AA21: =IF(D21="",0,COUNTIF(G21:Z21,"Y")) -> 0 | AB21: =IF(D21="","",VLOOKUP(AA21,TORCH_Tables!$E$3:$F$29,2,FALSE))
AA22: =IF(D22="",0,COUNTIF(G22:Z22,"Y")) -> 0 | AB22: =IF(D22="","",VLOOKUP(AA22,TORCH_Tables!$E$3:$F$29,2,FALSE))
AA23: =IF(D23="",0,COUNTIF(G23:Z23,"Y")) -> 0 | AB23: =IF(D23="","",VLOOKUP(AA23,TORCH_Tables!$E$3:$F$29,2,FALSE))
AA24: =IF(D24="",0,COUNTIF(G24:Z24,"Y")) -> 0 | AB24: =IF(D24="","",VLOOKUP(AA24,TORCH_Tables!$E$3:$F$29,2,FALSE))
AA25: =IF(D25="",0,COUNTIF(G25:Z25,"Y")) -> 0 | AB25: =IF(D25="","",VLOOKUP(AA25,TORCH_Tables!$E$3:$F$29,2,FALSE))
AA26: =IF(D26="",0,COUNTIF(G26:Z26,"Y")) -> 0 | AB26: =IF(D26="","",VLOOKUP(AA26,TORCH_Tables!$E$3:$F$29,2,FALSE))
AA27: =IF(D27="",0,COUNTIF(G27:Z27,"Y")) -> 0 | AB27: =IF(D27="","",VLOOKUP(AA27,TORCH_Tables!$E$3:$F$29,2,FALSE))
AA28: =IF(D28="",0,COUNTIF(G28:Z28,"Y")) -> 0 | AB28: =IF(D28="","",VLOOKUP(AA28,TORCH_Tables!$E$3:$F$29,2,FALSE))
AA29: =IF(D29="",0,COUNTIF(G29:Z29,"Y")) -> 0 | AB29: =IF(D29="","",VLOOKUP(AA29,TORCH_Tables!$E$3:$F$29,2,FALSE))
AA30: =IF(D30="",0,COUNTIF(G30:Z30,"Y")) -> 0 | AB30: =IF(D30="","",VLOOKUP(AA30,TORCH_Tables!$E$3:$F$29,2,FALSE))
AA31: =IF(D31="",0,COUNTIF(G31:Z31,"Y")) -> 0 | AB31: =IF(D31="","",VLOOKUP(AA31,TORCH_Tables!$E$3:$F$29,2,FALSE))
... AA503: =IF(D503="",0,COUNTIF(G503:Z503,"Y")) -> 0 | AB503: =IF(D503="","",VLOOKUP(AA503,TORCH_Tables!$E$3:$F$29,2,FALSE))

Sheet Puff
A1: TORCH - Feeding Puff
G3: QUESTION No. and ANSWER KEY (Enter the student's response - "Y" if correct, "N" if incorrect)
E4: Question Number | G4: 1 | H4: 2 | I4: 3 | J4: 4 | K4: 5 | L4: 6 | M4: 7 | N4: 8 | O4: 9 | P4: 10 | Q4: 11 | R4: 12 | S4: 13 | T4: 14 | U4: 15 | V4: 16 | W4: 17 | X4: 18 | Y4: 19 | Z4: 20 | AA4: 21 | AB4: 22
E5: Item Difficulty
E6: Skill Assessed
A8: Date (dd/mm/yy) | B8: Yr_Lev | C8: HG | D8: Surname | E8: First_Name | F8: Student_ID | G8: Y | H8: Y | I8: Y | J8: Y | K8: Y | L8: Y | M8: Y | N8: Y | O8: Y | P8: Y | Q8: Y | R8: Y | S8: Y | T8: Y | U8: Y | V8: Y | W8: Y | X8: Y | Y8: Y | Z8: Y | AA8: Y | AB8: Y | AC8: Raw Score | AD8: TORCH Score
A9: 45356 | B9: 3 | C9: 3A | D9: Lname1 | E9: Fname1 | F9: XXXXX1 | AC9: =IF(D9="",0,COUNTIF(G9:AB9,"Y")) -> 0 | AD9: =IF(D9="","",VLOOKUP(AC9,TORCH_Tables!$G$3:$H$29,2,FALSE)) -> 9.3
A10: 45356 | B10: 3 | C10: 3A | D10: Lname2 | E10: Fname2 | F10: XXXXX2 | AC10: =IF(D10="",0,COUNTIF(G10:AB10,"Y")) -> 0 | AD10: =IF(D10="","",VLOOKUP(AC10,TORCH_Tables!$G$3:$H$29,2,FALSE)) -> 9.3
A11: 45356 | B11: 3 | C11: 3A | D11: Lname3 | E11: Fname3 | F11: XXXXX3 | AC11: =IF(D11="",0,COUNTIF(G11:AB11,"Y")) -> 0 | AD11: =IF(D11="","",VLOOKUP(AC11,TORCH_Tables!$G$3:$H$29,2,FALSE)) -> 9.3
A12: 45356 | B12: 3 | C12: 3A | D12: Lname4 | E12: Fname4 | F12: XXXXX4 | AC12: =IF(D12="",0,COUNTIF(G12:AB12,"Y")) -> 0 | AD12: =IF(D12="","",VLOOKUP(AC12,TORCH_Tables!$G$3:$H$29,2,FALSE)) -> 9.3
A13: 45356 | B13: 3 | C13: 3B | D13: ULname13 | E13: UFname13 | F13: UNLISTED | AC13: =IF(D13="",0,COUNTIF(G13:AB13,"Y")) -> 0 | AD13: =IF(D13="","",VLOOKUP(AC13,TORCH_Tables!$G$3:$H$29,2,FALSE)) -> 9.3
A14: 45356 | B14: 3 | C14: 3A | D14: Lname5 | E14: Fname5 | F14: XXXXX5 | AC14: =IF(D14="",0,COUNTIF(G14:AB14,"Y")) -> 0 | AD14: =IF(D14="","",VLOOKUP(AC14,TORCH_Tables!$G$3:$H$29,2,FALSE)) -> 9.3
A15: 45356 | B15: 3 | C15: 3B | D15: Lname6 | E15: Fname6 | F15: XXXXX6 | AC15: =IF(D15="",0,COUNTIF(G15:AB15,"Y")) -> 0 | AD15: =IF(D15="","",VLOOKUP(AC15,TORCH_Tables!$G$3:$H$29,2,FALSE)) -> 9.3
A16: 45356 | B16: 3 | C16: 3B | D16: Lname7 | E16: Fname7 | F16: XXXXX7 | AC16: =IF(D16="",0,COUNTIF(G16:AB16,"Y")) -> 0 | AD16: =IF(D16="","",VLOOKUP(AC16,TORCH_Tables!$G$3:$H$29,2,FALSE)) -> 9.3
A17: 45356 | B17: 3 | C17: 3B | D17: Lname8 | E17: Fname8 | F17: XXXXX8 | AC17: =IF(D17="",0,COUNTIF(G17:AB17,"Y")) -> 0 | AD17: =IF(D17="","",VLOOKUP(AC17,TORCH_Tables!$G$3:$H$29,2,FALSE)) -> 9.3
A18: 45356 | B18: 3 | C18: 3B | D18: Lname9 | E18: Fname9 | F18: XXXXX9 | AC18: =IF(D18="",0,COUNTIF(G18:AB18,"Y")) -> 0 | AD18: =IF(D18="","",VLOOKUP(AC18,TORCH_Tables!$G$3:$H$29,2,FALSE)) -> 9.3
A19: 45356 | B19: 3 | C19: 3B | D19: Lname10 | E19: Fname10 | F19: XXXXX10 | AC19: =IF(D19="",0,COUNTIF(G19:AB19,"Y")) -> 0 | AD19: =IF(D19="","",VLOOKUP(AC19,TORCH_Tables!$G$3:$H$29,2,FALSE)) -> 9.3
AC20: =IF(D20="",0,COUNTIF(G20:AB20,"Y")) -> 0 | AD20: =IF(D20="","",VLOOKUP(AC20,TORCH_Tables!$G$3:$H$29,2,FALSE))
AC21: =IF(D21="",0,COUNTIF(G21:AB21,"Y")) -> 0 | AD21: =IF(D21="","",VLOOKUP(AC21,TORCH_Tables!$G$3:$H$29,2,FALSE))
AC22: =IF(D22="",0,COUNTIF(G22:AB22,"Y")) -> 0 | AD22: =IF(D22="","",VLOOKUP(AC22,TORCH_Tables!$G$3:$H$29,2,FALSE))
AC23: =IF(D23="",0,COUNTIF(G23:AB23,"Y")) -> 0 | AD23: =IF(D23="","",VLOOKUP(AC23,TORCH_Tables!$G$3:$H$29,2,FALSE))
AC24: =IF(D24="",0,COUNTIF(G24:AB24,"Y")) -> 0 | AD24: =IF(D24="","",VLOOKUP(AC24,TORCH_Tables!$G$3:$H$29,2,FALSE))
AC25: =IF(D25="",0,COUNTIF(G25:AB25,"Y")) -> 0 | AD25: =IF(D25="","",VLOOKUP(AC25,TORCH_Tables!$G$3:$H$29,2,FALSE))
AC26: =IF(D26="",0,COUNTIF(G26:AB26,"Y")) -> 0 | AD26: =IF(D26="","",VLOOKUP(AC26,TORCH_Tables!$G$3:$H$29,2,FALSE))
AC27: =IF(D27="",0,COUNTIF(G27:AB27,"Y")) -> 0 | AD27: =IF(D27="","",VLOOKUP(AC27,TORCH_Tables!$G$3:$H$29,2,FALSE))
AC28: =IF(D28="",0,COUNTIF(G28:AB28,"Y")) -> 0 | AD28: =IF(D28="","",VLOOKUP(AC28,TORCH_Tables!$G$3:$H$29,2,FALSE))
AC29: =IF(D29="",0,COUNTIF(G29:AB29,"Y")) -> 0 | AD29: =IF(D29="","",VLOOKUP(AC29,TORCH_Tables!$G$3:$H$29,2,FALSE))
AC30: =IF(D30="",0,COUNTIF(G30:AB30,"Y")) -> 0 | AD30: =IF(D30="","",VLOOKUP(AC30,TORCH_Tables!$G$3:$H$29,2,FALSE))
AC31: =IF(D31="",0,COUNTIF(G31:AB31,"Y")) -> 0 | AD31: =IF(D31="","",VLOOKUP(AC31,TORCH_Tables!$G$3:$H$29,2,FALSE))
... AC503: =IF(D503="",0,COUNTIF(G503:AB503,"Y")) -> 0 | AD503: =IF(D503="","",VLOOKUP(AC503,TORCH_Tables!$G$3:$H$29,2,FALSE))

Sheet Cats
A1: TORCH - The Cats
G3: QUESTION No. and ANSWER KEY (Enter the student's response - "Y" if correct, "N" if incorrect)
E4: Question Number | G4: 1 | H4: 2 | I4: 3 | J4: 4 | K4: 5 | L4: 6 | M4: 7 | N4: 8 | O4: 9 | P4: 10 | Q4: 11 | R4: 12 | S4: 13 | T4: 14 | U4: 15 | V4: 16 | W4: 17 | X4: 18 | Y4: 19 | Z4: 20
E5: Item Difficulty
E6: Skill Assessed
A8: Date (dd/mm/yy) | B8: Yr_Lev | C8: HG | D8: Surname | E8: First_Name | F8: Student_ID | G8: Y | H8: Y | I8: Y | J8: Y | K8: Y | L8: Y | M8: Y | N8: Y | O8: Y | P8: Y | Q8: Y | R8: Y | S8: Y | T8: Y | U8: Y | V8: Y | W8: Y | X8: Y | Y8: Y | Z8: Y | AA8: Raw Score | AB8: TORCH Score
AA9: =IF(D9="",0,COUNTIF(G9:Z9,"Y")) -> 0 | AB9: =IF(D9="","",VLOOKUP(AA9,TORCH_Tables!$K$3:$L$29,2,FALSE))
AA10: =IF(D10="",0,COUNTIF(G10:Z10,"Y")) -> 0 | AB10: =IF(D10="","",VLOOKUP(AA10,TORCH_Tables!$K$3:$L$29,2,FALSE))
AA11: =IF(D11="",0,COUNTIF(G11:Z11,"Y")) -> 0 | AB11: =IF(D11="","",VLOOKUP(AA11,TORCH_Tables!$K$3:$L$29,2,FALSE))
AA12: =IF(D12="",0,COUNTIF(G12:Z12,"Y")) -> 0 | AB12: =IF(D12="","",VLOOKUP(AA12,TORCH_Tables!$K$3:$L$29,2,FALSE))
AA13: =IF(D13="",0,COUNTIF(G13:Z13,"Y")) -> 0 | AB13: =IF(D13="","",VLOOKUP(AA13,TORCH_Tables!$K$3:$L$29,2,FALSE))
AA14: =IF(D14="",0,COUNTIF(G14:Z14,"Y")) -> 0 | AB14: =IF(D14="","",VLOOKUP(AA14,TORCH_Tables!$K$3:$L$29,2,FALSE))
AA15: =IF(D15="",0,COUNTIF(G15:Z15,"Y")) -> 0 | AB15: =IF(D15="","",VLOOKUP(AA15,TORCH_Tables!$K$3:$L$29,2,FALSE))
AA16: =IF(D16="",0,COUNTIF(G16:Z16,"Y")) -> 0 | AB16: =IF(D16="","",VLOOKUP(AA16,TORCH_Tables!$K$3:$L$29,2,FALSE))
AA17: =IF(D17="",0,COUNTIF(G17:Z17,"Y")) -> 0 | AB17: =IF(D17="","",VLOOKUP(AA17,TORCH_Tables!$K$3:$L$29,2,FALSE))
AA18: =IF(D18="",0,COUNTIF(G18:Z18,"Y")) -> 0 | AB18: =IF(D18="","",VLOOKUP(AA18,TORCH_Tables!$K$3:$L$29,2,FALSE))
AA19: =IF(D19="",0,COUNTIF(G19:Z19,"Y")) -> 0 | AB19: =IF(D19="","",VLOOKUP(AA19,TORCH_Tables!$K$3:$L$29,2,FALSE))
AA20: =IF(D20="",0,COUNTIF(G20:Z20,"Y")) -> 0 | AB20: =IF(D20="","",VLOOKUP(AA20,TORCH_Tables!$K$3:$L$29,2,FALSE))
... AA503: =IF(D503="",0,COUNTIF(G503:Z503,"Y")) -> 0 | AB503: =IF(D503="","",VLOOKUP(AA503,TORCH_Tables!$K$3:$L$29,2,FALSE))

Sheet Swamp
A1: TORCH - The Swamp-Creature
G3: QUESTION No. and ANSWER KEY (Enter the student's response - "Y" if correct, "N" if incorrect)
E4: Question Number | G4: 1 | H4: 2 | I4: 3 | J4: 4 | K4: 5 | L4: 6 | M4: 7 | N4: 8 | O4: 9 | P4: 10 | Q4: 11 | R4: 12 | S4: 13 | T4: 14 | U4: 15 | V4: 16 | W4: 17 | X4: 18 | Y4: 19 | Z4: 20 | AA4: 21 | AB4: 22 | AC4: 23 | AD4: 24
E5: Item Difficulty
E6: Skill Assessed
A8: Date (dd/mm/yy) | B8: Yr_Lev | C8: HG | D8: Surname | E8: First_Name | F8: Student_ID | G8: Y | H8: Y | I8: Y | J8: Y | K8: Y | L8: Y | M8: Y | N8: Y | O8: Y | P8: Y | Q8: Y | R8: Y | S8: Y | T8: Y | U8: Y | V8: Y | W8: Y | X8: Y | Y8: Y | Z8: Y | AA8: Y | AB8: Y | AC8: Y | AD8: Y | AE8: Raw Score | AF8: TORCH Score
A9: 45356 | B9: 3 | C9: 3A | D9: Lname1 | E9: Fname1 | F9: XXXXX1 | AE9: =IF(D9="",0,COUNTIF(G9:AD9,"Y")) -> 0 | AF9: =IF(D9="","",VLOOKUP(AE9,TORCH_Tables!$M$3:$N$29,2,FALSE)) -> 13.1
A10: 45356 | B10: 3 | C10: 3A | D10: Lname2 | E10: Fname2 | F10: XXXXX2 | AE10: =IF(D10="",0,COUNTIF(G10:AD10,"Y")) -> 0 | AF10: =IF(D10="","",VLOOKUP(AE10,TORCH_Tables!$M$3:$N$29,2,FALSE)) -> 13.1
A11: 45356 | B11: 3 | C11: 3A | D11: Lname3 | E11: Fname3 | F11: XXXXX3 | AE11: =IF(D11="",0,COUNTIF(G11:AD11,"Y")) -> 0 | AF11: =IF(D11="","",VLOOKUP(AE11,TORCH_Tables!$M$3:$N$29,2,FALSE)) -> 13.1
A12: 45356 | B12: 3 | C12: 3A | D12: Lname4 | E12: Fname4 | F12: XXXXX4 | AE12: =IF(D12="",0,COUNTIF(G12:AD12,"Y")) -> 0 | AF12: =IF(D12="","",VLOOKUP(AE12,TORCH_Tables!$M$3:$N$29,2,FALSE)) -> 13.1
A13: 45356 | B13: 3 | C13: 3B | D13: ULname13 | E13: UFname13 | F13: UNLISTED | AE13: =IF(D13="",0,COUNTIF(G13:AD13,"Y")) -> 0 | AF13: =IF(D13="","",VLOOKUP(AE13,TORCH_Tables!$M$3:$N$29,2,FALSE)) -> 13.1
A14: 45356 | B14: 3 | C14: 3A | D14: Lname5 | E14: Fname5 | F14: XXXXX5 | AE14: =IF(D14="",0,COUNTIF(G14:AD14,"Y")) -> 0 | AF14: =IF(D14="","",VLOOKUP(AE14,TORCH_Tables!$M$3:$N$29,2,FALSE)) -> 13.1
A15: 45356 | B15: 3 | C15: 3B | D15: Lname6 | E15: Fname6 | F15: XXXXX6 | AE15: =IF(D15="",0,COUNTIF(G15:AD15,"Y")) -> 0 | AF15: =IF(D15="","",VLOOKUP(AE15,TORCH_Tables!$M$3:$N$29,2,FALSE)) -> 13.1
A16: 45356 | B16: 3 | C16: 3B | D16: Lname7 | E16: Fname7 | F16: XXXXX7 | AE16: =IF(D16="",0,COUNTIF(G16:AD16,"Y")) -> 0 | AF16: =IF(D16="","",VLOOKUP(AE16,TORCH_Tables!$M$3:$N$29,2,FALSE)) -> 13.1
A17: 45356 | B17: 3 | C17: 3B | D17: Lname8 | E17: Fname8 | F17: XXXXX8 | AE17: =IF(D17="",0,COUNTIF(G17:AD17,"Y")) -> 0 | AF17: =IF(D17="","",VLOOKUP(AE17,TORCH_Tables!$M$3:$N$29,2,FALSE)) -> 13.1
A18: 45356 | B18: 3 | C18: 3B | D18: Lname9 | E18: Fname9 | F18: XXXXX9 | AE18: =IF(D18="",0,COUNTIF(G18:AD18,"Y")) -> 0 | AF18: =IF(D18="","",VLOOKUP(AE18,TORCH_Tables!$M$3:$N$29,2,FALSE)) -> 13.1
A19: 45356 | B19: 3 | C19: 3B | D19: Lname10 | E19: Fname10 | F19: XXXXX10 | AE19: =IF(D19="",0,COUNTIF(G19:AD19,"Y")) -> 0 | AF19: =IF(D19="","",VLOOKUP(AE19,TORCH_Tables!$M$3:$N$29,2,FALSE)) -> 13.1
AE20: =IF(D20="",0,COUNTIF(G20:AD20,"Y")) -> 0 | AF20: =IF(D20="","",VLOOKUP(AE20,TORCH_Tables!$M$3:$N$29,2,FALSE))
AE21: =IF(D21="",0,COUNTIF(G21:AD21,"Y")) -> 0 | AF21: =IF(D21="","",VLOOKUP(AE21,TORCH_Tables!$M$3:$N$29,2,FALSE))
AE22: =IF(D22="",0,COUNTIF(G22:AD22,"Y")) -> 0 | AF22: =IF(D22="","",VLOOKUP(AE22,TORCH_Tables!$M$3:$N$29,2,FALSE))
AE23: =IF(D23="",0,COUNTIF(G23:AD23,"Y")) -> 0 | AF23: =IF(D23="","",VLOOKUP(AE23,TORCH_Tables!$M$3:$N$29,2,FALSE))
AE24: =IF(D24="",0,COUNTIF(G24:AD24,"Y")) -> 0 | AF24: =IF(D24="","",VLOOKUP(AE24,TORCH_Tables!$M$3:$N$29,2,FALSE))
AE25: =IF(D25="",0,COUNTIF(G25:AD25,"Y")) -> 0 | AF25: =IF(D25="","",VLOOKUP(AE25,TORCH_Tables!$M$3:$N$29,2,FALSE))
AE26: =IF(D26="",0,COUNTIF(G26:AD26,"Y")) -> 0 | AF26: =IF(D26="","",VLOOKUP(AE26,TORCH_Tables!$M$3:$N$29,2,FALSE))
AE27: =IF(D27="",0,COUNTIF(G27:AD27,"Y")) -> 0 | AF27: =IF(D27="","",VLOOKUP(AE27,TORCH_Tables!$M$3:$N$29,2,FALSE))
AE28: =IF(D28="",0,COUNTIF(G28:AD28,"Y")) -> 0 | AF28: =IF(D28="","",VLOOKUP(AE28,TORCH_Tables!$M$3:$N$29,2,FALSE))
AE29: =IF(D29="",0,COUNTIF(G29:AD29,"Y")) -> 0 | AF29: =IF(D29="","",VLOOKUP(AE29,TORCH_Tables!$M$3:$N$29,2,FALSE))
AE30: =IF(D30="",0,COUNTIF(G30:AD30,"Y")) -> 0 | AF30: =IF(D30="","",VLOOKUP(AE30,TORCH_Tables!$M$3:$N$29,2,FALSE))
AE31: =IF(D31="",0,COUNTIF(G31:AD31,"Y")) -> 0 | AF31: =IF(D31="","",VLOOKUP(AE31,TORCH_Tables!$M$3:$N$29,2,FALSE))
... AE503: =IF(D503="",0,COUNTIF(G503:AD503,"Y")) -> 0 | AF503: =IF(D503="","",VLOOKUP(AE503,TORCH_Tables!$M$3:$N$29,2,FALSE))

Sheet Matches
A1: TORCH - Matches
G3: QUESTION No. and ANSWER KEY (Enter the student's response - "Y" if correct, "N" if incorrect)
E4: Question Number | G4: 1 | H4: 2 | I4: 3 | J4: 4 | K4: 5 | L4: 6 | M4: 7 | N4: 8 | O4: 9 | P4: 10 | Q4: 11 | R4: 12 | S4: 13 | T4: 14 | U4: 15 | V4: 16 | W4: 17 | X4: 18 | Y4: 19
E5: Item Difficulty
E6: Skill Assessed
A8: Date (dd/mm/yy) | B8: Yr_Lev | C8: HG | D8: Surname | E8: First_Name | F8: Student_ID | G8: Y | H8: Y | I8: Y | J8: Y | K8: Y | L8: Y | M8: Y | N8: Y | O8: Y | P8: Y | Q8: Y | R8: Y | S8: Y | T8: Y | U8: Y | V8: Y | W8: Y | X8: Y | Y8: Y | Z8: Raw Score | AA8: TORCH Score
A9: 45356 | B9: 3 | C9: 3A | D9: Lname1 | E9: Fname1 | F9: XXXXX1 | Z9: =IF(D9="",0,COUNTIF(G9:Y9,"Y")) -> 0 | AA9: =IF(D9="","",VLOOKUP(Z9,TORCH_Tables!$O$3:$P$29,2,FALSE)) -> 19.3
A10: 45356 | B10: 3 | C10: 3A | D10: Lname2 | E10: Fname2 | F10: XXXXX2 | Z10: =IF(D10="",0,COUNTIF(G10:Y10,"Y")) -> 0 | AA10: =IF(D10="","",VLOOKUP(Z10,TORCH_Tables!$O$3:$P$29,2,FALSE)) -> 19.3
A11: 45356 | B11: 3 | C11: 3A | D11: Lname3 | E11: Fname3 | F11: XXXXX3 | Z11: =IF(D11="",0,COUNTIF(G11:Y11,"Y")) -> 0 | AA11: =IF(D11="","",VLOOKUP(Z11,TORCH_Tables!$O$3:$P$29,2,FALSE)) -> 19.3
A12: 45356 | B12: 3 | C12: 3A | D12: Lname4 | E12: Fname4 | F12: XXXXX4 | Z12: =IF(D12="",0,COUNTIF(G12:Y12,"Y")) -> 0 | AA12: =IF(D12="","",VLOOKUP(Z12,TORCH_Tables!$O$3:$P$29,2,FALSE)) -> 19.3
A13: 45356 | B13: 3 | C13: 3B | D13: ULname13 | E13: UFname13 | F13: UNLISTED | Z13: =IF(D13="",0,COUNTIF(G13:Y13,"Y")) -> 0 | AA13: =IF(D13="","",VLOOKUP(Z13,TORCH_Tables!$O$3:$P$29,2,FALSE)) -> 19.3
A14: 45356 | B14: 3 | C14: 3A | D14: Lname5 | E14: Fname5 | F14: XXXXX5 | Z14: =IF(D14="",0,COUNTIF(G14:Y14,"Y")) -> 0 | AA14: =IF(D14="","",VLOOKUP(Z14,TORCH_Tables!$O$3:$P$29,2,FALSE)) -> 19.3
A15: 45356 | B15: 3 | C15: 3B | D15: Lname6 | E15: Fname6 | F15: XXXXX6 | Z15: =IF(D15="",0,COUNTIF(G15:Y15,"Y")) -> 0 | AA15: =IF(D15="","",VLOOKUP(Z15,TORCH_Tables!$O$3:$P$29,2,FALSE)) -> 19.3
A16: 45356 | B16: 3 | C16: 3B | D16: Lname7 | E16: Fname7 | F16: XXXXX7 | Z16: =IF(D16="",0,COUNTIF(G16:Y16,"Y")) -> 0 | AA16: =IF(D16="","",VLOOKUP(Z16,TORCH_Tables!$O$3:$P$29,2,FALSE)) -> 19.3
A17: 45356 | B17: 3 | C17: 3B | D17: Lname8 | E17: Fname8 | F17: XXXXX8 | Z17: =IF(D17="",0,COUNTIF(G17:Y17,"Y")) -> 0 | AA17: =IF(D17="","",VLOOKUP(Z17,TORCH_Tables!$O$3:$P$29,2,FALSE)) -> 19.3
A18: 45356 | B18: 3 | C18: 3B | D18: Lname9 | E18: Fname9 | F18: XXXXX9 | Z18: =IF(D18="",0,COUNTIF(G18:Y18,"Y")) -> 0 | AA18: =IF(D18="","",VLOOKUP(Z18,TORCH_Tables!$O$3:$P$29,2,FALSE)) -> 19.3
A19: 45356 | B19: 3 | C19: 3B | D19: Lname10 | E19: Fname10 | F19: XXXXX10 | Z19: =IF(D19="",0,COUNTIF(G19:Y19,"Y")) -> 0 | AA19: =IF(D19="","",VLOOKUP(Z19,TORCH_Tables!$O$3:$P$29,2,FALSE)) -> 19.3
Z20: =IF(D20="",0,COUNTIF(G20:Y20,"Y")) -> 0 | AA20: =IF(D20="","",VLOOKUP(Z20,TORCH_Tables!$O$3:$P$29,2,FALSE))
Z21: =IF(D21="",0,COUNTIF(G21:Y21,"Y")) -> 0 | AA21: =IF(D21="","",VLOOKUP(Z21,TORCH_Tables!$O$3:$P$29,2,FALSE))
Z22: =IF(D22="",0,COUNTIF(G22:Y22,"Y")) -> 0 | AA22: =IF(D22="","",VLOOKUP(Z22,TORCH_Tables!$O$3:$P$29,2,FALSE))
Z23: =IF(D23="",0,COUNTIF(G23:Y23,"Y")) -> 0 | AA23: =IF(D23="","",VLOOKUP(Z23,TORCH_Tables!$O$3:$P$29,2,FALSE))
Z24: =IF(D24="",0,COUNTIF(G24:Y24,"Y")) -> 0 | AA24: =IF(D24="","",VLOOKUP(Z24,TORCH_Tables!$O$3:$P$29,2,FALSE))
Z25: =IF(D25="",0,COUNTIF(G25:Y25,"Y")) -> 0 | AA25: =IF(D25="","",VLOOKUP(Z25,TORCH_Tables!$O$3:$P$29,2,FALSE))
Z26: =IF(D26="",0,COUNTIF(G26:Y26,"Y")) -> 0 | AA26: =IF(D26="","",VLOOKUP(Z26,TORCH_Tables!$O$3:$P$29,2,FALSE))
Z27: =IF(D27="",0,COUNTIF(G27:Y27,"Y")) -> 0 | AA27: =IF(D27="","",VLOOKUP(Z27,TORCH_Tables!$O$3:$P$29,2,FALSE))
Z28: =IF(D28="",0,COUNTIF(G28:Y28,"Y")) -> 0 | AA28: =IF(D28="","",VLOOKUP(Z28,TORCH_Tables!$O$3:$P$29,2,FALSE))
Z29: =IF(D29="",0,COUNTIF(G29:Y29,"Y")) -> 0 | AA29: =IF(D29="","",VLOOKUP(Z29,TORCH_Tables!$O$3:$P$29,2,FALSE))
Z30: =IF(D30="",0,COUNTIF(G30:Y30,"Y")) -> 0 | AA30: =IF(D30="","",VLOOKUP(Z30,TORCH_Tables!$O$3:$P$29,2,FALSE))
Z31: =IF(D31="",0,COUNTIF(G31:Y31,"Y")) -> 0 | AA31: =IF(D31="","",VLOOKUP(Z31,TORCH_Tables!$O$3:$P$29,2,FALSE))
... Z503: =IF(D503="",0,COUNTIF(G503:Y503,"Y")) -> 0 | AA503: =IF(D503="","",VLOOKUP(Z503,TORCH_Tables!$O$3:$P$29,2,FALSE))

Sheet Crying
A1: TORCH - She's Crying
G3: QUESTION No. and ANSWER KEY (Enter the student's response - "Y" if correct, "N" if incorrect)
E4: Question Number | G4: 1 | H4: 2 | I4: 3 | J4: 4 | K4: 5 | L4: 6 | M4: 7 | N4: 8 | O4: 9 | P4: 10 | Q4: 11 | R4: 12 | S4: 13 | T4: 14 | U4: 15 | V4: 16 | W4: 17 | X4: 18 | Y4: 19 | Z4: 20 | AA4: 21 | AB4: 22
E5: Item Difficulty
E6: Skill Assessed
A8: Date (dd/mm/yy) | B8: Yr_Lev | C8: HG | D8: Surname | E8: First_Name | F8: Student_ID | G8: Y | H8: Y | I8: Y | J8: Y | K8: Y | L8: Y | M8: Y | N8: Y | O8: Y | P8: Y | Q8: Y | R8: Y | S8: Y | T8: Y | U8: Y | V8: Y | W8: Y | X8: Y | Y8: Y | Z8: Y | AA8: Y | AB8: Y | AC8: Raw Score | AD8: TORCH Score
A9: 45356 | B9: 3 | C9: 3A | D9: Lname1 | E9: Fname1 | F9: XXXXX1 | AC9: =IF(D9="",0,COUNTIF(G9:AB9,"Y")) -> 0 | AD9: =IF(D9="","",VLOOKUP(AC9,TORCH_Tables!$Q$3:$R$29,2,FALSE)) -> 16.4
A10: 45356 | B10: 3 | C10: 3A | D10: Lname2 | E10: Fname2 | F10: XXXXX2 | AC10: =IF(D10="",0,COUNTIF(G10:AB10,"Y")) -> 0 | AD10: =IF(D10="","",VLOOKUP(AC10,TORCH_Tables!$Q$3:$R$29,2,FALSE)) -> 16.4
A11: 45356 | B11: 3 | C11: 3A | D11: Lname3 | E11: Fname3 | F11: XXXXX3 | AC11: =IF(D11="",0,COUNTIF(G11:AB11,"Y")) -> 0 | AD11: =IF(D11="","",VLOOKUP(AC11,TORCH_Tables!$Q$3:$R$29,2,FALSE)) -> 16.4
A12: 45356 | B12: 3 | C12: 3A | D12: Lname4 | E12: Fname4 | F12: XXXXX4 | AC12: =IF(D12="",0,COUNTIF(G12:AB12,"Y")) -> 0 | AD12: =IF(D12="","",VLOOKUP(AC12,TORCH_Tables!$Q$3:$R$29,2,FALSE)) -> 16.4
A13: 45356 | B13: 3 | C13: 3B | D13: ULname13 | E13: UFname13 | F13: UNLISTED | AC13: =IF(D13="",0,COUNTIF(G13:AB13,"Y")) -> 0 | AD13: =IF(D13="","",VLOOKUP(AC13,TORCH_Tables!$Q$3:$R$29,2,FALSE)) -> 16.4
A14: 45356 | B14: 3 | C14: 3A | D14: Lname5 | E14: Fname5 | F14: XXXXX5 | AC14: =IF(D14="",0,COUNTIF(G14:AB14,"Y")) -> 0 | AD14: =IF(D14="","",VLOOKUP(AC14,TORCH_Tables!$Q$3:$R$29,2,FALSE)) -> 16.4
A15: 45356 | B15: 3 | C15: 3B | D15: Lname6 | E15: Fname6 | F15: XXXXX6 | AC15: =IF(D15="",0,COUNTIF(G15:AB15,"Y")) -> 0 | AD15: =IF(D15="","",VLOOKUP(AC15,TORCH_Tables!$Q$3:$R$29,2,FALSE)) -> 16.4
A16: 45356 | B16: 3 | C16: 3B | D16: Lname7 | E16: Fname7 | F16: XXXXX7 | AC16: =IF(D16="",0,COUNTIF(G16:AB16,"Y")) -> 0 | AD16: =IF(D16="","",VLOOKUP(AC16,TORCH_Tables!$Q$3:$R$29,2,FALSE)) -> 16.4
A17: 45356 | B17: 3 | C17: 3B | D17: Lname8 | E17: Fname8 | F17: XXXXX8 | AC17: =IF(D17="",0,COUNTIF(G17:AB17,"Y")) -> 0 | AD17: =IF(D17="","",VLOOKUP(AC17,TORCH_Tables!$Q$3:$R$29,2,FALSE)) -> 16.4
A18: 45356 | B18: 3 | C18: 3B | D18: Lname9 | E18: Fname9 | F18: XXXXX9 | AC18: =IF(D18="",0,COUNTIF(G18:AB18,"Y")) -> 0 | AD18: =IF(D18="","",VLOOKUP(AC18,TORCH_Tables!$Q$3:$R$29,2,FALSE)) -> 16.4
A19: 45356 | B19: 3 | C19: 3B | D19: Lname10 | E19: Fname10 | F19: XXXXX10 | AC19: =IF(D19="",0,COUNTIF(G19:AB19,"Y")) -> 0 | AD19: =IF(D19="","",VLOOKUP(AC19,TORCH_Tables!$Q$3:$R$29,2,FALSE)) -> 16.4
AC20: =IF(D20="",0,COUNTIF(G20:AB20,"Y")) -> 0 | AD20: =IF(D20="","",VLOOKUP(AC20,TORCH_Tables!$Q$3:$R$29,2,FALSE))
AC21: =IF(D21="",0,COUNTIF(G21:AB21,"Y")) -> 0 | AD21: =IF(D21="","",VLOOKUP(AC21,TORCH_Tables!$Q$3:$R$29,2,FALSE))
AC22: =IF(D22="",0,COUNTIF(G22:AB22,"Y")) -> 0 | AD22: =IF(D22="","",VLOOKUP(AC22,TORCH_Tables!$Q$3:$R$29,2,FALSE))
AC23: =IF(D23="",0,COUNTIF(G23:AB23,"Y")) -> 0 | AD23: =IF(D23="","",VLOOKUP(AC23,TORCH_Tables!$Q$3:$R$29,2,FALSE))
AC24: =IF(D24="",0,COUNTIF(G24:AB24,"Y")) -> 0 | AD24: =IF(D24="","",VLOOKUP(AC24,TORCH_Tables!$Q$3:$R$29,2,FALSE))
AC25: =IF(D25="",0,COUNTIF(G25:AB25,"Y")) -> 0 | AD25: =IF(D25="","",VLOOKUP(AC25,TORCH_Tables!$Q$3:$R$29,2,FALSE))
AC26: =IF(D26="",0,COUNTIF(G26:AB26,"Y")) -> 0 | AD26: =IF(D26="","",VLOOKUP(AC26,TORCH_Tables!$Q$3:$R$29,2,FALSE))
AC27: =IF(D27="",0,COUNTIF(G27:AB27,"Y")) -> 0 | AD27: =IF(D27="","",VLOOKUP(AC27,TORCH_Tables!$Q$3:$R$29,2,FALSE))
AC28: =IF(D28="",0,COUNTIF(G28:AB28,"Y")) -> 0 | AD28: =IF(D28="","",VLOOKUP(AC28,TORCH_Tables!$Q$3:$R$29,2,FALSE))
AC29: =IF(D29="",0,COUNTIF(G29:AB29,"Y")) -> 0 | AD29: =IF(D29="","",VLOOKUP(AC29,TORCH_Tables!$Q$3:$R$29,2,FALSE))
AC30: =IF(D30="",0,COUNTIF(G30:AB30,"Y")) -> 0 | AD30: =IF(D30="","",VLOOKUP(AC30,TORCH_Tables!$Q$3:$R$29,2,FALSE))
AC31: =IF(D31="",0,COUNTIF(G31:AB31,"Y")) -> 0 | AD31: =IF(D31="","",VLOOKUP(AC31,TORCH_Tables!$Q$3:$R$29,2,FALSE))
... AC503: =IF(D503="",0,COUNTIF(G503:AB503,"Y")) -> 0 | AD503: =IF(D503="","",VLOOKUP(AC503,TORCH_Tables!$Q$3:$R$29,2,FALSE))

Sheet Accident
A1: TORCH - The Accident
G3: QUESTION No. and ANSWER KEY (Enter the student's response - "Y" if correct, "N" if incorrect)
E4: Question Number | G4: 1 | H4: 2 | I4: 3 | J4: 4 | K4: 5 | L4: 6 | M4: 7 | N4: 8 | O4: 9 | P4: 10 | Q4: 11 | R4: 12 | S4: 13 | T4: 14 | U4: 15 | V4: 16 | W4: 17 | X4: 18 | Y4: 19 | Z4: 20 | AA4: 21 | AB4: 22 | AC4: 23
E5: Item Difficulty
E6: Skill Assessed
A8: Date (dd/mm/yy) | B8: Yr_Lev | C8: HG | D8: Surname | E8: First_Name | F8: Student_ID | G8: Y | H8: Y | I8: Y | J8: Y | K8: Y | L8: Y | M8: Y | N8: Y | O8: Y | P8: Y | Q8: Y | R8: Y | S8: Y | T8: Y | U8: Y | V8: Y | W8: Y | X8: Y | Y8: Y | Z8: Y | AA8: Y | AB8: Y | AC8: Y | AD8: Raw Score | AE8: TORCH Score
A9: 45356 | B9: 3 | C9: 3A | D9: Lname1 | E9: Fname1 | F9: XXXXX1 | AD9: =IF(D9="",0,COUNTIF(G9:AC9,"Y")) -> 0 | AE9: =IF(D9="","",VLOOKUP(AD9,TORCH_Tables!$S$3:$T$29,2,FALSE)) -> 21.3
A10: 45356 | B10: 3 | C10: 3A | D10: Lname2 | E10: Fname2 | F10: XXXXX2 | AD10: =IF(D10="",0,COUNTIF(G10:AC10,"Y")) -> 0 | AE10: =IF(D10="","",VLOOKUP(AD10,TORCH_Tables!$S$3:$T$29,2,FALSE)) -> 21.3
A11: 45356 | B11: 3 | C11: 3A | D11: Lname3 | E11: Fname3 | F11: XXXXX3 | AD11: =IF(D11="",0,COUNTIF(G11:AC11,"Y")) -> 0 | AE11: =IF(D11="","",VLOOKUP(AD11,TORCH_Tables!$S$3:$T$29,2,FALSE)) -> 21.3
A12: 45356 | B12: 3 | C12: 3A | D12: Lname4 | E12: Fname4 | F12: XXXXX4 | AD12: =IF(D12="",0,COUNTIF(G12:AC12,"Y")) -> 0 | AE12: =IF(D12="","",VLOOKUP(AD12,TORCH_Tables!$S$3:$T$29,2,FALSE)) -> 21.3
A13: 45356 | B13: 3 | C13: 3B | D13: ULname13 | E13: UFname13 | F13: UNLISTED | AD13: =IF(D13="",0,COUNTIF(G13:AC13,"Y")) -> 0 | AE13: =IF(D13="","",VLOOKUP(AD13,TORCH_Tables!$S$3:$T$29,2,FALSE)) -> 21.3
A14: 45356 | B14: 3 | C14: 3A | D14: Lname5 | E14: Fname5 | F14: XXXXX5 | AD14: =IF(D14="",0,COUNTIF(G14:AC14,"Y")) -> 0 | AE14: =IF(D14="","",VLOOKUP(AD14,TORCH_Tables!$S$3:$T$29,2,FALSE)) -> 21.3
A15: 45356 | B15: 3 | C15: 3B | D15: Lname6 | E15: Fname6 | F15: XXXXX6 | AD15: =IF(D15="",0,COUNTIF(G15:AC15,"Y")) -> 0 | AE15: =IF(D15="","",VLOOKUP(AD15,TORCH_Tables!$S$3:$T$29,2,FALSE)) -> 21.3
A16: 45356 | B16: 3 | C16: 3B | D16: Lname7 | E16: Fname7 | F16: XXXXX7 | AD16: =IF(D16="",0,COUNTIF(G16:AC16,"Y")) -> 0 | AE16: =IF(D16="","",VLOOKUP(AD16,TORCH_Tables!$S$3:$T$29,2,FALSE)) -> 21.3
A17: 45356 | B17: 3 | C17: 3B | D17: Lname8 | E17: Fname8 | F17: XXXXX8 | AD17: =IF(D17="",0,COUNTIF(G17:AC17,"Y")) -> 0 | AE17: =IF(D17="","",VLOOKUP(AD17,TORCH_Tables!$S$3:$T$29,2,FALSE)) -> 21.3
A18: 45356 | B18: 3 | C18: 3B | D18: Lname9 | E18: Fname9 | F18: XXXXX9 | AD18: =IF(D18="",0,COUNTIF(G18:AC18,"Y")) -> 0 | AE18: =IF(D18="","",VLOOKUP(AD18,TORCH_Tables!$S$3:$T$29,2,FALSE)) -> 21.3
A19: 45356 | B19: 3 | C19: 3B | D19: Lname10 | E19: Fname10 | F19: XXXXX10 | AD19: =IF(D19="",0,COUNTIF(G19:AC19,"Y")) -> 0 | AE19: =IF(D19="","",VLOOKUP(AD19,TORCH_Tables!$S$3:$T$29,2,FALSE)) -> 21.3
AD20: =IF(D20="",0,COUNTIF(G20:AC20,"Y")) -> 0 | AE20: =IF(D20="","",VLOOKUP(AD20,TORCH_Tables!$S$3:$T$29,2,FALSE))
AD21: =IF(D21="",0,COUNTIF(G21:AC21,"Y")) -> 0 | AE21: =IF(D21="","",VLOOKUP(AD21,TORCH_Tables!$S$3:$T$29,2,FALSE))
AD22: =IF(D22="",0,COUNTIF(G22:AC22,"Y")) -> 0 | AE22: =IF(D22="","",VLOOKUP(AD22,TORCH_Tables!$S$3:$T$29,2,FALSE))
AD23: =IF(D23="",0,COUNTIF(G23:AC23,"Y")) -> 0 | AE23: =IF(D23="","",VLOOKUP(AD23,TORCH_Tables!$S$3:$T$29,2,FALSE))
AD24: =IF(D24="",0,COUNTIF(G24:AC24,"Y")) -> 0 | AE24: =IF(D24="","",VLOOKUP(AD24,TORCH_Tables!$S$3:$T$29,2,FALSE))
AD25: =IF(D25="",0,COUNTIF(G25:AC25,"Y")) -> 0 | AE25: =IF(D25="","",VLOOKUP(AD25,TORCH_Tables!$S$3:$T$29,2,FALSE))
AD26: =IF(D26="",0,COUNTIF(G26:AC26,"Y")) -> 0 | AE26: =IF(D26="","",VLOOKUP(AD26,TORCH_Tables!$S$3:$T$29,2,FALSE))
AD27: =IF(D27="",0,COUNTIF(G27:AC27,"Y")) -> 0 | AE27: =IF(D27="","",VLOOKUP(AD27,TORCH_Tables!$S$3:$T$29,2,FALSE))
AD28: =IF(D28="",0,COUNTIF(G28:AC28,"Y")) -> 0 | AE28: =IF(D28="","",VLOOKUP(AD28,TORCH_Tables!$S$3:$T$29,2,FALSE))
AD29: =IF(D29="",0,COUNTIF(G29:AC29,"Y")) -> 0 | AE29: =IF(D29="","",VLOOKUP(AD29,TORCH_Tables!$S$3:$T$29,2,FALSE))
AD30: =IF(D30="",0,COUNTIF(G30:AC30,"Y")) -> 0 | AE30: =IF(D30="","",VLOOKUP(AD30,TORCH_Tables!$S$3:$T$29,2,FALSE))
AD31: =IF(D31="",0,COUNTIF(G31:AC31,"Y")) -> 0 | AE31: =IF(D31="","",VLOOKUP(AD31,TORCH_Tables!$S$3:$T$29,2,FALSE))
... AD503: =IF(D503="",0,COUNTIF(G503:AC503,"Y")) -> 0 | AE503: =IF(D503="","",VLOOKUP(AD503,TORCH_Tables!$S$3:$T$29,2,FALSE))

Sheet RedAce
A1: TORCH - The Red Ace of Spades
G3: QUESTION No. and ANSWER KEY (Enter the student's response - "Y" if correct, "N" if incorrect)
E4: Question Number | G4: 1 | H4: 2 | I4: 3 | J4: 4 | K4: 5 | L4: 6 | M4: 7 | N4: 8 | O4: 9 | P4: 10 | Q4: 11 | R4: 12 | S4: 13 | T4: 14 | U4: 15 | V4: 16 | W4: 17 | X4: 18 | Y4: 19 | Z4: 20 | AA4: 21 | AB4: 22
E5: Item Difficulty
E6: Skill Assessed
A8: Date (dd/mm/yy) | B8: Yr_Lev | C8: HG | D8: Surname | E8: First_Name | F8: Student_ID | G8: Y | H8: Y | I8: Y | J8: Y | K8: Y | L8: Y | M8: Y | N8: Y | O8: Y | P8: Y | Q8: Y | R8: Y | S8: Y | T8: Y | U8: Y | V8: Y | W8: Y | X8: Y | Y8: Y | Z8: Y | AA8: Y | AB8: Y | AC8: Raw Score | AD8: TORCH Score
A9: 45356 | B9: 3 | C9: 3A | D9: Lname1 | E9: Fname1 | F9: XXXXX1 | AC9: =IF(D9="",0,COUNTIF(G9:AB9,"Y")) -> 0 | AD9: =IF(D9="","",VLOOKUP(AC9,TORCH_Tables!$U$3:$V$29,2,FALSE)) -> 23.7
A10: 45356 | B10: 3 | C10: 3A | D10: Lname2 | E10: Fname2 | F10: XXXXX2 | AC10: =IF(D10="",0,COUNTIF(G10:AB10,"Y")) -> 0 | AD10: =IF(D10="","",VLOOKUP(AC10,TORCH_Tables!$U$3:$V$29,2,FALSE)) -> 23.7
A11: 45356 | B11: 3 | C11: 3A | D11: Lname3 | E11: Fname3 | F11: XXXXX3 | AC11: =IF(D11="",0,COUNTIF(G11:AB11,"Y")) -> 0 | AD11: =IF(D11="","",VLOOKUP(AC11,TORCH_Tables!$U$3:$V$29,2,FALSE)) -> 23.7
A12: 45356 | B12: 3 | C12: 3A | D12: Lname4 | E12: Fname4 | F12: XXXXX4 | AC12: =IF(D12="",0,COUNTIF(G12:AB12,"Y")) -> 0 | AD12: =IF(D12="","",VLOOKUP(AC12,TORCH_Tables!$U$3:$V$29,2,FALSE)) -> 23.7
A13: 45356 | B13: 3 | C13: 3B | D13: ULname13 | E13: UFname13 | F13: UNLISTED | AC13: =IF(D13="",0,COUNTIF(G13:AB13,"Y")) -> 0 | AD13: =IF(D13="","",VLOOKUP(AC13,TORCH_Tables!$U$3:$V$29,2,FALSE)) -> 23.7
A14: 45356 | B14: 3 | C14: 3A | D14: Lname5 | E14: Fname5 | F14: XXXXX5 | AC14: =IF(D14="",0,COUNTIF(G14:AB14,"Y")) -> 0 | AD14: =IF(D14="","",VLOOKUP(AC14,TORCH_Tables!$U$3:$V$29,2,FALSE)) -> 23.7
A15: 45356 | B15: 3 | C15: 3B | D15: Lname6 | E15: Fname6 | F15: XXXXX6 | AC15: =IF(D15="",0,COUNTIF(G15:AB15,"Y")) -> 0 | AD15: =IF(D15="","",VLOOKUP(AC15,TORCH_Tables!$U$3:$V$29,2,FALSE)) -> 23.7
A16: 45356 | B16: 3 | C16: 3B | D16: Lname7 | E16: Fname7 | F16: XXXXX7 | AC16: =IF(D16="",0,COUNTIF(G16:AB16,"Y")) -> 0 | AD16: =IF(D16="","",VLOOKUP(AC16,TORCH_Tables!$U$3:$V$29,2,FALSE)) -> 23.7
A17: 45356 | B17: 3 | C17: 3B | D17: Lname8 | E17: Fname8 | F17: XXXXX8 | AC17: =IF(D17="",0,COUNTIF(G17:AB17,"Y")) -> 0 | AD17: =IF(D17="","",VLOOKUP(AC17,TORCH_Tables!$U$3:$V$29,2,FALSE)) -> 23.7
A18: 45356 | B18: 3 | C18: 3B | D18: Lname9 | E18: Fname9 | F18: XXXXX9 | AC18: =IF(D18="",0,COUNTIF(G18:AB18,"Y")) -> 0 | AD18: =IF(D18="","",VLOOKUP(AC18,TORCH_Tables!$U$3:$V$29,2,FALSE)) -> 23.7
A19: 45356 | B19: 3 | C19: 3B | D19: Lname10 | E19: Fname10 | F19: XXXXX10 | AC19: =IF(D19="",0,COUNTIF(G19:AB19,"Y")) -> 0 | AD19: =IF(D19="","",VLOOKUP(AC19,TORCH_Tables!$U$3:$V$29,2,FALSE)) -> 23.7
AC20: =IF(D20="",0,COUNTIF(G20:AB20,"Y")) -> 0 | AD20: =IF(D20="","",VLOOKUP(AC20,TORCH_Tables!$U$3:$V$29,2,FALSE))
AC21: =IF(D21="",0,COUNTIF(G21:AB21,"Y")) -> 0 | AD21: =IF(D21="","",VLOOKUP(AC21,TORCH_Tables!$U$3:$V$29,2,FALSE))
AC22: =IF(D22="",0,COUNTIF(G22:AB22,"Y")) -> 0 | AD22: =IF(D22="","",VLOOKUP(AC22,TORCH_Tables!$U$3:$V$29,2,FALSE))
AC23: =IF(D23="",0,COUNTIF(G23:AB23,"Y")) -> 0 | AD23: =IF(D23="","",VLOOKUP(AC23,TORCH_Tables!$U$3:$V$29,2,FALSE))
AC24: =IF(D24="",0,COUNTIF(G24:AB24,"Y")) -> 0 | AD24: =IF(D24="","",VLOOKUP(AC24,TORCH_Tables!$U$3:$V$29,2,FALSE))
AC25: =IF(D25="",0,COUNTIF(G25:AB25,"Y")) -> 0 | AD25: =IF(D25="","",VLOOKUP(AC25,TORCH_Tables!$U$3:$V$29,2,FALSE))
AC26: =IF(D26="",0,COUNTIF(G26:AB26,"Y")) -> 0 | AD26: =IF(D26="","",VLOOKUP(AC26,TORCH_Tables!$U$3:$V$29,2,FALSE))
AC27: =IF(D27="",0,COUNTIF(G27:AB27,"Y")) -> 0 | AD27: =IF(D27="","",VLOOKUP(AC27,TORCH_Tables!$U$3:$V$29,2,FALSE))
AC28: =IF(D28="",0,COUNTIF(G28:AB28,"Y")) -> 0 | AD28: =IF(D28="","",VLOOKUP(AC28,TORCH_Tables!$U$3:$V$29,2,FALSE))
AC29: =IF(D29="",0,COUNTIF(G29:AB29,"Y")) -> 0 | AD29: =IF(D29="","",VLOOKUP(AC29,TORCH_Tables!$U$3:$V$29,2,FALSE))
AC30: =IF(D30="",0,COUNTIF(G30:AB30,"Y")) -> 0 | AD30: =IF(D30="","",VLOOKUP(AC30,TORCH_Tables!$U$3:$V$29,2,FALSE))
AC31: =IF(D31="",0,COUNTIF(G31:AB31,"Y")) -> 0 | AD31: =IF(D31="","",VLOOKUP(AC31,TORCH_Tables!$U$3:$V$29,2,FALSE))
... AC503: =IF(D503="",0,COUNTIF(G503:AB503,"Y")) -> 0 | AD503: =IF(D503="","",VLOOKUP(AC503,TORCH_Tables!$U$3:$V$29,2,FALSE))

Sheet Rages
A1: TORCH - The Rages of Mrs Torrens
G3: QUESTION No. and ANSWER KEY (Enter the student's response - "Y" if correct, "N" if incorrect)
E4: Question Number | G4: 1 | H4: 2 | I4: 3 | J4: 4 | K4: 5 | L4: 6 | M4: 7 | N4: 8 | O4: 9 | P4: 10 | Q4: 11 | R4: 12 | S4: 13 | T4: 14 | U4: 15 | V4: 16 | W4: 17 | X4: 18 | Y4: 19 | Z4: 20 | AA4: 21 | AB4: 22 | AC4: 23 | AD4: 24 | AE4: 25
E5: Item Difficulty
E6: Skill Assessed
A8: Date (dd/mm/yy) | B8: Yr_Lev | C8: HG | D8: Surname | E8: First_Name | F8: Student_ID | G8: Y | H8: Y | I8: Y | J8: Y | K8: Y | L8: Y | M8: Y | N8: Y | O8: Y | P8: Y | Q8: Y | R8: Y | S8: Y | T8: Y | U8: Y | V8: Y | W8: Y | X8: Y | Y8: Y | Z8: Y | AA8: Y | AB8: Y | AC8: Y | AD8: Y | AE8: Y | AF8: Raw Score | AG8: TORCH Score
A9: 45356 | B9: 3 | C9: 3A | D9: Lname1 | E9: Fname1 | F9: XXXXX1 | AF9: =IF(D9="",0,COUNTIF(G9:AE9,"Y")) -> 0 | AG9: =IF(D9="","",VLOOKUP(AF9,TORCH_Tables!$W$3:$X$29,2,FALSE)) -> 24
A10: 45356 | B10: 3 | C10: 3A | D10: Lname2 | E10: Fname2 | F10: XXXXX2 | AF10: =IF(D10="",0,COUNTIF(G10:AE10,"Y")) -> 0 | AG10: =IF(D10="","",VLOOKUP(AF10,TORCH_Tables!$W$3:$X$29,2,FALSE)) -> 24
A11: 45356 | B11: 3 | C11: 3A | D11: Lname3 | E11: Fname3 | F11: XXXXX3 | AF11: =IF(D11="",0,COUNTIF(G11:AE11,"Y")) -> 0 | AG11: =IF(D11="","",VLOOKUP(AF11,TORCH_Tables!$W$3:$X$29,2,FALSE)) -> 24
A12: 45356 | B12: 3 | C12: 3A | D12: Lname4 | E12: Fname4 | F12: XXXXX4 | AF12: =IF(D12="",0,COUNTIF(G12:AE12,"Y")) -> 0 | AG12: =IF(D12="","",VLOOKUP(AF12,TORCH_Tables!$W$3:$X$29,2,FALSE)) -> 24
A13: 45356 | B13: 3 | C13: 3B | D13: ULname13 | E13: UFname13 | F13: UNLISTED | AF13: =IF(D13="",0,COUNTIF(G13:AE13,"Y")) -> 0 | AG13: =IF(D13="","",VLOOKUP(AF13,TORCH_Tables!$W$3:$X$29,2,FALSE)) -> 24
A14: 45356 | B14: 3 | C14: 3A | D14: Lname5 | E14: Fname5 | F14: XXXXX5 | AF14: =IF(D14="",0,COUNTIF(G14:AE14,"Y")) -> 0 | AG14: =IF(D14="","",VLOOKUP(AF14,TORCH_Tables!$W$3:$X$29,2,FALSE)) -> 24
A15: 45356 | B15: 3 | C15: 3B | D15: Lname6 | E15: Fname6 | F15: XXXXX6 | AF15: =IF(D15="",0,COUNTIF(G15:AE15,"Y")) -> 0 | AG15: =IF(D15="","",VLOOKUP(AF15,TORCH_Tables!$W$3:$X$29,2,FALSE)) -> 24
A16: 45356 | B16: 3 | C16: 3B | D16: Lname7 | E16: Fname7 | F16: XXXXX7 | AF16: =IF(D16="",0,COUNTIF(G16:AE16,"Y")) -> 0 | AG16: =IF(D16="","",VLOOKUP(AF16,TORCH_Tables!$W$3:$X$29,2,FALSE)) -> 24
A17: 45356 | B17: 3 | C17: 3B | D17: Lname8 | E17: Fname8 | F17: XXXXX8 | AF17: =IF(D17="",0,COUNTIF(G17:AE17,"Y")) -> 0 | AG17: =IF(D17="","",VLOOKUP(AF17,TORCH_Tables!$W$3:$X$29,2,FALSE)) -> 24
A18: 45356 | B18: 3 | C18: 3B | D18: Lname9 | E18: Fname9 | F18: XXXXX9 | AF18: =IF(D18="",0,COUNTIF(G18:AE18,"Y")) -> 0 | AG18: =IF(D18="","",VLOOKUP(AF18,TORCH_Tables!$W$3:$X$29,2,FALSE)) -> 24
A19: 45356 | B19: 3 | C19: 3B | D19: Lname10 | E19: Fname10 | F19: XXXXX10 | AF19: =IF(D19="",0,COUNTIF(G19:AE19,"Y")) -> 0 | AG19: =IF(D19="","",VLOOKUP(AF19,TORCH_Tables!$W$3:$X$29,2,FALSE)) -> 24
AF20: =IF(D20="",0,COUNTIF(G20:AE20,"Y")) -> 0 | AG20: =IF(D20="","",VLOOKUP(AF20,TORCH_Tables!$W$3:$X$29,2,FALSE))
AF21: =IF(D21="",0,COUNTIF(G21:AE21,"Y")) -> 0 | AG21: =IF(D21="","",VLOOKUP(AF21,TORCH_Tables!$W$3:$X$29,2,FALSE))
AF22: =IF(D22="",0,COUNTIF(G22:AE22,"Y")) -> 0 | AG22: =IF(D22="","",VLOOKUP(AF22,TORCH_Tables!$W$3:$X$29,2,FALSE))
AF23: =IF(D23="",0,COUNTIF(G23:AE23,"Y")) -> 0 | AG23: =IF(D23="","",VLOOKUP(AF23,TORCH_Tables!$W$3:$X$29,2,FALSE))
AF24: =IF(D24="",0,COUNTIF(G24:AE24,"Y")) -> 0 | AG24: =IF(D24="","",VLOOKUP(AF24,TORCH_Tables!$W$3:$X$29,2,FALSE))
AF25: =IF(D25="",0,COUNTIF(G25:AE25,"Y")) -> 0 | AG25: =IF(D25="","",VLOOKUP(AF25,TORCH_Tables!$W$3:$X$29,2,FALSE))
AF26: =IF(D26="",0,COUNTIF(G26:AE26,"Y")) -> 0 | AG26: =IF(D26="","",VLOOKUP(AF26,TORCH_Tables!$W$3:$X$29,2,FALSE))
AF27: =IF(D27="",0,COUNTIF(G27:AE27,"Y")) -> 0 | AG27: =IF(D27="","",VLOOKUP(AF27,TORCH_Tables!$W$3:$X$29,2,FALSE))
AF28: =IF(D28="",0,COUNTIF(G28:AE28,"Y")) -> 0 | AG28: =IF(D28="","",VLOOKUP(AF28,TORCH_Tables!$W$3:$X$29,2,FALSE))
AF29: =IF(D29="",0,COUNTIF(G29:AE29,"Y")) -> 0 | AG29: =IF(D29="","",VLOOKUP(AF29,TORCH_Tables!$W$3:$X$29,2,FALSE))
AF30: =IF(D30="",0,COUNTIF(G30:AE30,"Y")) -> 0 | AG30: =IF(D30="","",VLOOKUP(AF30,TORCH_Tables!$W$3:$X$29,2,FALSE))
AF31: =IF(D31="",0,COUNTIF(G31:AE31,"Y")) -> 0 | AG31: =IF(D31="","",VLOOKUP(AF31,TORCH_Tables!$W$3:$X$29,2,FALSE))
... AF503: =IF(D503="",0,COUNTIF(G503:AE503,"Y")) -> 0 | AG503: =IF(D503="","",VLOOKUP(AF503,TORCH_Tables!$W$3:$X$29,2,FALSE))

Sheet Kiss
A1: TORCH - Kiss and Make Up
G3: QUESTION No. and ANSWER KEY (Enter the student's response - "Y" if correct, "N" if incorrect)
E4: Question Number | G4: 1 | H4: 2 | I4: 3 | J4: 4 | K4: 5 | L4: 6 | M4: 7 | N4: 8 | O4: 9 | P4: 10 | Q4: 11 | R4: 12 | S4: 13 | T4: 14 | U4: 15 | V4: 16 | W4: 17 | X4: 18 | Y4: 19 | Z4: 20 | AA4: 21 | AB4: 22 | AC4: 23 | AD4: 24
E5: Item Difficulty
E6: Skill Assessed
A8: Date (dd/mm/yy) | B8: Yr_Lev | C8: HG | D8: Surname | E8: First_Name | F8: Student_ID | G8: Y | H8: Y | I8: Y | J8: Y | K8: Y | L8: Y | M8: Y | N8: Y | O8: Y | P8: Y | Q8: Y | R8: Y | S8: Y | T8: Y | U8: Y | V8: Y | W8: Y | X8: Y | Y8: Y | Z8: Y | AA8: Y | AB8: Y | AC8: Y | AD8: Y | AE8: Raw Score | AF8: TORCH Score
A9: 45356 | B9: 3 | C9: 3A | D9: Lname1 | E9: Fname1 | F9: XXXXX1 | AE9: =IF(D9="",0,COUNTIF(G9:AD9,"Y")) -> 0 | AF9: =IF(D9="","",VLOOKUP(AE9,TORCH_Tables!$Y$3:$Z$29,2,FALSE)) -> 29
A10: 45356 | B10: 3 | C10: 3A | D10: Lname2 | E10: Fname2 | F10: XXXXX2 | AE10: =IF(D10="",0,COUNTIF(G10:AD10,"Y")) -> 0 | AF10: =IF(D10="","",VLOOKUP(AE10,TORCH_Tables!$Y$3:$Z$29,2,FALSE)) -> 29
A11: 45356 | B11: 3 | C11: 3A | D11: Lname3 | E11: Fname3 | F11: XXXXX3 | AE11: =IF(D11="",0,COUNTIF(G11:AD11,"Y")) -> 0 | AF11: =IF(D11="","",VLOOKUP(AE11,TORCH_Tables!$Y$3:$Z$29,2,FALSE)) -> 29
A12: 45356 | B12: 3 | C12: 3A | D12: Lname4 | E12: Fname4 | F12: XXXXX4 | AE12: =IF(D12="",0,COUNTIF(G12:AD12,"Y")) -> 0 | AF12: =IF(D12="","",VLOOKUP(AE12,TORCH_Tables!$Y$3:$Z$29,2,FALSE)) -> 29
A13: 45356 | B13: 3 | C13: 3B | D13: ULname13 | E13: UFname13 | F13: UNLISTED | AE13: =IF(D13="",0,COUNTIF(G13:AD13,"Y")) -> 0 | AF13: =IF(D13="","",VLOOKUP(AE13,TORCH_Tables!$Y$3:$Z$29,2,FALSE)) -> 29
A14: 45356 | B14: 3 | C14: 3A | D14: Lname5 | E14: Fname5 | F14: XXXXX5 | AE14: =IF(D14="",0,COUNTIF(G14:AD14,"Y")) -> 0 | AF14: =IF(D14="","",VLOOKUP(AE14,TORCH_Tables!$Y$3:$Z$29,2,FALSE)) -> 29
A15: 45356 | B15: 3 | C15: 3B | D15: Lname6 | E15: Fname6 | F15: XXXXX6 | AE15: =IF(D15="",0,COUNTIF(G15:AD15,"Y")) -> 0 | AF15: =IF(D15="","",VLOOKUP(AE15,TORCH_Tables!$Y$3:$Z$29,2,FALSE)) -> 29
A16: 45356 | B16: 3 | C16: 3B | D16: Lname7 | E16: Fname7 | F16: XXXXX7 | AE16: =IF(D16="",0,COUNTIF(G16:AD16,"Y")) -> 0 | AF16: =IF(D16="","",VLOOKUP(AE16,TORCH_Tables!$Y$3:$Z$29,2,FALSE)) -> 29
A17: 45356 | B17: 3 | C17: 3B | D17: Lname8 | E17: Fname8 | F17: XXXXX8 | AE17: =IF(D17="",0,COUNTIF(G17:AD17,"Y")) -> 0 | AF17: =IF(D17="","",VLOOKUP(AE17,TORCH_Tables!$Y$3:$Z$29,2,FALSE)) -> 29
A18: 45356 | B18: 3 | C18: 3B | D18: Lname9 | E18: Fname9 | F18: XXXXX9 | AE18: =IF(D18="",0,COUNTIF(G18:AD18,"Y")) -> 0 | AF18: =IF(D18="","",VLOOKUP(AE18,TORCH_Tables!$Y$3:$Z$29,2,FALSE)) -> 29
A19: 45356 | B19: 3 | C19: 3B | D19: Lname10 | E19: Fname10 | F19: XXXXX10 | AE19: =IF(D19="",0,COUNTIF(G19:AD19,"Y")) -> 0 | AF19: =IF(D19="","",VLOOKUP(AE19,TORCH_Tables!$Y$3:$Z$29,2,FALSE)) -> 29
AE20: =IF(D20="",0,COUNTIF(G20:AD20,"Y")) -> 0 | AF20: =IF(D20="","",VLOOKUP(AE20,TORCH_Tables!$Y$3:$Z$29,2,FALSE))
AE21: =IF(D21="",0,COUNTIF(G21:AD21,"Y")) -> 0 | AF21: =IF(D21="","",VLOOKUP(AE21,TORCH_Tables!$Y$3:$Z$29,2,FALSE))
AE22: =IF(D22="",0,COUNTIF(G22:AD22,"Y")) -> 0 | AF22: =IF(D22="","",VLOOKUP(AE22,TORCH_Tables!$Y$3:$Z$29,2,FALSE))
AE23: =IF(D23="",0,COUNTIF(G23:AD23,"Y")) -> 0 | AF23: =IF(D23="","",VLOOKUP(AE23,TORCH_Tables!$Y$3:$Z$29,2,FALSE))
AE24: =IF(D24="",0,COUNTIF(G24:AD24,"Y")) -> 0 | AF24: =IF(D24="","",VLOOKUP(AE24,TORCH_Tables!$Y$3:$Z$29,2,FALSE))
AE25: =IF(D25="",0,COUNTIF(G25:AD25,"Y")) -> 0 | AF25: =IF(D25="","",VLOOKUP(AE25,TORCH_Tables!$Y$3:$Z$29,2,FALSE))
AE26: =IF(D26="",0,COUNTIF(G26:AD26,"Y")) -> 0 | AF26: =IF(D26="","",VLOOKUP(AE26,TORCH_Tables!$Y$3:$Z$29,2,FALSE))
AE27: =IF(D27="",0,COUNTIF(G27:AD27,"Y")) -> 0 | AF27: =IF(D27="","",VLOOKUP(AE27,TORCH_Tables!$Y$3:$Z$29,2,FALSE))
AE28: =IF(D28="",0,COUNTIF(G28:AD28,"Y")) -> 0 | AF28: =IF(D28="","",VLOOKUP(AE28,TORCH_Tables!$Y$3:$Z$29,2,FALSE))
AE29: =IF(D29="",0,COUNTIF(G29:AD29,"Y")) -> 0 | AF29: =IF(D29="","",VLOOKUP(AE29,TORCH_Tables!$Y$3:$Z$29,2,FALSE))
AE30: =IF(D30="",0,COUNTIF(G30:AD30,"Y")) -> 0 | AF30: =IF(D30="","",VLOOKUP(AE30,TORCH_Tables!$Y$3:$Z$29,2,FALSE))
AE31: =IF(D31="",0,COUNTIF(G31:AD31,"Y")) -> 0 | AF31: =IF(D31="","",VLOOKUP(AE31,TORCH_Tables!$Y$3:$Z$29,2,FALSE))
... AE503: =IF(D503="",0,COUNTIF(G503:AD503,"Y")) -> 0 | AF503: =IF(D503="","",VLOOKUP(AE503,TORCH_Tables!$Y$3:$Z$29,2,FALSE))

Sheet Purple
A1: TORCH - The Purple Children
G3: QUESTION No. and ANSWER KEY (Enter the student's response - "Y" if correct, "N" if incorrect)
E4: Question Number | G4: 1 | H4: 2 | I4: 3 | J4: 4 | K4: 5 | L4: 6 | M4: 7 | N4: 8 | O4: 9 | P4: 10 | Q4: 11 | R4: 12 | S4: 13 | T4: 14 | U4: 15 | V4: 16 | W4: 17 | X4: 18
E5: Item Difficulty
E6: Skill Assessed
A8: Date (dd/mm/yy) | B8: Yr_Lev | C8: HG | D8: Surname | E8: First_Name | F8: Student_ID | G8: Y | H8: Y | I8: Y | J8: Y | K8: Y | L8: Y | M8: Y | N8: Y | O8: Y | P8: Y | Q8: Y | R8: Y | S8: Y | T8: Y | U8: Y | V8: Y | W8: Y | X8: Y | Y8: Raw Score | Z8: TORCH Score
Y9: =IF(D9="",0,COUNTIF(G9:X9,"Y")) -> 0 | Z9: =IF(D9="","",VLOOKUP(Y9,TORCH_Tables!$AA$3:$AB$29,2,FALSE))
Y10: =IF(D10="",0,COUNTIF(G10:X10,"Y")) -> 0 | Z10: =IF(D10="","",VLOOKUP(Y10,TORCH_Tables!$AA$3:$AB$29,2,FALSE))
Y11: =IF(D11="",0,COUNTIF(G11:X11,"Y")) -> 0 | Z11: =IF(D11="","",VLOOKUP(Y11,TORCH_Tables!$AA$3:$AB$29,2,FALSE))
Y12: =IF(D12="",0,COUNTIF(G12:X12,"Y")) -> 0 | Z12: =IF(D12="","",VLOOKUP(Y12,TORCH_Tables!$AA$3:$AB$29,2,FALSE))
Y13: =IF(D13="",0,COUNTIF(G13:X13,"Y")) -> 0 | Z13: =IF(D13="","",VLOOKUP(Y13,TORCH_Tables!$AA$3:$AB$29,2,FALSE))
Y14: =IF(D14="",0,COUNTIF(G14:X14,"Y")) -> 0 | Z14: =IF(D14="","",VLOOKUP(Y14,TORCH_Tables!$AA$3:$AB$29,2,FALSE))
Y15: =IF(D15="",0,COUNTIF(G15:X15,"Y")) -> 0 | Z15: =IF(D15="","",VLOOKUP(Y15,TORCH_Tables!$AA$3:$AB$29,2,FALSE))
Y16: =IF(D16="",0,COUNTIF(G16:X16,"Y")) -> 0 | Z16: =IF(D16="","",VLOOKUP(Y16,TORCH_Tables!$AA$3:$AB$29,2,FALSE))
Y17: =IF(D17="",0,COUNTIF(G17:X17,"Y")) -> 0 | Z17: =IF(D17="","",VLOOKUP(Y17,TORCH_Tables!$AA$3:$AB$29,2,FALSE))
Y18: =IF(D18="",0,COUNTIF(G18:X18,"Y")) -> 0 | Z18: =IF(D18="","",VLOOKUP(Y18,TORCH_Tables!$AA$3:$AB$29,2,FALSE))
Y19: =IF(D19="",0,COUNTIF(G19:X19,"Y")) -> 0 | Z19: =IF(D19="","",VLOOKUP(Y19,TORCH_Tables!$AA$3:$AB$29,2,FALSE))
Y20: =IF(D20="",0,COUNTIF(G20:X20,"Y")) -> 0 | Z20: =IF(D20="","",VLOOKUP(Y20,TORCH_Tables!$AA$3:$AB$29,2,FALSE))
... Y503: =IF(D503="",0,COUNTIF(G503:X503,"Y")) -> 0 | Z503: =IF(D503="","",VLOOKUP(Y503,TORCH_Tables!$AA$3:$AB$29,2,FALSE))

Sheet Dissection
A1: TORCH - Dissection in the Classroom
G3: QUESTION No. and ANSWER KEY (Enter the student's response - "Y" if correct, "N" if incorrect)
E4: Question Number | G4: 1 | H4: 2 | I4: 3 | J4: 4 | K4: 5 | L4: 6 | M4: 7 | N4: 8 | O4: 9 | P4: 10 | Q4: 11 | R4: 12 | S4: 13 | T4: 14 | U4: 15 | V4: 16 | W4: 17 | X4: 18 | Y4: 19 | Z4: 20 | AA4: 21 | AB4: 22 | AC4: 23 | AD4: 24 | AE4: 25 | AF4: 26
E5: Item Difficulty
E6: Skill Assessed
A8: Date (dd/mm/yy) | B8: Yr_Lev | C8: HG | D8: Surname | E8: First_Name | F8: Student_ID | G8: Y | H8: Y | I8: Y | J8: Y | K8: Y | L8: Y | M8: Y | N8: Y | O8: Y | P8: Y | Q8: Y | R8: Y | S8: Y | T8: Y | U8: Y | V8: Y | W8: Y | X8: Y | Y8: Y | Z8: Y | AA8: Y | AB8: Y | AC8: Y | AD8: Y | AE8: Y | AF8: Y | AG8: Raw Score | AH8: TORCH Score
A9: 45356 | B9: 3 | C9: 3A | D9: Lname1 | E9: Fname1 | F9: XXXXX1 | AG9: =IF(D9="",0,COUNTIF(G9:AF9,"Y")) -> 0 | AH9: =IF(D9="","",VLOOKUP(AG9,TORCH_Tables!$AC$3:$AD$29,2,FALSE)) -> 36
A10: 45356 | B10: 3 | C10: 3A | D10: Lname2 | E10: Fname2 | F10: XXXXX2 | AG10: =IF(D10="",0,COUNTIF(G10:AF10,"Y")) -> 0 | AH10: =IF(D10="","",VLOOKUP(AG10,TORCH_Tables!$AC$3:$AD$29,2,FALSE)) -> 36
A11: 45356 | B11: 3 | C11: 3A | D11: Lname3 | E11: Fname3 | F11: XXXXX3 | AG11: =IF(D11="",0,COUNTIF(G11:AF11,"Y")) -> 0 | AH11: =IF(D11="","",VLOOKUP(AG11,TORCH_Tables!$AC$3:$AD$29,2,FALSE)) -> 36
A12: 45356 | B12: 3 | C12: 3A | D12: Lname4 | E12: Fname4 | F12: XXXXX4 | AG12: =IF(D12="",0,COUNTIF(G12:AF12,"Y")) -> 0 | AH12: =IF(D12="","",VLOOKUP(AG12,TORCH_Tables!$AC$3:$AD$29,2,FALSE)) -> 36
A13: 45356 | B13: 3 | C13: 3B | D13: ULname13 | E13: UFname13 | F13: UNLISTED | AG13: =IF(D13="",0,COUNTIF(G13:AF13,"Y")) -> 0 | AH13: =IF(D13="","",VLOOKUP(AG13,TORCH_Tables!$AC$3:$AD$29,2,FALSE)) -> 36
A14: 45356 | B14: 3 | C14: 3A | D14: Lname5 | E14: Fname5 | F14: XXXXX5 | AG14: =IF(D14="",0,COUNTIF(G14:AF14,"Y")) -> 0 | AH14: =IF(D14="","",VLOOKUP(AG14,TORCH_Tables!$AC$3:$AD$29,2,FALSE)) -> 36
A15: 45356 | B15: 3 | C15: 3B | D15: Lname6 | E15: Fname6 | F15: XXXXX6 | AG15: =IF(D15="",0,COUNTIF(G15:AF15,"Y")) -> 0 | AH15: =IF(D15="","",VLOOKUP(AG15,TORCH_Tables!$AC$3:$AD$29,2,FALSE)) -> 36
A16: 45356 | B16: 3 | C16: 3B | D16: Lname7 | E16: Fname7 | F16: XXXXX7 | AG16: =IF(D16="",0,COUNTIF(G16:AF16,"Y")) -> 0 | AH16: =IF(D16="","",VLOOKUP(AG16,TORCH_Tables!$AC$3:$AD$29,2,FALSE)) -> 36
