Workbook

Sheet Main Menu
B2: Single Word Spelling Test Scoring Templates
B4: This series of spreadsheets provide the templates required to enter ACER's Single Word Spelling Test (SWST) results into the Student Performance Analyser (SPA). Click on the appropriate button (at right) to select the correct Test Form proforma to complete. Follow the instructions opposite. | H4: Step 1: Click on the appropriate button (at left) to select the correct Test Form proforma to complete. Step 2: For each student, enter the Date (when test was sat), Year Level, Home Group, Name, and Student ID (CASES No. or Student No.). Step 3: For each question, enter their response (their score will be calculated) OR enter their Raw Score OR enter their PAT Score. Step 4: Save and upload into SPA.
B29: Click here to find out more about other tests available from ACER | H29: Click here to find out more about the Student Performance Analyser

Sheet SWST A
A1: SWST - Test A
H3: QUESTION No. and ANSWER KEY (Enter the student's response - "Y" if correct; "N" if incorrect )
F4: Question Number | H4: 1 | I4: 2 | J4: 3 | K4: 4 | L4: 5 | M4: 6 | N4: 7 | O4: 8 | P4: 9 | Q4: 10 | R4: 11 | S4: 12 | T4: 13 | U4: 14 | V4: 15 | W4: 16 | X4: 17 | Y4: 18 | Z4: 19 | AA4: 20 | AB4: 21 | AC4: 22 | AD4: 23 | AE4: 24 | AF4: 25 | AG4: 26 | AH4: 27 | AI4: 28 | AJ4: 29 | AK4: 30
F5: Spelling Words | H5: ON | I5: IT | J5: UP | K5: AND | L5: CAN | M5: BUT | N5: YES | O5: FOX | P5: WENT | Q5: FROM | R5: WAS | S5: PLUG | T5: DRUM | U5: HOME | V5: BLACK | W5: RING | X5: HAVE | Y5: LIKE | Z5: JUMP | AA5: SOME | AB5: CALL | AC5: MADE | AD5: FLY | AE5: TRICK | AF5: SMELL | AG5: KEEP | AH5: THINK | AI5: FOOTBALL | AJ5: SHOUT | AK5: TEAM
A7: required | B7: required | C7: required | D7: optional | E7: required | F7: required | G7: required
A8: Test Date (dd/mm/yy) | B8: Date of Birth (dd/mm/yy) | C8: Yr_Lev | D8: Grp | E8: Surname | F8: First_Name | G8: Student_ID | H8: Y | I8: Y | J8: Y | K8: Y | L8: Y | M8: Y | N8: Y | O8: Y | P8: Y | Q8: Y | R8: Y | S8: Y | T8: Y | U8: Y | V8: Y | W8: Y | X8: Y | Y8: Y | Z8: Y | AA8: Y | AB8: Y | AC8: Y | AD8: Y | AE8: Y | AF8: Y | AG8: Y | AH8: Y | AI8: Y | AJ8: Y | AK8: Y | AL8: Raw Score | AM8: Progress Score | AN8: Spelling Age
A9: 45356 | B9: 40959 | C9: 3 | D9: 3A | E9: Lname1 | F9: Fname1 | G9: XXXXX1 | AL9: =IF(E9="",0,COUNTIF(H9:AK9,"=Y")) -> 0 | AM9: =IF(E9="","",VLOOKUP(AL9,LookUp!$A$3:$C$33,2,FALSE)) -> 0 | AN9: =IF(E9="","",VLOOKUP(AL9,LookUp!$A$3:$C$33,3,FALSE)) -> <=5:10
A10: 45356 | B10: 40960 | C10: 3 | D10: 3A | E10: Lname2 | F10: Fname2 | G10: XXXXX2 | AL10: =IF(E10="",0,COUNTIF(H10:AK10,"=Y")) -> 0 | AM10: =IF(E10="","",VLOOKUP(AL10,LookUp!$A$3:$C$33,2,FALSE)) -> 0 | AN10: =IF(E10="","",VLOOKUP(AL10,LookUp!$A$3:$C$33,3,FALSE)) -> <=5:10
A11: 45356 | B11: 40961 | C11: 3 | D11: 3A | E11: Lname3 | F11: Fname3 | G11: XXXXX3 | AL11: =IF(E11="",0,COUNTIF(H11:AK11,"=Y")) -> 0 | AM11: =IF(E11="","",VLOOKUP(AL11,LookUp!$A$3:$C$33,2,FALSE)) -> 0 | AN11: =IF(E11="","",VLOOKUP(AL11,LookUp!$A$3:$C$33,3,FALSE)) -> <=5:10
A12: 45356 | B12: 40962 | C12: 3 | D12: 3A | E12: Lname4 | F12: Fname4 | G12: XXXXX4 | AL12: =IF(E12="",0,COUNTIF(H12:AK12,"=Y")) -> 0 | AM12: =IF(E12="","",VLOOKUP(AL12,LookUp!$A$3:$C$33,2,FALSE)) -> 0 | AN12: =IF(E12="","",VLOOKUP(AL12,LookUp!$A$3:$C$33,3,FALSE)) -> <=5:10
A13: 45356 | B13: 40970 | C13: 3 | D13: 3B | E13: ULname13 | F13: UFname13 | G13: UNLISTED | AL13: =IF(E13="",0,COUNTIF(H13:AK13,"=Y")) -> 0 | AM13: =IF(E13="","",VLOOKUP(AL13,LookUp!$A$3:$C$33,2,FALSE)) -> 0 | AN13: =IF(E13="","",VLOOKUP(AL13,LookUp!$A$3:$C$33,3,FALSE)) -> <=5:10
A14: 45356 | B14: 40963 | C14: 3 | D14: 3A | E14: Lname5 | F14: Fname5 | G14: XXXXX5 | AL14: =IF(E14="",0,COUNTIF(H14:AK14,"=Y")) -> 0 | AM14: =IF(E14="","",VLOOKUP(AL14,LookUp!$A$3:$C$33,2,FALSE)) -> 0 | AN14: =IF(E14="","",VLOOKUP(AL14,LookUp!$A$3:$C$33,3,FALSE)) -> <=5:10
A15: 45356 | B15: 40964 | C15: 3 | D15: 3B | E15: Lname6 | F15: Fname6 | G15: XXXXX6 | AL15: =IF(E15="",0,COUNTIF(H15:AK15,"=Y")) -> 0 | AM15: =IF(E15="","",VLOOKUP(AL15,LookUp!$A$3:$C$33,2,FALSE)) -> 0 | AN15: =IF(E15="","",VLOOKUP(AL15,LookUp!$A$3:$C$33,3,FALSE)) -> <=5:10
A16: 45356 | B16: 40965 | C16: 3 | D16: 3B | E16: Lname7 | F16: Fname7 | G16: XXXXX7 | AL16: =IF(E16="",0,COUNTIF(H16:AK16,"=Y")) -> 0 | AM16: =IF(E16="","",VLOOKUP(AL16,LookUp!$A$3:$C$33,2,FALSE)) -> 0 | AN16: =IF(E16="","",VLOOKUP(AL16,LookUp!$A$3:$C$33,3,FALSE)) -> <=5:10
A17: 45356 | B17: 40966 | C17: 3 | D17: 3B | E17: Lname8 | F17: Fname8 | G17: XXXXX8 | AL17: =IF(E17="",0,COUNTIF(H17:AK17,"=Y")) -> 0 | AM17: =IF(E17="","",VLOOKUP(AL17,LookUp!$A$3:$C$33,2,FALSE)) -> 0 | AN17: =IF(E17="","",VLOOKUP(AL17,LookUp!$A$3:$C$33,3,FALSE)) -> <=5:10
A18: 45356 | B18: 40967 | C18: 3 | D18: 3B | E18: Lname9 | F18: Fname9 | G18: XXXXX9 | AL18: =IF(E18="",0,COUNTIF(H18:AK18,"=Y")) -> 0 | AM18: =IF(E18="","",VLOOKUP(AL18,LookUp!$A$3:$C$33,2,FALSE)) -> 0 | AN18: =IF(E18="","",VLOOKUP(AL18,LookUp!$A$3:$C$33,3,FALSE)) -> <=5:10
A19: 45356 | B19: 40968 | C19: 3 | D19: 3B | E19: Lname10 | F19: Fname10 | G19: XXXXX10 | AL19: =IF(E19="",0,COUNTIF(H19:AK19,"=Y")) -> 0 | AM19: =IF(E19="","",VLOOKUP(AL19,LookUp!$A$3:$C$33,2,FALSE)) -> 0 | AN19: =IF(E19="","",VLOOKUP(AL19,LookUp!$A$3:$C$33,3,FALSE)) -> <=5:10
AL20: =IF(E20="",0,COUNTIF(H20:AK20,"=Y")) -> 0 | AM20: =IF(E20="","",VLOOKUP(AL20,LookUp!$A$3:$C$33,2,FALSE)) | AN20: =IF(E20="","",VLOOKUP(AL20,LookUp!$A$3:$C$33,3,FALSE))
AL21: =IF(E21="",0,COUNTIF(H21:AK21,"=Y")) -> 0 | AM21: =IF(E21="","",VLOOKUP(AL21,LookUp!$A$3:$C$33,2,FALSE)) | AN21: =IF(E21="","",VLOOKUP(AL21,LookUp!$A$3:$C$33,3,FALSE))
AL22: =IF(E22="",0,COUNTIF(H22:AK22,"=Y")) -> 0 | AM22: =IF(E22="","",VLOOKUP(AL22,LookUp!$A$3:$C$33,2,FALSE)) | AN22: =IF(E22="","",VLOOKUP(AL22,LookUp!$A$3:$C$33,3,FALSE))
AL23: =IF(E23="",0,COUNTIF(H23:AK23,"=Y")) -> 0 | AM23: =IF(E23="","",VLOOKUP(AL23,LookUp!$A$3:$C$33,2,FALSE)) | AN23: =IF(E23="","",VLOOKUP(AL23,LookUp!$A$3:$C$33,3,FALSE))
AL24: =IF(E24="",0,COUNTIF(H24:AK24,"=Y")) -> 0 | AM24: =IF(E24="","",VLOOKUP(AL24,LookUp!$A$3:$C$33,2,FALSE)) | AN24: =IF(E24="","",VLOOKUP(AL24,LookUp!$A$3:$C$33,3,FALSE))
AL25: =IF(E25="",0,COUNTIF(H25:AK25,"=Y")) -> 0 | AM25: =IF(E25="","",VLOOKUP(AL25,LookUp!$A$3:$C$33,2,FALSE)) | AN25: =IF(E25="","",VLOOKUP(AL25,LookUp!$A$3:$C$33,3,FALSE))
AL26: =IF(E26="",0,COUNTIF(H26:AK26,"=Y")) -> 0 | AM26: =IF(E26="","",VLOOKUP(AL26,LookUp!$A$3:$C$33,2,FALSE)) | AN26: =IF(E26="","",VLOOKUP(AL26,LookUp!$A$3:$C$33,3,FALSE))
AL27: =IF(E27="",0,COUNTIF(H27:AK27,"=Y")) -> 0 | AM27: =IF(E27="","",VLOOKUP(AL27,LookUp!$A$3:$C$33,2,FALSE)) | AN27: =IF(E27="","",VLOOKUP(AL27,LookUp!$A$3:$C$33,3,FALSE))
AL28: =IF(E28="",0,COUNTIF(H28:AK28,"=Y")) -> 0 | AM28: =IF(E28="","",VLOOKUP(AL28,LookUp!$A$3:$C$33,2,FALSE)) | AN28: =IF(E28="","",VLOOKUP(AL28,LookUp!$A$3:$C$33,3,FALSE))
AL29: =IF(E29="",0,COUNTIF(H29:AK29,"=Y")) -> 0 | AM29: =IF(E29="","",VLOOKUP(AL29,LookUp!$A$3:$C$33,2,FALSE)) | AN29: =IF(E29="","",VLOOKUP(AL29,LookUp!$A$3:$C$33,3,FALSE))
AL30: =IF(E30="",0,COUNTIF(H30:AK30,"=Y")) -> 0 | AM30: =IF(E30="","",VLOOKUP(AL30,LookUp!$A$3:$C$33,2,FALSE)) | AN30: =IF(E30="","",VLOOKUP(AL30,LookUp!$A$3:$C$33,3,FALSE))
AL31: =IF(E31="",0,COUNTIF(H31:AK31,"=Y")) -> 0 | AM31: =IF(E31="","",VLOOKUP(AL31,LookUp!$A$3:$C$33,2,FALSE)) | AN31: =IF(E31="","",VLOOKUP(AL31,LookUp!$A$3:$C$33,3,FALSE))
... AL471: =IF(E471="",0,COUNTIF(H471:AK471,"=Y")) -> 0 | AM471: =IF(E471="","",VLOOKUP(AL471,LookUp!$A$3:$C$33,2,FALSE)) | AN471: =IF(E471="","",VLOOKUP(AL471,LookUp!$A$3:$C$33,3,FALSE))

Sheet SWST B
A1: SWST - Test B
H3: QUESTION No. and ANSWER KEY (Enter the student's response - "Y" if correct; "N" if incorrect )
F4: Question Number | H4: 1 | I4: 2 | J4: 3 | K4: 4 | L4: 5 | M4: 6 | N4: 7 | O4: 8 | P4: 9 | Q4: 10 | R4: 11 | S4: 12 | T4: 13 | U4: 14 | V4: 15 | W4: 16 | X4: 17 | Y4: 18 | Z4: 19 | AA4: 20 | AB4: 21 | AC4: 22 | AD4: 23 | AE4: 24 | AF4: 25 | AG4: 26 | AH4: 27 | AI4: 28 | AJ4: 29 | AK4: 30 | AL4: 31 | AM4: 32 | AN4: 33 | AO4: 34 | AP4: 35
F5: Spelling Words | H5: CAN | I5: BUT | J5: YES | K5: FOX | L5: WAS | M5: FROM | N5: TODAY | O5: WENT | P5: PLUG | Q5: HOME | R5: RING | S5: HAVE | T5: JUMP | U5: MADE | V5: NIGHT | W5: FLY | X5: CALL | Y5: LIFT | Z5: WEEKEND | AA5: SOME | AB5: TRICK | AC5: FOOTBALL | AD5: OUTSIDE | AE5: KEEP | AF5: BECAUSE | AG5: THINK | AH5: SHOWER | AI5: KICKING | AJ5: AGAIN | AK5: TEAM | AL5: FLOAT | AM5: USED | AN5: TRIED | AO5: DANCING | AP5: INFORMATION
A7: required | B7: required | C7: required | D7: optional | E7: required | F7: required | G7: required
A8: Test Date (dd/mm/yy) | B8: Date of Birth (dd/mm/yy) | C8: Yr_Lev | D8: Grp | E8: Surname | F8: First_Name | G8: Student_ID | H8: Y | I8: Y | J8: Y | K8: Y | L8: Y | M8: Y | N8: Y | O8: Y | P8: Y | Q8: Y | R8: Y | S8: Y | T8: Y | U8: Y | V8: Y | W8: Y | X8: Y | Y8: Y | Z8: Y | AA8: Y | AB8: Y | AC8: Y | AD8: Y | AE8: Y | AF8: Y | AG8: Y | AH8: Y | AI8: Y | AJ8: Y | AK8: Y | AL8: Y | AM8: Y | AN8: Y | AO8: Y | AP8: Y | AQ8: Raw Score | AR8: Progress Score | AS8: Spelling Age
A9: 45356 | B9: 40959 | C9: 3 | D9: 3A | E9: Lname1 | F9: Fname1 | G9: XXXXX1 | AQ9: =IF(E9="",0,COUNTIF(H9:AP9,"=Y")) -> 0 | AR9: =IF(E9="","",VLOOKUP(AQ9,LookUp!$E$3:$G$38,2,FALSE)) -> 14 | AS9: =IF(E9="","",VLOOKUP(AQ9,LookUp!$E$3:$G$38,3,FALSE)) -> <=5:10
A10: 45356 | B10: 40960 | C10: 3 | D10: 3A | E10: Lname2 | F10: Fname2 | G10: XXXXX2 | AQ10: =IF(E10="",0,COUNTIF(H10:AP10,"=Y")) -> 0 | AR10: =IF(E10="","",VLOOKUP(AQ10,LookUp!$E$3:$G$38,2,FALSE)) -> 14 | AS10: =IF(E10="","",VLOOKUP(AQ10,LookUp!$E$3:$G$38,3,FALSE)) -> <=5:10
A11: 45356 | B11: 40961 | C11: 3 | D11: 3A | E11: Lname3 | F11: Fname3 | G11: XXXXX3 | AQ11: =IF(E11="",0,COUNTIF(H11:AP11,"=Y")) -> 0 | AR11: =IF(E11="","",VLOOKUP(AQ11,LookUp!$E$3:$G$38,2,FALSE)) -> 14 | AS11: =IF(E11="","",VLOOKUP(AQ11,LookUp!$E$3:$G$38,3,FALSE)) -> <=5:10
A12: 45356 | B12: 40962 | C12: 3 | D12: 3A | E12: Lname4 | F12: Fname4 | G12: XXXXX4 | AQ12: =IF(E12="",0,COUNTIF(H12:AP12,"=Y")) -> 0 | AR12: =IF(E12="","",VLOOKUP(AQ12,LookUp!$E$3:$G$38,2,FALSE)) -> 14 | AS12: =IF(E12="","",VLOOKUP(AQ12,LookUp!$E$3:$G$38,3,FALSE)) -> <=5:10
A13: 45356 | B13: 40970 | C13: 3 | D13: 3B | E13: ULname13 | F13: UFname13 | G13: UNLISTED | AQ13: =IF(E13="",0,COUNTIF(H13:AP13,"=Y")) -> 0 | AR13: =IF(E13="","",VLOOKUP(AQ13,LookUp!$E$3:$G$38,2,FALSE)) -> 14 | AS13: =IF(E13="","",VLOOKUP(AQ13,LookUp!$E$3:$G$38,3,FALSE)) -> <=5:10
A14: 45356 | B14: 40963 | C14: 3 | D14: 3A | E14: Lname5 | F14: Fname5 | G14: XXXXX5 | AQ14: =IF(E14="",0,COUNTIF(H14:AP14,"=Y")) -> 0 | AR14: =IF(E14="","",VLOOKUP(AQ14,LookUp!$E$3:$G$38,2,FALSE)) -> 14 | AS14: =IF(E14="","",VLOOKUP(AQ14,LookUp!$E$3:$G$38,3,FALSE)) -> <=5:10
A15: 45356 | B15: 40964 | C15: 3 | D15: 3B | E15: Lname6 | F15: Fname6 | G15: XXXXX6 | AQ15: =IF(E15="",0,COUNTIF(H15:AP15,"=Y")) -> 0 | AR15: =IF(E15="","",VLOOKUP(AQ15,LookUp!$E$3:$G$38,2,FALSE)) -> 14 | AS15: =IF(E15="","",VLOOKUP(AQ15,LookUp!$E$3:$G$38,3,FALSE)) -> <=5:10
A16: 45356 | B16: 40965 | C16: 3 | D16: 3B | E16: Lname7 | F16: Fname7 | G16: XXXXX7 | AQ16: =IF(E16="",0,COUNTIF(H16:AP16,"=Y")) -> 0 | AR16: =IF(E16="","",VLOOKUP(AQ16,LookUp!$E$3:$G$38,2,FALSE)) -> 14 | AS16: =IF(E16="","",VLOOKUP(AQ16,LookUp!$E$3:$G$38,3,FALSE)) -> <=5:10
A17: 45356 | B17: 40966 | C17: 3 | D17: 3B | E17: Lname8 | F17: Fname8 | G17: XXXXX8 | AQ17: =IF(E17="",0,COUNTIF(H17:AP17,"=Y")) -> 0 | AR17: =IF(E17="","",VLOOKUP(AQ17,LookUp!$E$3:$G$38,2,FALSE)) -> 14 | AS17: =IF(E17="","",VLOOKUP(AQ17,LookUp!$E$3:$G$38,3,FALSE)) -> <=5:10
A18: 45356 | B18: 40967 | C18: 3 | D18: 3B | E18: Lname9 | F18: Fname9 | G18: XXXXX9 | AQ18: =IF(E18="",0,COUNTIF(H18:AP18,"=Y")) -> 0 | AR18: =IF(E18="","",VLOOKUP(AQ18,LookUp!$E$3:$G$38,2,FALSE)) -> 14 | AS18: =IF(E18="","",VLOOKUP(AQ18,LookUp!$E$3:$G$38,3,FALSE)) -> <=5:10
A19: 45356 | B19: 40968 | C19: 3 | D19: 3B | E19: Lname10 | F19: Fname10 | G19: XXXXX10 | AQ19: =IF(E19="",0,COUNTIF(H19:AP19,"=Y")) -> 0 | AR19: =IF(E19="","",VLOOKUP(AQ19,LookUp!$E$3:$G$38,2,FALSE)) -> 14 | AS19: =IF(E19="","",VLOOKUP(AQ19,LookUp!$E$3:$G$38,3,FALSE)) -> <=5:10
AQ20: =IF(E20="",0,COUNTIF(H20:AP20,"=Y")) -> 0 | AR20: =IF(E20="","",VLOOKUP(AQ20,LookUp!$E$3:$G$38,2,FALSE)) | AS20: =IF(E20="","",VLOOKUP(AQ20,LookUp!$E$3:$G$38,3,FALSE))
AQ21: =IF(E21="",0,COUNTIF(H21:AP21,"=Y")) -> 0 | AR21: =IF(E21="","",VLOOKUP(AQ21,LookUp!$E$3:$G$38,2,FALSE)) | AS21: =IF(E21="","",VLOOKUP(AQ21,LookUp!$E$3:$G$38,3,FALSE))
AQ22: =IF(E22="",0,COUNTIF(H22:AP22,"=Y")) -> 0 | AR22: =IF(E22="","",VLOOKUP(AQ22,LookUp!$E$3:$G$38,2,FALSE)) | AS22: =IF(E22="","",VLOOKUP(AQ22,LookUp!$E$3:$G$38,3,FALSE))
AQ23: =IF(E23="",0,COUNTIF(H23:AP23,"=Y")) -> 0 | AR23: =IF(E23="","",VLOOKUP(AQ23,LookUp!$E$3:$G$38,2,FALSE)) | AS23: =IF(E23="","",VLOOKUP(AQ23,LookUp!$E$3:$G$38,3,FALSE))
AQ24: =IF(E24="",0,COUNTIF(H24:AP24,"=Y")) -> 0 | AR24: =IF(E24="","",VLOOKUP(AQ24,LookUp!$E$3:$G$38,2,FALSE)) | AS24: =IF(E24="","",VLOOKUP(AQ24,LookUp!$E$3:$G$38,3,FALSE))
AQ25: =IF(E25="",0,COUNTIF(H25:AP25,"=Y")) -> 0 | AR25: =IF(E25="","",VLOOKUP(AQ25,LookUp!$E$3:$G$38,2,FALSE)) | AS25: =IF(E25="","",VLOOKUP(AQ25,LookUp!$E$3:$G$38,3,FALSE))
AQ26: =IF(E26="",0,COUNTIF(H26:AP26,"=Y")) -> 0 | AR26: =IF(E26="","",VLOOKUP(AQ26,LookUp!$E$3:$G$38,2,FALSE)) | AS26: =IF(E26="","",VLOOKUP(AQ26,LookUp!$E$3:$G$38,3,FALSE))
AQ27: =IF(E27="",0,COUNTIF(H27:AP27,"=Y")) -> 0 | AR27: =IF(E27="","",VLOOKUP(AQ27,LookUp!$E$3:$G$38,2,FALSE)) | AS27: =IF(E27="","",VLOOKUP(AQ27,LookUp!$E$3:$G$38,3,FALSE))
AQ28: =IF(E28="",0,COUNTIF(H28:AP28,"=Y")) -> 0 | AR28: =IF(E28="","",VLOOKUP(AQ28,LookUp!$E$3:$G$38,2,FALSE)) | AS28: =IF(E28="","",VLOOKUP(AQ28,LookUp!$E$3:$G$38,3,FALSE))
AQ29: =IF(E29="",0,COUNTIF(H29:AP29,"=Y")) -> 0 | AR29: =IF(E29="","",VLOOKUP(AQ29,LookUp!$E$3:$G$38,2,FALSE)) | AS29: =IF(E29="","",VLOOKUP(AQ29,LookUp!$E$3:$G$38,3,FALSE))
AQ30: =IF(E30="",0,COUNTIF(H30:AP30,"=Y")) -> 0 | AR30: =IF(E30="","",VLOOKUP(AQ30,LookUp!$E$3:$G$38,2,FALSE)) | AS30: =IF(E30="","",VLOOKUP(AQ30,LookUp!$E$3:$G$38,3,FALSE))
AQ31: =IF(E31="",0,COUNTIF(H31:AP31,"=Y")) -> 0 | AR31: =IF(E31="","",VLOOKUP(AQ31,LookUp!$E$3:$G$38,2,FALSE)) | AS31: =IF(E31="","",VLOOKUP(AQ31,LookUp!$E$3:$G$38,3,FALSE))
... AQ467: =IF(E467="",0,COUNTIF(H467:AP467,"=Y")) -> 0 | AR467: =IF(E467="","",VLOOKUP(AQ467,LookUp!$E$3:$G$38,2,FALSE)) | AS467: =IF(E467="","",VLOOKUP(AQ467,LookUp!$E$3:$G$38,3,FALSE))

Sheet SWST C
A1: SWST - Test C
H3: QUESTION No. and ANSWER KEY (Enter the student's response - "Y" if correct; "N" if incorrect )
F4: Question Number | H4: 1 | I4: 2 | J4: 3 | K4: 4 | L4: 5 | M4: 6 | N4: 7 | O4: 8 | P4: 9 | Q4: 10 | R4: 11 | S4: 12 | T4: 13 | U4: 14 | V4: 15 | W4: 16 | X4: 17 | Y4: 18 | Z4: 19 | AA4: 20 | AB4: 21 | AC4: 22 | AD4: 23 | AE4: 24 | AF4: 25 | AG4: 26 | AH4: 27 | AI4: 28 | AJ4: 29 | AK4: 30 | AL4: 31 | AM4: 32 | AN4: 33 | AO4: 34 | AP4: 35 | AQ4: 36 | AR4: 37 | AS4: 38 | AT4: 39 | AU4: 40 | AV4: 41 | AW4: 42 | AX4: 43 | AY4: 44 | AZ4: 45
F5: Spelling Words | H5: BUT | I5: WAS | J5: FROM | K5: TODAY | L5: WENT | M5: JUMP | N5: FOOTBALL | O5: SAID | P5: NIGHT | Q5: WITHOUT | R5: STAMP | S5: THINK | T5: TEAM | U5: STARTED | V5: ROUND | W5: COULD | X5: BIRTHDAY | Y5: KICKING | Z5: SWIMMING | AA5: SHOWER | AB5: SMOKE | AC5: AGAIN | AD5: HOPING | AE5: UNSELFISH | AF5: CATCH | AG5: USED | AH5: COMING | AI5: FLOAT | AJ5: BRUSHES | AK5: CRIED | AL5: DRESSED | AM5: LEAVES | AN5: VOICE | AO5: CIRCLE | AP5: DANCING | AQ5: PRIZES | AR5: HEDGE | AS5: ENJOYABLE | AT5: INFORMATION | AU5: PARTIES | AV5: EXCITING | AW5: PHOTOGRAPHS | AX5: COMPLAINED | AY5: DANGEROUS | AZ5: MEASURED
A7: required | B7: required | C7: required | D7: optional | E7: required | F7: required | G7: required
A8: Test Date (dd/mm/yy) | B8: Date of Birth (dd/mm/yy) | C8: Yr_Lev | D8: Grp | E8: Surname | F8: First_Name | G8: Student_ID | H8: Y | I8: Y | J8: Y | K8: Y | L8: Y | M8: Y | N8: Y | O8: Y | P8: Y | Q8: Y | R8: Y | S8: Y | T8: Y | U8: Y | V8: Y | W8: Y | X8: Y | Y8: Y | Z8: Y | AA8: Y | AB8: Y | AC8: Y | AD8: Y | AE8: Y | AF8: Y | AG8: Y | AH8: Y | AI8: Y | AJ8: Y | AK8: Y | AL8: Y | AM8: Y | AN8: Y | AO8: Y | AP8: Y | AQ8: Y | AR8: Y | AS8: Y | AT8: Y | AU8: Y | AV8: Y | AW8: Y | AX8: Y | AY8: Y | AZ8: Y | BA8: Raw Score | BB8: Progress Score | BC8: Spelling Age
A9: 45356 | B9: 40959 | C9: 3 | D9: 3A | E9: Lname1 | F9: Fname1 | G9: XXXXX1 | BA9: =IF(E9="",0,COUNTIF(H9:AZ9,"=Y")) -> 0 | BB9: =IF(E9="","",VLOOKUP(BA9,LookUp!$I$3:$K$48,2,FALSE)) -> 32 | BC9: =IF(E9="","",VLOOKUP(BA9,LookUp!$I$3:$K$48,3,FALSE)) -> <=5:10
A10: 45356 | B10: 40960 | C10: 3 | D10: 3A | E10: Lname2 | F10: Fname2 | G10: XXXXX2 | BA10: =IF(E10="",0,COUNTIF(H10:AZ10,"=Y")) -> 0 | BB10: =IF(E10="","",VLOOKUP(BA10,LookUp!$I$3:$K$48,2,FALSE)) -> 32 | BC10: =IF(E10="","",VLOOKUP(BA10,LookUp!$I$3:$K$48,3,FALSE)) -> <=5:10
A11: 45356 | B11: 40961 | C11: 3 | D11: 3A | E11: Lname3 | F11: Fname3 | G11: XXXXX3 | BA11: =IF(E11="",0,COUNTIF(H11:AZ11,"=Y")) -> 0 | BB11: =IF(E11="","",VLOOKUP(BA11,LookUp!$I$3:$K$48,2,FALSE)) -> 32 | BC11: =IF(E11="","",VLOOKUP(BA11,LookUp!$I$3:$K$48,3,FALSE)) -> <=5:10
A12: 45356 | B12: 40962 | C12: 3 | D12: 3A | E12: Lname4 | F12: Fname4 | G12: XXXXX4 | BA12: =IF(E12="",0,COUNTIF(H12:AZ12,"=Y")) -> 0 | BB12: =IF(E12="","",VLOOKUP(BA12,LookUp!$I$3:$K$48,2,FALSE)) -> 32 | BC12: =IF(E12="","",VLOOKUP(BA12,LookUp!$I$3:$K$48,3,FALSE)) -> <=5:10
A13: 45356 | B13: 40970 | C13: 3 | D13: 3B | E13: ULname13 | F13: UFname13 | G13: UNLISTED | BA13: =IF(E13="",0,COUNTIF(H13:AZ13,"=Y")) -> 0 | BB13: =IF(E13="","",VLOOKUP(BA13,LookUp!$I$3:$K$48,2,FALSE)) -> 32 | BC13: =IF(E13="","",VLOOKUP(BA13,LookUp!$I$3:$K$48,3,FALSE)) -> <=5:10
A14: 45356 | B14: 40963 | C14: 3 | D14: 3A | E14: Lname5 | F14: Fname5 | G14: XXXXX5 | BA14: =IF(E14="",0,COUNTIF(H14:AZ14,"=Y")) -> 0 | BB14: =IF(E14="","",VLOOKUP(BA14,LookUp!$I$3:$K$48,2,FALSE)) -> 32 | BC14: =IF(E14="","",VLOOKUP(BA14,LookUp!$I$3:$K$48,3,FALSE)) -> <=5:10
A15: 45356 | B15: 40964 | C15: 3 | D15: 3B | E15: Lname6 | F15: Fname6 | G15: XXXXX6 | BA15: =IF(E15="",0,COUNTIF(H15:AZ15,"=Y")) -> 0 | BB15: =IF(E15="","",VLOOKUP(BA15,LookUp!$I$3:$K$48,2,FALSE)) -> 32 | BC15: =IF(E15="","",VLOOKUP(BA15,LookUp!$I$3:$K$48,3,FALSE)) -> <=5:10
A16: 45356 | B16: 40965 | C16: 3 | D16: 3B | E16: Lname7 | F16: Fname7 | G16: XXXXX7 | BA16: =IF(E16="",0,COUNTIF(H16:AZ16,"=Y")) -> 0 | BB16: =IF(E16="","",VLOOKUP(BA16,LookUp!$I$3:$K$48,2,FALSE)) -> 32 | BC16: =IF(E16="","",VLOOKUP(BA16,LookUp!$I$3:$K$48,3,FALSE)) -> <=5:10
A17: 45356 | B17: 40966 | C17: 3 | D17: 3B | E17: Lname8 | F17: Fname8 | G17: XXXXX8 | BA17: =IF(E17="",0,COUNTIF(H17:AZ17,"=Y")) -> 0 | BB17: =IF(E17="","",VLOOKUP(BA17,LookUp!$I$3:$K$48,2,FALSE)) -> 32 | BC17: =IF(E17="","",VLOOKUP(BA17,LookUp!$I$3:$K$48,3,FALSE)) -> <=5:10
A18: 45356 | B18: 40967 | C18: 3 | D18: 3B | E18: Lname9 | F18: Fname9 | G18: XXXXX9 | BA18: =IF(E18="",0,COUNTIF(H18:AZ18,"=Y")) -> 0 | BB18: =IF(E18="","",VLOOKUP(BA18,LookUp!$I$3:$K$48,2,FALSE)) -> 32 | BC18: =IF(E18="","",VLOOKUP(BA18,LookUp!$I$3:$K$48,3,FALSE)) -> <=5:10
A19: 45356 | B19: 40968 | C19: 3 | D19: 3B | E19: Lname10 | F19: Fname10 | G19: XXXXX10 | BA19: =IF(E19="",0,COUNTIF(H19:AZ19,"=Y")) -> 0 | BB19: =IF(E19="","",VLOOKUP(BA19,LookUp!$I$3:$K$48,2,FALSE)) -> 32 | BC19: =IF(E19="","",VLOOKUP(BA19,LookUp!$I$3:$K$48,3,FALSE)) -> <=5:10
BA20: =IF(E20="",0,COUNTIF(H20:AZ20,"=Y")) -> 0 | BB20: =IF(E20="","",VLOOKUP(BA20,LookUp!$I$3:$K$48,2,FALSE)) | BC20: =IF(E20="","",VLOOKUP(BA20,LookUp!$I$3:$K$48,3,FALSE))
BA21: =IF(E21="",0,COUNTIF(H21:AZ21,"=Y")) -> 0 | BB21: =IF(E21="","",VLOOKUP(BA21,LookUp!$I$3:$K$48,2,FALSE)) | BC21: =IF(E21="","",VLOOKUP(BA21,LookUp!$I$3:$K$48,3,FALSE))
BA22: =IF(E22="",0,COUNTIF(H22:AZ22,"=Y")) -> 0 | BB22: =IF(E22="","",VLOOKUP(BA22,LookUp!$I$3:$K$48,2,FALSE)) | BC22: =IF(E22="","",VLOOKUP(BA22,LookUp!$I$3:$K$48,3,FALSE))
BA23: =IF(E23="",0,COUNTIF(H23:AZ23,"=Y")) -> 0 | BB23: =IF(E23="","",VLOOKUP(BA23,LookUp!$I$3:$K$48,2,FALSE)) | BC23: =IF(E23="","",VLOOKUP(BA23,LookUp!$I$3:$K$48,3,FALSE))
BA24: =IF(E24="",0,COUNTIF(H24:AZ24,"=Y")) -> 0 | BB24: =IF(E24="","",VLOOKUP(BA24,LookUp!$I$3:$K$48,2,FALSE)) | BC24: =IF(E24="","",VLOOKUP(BA24,LookUp!$I$3:$K$48,3,FALSE))
BA25: =IF(E25="",0,COUNTIF(H25:AZ25,"=Y")) -> 0 | BB25: =IF(E25="","",VLOOKUP(BA25,LookUp!$I$3:$K$48,2,FALSE)) | BC25: =IF(E25="","",VLOOKUP(BA25,LookUp!$I$3:$K$48,3,FALSE))
BA26: =IF(E26="",0,COUNTIF(H26:AZ26,"=Y")) -> 0 | BB26: =IF(E26="","",VLOOKUP(BA26,LookUp!$I$3:$K$48,2,FALSE)) | BC26: =IF(E26="","",VLOOKUP(BA26,LookUp!$I$3:$K$48,3,FALSE))
BA27: =IF(E27="",0,COUNTIF(H27:AZ27,"=Y")) -> 0 | BB27: =IF(E27="","",VLOOKUP(BA27,LookUp!$I$3:$K$48,2,FALSE)) | BC27: =IF(E27="","",VLOOKUP(BA27,LookUp!$I$3:$K$48,3,FALSE))
BA28: =IF(E28="",0,COUNTIF(H28:AZ28,"=Y")) -> 0 | BB28: =IF(E28="","",VLOOKUP(BA28,LookUp!$I$3:$K$48,2,FALSE)) | BC28: =IF(E28="","",VLOOKUP(BA28,LookUp!$I$3:$K$48,3,FALSE))
BA29: =IF(E29="",0,COUNTIF(H29:AZ29,"=Y")) -> 0 | BB29: =IF(E29="","",VLOOKUP(BA29,LookUp!$I$3:$K$48,2,FALSE)) | BC29: =IF(E29="","",VLOOKUP(BA29,LookUp!$I$3:$K$48,3,FALSE))
BA30: =IF(E30="",0,COUNTIF(H30:AZ30,"=Y")) -> 0 | BB30: =IF(E30="","",VLOOKUP(BA30,LookUp!$I$3:$K$48,2,FALSE)) | BC30: =IF(E30="","",VLOOKUP(BA30,LookUp!$I$3:$K$48,3,FALSE))
BA31: =IF(E31="",0,COUNTIF(H31:AZ31,"=Y")) -> 0 | BB31: =IF(E31="","",VLOOKUP(BA31,LookUp!$I$3:$K$48,2,FALSE)) | BC31: =IF(E31="","",VLOOKUP(BA31,LookUp!$I$3:$K$48,3,FALSE))
... BA457: =IF(E457="",0,COUNTIF(H457:AZ457,"=Y")) -> 0 | BB457: =IF(E457="","",VLOOKUP(BA457,LookUp!$I$3:$K$48,2,FALSE)) | BC457: =IF(E457="","",VLOOKUP(BA457,LookUp!$I$3:$K$48,3,FALSE))

Sheet SWST D
A1: SWST - Test D
H3: QUESTION No. and ANSWER KEY (Enter the student's response - "Y" if correct; "N" if incorrect )
F4: Question Number | H4: 1 | I4: 2 | J4: 3 | K4: 4 | L4: 5 | M4: 6 | N4: 7 | O4: 8 | P4: 9 | Q4: 10 | R4: 11 | S4: 12 | T4: 13 | U4: 14 | V4: 15 | W4: 16 | X4: 17 | Y4: 18 | Z4: 19 | AA4: 20 | AB4: 21 | AC4: 22 | AD4: 23 | AE4: 24 | AF4: 25 | AG4: 26 | AH4: 27 | AI4: 28 | AJ4: 29 | AK4: 30 | AL4: 31 | AM4: 32 | AN4: 33 | AO4: 34 | AP4: 35 | AQ4: 36 | AR4: 37 | AS4: 38 | AT4: 39 | AU4: 40 | AV4: 41 | AW4: 42 | AX4: 43 | AY4: 44 | AZ4: 45 | BA4: 46 | BB4: 47 | BC4: 48 | BD4: 49 | BE4: 50
F5: Spelling Words | H5: TODAY | I5: JUMP | J5: THINK | K5: WENT | L5: TEAM | M5: SHOWER | N5: KICKING | O5: DEFROST | P5: AGAIN | Q5: FOUND | R5: CLASSES | S5: WOULD | T5: USED | U5: TRIES | V5: MATCH | W5: TOGETHER | X5: INVENTED | Y5: FRIENDS | Z5: VOICE | AA5: WRITING | AB5: ADVENTURE | AC5: STOPPED | AD5: DANCING | AE5: HEARD | AF5: EVERYWHERE | AG5: THIRTEEN | AH5: SKIPPING | AI5: HEDGE | AJ5: SUDDENLY | AK5: TIGHTER | AL5: DISAGREE | AM5: ALREADY | AN5: CHURCHES | AO5: INFORMATION | AP5: DANGEROUS | AQ5: STORIES | AR5: HAPPILY | AS5: ENOUGH | AT5: POTATOES | AU5: RESOECTFUL | AV5: COMPLAINED | AW5: OURSELVES | AX5: PHOTOGRAPHS | AY5: SANDWICHES | AZ5: MEASURED | BA5: WRAPPED | BB5: EXCITING | BC5: FRIGHTENED | BD5: EXPLOSION | BE5: CANCELLED
A7: required | B7: required | C7: required | D7: optional | E7: required | F7: required | G7: required
A8: Test Date (dd/mm/yy) | B8: Date of Birth (dd/mm/yy) | C8: Yr_Lev | D8: Grp | E8: Surname | F8: First_Name | G8: Student_ID | H8: Y | I8: Y | J8: Y | K8: Y | L8: Y | M8: Y | N8: Y | O8: Y | P8: Y | Q8: Y | R8: Y | S8: Y | T8: Y | U8: Y | V8: Y | W8: Y | X8: Y | Y8: Y | Z8: Y | AA8: Y | AB8: Y | AC8: Y | AD8: Y | AE8: Y | AF8: Y | AG8: Y | AH8: Y | AI8: Y | AJ8: Y | AK8: Y | AL8: Y | AM8: Y | AN8: Y | AO8: Y | AP8: Y | AQ8: Y | AR8: Y | AS8: Y | AT8: Y | AU8: Y | AV8: Y | AW8: Y | AX8: Y | AY8: Y | AZ8: Y | BA8: Y | BB8: Y | BC8: Y | BD8: Y | BE8: Y | BF8: Raw Score | BG8: Progress Score | BH8: Spelling Age
BF9: =IF(E9="",0,COUNTIF(H9:BE9,"=Y")) -> 0 | BG9: =IF(E9="","",VLOOKUP(BF9,LookUp!$M$3:$O$53,2,FALSE)) | BH9: =IF(E9="","",VLOOKUP(BF9,LookUp!$M$3:$O$53,3,FALSE))
BF10: =IF(E10="",0,COUNTIF(H10:BE10,"=Y")) -> 0 | BG10: =IF(E10="","",VLOOKUP(BF10,LookUp!$M$3:$O$53,2,FALSE)) | BH10: =IF(E10="","",VLOOKUP(BF10,LookUp!$M$3:$O$53,3,FALSE))
BF11: =IF(E11="",0,COUNTIF(H11:BE11,"=Y")) -> 0 | BG11: =IF(E11="","",VLOOKUP(BF11,LookUp!$M$3:$O$53,2,FALSE)) | BH11: =IF(E11="","",VLOOKUP(BF11,LookUp!$M$3:$O$53,3,FALSE))
BF12: =IF(E12="",0,COUNTIF(H12:BE12,"=Y")) -> 0 | BG12: =IF(E12="","",VLOOKUP(BF12,LookUp!$M$3:$O$53,2,FALSE)) | BH12: =IF(E12="","",VLOOKUP(BF12,LookUp!$M$3:$O$53,3,FALSE))
BF13: =IF(E13="",0,COUNTIF(H13:BE13,"=Y")) -> 0 | BG13: =IF(E13="","",VLOOKUP(BF13,LookUp!$M$3:$O$53,2,FALSE)) | BH13: =IF(E13="","",VLOOKUP(BF13,LookUp!$M$3:$O$53,3,FALSE))
BF14: =IF(E14="",0,COUNTIF(H14:BE14,"=Y")) -> 0 | BG14: =IF(E14="","",VLOOKUP(BF14,LookUp!$M$3:$O$53,2,FALSE)) | BH14: =IF(E14="","",VLOOKUP(BF14,LookUp!$M$3:$O$53,3,FALSE))
BF15: =IF(E15="",0,COUNTIF(H15:BE15,"=Y")) -> 0 | BG15: =IF(E15="","",VLOOKUP(BF15,LookUp!$M$3:$O$53,2,FALSE)) | BH15: =IF(E15="","",VLOOKUP(BF15,LookUp!$M$3:$O$53,3,FALSE))
BF16: =IF(E16="",0,COUNTIF(H16:BE16,"=Y")) -> 0 | BG16: =IF(E16="","",VLOOKUP(BF16,LookUp!$M$3:$O$53,2,FALSE)) | BH16: =IF(E16="","",VLOOKUP(BF16,LookUp!$M$3:$O$53,3,FALSE))
BF17: =IF(E17="",0,COUNTIF(H17:BE17,"=Y")) -> 0 | BG17: =IF(E17="","",VLOOKUP(BF17,LookUp!$M$3:$O$53,2,FALSE)) | BH17: =IF(E17="","",VLOOKUP(BF17,LookUp!$M$3:$O$53,3,FALSE))
BF18: =IF(E18="",0,COUNTIF(H18:BE18,"=Y")) -> 0 | BG18: =IF(E18="","",VLOOKUP(BF18,LookUp!$M$3:$O$53,2,FALSE)) | BH18: =IF(E18="","",VLOOKUP(BF18,LookUp!$M$3:$O$53,3,FALSE))
BF19: =IF(E19="",0,COUNTIF(H19:BE19,"=Y")) -> 0 | BG19: =IF(E19="","",VLOOKUP(BF19,LookUp!$M$3:$O$53,2,FALSE)) | BH19: =IF(E19="","",VLOOKUP(BF19,LookUp!$M$3:$O$53,3,FALSE))
BF20: =IF(E20="",0,COUNTIF(H20:BE20,"=Y")) -> 0 | BG20: =IF(E20="","",VLOOKUP(BF20,LookUp!$M$3:$O$53,2,FALSE)) | BH20: =IF(E20="","",VLOOKUP(BF20,LookUp!$M$3:$O$53,3,FALSE))
... BF452: =IF(E452="",0,COUNTIF(H452:BE452,"=Y")) -> 0 | BG452: =IF(E452="","",VLOOKUP(BF452,LookUp!$M$3:$O$53,2,FALSE)) | BH452: =IF(E452="","",VLOOKUP(BF452,LookUp!$M$3:$O$53,3,FALSE))

Sheet SWST E
A1: SWST - Test E
H3: QUESTION No. and ANSWER KEY (Enter the student's response - "Y" if correct; "N" if incorrect )
F4: Question Number | H4: 1 | I4: 2 | J4: 3 | K4: 4 | L4: 5 | M4: 6 | N4: 7 | O4: 8 | P4: 9 | Q4: 10 | R4: 11 | S4: 12 | T4: 13 | U4: 14 | V4: 15 | W4: 16 | X4: 17 | Y4: 18 | Z4: 19 | AA4: 20 | AB4: 21 | AC4: 22 | AD4: 23 | AE4: 24 | AF4: 25 | AG4: 26 | AH4: 27 | AI4: 28 | AJ4: 29 | AK4: 30 | AL4: 31 | AM4: 32 | AN4: 33 | AO4: 34 | AP4: 35 | AQ4: 36 | AR4: 37 | AS4: 38 | AT4: 39 | AU4: 40 | AV4: 41 | AW4: 42 | AX4: 43 | AY4: 44 | AZ4: 45 | BA4: 46 | BB4: 47 | BC4: 48 | BD4: 49 | BE4: 50
F5: Spelling Words | H5: TEAM | I5: FOUND | J5: BETWEEN | K5: DARKNESS | L5: KICKING | M5: AGAIN | N5: USED | O5: VOICE | P5: EARTHWORM | Q5: KNEW | R5: ANOTHER | S5: POWERFUL | T5: TREATMENT | U5: WATCH | V5: ADVENTURE | W5: WRITING | X5: REPLIED | Y5: THROUGH | Z5: STOPPED | AA5: UNFRIENDLY | AB5: CIRCLE | AC5: IMPORTANT | AD5: STORIES | AE5: HEDGE | AF5: ENJOYABLE | AG5: SHELVES | AH5: DANGEROUS | AI5: THOUGHTLESS | AJ5: RESPECTFUL | AK5: COMPLAINED | AL5: POTATOES | AM5: HALVES | AN5: PREDICTION | AO5: WRAPPED | AP5: MEASURED | AQ5: EXCITING | AR5: PARAGRAPHS | AS5: OMAGINE | AT5: POISONOUS | AU5: SENSIBLE | AV5: EXPLOSION | AW5: FRIGHTENED | AX5: UNINTERESTED | AY5: SURPRISE | AZ5: CEILING | BA5: TRAVELLED | BB5: ACHIEVE | BC5: MUSICIAN | BD5: EXCELLENT | BE5: DISCONNECTED
A7: required | B7: required | C7: required | D7: optional | E7: required | F7: required | G7: required
A8: Test Date (dd/mm/yy) | B8: Date of Birth (dd/mm/yy) | C8: Yr_Lev | D8: Grp | E8: Surname | F8: First_Name | G8: Student_ID | H8: Y | I8: Y | J8: Y | K8: Y | L8: Y | M8: Y | N8: Y | O8: Y | P8: Y | Q8: Y | R8: Y | S8: Y | T8: Y | U8: Y | V8: Y | W8: Y | X8: Y | Y8: Y | Z8: Y | AA8: Y | AB8: Y | AC8: Y | AD8: Y | AE8: Y | AF8: Y | AG8: Y | AH8: Y | AI8: Y | AJ8: Y | AK8: Y | AL8: Y | AM8: Y | AN8: Y | AO8: Y | AP8: Y | AQ8: Y | AR8: Y | AS8: Y | AT8: Y | AU8: Y | AV8: Y | AW8: Y | AX8: Y | AY8: Y | AZ8: Y | BA8: Y | BB8: Y | BC8: Y | BD8: Y | BE8: Y | BF8: Raw Score | BG8: Progress Score | BH8: Spelling Age
A9: 45356 | B9: 40959 | C9: 3 | D9: 3A | E9: Lname1 | F9: Fname1 | G9: XXXXX1 | BF9: =IF(E9="",0,COUNTIF(H9:BE9,"=Y")) -> 0 | BG9: =IF(E9="","",VLOOKUP(BF9,LookUp!$Q$3:$S$53,2,FALSE)) -> 53 | BH9: =IF(E9="","",VLOOKUP(BF9,LookUp!$Q$3:$S$53,3,FALSE)) -> <=6:10
A10: 45356 | B10: 40960 | C10: 3 | D10: 3A | E10: Lname2 | F10: Fname2 | G10: XXXXX2 | BF10: =IF(E10="",0,COUNTIF(H10:BE10,"=Y")) -> 0 | BG10: =IF(E10="","",VLOOKUP(BF10,LookUp!$Q$3:$S$53,2,FALSE)) -> 53 | BH10: =IF(E10="","",VLOOKUP(BF10,LookUp!$Q$3:$S$53,3,FALSE)) -> <=6:10
A11: 45356 | B11: 40961 | C11: 3 | D11: 3A | E11: Lname3 | F11: Fname3 | G11: XXXXX3 | BF11: =IF(E11="",0,COUNTIF(H11:BE11,"=Y")) -> 0 | BG11: =IF(E11="","",VLOOKUP(BF11,LookUp!$Q$3:$S$53,2,FALSE)) -> 53 | BH11: =IF(E11="","",VLOOKUP(BF11,LookUp!$Q$3:$S$53,3,FALSE)) -> <=6:10
A12: 45356 | B12: 40962 | C12: 3 | D12: 3A | E12: Lname4 | F12: Fname4 | G12: XXXXX4 | BF12: =IF(E12="",0,COUNTIF(H12:BE12,"=Y")) -> 0 | BG12: =IF(E12="","",VLOOKUP(BF12,LookUp!$Q$3:$S$53,2,FALSE)) -> 53 | BH12: =IF(E12="","",VLOOKUP(BF12,LookUp!$Q$3:$S$53,3,FALSE)) -> <=6:10
A13: 45356 | B13: 40970 | C13: 3 | D13: 3B | E13: ULname13 | F13: UFname13 | G13: UNLISTED | BF13: =IF(E13="",0,COUNTIF(H13:BE13,"=Y")) -> 0 | BG13: =IF(E13="","",VLOOKUP(BF13,LookUp!$Q$3:$S$53,2,FALSE)) -> 53 | BH13: =IF(E13="","",VLOOKUP(BF13,LookUp!$Q$3:$S$53,3,FALSE)) -> <=6:10
A14: 45356 | B14: 40963 | C14: 3 | D14: 3A | E14: Lname5 | F14: Fname5 | G14: XXXXX5 | BF14: =IF(E14="",0,COUNTIF(H14:BE14,"=Y")) -> 0 | BG14: =IF(E14="","",VLOOKUP(BF14,LookUp!$Q$3:$S$53,2,FALSE)) -> 53 | BH14: =IF(E14="","",VLOOKUP(BF14,LookUp!$Q$3:$S$53,3,FALSE)) -> <=6:10
A15: 45356 | B15: 40964 | C15: 3 | D15: 3B | E15: Lname6 | F15: Fname6 | G15: XXXXX6 | BF15: =IF(E15="",0,COUNTIF(H15:BE15,"=Y")) -> 0 | BG15: =IF(E15="","",VLOOKUP(BF15,LookUp!$Q$3:$S$53,2,FALSE)) -> 53 | BH15: =IF(E15="","",VLOOKUP(BF15,LookUp!$Q$3:$S$53,3,FALSE)) -> <=6:10
A16: 45356 | B16: 40965 | C16: 3 | D16: 3B | E16: Lname7 | F16: Fname7 | G16: XXXXX7 | BF16: =IF(E16="",0,COUNTIF(H16:BE16,"=Y")) -> 0 | BG16: =IF(E16="","",VLOOKUP(BF16,LookUp!$Q$3:$S$53,2,FALSE)) -> 53 | BH16: =IF(E16="","",VLOOKUP(BF16,LookUp!$Q$3:$S$53,3,FALSE)) -> <=6:10
A17: 45356 | B17: 40966 | C17: 3 | D17: 3B | E17: Lname8 | F17: Fname8 | G17: XXXXX8 | BF17: =IF(E17="",0,COUNTIF(H17:BE17,"=Y")) -> 0 | BG17: =IF(E17="","",VLOOKUP(BF17,LookUp!$Q$3:$S$53,2,FALSE)) -> 53 | BH17: =IF(E17="","",VLOOKUP(BF17,LookUp!$Q$3:$S$53,3,FALSE)) -> <=6:10
A18: 45356 | B18: 40967 | C18: 3 | D18: 3B | E18: Lname9 | F18: Fname9 | G18: XXXXX9 | BF18: =IF(E18="",0,COUNTIF(H18:BE18,"=Y")) -> 0 | BG18: =IF(E18="","",VLOOKUP(BF18,LookUp!$Q$3:$S$53,2,FALSE)) -> 53 | BH18: =IF(E18="","",VLOOKUP(BF18,LookUp!$Q$3:$S$53,3,FALSE)) -> <=6:10
A19: 45356 | B19: 40968 | C19: 3 | D19: 3B | E19: Lname10 | F19: Fname10 | G19: XXXXX10 | BF19: =IF(E19="",0,COUNTIF(H19:BE19,"=Y")) -> 0 | BG19: =IF(E19="","",VLOOKUP(BF19,LookUp!$Q$3:$S$53,2,FALSE)) -> 53 | BH19: =IF(E19="","",VLOOKUP(BF19,LookUp!$Q$3:$S$53,3,FALSE)) -> <=6:10
BF20: =IF(E20="",0,COUNTIF(H20:BE20,"=Y")) -> 0 | BG20: =IF(E20="","",VLOOKUP(BF20,LookUp!$Q$3:$S$53,2,FALSE)) | BH20: =IF(E20="","",VLOOKUP(BF20,LookUp!$Q$3:$S$53,3,FALSE))
BF21: =IF(E21="",0,COUNTIF(H21:BE21,"=Y")) -> 0 | BG21: =IF(E21="","",VLOOKUP(BF21,LookUp!$Q$3:$S$53,2,FALSE)) | BH21: =IF(E21="","",VLOOKUP(BF21,LookUp!$Q$3:$S$53,3,FALSE))
BF22: =IF(E22="",0,COUNTIF(H22:BE22,"=Y")) -> 0 | BG22: =IF(E22="","",VLOOKUP(BF22,LookUp!$Q$3:$S$53,2,FALSE)) | BH22: =IF(E22="","",VLOOKUP(BF22,LookUp!$Q$3:$S$53,3,FALSE))
BF23: =IF(E23="",0,COUNTIF(H23:BE23,"=Y")) -> 0 | BG23: =IF(E23="","",VLOOKUP(BF23,LookUp!$Q$3:$S$53,2,FALSE)) | BH23: =IF(E23="","",VLOOKUP(BF23,LookUp!$Q$3:$S$53,3,FALSE))
BF24: =IF(E24="",0,COUNTIF(H24:BE24,"=Y")) -> 0 | BG24: =IF(E24="","",VLOOKUP(BF24,LookUp!$Q$3:$S$53,2,FALSE)) | BH24: =IF(E24="","",VLOOKUP(BF24,LookUp!$Q$3:$S$53,3,FALSE))
BF25: =IF(E25="",0,COUNTIF(H25:BE25,"=Y")) -> 0 | BG25: =IF(E25="","",VLOOKUP(BF25,LookUp!$Q$3:$S$53,2,FALSE)) | BH25: =IF(E25="","",VLOOKUP(BF25,LookUp!$Q$3:$S$53,3,FALSE))
BF26: =IF(E26="",0,COUNTIF(H26:BE26,"=Y")) -> 0 | BG26: =IF(E26="","",VLOOKUP(BF26,LookUp!$Q$3:$S$53,2,FALSE)) | BH26: =IF(E26="","",VLOOKUP(BF26,LookUp!$Q$3:$S$53,3,FALSE))
BF27: =IF(E27="",0,COUNTIF(H27:BE27,"=Y")) -> 0 | BG27: =IF(E27="","",VLOOKUP(BF27,LookUp!$Q$3:$S$53,2,FALSE)) | BH27: =IF(E27="","",VLOOKUP(BF27,LookUp!$Q$3:$S$53,3,FALSE))
BF28: =IF(E28="",0,COUNTIF(H28:BE28,"=Y")) -> 0 | BG28: =IF(E28="","",VLOOKUP(BF28,LookUp!$Q$3:$S$53,2,FALSE)) | BH28: =IF(E28="","",VLOOKUP(BF28,LookUp!$Q$3:$S$53,3,FALSE))
BF29: =IF(E29="",0,COUNTIF(H29:BE29,"=Y")) -> 0 | BG29: =IF(E29="","",VLOOKUP(BF29,LookUp!$Q$3:$S$53,2,FALSE)) | BH29: =IF(E29="","",VLOOKUP(BF29,LookUp!$Q$3:$S$53,3,FALSE))
BF30: =IF(E30="",0,COUNTIF(H30:BE30,"=Y")) -> 0 | BG30: =IF(E30="","",VLOOKUP(BF30,LookUp!$Q$3:$S$53,2,FALSE)) | BH30: =IF(E30="","",VLOOKUP(BF30,LookUp!$Q$3:$S$53,3,FALSE))
BF31: =IF(E31="",0,COUNTIF(H31:BE31,"=Y")) -> 0 | BG31: =IF(E31="","",VLOOKUP(BF31,LookUp!$Q$3:$S$53,2,FALSE)) | BH31: =IF(E31="","",VLOOKUP(BF31,LookUp!$Q$3:$S$53,3,FALSE))
... BF452: =IF(E452="",0,COUNTIF(H452:BE452,"=Y")) -> 0 | BG452: =IF(E452="","",VLOOKUP(BF452,LookUp!$Q$3:$S$53,2,FALSE)) | BH452: =IF(E452="","",VLOOKUP(BF452,LookUp!$Q$3:$S$53,3,FALSE))

Sheet SWST F
A1: SWST - Test F
H3: QUESTION No. and ANSWER KEY (Enter the student's response - "Y" if correct; "N" if incorrect )
F4: Question Number | H4: 1 | I4: 2 | J4: 3 | K4: 4 | L4: 5 | M4: 6 | N4: 7 | O4: 8 | P4: 9 | Q4: 10 | R4: 11 | S4: 12 | T4: 13 | U4: 14 | V4: 15 | W4: 16 | X4: 17 | Y4: 18 | Z4: 19 | AA4: 20 | AB4: 21 | AC4: 22 | AD4: 23 | AE4: 24 | AF4: 25 | AG4: 26 | AH4: 27 | AI4: 28 | AJ4: 29 | AK4: 30 | AL4: 31 | AM4: 32 | AN4: 33 | AO4: 34 | AP4: 35 | AQ4: 36 | AR4: 37 | AS4: 38 | AT4: 39 | AU4: 40 | AV4: 41 | AW4: 42 | AX4: 43 | AY4: 44 | AZ4: 45 | BA4: 46 | BB4: 47 | BC4: 48 | BD4: 49 | BE4: 50
F5: Spelling Words | H5: DREAM | I5: CHAIR | J5: STICKING | K5: BECAUSE | L5: NIGHT | M5: WATCH | N5: ADVENTURE | O5: WRITING | P5: STOPPED | Q5: ALTOGETHER | R5: REPLIED | S5: GLASSES | T5: BRIDGE | U5: INFORMATION | V5: DANGEROUS | W5: INSTEAD | X5: KNEW | Y5: TREASURE | Z5: BOUNCING | AA5: RESPECTFUL | AB5: COMPLAINED | AC5: DICTIONARY | AD5: PARTIES | AE5: DISCOVERED | AF5: HALVES | AG5: DISUSED | AH5: CHURCHES | AI5: SEARCH | AJ5: ENTERTAINED | AK5: PARAGRAPHS | AL5: THIRSTY | AM5: DAMAGING | AN5: PLANNING | AO5: LAUGHING | AP5: WORRIED | AQ5: MISUNDERSTANDING | AR5: ENVIRONMENT | AS5: AUTOMATIC | AT5: TOMATOES | AU5: INVASION | AV5: SURROUNDED | AW5: FAVOURITE | AX5: CELEBRATIONS | AY5: QUIETLY | AZ5: POISONOUS | BA5: MAGICIAN | BB5: CHARACTER | BC5: RESPONSIBLE | BD5: MARVELLOUS | BE5: CIRCUMFERENCE
A7: required | B7: required | C7: required | D7: optional | E7: required | F7: required | G7: required
A8: Test Date (dd/mm/yy) | B8: Date of Birth (dd/mm/yy) | C8: Yr_Lev | D8: Grp | E8: Surname | F8: First_Name | G8: Student_ID | H8: Y | I8: Y | J8: Y | K8: Y | L8: Y | M8: Y | N8: Y | O8: Y | P8: Y | Q8: Y | R8: Y | S8: Y | T8: Y | U8: Y | V8: Y | W8: Y | X8: Y | Y8: Y | Z8: Y | AA8: Y | AB8: Y | AC8: Y | AD8: Y | AE8: Y | AF8: Y | AG8: Y | AH8: Y | AI8: Y | AJ8: Y | AK8: Y | AL8: Y | AM8: Y | AN8: Y | AO8: Y | AP8: Y | AQ8: Y | AR8: Y | AS8: Y | AT8: Y | AU8: Y | AV8: Y | AW8: Y | AX8: Y | AY8: Y | AZ8: Y | BA8: Y | BB8: Y | BC8: Y | BD8: Y | BE8: Y | BF8: Raw Score | BG8: Progress Score | BH8: Spelling Age
A9: 45356 | B9: 40959 | C9: 3 | D9: 3A | E9: Lname1 | F9: Fname1 | G9: XXXXX1 | BF9: =IF(E9="",0,COUNTIF(H9:BE9,"=Y")) -> 0 | BG9: =IF(E9="","",VLOOKUP(BF9,LookUp!$U$3:$W$53,2,FALSE)) -> 56 | BH9: =IF(E9="","",VLOOKUP(BF9,LookUp!$U$3:$W$53,3,FALSE)) -> <=7:00
A10: 45356 | B10: 40960 | C10: 3 | D10: 3A | E10: Lname2 | F10: Fname2 | G10: XXXXX2 | BF10: =IF(E10="",0,COUNTIF(H10:BE10,"=Y")) -> 0 | BG10: =IF(E10="","",VLOOKUP(BF10,LookUp!$U$3:$W$53,2,FALSE)) -> 56 | BH10: =IF(E10="","",VLOOKUP(BF10,LookUp!$U$3:$W$53,3,FALSE)) -> <=7:00
A11: 45356 | B11: 40961 | C11: 3 | D11: 3A | E11: Lname3 | F11: Fname3 | G11: XXXXX3 | BF11: =IF(E11="",0,COUNTIF(H11:BE11,"=Y")) -> 0 | BG11: =IF(E11="","",VLOOKUP(BF11,LookUp!$U$3:$W$53,2,FALSE)) -> 56 | BH11: =IF(E11="","",VLOOKUP(BF11,LookUp!$U$3:$W$53,3,FALSE)) -> <=7:00
A12: 45356 | B12: 40962 | C12: 3 | D12: 3A | E12: Lname4 | F12: Fname4 | G12: XXXXX4 | BF12: =IF(E12="",0,COUNTIF(H12:BE12,"=Y")) -> 0 | BG12: =IF(E12="","",VLOOKUP(BF12,LookUp!$U$3:$W$53,2,FALSE)) -> 56 | BH12: =IF(E12="","",VLOOKUP(BF12,LookUp!$U$3:$W$53,3,FALSE)) -> <=7:00
A13: 45356 | B13: 40970 | C13: 3 | D13: 3B | E13: ULname13 | F13: UFname13 | G13: UNLISTED | BF13: =IF(E13="",0,COUNTIF(H13:BE13,"=Y")) -> 0 | BG13: =IF(E13="","",VLOOKUP(BF13,LookUp!$U$3:$W$53,2,FALSE)) -> 56 | BH13: =IF(E13="","",VLOOKUP(BF13,LookUp!$U$3:$W$53,3,FALSE)) -> <=7:00
A14: 45356 | B14: 40963 | C14: 3 | D14: 3A | E14: Lname5 | F14: Fname5 | G14: XXXXX5 | BF14: =IF(E14="",0,COUNTIF(H14:BE14,"=Y")) -> 0 | BG14: =IF(E14="","",VLOOKUP(BF14,LookUp!$U$3:$W$53,2,FALSE)) -> 56 | BH14: =IF(E14="","",VLOOKUP(BF14,LookUp!$U$3:$W$53,3,FALSE)) -> <=7:00
A15: 45356 | B15: 40964 | C15: 3 | D15: 3B | E15: Lname6 | F15: Fname6 | G15: XXXXX6 | BF15: =IF(E15="",0,COUNTIF(H15:BE15,"=Y")) -> 0 | BG15: =IF(E15="","",VLOOKUP(BF15,LookUp!$U$3:$W$53,2,FALSE)) -> 56 | BH15: =IF(E15="","",VLOOKUP(BF15,LookUp!$U$3:$W$53,3,FALSE)) -> <=7:00
A16: 45356 | B16: 40965 | C16: 3 | D16: 3B | E16: Lname7 | F16: Fname7 | G16: XXXXX7 | BF16: =IF(E16="",0,COUNTIF(H16:BE16,"=Y")) -> 0 | BG16: =IF(E16="","",VLOOKUP(BF16,LookUp!$U$3:$W$53,2,FALSE)) -> 56 | BH16: =IF(E16="","",VLOOKUP(BF16,LookUp!$U$3:$W$53,3,FALSE)) -> <=7:00
A17: 45356 | B17: 40966 | C17: 3 | D17: 3B | E17: Lname8 | F17: Fname8 | G17: XXXXX8 | BF17: =IF(E17="",0,COUNTIF(H17:BE17,"=Y")) -> 0 | BG17: =IF(E17="","",VLOOKUP(BF17,LookUp!$U$3:$W$53,2,FALSE)) -> 56 | BH17: =IF(E17="","",VLOOKUP(BF17,LookUp!$U$3:$W$53,3,FALSE)) -> <=7:00
A18: 45356 | B18: 40967 | C18: 3 | D18: 3B | E18: Lname9 | F18: Fname9 | G18: XXXXX9 | BF18: =IF(E18="",0,COUNTIF(H18:BE18,"=Y")) -> 0 | BG18: =IF(E18="","",VLOOKUP(BF18,LookUp!$U$3:$W$53,2,FALSE)) -> 56 | BH18: =IF(E18="","",VLOOKUP(BF18,LookUp!$U$3:$W$53,3,FALSE)) -> <=7:00
A19: 45356 | B19: 40968 | C19: 3 | D19: 3B | E19: Lname10 | F19: Fname10 | G19: XXXXX10 | BF19: =IF(E19="",0,COUNTIF(H19:BE19,"=Y")) -> 0 | BG19: =IF(E19="","",VLOOKUP(BF19,LookUp!$U$3:$W$53,2,FALSE)) -> 56 | BH19: =IF(E19="","",VLOOKUP(BF19,LookUp!$U$3:$W$53,3,FALSE)) -> <=7:00
BF20: =IF(E20="",0,COUNTIF(H20:BE20,"=Y")) -> 0 | BG20: =IF(E20="","",VLOOKUP(BF20,LookUp!$U$3:$W$53,2,FALSE)) | BH20: =IF(E20="","",VLOOKUP(BF20,LookUp!$U$3:$W$53,3,FALSE))
BF21: =IF(E21="",0,COUNTIF(H21:BE21,"=Y")) -> 0 | BG21: =IF(E21="","",VLOOKUP(BF21,LookUp!$U$3:$W$53,2,FALSE)) | BH21: =IF(E21="","",VLOOKUP(BF21,LookUp!$U$3:$W$53,3,FALSE))
BF22: =IF(E22="",0,COUNTIF(H22:BE22,"=Y")) -> 0 | BG22: =IF(E22="","",VLOOKUP(BF22,LookUp!$U$3:$W$53,2,FALSE)) | BH22: =IF(E22="","",VLOOKUP(BF22,LookUp!$U$3:$W$53,3,FALSE))
BF23: =IF(E23="",0,COUNTIF(H23:BE23,"=Y")) -> 0 | BG23: =IF(E23="","",VLOOKUP(BF23,LookUp!$U$3:$W$53,2,FALSE)) | BH23: =IF(E23="","",VLOOKUP(BF23,LookUp!$U$3:$W$53,3,FALSE))
BF24: =IF(E24="",0,COUNTIF(H24:BE24,"=Y")) -> 0 | BG24: =IF(E24="","",VLOOKUP(BF24,LookUp!$U$3:$W$53,2,FALSE)) | BH24: =IF(E24="","",VLOOKUP(BF24,LookUp!$U$3:$W$53,3,FALSE))
BF25: =IF(E25="",0,COUNTIF(H25:BE25,"=Y")) -> 0 | BG25: =IF(E25="","",VLOOKUP(BF25,LookUp!$U$3:$W$53,2,FALSE)) | BH25: =IF(E25="","",VLOOKUP(BF25,LookUp!$U$3:$W$53,3,FALSE))
BF26: =IF(E26="",0,COUNTIF(H26:BE26,"=Y")) -> 0 | BG26: =IF(E26="","",VLOOKUP(BF26,LookUp!$U$3:$W$53,2,FALSE)) | BH26: =IF(E26="","",VLOOKUP(BF26,LookUp!$U$3:$W$53,3,FALSE))
BF27: =IF(E27="",0,COUNTIF(H27:BE27,"=Y")) -> 0 | BG27: =IF(E27="","",VLOOKUP(BF27,LookUp!$U$3:$W$53,2,FALSE)) | BH27: =IF(E27="","",VLOOKUP(BF27,LookUp!$U$3:$W$53,3,FALSE))
BF28: =IF(E28="",0,COUNTIF(H28:BE28,"=Y")) -> 0 | BG28: =IF(E28="","",VLOOKUP(BF28,LookUp!$U$3:$W$53,2,FALSE)) | BH28: =IF(E28="","",VLOOKUP(BF28,LookUp!$U$3:$W$53,3,FALSE))
BF29: =IF(E29="",0,COUNTIF(H29:BE29,"=Y")) -> 0 | BG29: =IF(E29="","",VLOOKUP(BF29,LookUp!$U$3:$W$53,2,FALSE)) | BH29: =IF(E29="","",VLOOKUP(BF29,LookUp!$U$3:$W$53,3,FALSE))
BF30: =IF(E30="",0,COUNTIF(H30:BE30,"=Y")) -> 0 | BG30: =IF(E30="","",VLOOKUP(BF30,LookUp!$U$3:$W$53,2,FALSE)) | BH30: =IF(E30="","",VLOOKUP(BF30,LookUp!$U$3:$W$53,3,FALSE))
BF31: =IF(E31="",0,COUNTIF(H31:BE31,"=Y")) -> 0 | BG31: =IF(E31="","",VLOOKUP(BF31,LookUp!$U$3:$W$53,2,FALSE)) | BH31: =IF(E31="","",VLOOKUP(BF31,LookUp!$U$3:$W$53,3,FALSE))
... BF452: =IF(E452="",0,COUNTIF(H452:BE452,"=Y")) -> 0 | BG452: =IF(E452="","",VLOOKUP(BF452,LookUp!$U$3:$W$53,2,FALSE)) | BH452: =IF(E452="","",VLOOKUP(BF452,LookUp!$U$3:$W$53,3,FALSE))

Sheet SWST G
A1: SWST - Test G
H3: QUESTION No. and ANSWER KEY (Enter the student's response - "Y" if correct; "N" if incorrect )
F4: Question Number | H4: 1 | I4: 2 | J4: 3 | K4: 4 | L4: 5 | M4: 6 | N4: 7 | O4: 8 | P4: 9 | Q4: 10 | R4: 11 | S4: 12 | T4: 13 | U4: 14 | V4: 15 | W4: 16 | X4: 17 | Y4: 18 | Z4: 19 | AA4: 20 | AB4: 21 | AC4: 22 | AD4: 23 | AE4: 24 | AF4: 25 | AG4: 26 | AH4: 27 | AI4: 28 | AJ4: 29 | AK4: 30 | AL4: 31 | AM4: 32 | AN4: 33 | AO4: 34 | AP4: 35 | AQ4: 36 | AR4: 37 | AS4: 38 | AT4: 39 | AU4: 40 | AV4: 41 | AW4: 42 | AX4: 43 | AY4: 44 | AZ4: 45 | BA4: 46 | BB4: 47 | BC4: 48 | BD4: 49 | BE4: 50
F5: Spelling Words | H5: BLINK | I5: AGAIN | J5: KICKING | K5: USED | L5: CATCH | M5: LEARN | N5: POWERFUL | O5: TREATMENT | P5: DIFFERENT | Q5: TIGHTER | R5: CROWDED | S5: CHOICE | T5: PARAGRAPHS | U5: DANGEROUS | V5: REPLIED | W5: ELECTRICITY | X5: AUTOGRAPH | Y5: SPECIAL | Z5: THIRSTY | AA5: CONVERSATION | AB5: JUDGES | AC5: THOUGHTLESS | AD5: SCIENTIFIC | AE5: CERTAIN | AF5: TOMATOES | AG5: THROAT | AH5: UNINTERESTED | AI5: ADDRESSES | AJ5: WISPERED | AK5: ARMIES | AL5: FRIGHTENED | AM5: HALVES | AN5: IMAGINE | AO5: QUALIFIED | AP5: FAVOURITE | AQ5: BELIEVE | AR5: WRAPPED | AS5: PURPOSE | AT5: TRAVELLED | AU5: CEILING | AV5: UNCOMFORTABLE | AW5: EXCELLENT | AX5: MAGICIAN | AY5: BEGINNING | AZ5: SUCCESSFUL | BA5: NOISILY | BB5: CIRCUMFERENCE | BC5: DISAPPEARED | BD5: REHEARSE | BE5: INCONVENIENT
A7: required | B7: required | C7: required | D7: optional | E7: required | F7: required | G7: required
A8: Test Date (dd/mm/yy) | B8: Date of Birth (dd/mm/yy) | C8: Yr_Lev | D8: Grp | E8: Surname | F8: First_Name | G8: Student_ID | H8: Y | I8: Y | J8: Y | K8: Y | L8: Y | M8: Y | N8: Y | O8: Y | P8: Y | Q8: Y | R8: Y | S8: Y | T8: Y | U8: Y | V8: Y | W8: Y | X8: Y | Y8: Y | Z8: Y | AA8: Y | AB8: Y | AC8: Y | AD8: Y | AE8: Y | AF8: Y | AG8: Y | AH8: Y | AI8: Y | AJ8: Y | AK8: Y | AL8: Y | AM8: Y | AN8: Y | AO8: Y | AP8: Y | AQ8: Y | AR8: Y | AS8: Y | AT8: Y | AU8: Y | AV8: Y | AW8: Y | AX8: Y | AY8: Y | AZ8: Y | BA8: Y | BB8: Y | BC8: Y | BD8: Y | BE8: Y | BF8: Raw Score | BG8: Progress Score | BH8: Spelling Age
A9: 45356 | B9: 40959 | C9: 3 | D9: 3A | E9: Lname1 | F9: Fname1 | G9: XXXXX1 | BF9: =IF(E9="",0,COUNTIF(H9:BE9,"=Y")) -> 0 | BG9: =IF(E9="","",VLOOKUP(BF9,LookUp!$Y$3:$AA$53,2,FALSE)) -> 62 | BH9: =IF(E9="","",VLOOKUP(BF9,LookUp!$Y$3:$AA$53,3,FALSE)) -> <=7:05
A10: 45356 | B10: 40960 | C10: 3 | D10: 3A | E10: Lname2 | F10: Fname2 | G10: XXXXX2 | BF10: =IF(E10="",0,COUNTIF(H10:BE10,"=Y")) -> 0 | BG10: =IF(E10="","",VLOOKUP(BF10,LookUp!$Y$3:$AA$53,2,FALSE)) -> 62 | BH10: =IF(E10="","",VLOOKUP(BF10,LookUp!$Y$3:$AA$53,3,FALSE)) -> <=7:05
A11: 45356 | B11: 40961 | C11: 3 | D11: 3A | E11: Lname3 | F11: Fname3 | G11: XXXXX3 | BF11: =IF(E11="",0,COUNTIF(H11:BE11,"=Y")) -> 0 | BG11: =IF(E11="","",VLOOKUP(BF11,LookUp!$Y$3:$AA$53,2,FALSE)) -> 62 | BH11: =IF(E11="","",VLOOKUP(BF11,LookUp!$Y$3:$AA$53,3,FALSE)) -> <=7:05
A12: 45356 | B12: 40962 | C12: 3 | D12: 3A | E12: Lname4 | F12: Fname4 | G12: XXXXX4 | BF12: =IF(E12="",0,COUNTIF(H12:BE12,"=Y")) -> 0 | BG12: =IF(E12="","",VLOOKUP(BF12,LookUp!$Y$3:$AA$53,2,FALSE)) -> 62 | BH12: =IF(E12="","",VLOOKUP(BF12,LookUp!$Y$3:$AA$53,3,FALSE)) -> <=7:05
A13: 45356 | B13: 40970 | C13: 3 | D13: 3B | E13: ULname13 | F13: UFname13 | G13: UNLISTED | BF13: =IF(E13="",0,COUNTIF(H13:BE13,"=Y")) -> 0 | BG13: =IF(E13="","",VLOOKUP(BF13,LookUp!$Y$3:$AA$53,2,FALSE)) -> 62 | BH13: =IF(E13="","",VLOOKUP(BF13,LookUp!$Y$3:$AA$53,3,FALSE)) -> <=7:05
A14: 45356 | B14: 40963 | C14: 3 | D14: 3A | E14: Lname5 | F14: Fname5 | G14: XXXXX5 | BF14: =IF(E14="",0,COUNTIF(H14:BE14,"=Y")) -> 0 | BG14: =IF(E14="","",VLOOKUP(BF14,LookUp!$Y$3:$AA$53,2,FALSE)) -> 62 | BH14: =IF(E14="","",VLOOKUP(BF14,LookUp!$Y$3:$AA$53,3,FALSE)) -> <=7:05
A15: 45356 | B15: 40964 | C15: 3 | D15: 3B | E15: Lname6 | F15: Fname6 | G15: XXXXX6 | BF15: =IF(E15="",0,COUNTIF(H15:BE15,"=Y")) -> 0 | BG15: =IF(E15="","",VLOOKUP(BF15,LookUp!$Y$3:$AA$53,2,FALSE)) -> 62 | BH15: =IF(E15="","",VLOOKUP(BF15,LookUp!$Y$3:$AA$53,3,FALSE)) -> <=7:05
A16: 45356 | B16: 40965 | C16: 3 | D16: 3B | E16: Lname7 | F16: Fname7 | G16: XXXXX7 | BF16: =IF(E16="",0,COUNTIF(H16:BE16,"=Y")) -> 0 | BG16: =IF(E16="","",VLOOKUP(BF16,LookUp!$Y$3:$AA$53,2,FALSE)) -> 62 | BH16: =IF(E16="","",VLOOKUP(BF16,LookUp!$Y$3:$AA$53,3,FALSE)) -> <=7:05
A17: 45356 | B17: 40966 | C17: 3 | D17: 3B | E17: Lname8 | F17: Fname8 | G17: XXXXX8 | BF17: =IF(E17="",0,COUNTIF(H17:BE17,"=Y")) -> 0 | BG17: =IF(E17="","",VLOOKUP(BF17,LookUp!$Y$3:$AA$53,2,FALSE)) -> 62 | BH17: =IF(E17="","",VLOOKUP(BF17,LookUp!$Y$3:$AA$53,3,FALSE)) -> <=7:05
A18: 45356 | B18: 40967 | C18: 3 | D18: 3B | E18: Lname9 | F18: Fname9 | G18: XXXXX9 | BF18: =IF(E18="",0,COUNTIF(H18:BE18,"=Y")) -> 0 | BG18: =IF(E18="","",VLOOKUP(BF18,LookUp!$Y$3:$AA$53,2,FALSE)) -> 62 | BH18: =IF(E18="","",VLOOKUP(BF18,LookUp!$Y$3:$AA$53,3,FALSE)) -> <=7:05
A19: 45356 | B19: 40968 | C19: 3 | D19: 3B | E19: Lname10 | F19: Fname10 | G19: XXXXX10 | BF19: =IF(E19="",0,COUNTIF(H19:BE19,"=Y")) -> 0 | BG19: =IF(E19="","",VLOOKUP(BF19,LookUp!$Y$3:$AA$53,2,FALSE)) -> 62 | BH19: =IF(E19="","",VLOOKUP(BF19,LookUp!$Y$3:$AA$53,3,FALSE)) -> <=7:05
BF20: =IF(E20="",0,COUNTIF(H20:BE20,"=Y")) -> 0 | BG20: =IF(E20="","",VLOOKUP(BF20,LookUp!$Y$3:$AA$53,2,FALSE)) | BH20: =IF(E20="","",VLOOKUP(BF20,LookUp!$Y$3:$AA$53,3,FALSE))
BF21: =IF(E21="",0,COUNTIF(H21:BE21,"=Y")) -> 0 | BG21: =IF(E21="","",VLOOKUP(BF21,LookUp!$Y$3:$AA$53,2,FALSE)) | BH21: =IF(E21="","",VLOOKUP(BF21,LookUp!$Y$3:$AA$53,3,FALSE))
BF22: =IF(E22="",0,COUNTIF(H22:BE22,"=Y")) -> 0 | BG22: =IF(E22="","",VLOOKUP(BF22,LookUp!$Y$3:$AA$53,2,FALSE)) | BH22: =IF(E22="","",VLOOKUP(BF22,LookUp!$Y$3:$AA$53,3,FALSE))
BF23: =IF(E23="",0,COUNTIF(H23:BE23,"=Y")) -> 0 | BG23: =IF(E23="","",VLOOKUP(BF23,LookUp!$Y$3:$AA$53,2,FALSE)) | BH23: =IF(E23="","",VLOOKUP(BF23,LookUp!$Y$3:$AA$53,3,FALSE))
BF24: =IF(E24="",0,COUNTIF(H24:BE24,"=Y")) -> 0 | BG24: =IF(E24="","",VLOOKUP(BF24,LookUp!$Y$3:$AA$53,2,FALSE)) | BH24: =IF(E24="","",VLOOKUP(BF24,LookUp!$Y$3:$AA$53,3,FALSE))
BF25: =IF(E25="",0,COUNTIF(H25:BE25,"=Y")) -> 0 | BG25: =IF(E25="","",VLOOKUP(BF25,LookUp!$Y$3:$AA$53,2,FALSE)) | BH25: =IF(E25="","",VLOOKUP(BF25,LookUp!$Y$3:$AA$53,3,FALSE))
BF26: =IF(E26="",0,COUNTIF(H26:BE26,"=Y")) -> 0 | BG26: =IF(E26="","",VLOOKUP(BF26,LookUp!$Y$3:$AA$53,2,FALSE)) | BH26: =IF(E26="","",VLOOKUP(BF26,LookUp!$Y$3:$AA$53,3,FALSE))
BF27: =IF(E27="",0,COUNTIF(H27:BE27,"=Y")) -> 0 | BG27: =IF(E27="","",VLOOKUP(BF27,LookUp!$Y$3:$AA$53,2,FALSE)) | BH27: =IF(E27="","",VLOOKUP(BF27,LookUp!$Y$3:$AA$53,3,FALSE))
BF28: =IF(E28="",0,COUNTIF(H28:BE28,"=Y")) -> 0 | BG28: =IF(E28="","",VLOOKUP(BF28,LookUp!$Y$3:$AA$53,2,FALSE)) | BH28: =IF(E28="","",VLOOKUP(BF28,LookUp!$Y$3:$AA$53,3,FALSE))
BF29: =IF(E29="",0,COUNTIF(H29:BE29,"=Y")) -> 0 | BG29: =IF(E29="","",VLOOKUP(BF29,LookUp!$Y$3:$AA$53,2,FALSE)) | BH29: =IF(E29="","",VLOOKUP(BF29,LookUp!$Y$3:$AA$53,3,FALSE))
BF30: =IF(E30="",0,COUNTIF(H30:BE30,"=Y")) -> 0 | BG30: =IF(E30="","",VLOOKUP(BF30,LookUp!$Y$3:$AA$53,2,FALSE)) | BH30: =IF(E30="","",VLOOKUP(BF30,LookUp!$Y$3:$AA$53,3,FALSE))
BF31: =IF(E31="",0,COUNTIF(H31:BE31,"=Y")) -> 0 | BG31: =IF(E31="","",VLOOKUP(BF31,LookUp!$Y$3:$AA$53,2,FALSE)) | BH31: =IF(E31="","",VLOOKUP(BF31,LookUp!$Y$3:$AA$53,3,FALSE))
... BF452: =IF(E452="",0,COUNTIF(H452:BE452,"=Y")) -> 0 | BG452: =IF(E452="","",VLOOKUP(BF452,LookUp!$Y$3:$AA$53,2,FALSE)) | BH452: =IF(E452="","",VLOOKUP(BF452,LookUp!$Y$3:$AA$53,3,FALSE))

Sheet SWST H
A1: SWST - Test H
H3: QUESTION No. and ANSWER KEY (Enter the student's response - "Y" if correct; "N" if incorrect )
F4: Question Number | H4: 1 | I4: 2 | J4: 3 | K4: 4 | L4: 5 | M4: 6 | N4: 7 | O4: 8 | P4: 9 | Q4: 10 | R4: 11 | S4: 12 | T4: 13 | U4: 14 | V4: 15 | W4: 16 | X4: 17 | Y4: 18 | Z4: 19 | AA4: 20 | AB4: 21 | AC4: 22 | AD4: 23 | AE4: 24 | AF4: 25 | AG4: 26 | AH4: 27 | AI4: 28 | AJ4: 29 | AK4: 30 | AL4: 31 | AM4: 32 | AN4: 33 | AO4: 34 | AP4: 35 | AQ4: 36 | AR4: 37 | AS4: 38 | AT4: 39 | AU4: 40 | AV4: 41 | AW4: 42 | AX4: 43 | AY4: 44 | AZ4: 45 | BA4: 46 | BB4: 47 | BC4: 48 | BD4: 49 | BE4: 50
F5: Spelling Words | H5: CHOICE | I5: SHOULD | J5: FRIENDSHIP | K5: CROWDED | L5: KNEW | M5: SWITCH | N5: LEARN | O5: QUESTION | P5: TOMATOES | Q5: INVESTIGATION | R5: RESPECTFUL | S5: SHRUGGED | T5: BRIDGE | U5: KNOCKING | V5: INCREASE | W5: STRETCH | X5: MISUSED | Y5: UNPLEASANT | Z5: SLIGHTLY | AA5: ALTHOUGH | AB5: FRIGHTENED | AC5: HEAVILY | AD5: WRAPPED | AE5: IMPOSSIBLE | AF5: NEIGHBOURS | AG5: EXCELLENT | AH5: MECHANICAL | AI5: COMPETITION | AJ5: VOLCANO | AK5: CONCLUSION | AL5: NOISILY | AM5: IMPATIENT | AN5: FAVOURITE | AO5: MURMURING | AP5: REHEARSE | AQ5: BEGINNING | AR5: MYSTERIOUS | AS5: EMEMIES | AT5: DISAPPEARED | AU5: SUCCESSFUL | AV5: THIEVES | AW5: CANCELLED | AX5: MAGICIAN | AY5: PHYSICALLY | AZ5: CIRCUMFERENCE | BA5: AUTOBIOGRAPHY | BB5: INCONVENIENT | BC5: ACCELERATE | BD5: DICIEVED | BE5: DIFINITELY
A7: required | B7: required | C7: required | D7: optional | E7: required | F7: required | G7: required
A8: Test Date (dd/mm/yy) | B8: Date of Birth (dd/mm/yy) | C8: Yr_Lev | D8: Grp | E8: Surname | F8: First_Name | G8: Student_ID | H8: Y | I8: Y | J8: Y | K8: Y | L8: Y | M8: Y | N8: Y | O8: Y | P8: Y | Q8: Y | R8: Y | S8: Y | T8: Y | U8: Y | V8: Y | W8: Y | X8: Y | Y8: Y | Z8: Y | AA8: Y | AB8: Y | AC8: Y | AD8: Y | AE8: Y | AF8: Y | AG8: Y | AH8: Y | AI8: Y | AJ8: Y | AK8: Y | AL8: Y | AM8: Y | AN8: Y | AO8: Y | AP8: Y | AQ8: Y | AR8: Y | AS8: Y | AT8: Y | AU8: Y | AV8: Y | AW8: Y | AX8: Y | AY8: Y | AZ8: Y | BA8: Y | BB8: Y | BC8: Y | BD8: Y | BE8: Y | BF8: Raw Score | BG8: Progress Score | BH8: Spelling Age
A9: 45356 | B9: 40959 | C9: 3 | D9: 3A | E9: Lname1 | F9: Fname1 | G9: XXXXX1 | BF9: =IF(E9="",0,COUNTIF(H9:BE9,"=Y")) -> 0 | BG9: =IF(E9="","",VLOOKUP(BF9,LookUp!$AC$3:$AE$53,2,FALSE)) -> 66 | BH9: =IF(E9="","",VLOOKUP(BF9,LookUp!$AC$3:$AE$53,3,FALSE)) -> <=7:09
A10: 45356 | B10: 40960 | C10: 3 | D10: 3A | E10: Lname2 | F10: Fname2 | G10: XXXXX2 | BF10: =IF(E10="",0,COUNTIF(H10:BE10,"=Y")) -> 0 | BG10: =IF(E10="","",VLOOKUP(BF10,LookUp!$AC$3:$AE$53,2,FALSE)) -> 66 | BH10: =IF(E10="","",VLOOKUP(BF10,LookUp!$AC$3:$AE$53,3,FALSE)) -> <=7:09
A11: 45356 | B11: 40961 | C11: 3 | D11: 3A | E11: Lname3 | F11: Fname3 | G11: XXXXX3 | BF11: =IF(E11="",0,COUNTIF(H11:BE11,"=Y")) -> 0 | BG11: =IF(E11="","",VLOOKUP(BF11,LookUp!$AC$3:$AE$53,2,FALSE)) -> 66 | BH11: =IF(E11="","",VLOOKUP(BF11,LookUp!$AC$3:$AE$53,3,FALSE)) -> <=7:09
A12: 45356 | B12: 40962 | C12: 3 | D12: 3A | E12: Lname4 | F12: Fname4 | G12: XXXXX4 | BF12: =IF(E12="",0,COUNTIF(H12:BE12,"=Y")) -> 0 | BG12: =IF(E12="","",VLOOKUP(BF12,LookUp!$AC$3:$AE$53,2,FALSE)) -> 66 | BH12: =IF(E12="","",VLOOKUP(BF12,LookUp!$AC$3:$AE$53,3,FALSE)) -> <=7:09
A13: 45356 | B13: 40970 | C13: 3 | D13: 3B | E13: ULname13 | F13: UFname13 | G13: UNLISTED | BF13: =IF(E13="",0,COUNTIF(H13:BE13,"=Y")) -> 0 | BG13: =IF(E13="","",VLOOKUP(BF13,LookUp!$AC$3:$AE$53,2,FALSE)) -> 66 | BH13: =IF(E13="","",VLOOKUP(BF13,LookUp!$AC$3:$AE$53,3,FALSE)) -> <=7:09
A14: 45356 | B14: 40963 | C14: 3 | D14: 3A | E14: Lname5 | F14: Fname5 | G14: XXXXX5 | BF14: =IF(E14="",0,COUNTIF(H14:BE14,"=Y")) -> 0 | BG14: =IF(E14="","",VLOOKUP(BF14,LookUp!$AC$3:$AE$53,2,FALSE)) -> 66 | BH14: =IF(E14="","",VLOOKUP(BF14,LookUp!$AC$3:$AE$53,3,FALSE)) -> <=7:09
A15: 45356 | B15: 40964 | C15: 3 | D15: 3B | E15: Lname6 | F15: Fname6 | G15: XXXXX6 | BF15: =IF(E15="",0,COUNTIF(H15:BE15,"=Y")) -> 0 | BG15: =IF(E15="","",VLOOKUP(BF15,LookUp!$AC$3:$AE$53,2,FALSE)) -> 66 | BH15: =IF(E15="","",VLOOKUP(BF15,LookUp!$AC$3:$AE$53,3,FALSE)) -> <=7:09
A16: 45356 | B16: 40965 | C16: 3 | D16: 3B | E16: Lname7 | F16: Fname7 | G16: XXXXX7 | BF16: =IF(E16="",0,COUNTIF(H16:BE16,"=Y")) -> 0 | BG16: =IF(E16="","",VLOOKUP(BF16,LookUp!$AC$3:$AE$53,2,FALSE)) -> 66 | BH16: =IF(E16="","",VLOOKUP(BF16,LookUp!$AC$3:$AE$53,3,FALSE)) -> <=7:09
A17: 45356 | B17: 40966 | C17: 3 | D17: 3B | E17: Lname8 | F17: Fname8 | G17: XXXXX8 | BF17: =IF(E17="",0,COUNTIF(H17:BE17,"=Y")) -> 0 | BG17: =IF(E17="","",VLOOKUP(BF17,LookUp!$AC$3:$AE$53,2,FALSE)) -> 66 | BH17: =IF(E17="","",VLOOKUP(BF17,LookUp!$AC$3:$AE$53,3,FALSE)) -> <=7:09
A18: 45356 | B18: 40967 | C18: 3 | D18: 3B | E18: Lname9 | F18: Fname9 | G18: XXXXX9 | BF18: =IF(E18="",0,COUNTIF(H18:BE18,"=Y")) -> 0 | BG18: =IF(E18="","",VLOOKUP(BF18,LookUp!$AC$3:$AE$53,2,FALSE)) -> 66 | BH18: =IF(E18="","",VLOOKUP(BF18,LookUp!$AC$3:$AE$53,3,FALSE)) -> <=7:09
A19: 45356 | B19: 40968 | C19: 3 | D19: 3B | E19: Lname10 | F19: Fname10 | G19: XXXXX10 | BF19: =IF(E19="",0,COUNTIF(H19:BE19,"=Y")) -> 0 | BG19: =IF(E19="","",VLOOKUP(BF19,LookUp!$AC$3:$AE$53,2,FALSE)) -> 66 | BH19: =IF(E19="","",VLOOKUP(BF19,LookUp!$AC$3:$AE$53,3,FALSE)) -> <=7:09
BF20: =IF(E20="",0,COUNTIF(H20:BE20,"=Y")) -> 0 | BG20: =IF(E20="","",VLOOKUP(BF20,LookUp!$AC$3:$AE$53,2,FALSE)) | BH20: =IF(E20="","",VLOOKUP(BF20,LookUp!$AC$3:$AE$53,3,FALSE))
BF21: =IF(E21="",0,COUNTIF(H21:BE21,"=Y")) -> 0 | BG21: =IF(E21="","",VLOOKUP(BF21,LookUp!$AC$3:$AE$53,2,FALSE)) | BH21: =IF(E21="","",VLOOKUP(BF21,LookUp!$AC$3:$AE$53,3,FALSE))
BF22: =IF(E22="",0,COUNTIF(H22:BE22,"=Y")) -> 0 | BG22: =IF(E22="","",VLOOKUP(BF22,LookUp!$AC$3:$AE$53,2,FALSE)) | BH22: =IF(E22="","",VLOOKUP(BF22,LookUp!$AC$3:$AE$53,3,FALSE))
BF23: =IF(E23="",0,COUNTIF(H23:BE23,"=Y")) -> 0 | BG23: =IF(E23="","",VLOOKUP(BF23,LookUp!$AC$3:$AE$53,2,FALSE)) | BH23: =IF(E23="","",VLOOKUP(BF23,LookUp!$AC$3:$AE$53,3,FALSE))
BF24: =IF(E24="",0,COUNTIF(H24:BE24,"=Y")) -> 0 | BG24: =IF(E24="","",VLOOKUP(BF24,LookUp!$AC$3:$AE$53,2,FALSE)) | BH24: =IF(E24="","",VLOOKUP(BF24,LookUp!$AC$3:$AE$53,3,FALSE))
BF25: =IF(E25="",0,COUNTIF(H25:BE25,"=Y")) -> 0 | BG25: =IF(E25="","",VLOOKUP(BF25,LookUp!$AC$3:$AE$53,2,FALSE)) | BH25: =IF(E25="","",VLOOKUP(BF25,LookUp!$AC$3:$AE$53,3,FALSE))
BF26: =IF(E26="",0,COUNTIF(H26:BE26,"=Y")) -> 0 | BG26: =IF(E26="","",VLOOKUP(BF26,LookUp!$AC$3:$AE$53,2,FALSE)) | BH26: =IF(E26="","",VLOOKUP(BF26,LookUp!$AC$3:$AE$53,3,FALSE))
BF27: =IF(E27="",0,COUNTIF(H27:BE27,"=Y")) -> 0 | BG27: =IF(E27="","",VLOOKUP(BF27,LookUp!$AC$3:$AE$53,2,FALSE)) | BH27: =IF(E27="","",VLOOKUP(BF27,LookUp!$AC$3:$AE$53,3,FALSE))
BF28: =IF(E28="",0,COUNTIF(H28:BE28,"=Y")) -> 0 | BG28: =IF(E28="","",VLOOKUP(BF28,LookUp!$AC$3:$AE$53,2,FALSE)) | BH28: =IF(E28="","",VLOOKUP(BF28,LookUp!$AC$3:$AE$53,3,FALSE))
BF29: =IF(E29="",0,COUNTIF(H29:BE29,"=Y")) -> 0 | BG29: =IF(E29="","",VLOOKUP(BF29,LookUp!$AC$3:$AE$53,2,FALSE)) | BH29: =IF(E29="","",VLOOKUP(BF29,LookUp!$AC$3:$AE$53,3,FALSE))
BF30: =IF(E30="",0,COUNTIF(H30:BE30,"=Y")) -> 0 | BG30: =IF(E30="","",VLOOKUP(BF30,LookUp!$AC$3:$AE$53,2,FALSE)) | BH30: =IF(E30="","",VLOOKUP(BF30,LookUp!$AC$3:$AE$53,3,FALSE))
BF31: =IF(E31="",0,COUNTIF(H31:BE31,"=Y")) -> 0 | BG31: =IF(E31="","",VLOOKUP(BF31,LookUp!$AC$3:$AE$53,2,FALSE)) | BH31: =IF(E31="","",VLOOKUP(BF31,LookUp!$AC$3:$AE$53,3,FALSE))
... BF452: =IF(E452="",0,COUNTIF(H452:BE452,"=Y")) -> 0 | BG452: =IF(E452="","",VLOOKUP(BF452,LookUp!$AC$3:$AE$53,2,FALSE)) | BH452: =IF(E452="","",VLOOKUP(BF452,LookUp!$AC$3:$AE$53,3,FALSE))

Sheet SWST I
A1: SWST - Test I
H3: QUESTION No. and ANSWER KEY (Enter the student's response - "Y" if correct; "N" if incorrect )
F4: Question Number | H4: 1 | I4: 2 | J4: 3 | K4: 4 | L4: 5 | M4: 6 | N4: 7 | O4: 8 | P4: 9 | Q4: 10 | R4: 11 | S4: 12 | T4: 13 | U4: 14 | V4: 15 | W4: 16 | X4: 17 | Y4: 18 | Z4: 19 | AA4: 20 | AB4: 21 | AC4: 22 | AD4: 23 | AE4: 24 | AF4: 25 | AG4: 26 | AH4: 27 | AI4: 28 | AJ4: 29 | AK4: 30 | AL4: 31 | AM4: 32 | AN4: 33 | AO4: 34 | AP4: 35 | AQ4: 36 | AR4: 37 | AS4: 38 | AT4: 39 | AU4: 40 | AV4: 41 | AW4: 42 | AX4: 43 | AY4: 44 | AZ4: 45 | BA4: 46 | BB4: 47 | BC4: 48 | BD4: 49 | BE4: 50
F5: Spelling Words | H5: STANDING | I5: DEFROST | J5: TIGHTER | K5: DIFFERENT | L5: HEDGE | M5: ELECTRICITY | N5: SPRAINED | O5: MANUFACTURED | P5: OBVIOUS | Q5: BEAUTIFUL | R5: UNINTERESTED | S5: FASHIONABLE | T5: KNIVES | U5: QUALIFIED | V5: MUSICIAN | W5: INFECTIOUS | X5: FAVOURITE | Y5: TRAVELLED | Z5: EXCELLENT | AA5: MAGICIAN | AB5: SIGNATURE | AC5: EXCEPTIONAL | AD5: BEHAVIOUR | AE5: IMPATIENT | AF5: ARTIFICIAL | AG5: FOREIGN | AH5: ACHIEVE | AI5: DISCUSSION | AJ5: BEGINNING | AK5: CIRCUMFERENCE | AL5: PHYSICALLY | AM5: REHEARSE | AN5: SUCCESSFUL | AO5: LIBRARIES | AP5: COINCIDENCE | AQ5: POISONOUS | AR5: DISAPPOINTED | AS5: NOTICEABLE | AT5: NOISILY | AU5: IRRESPONSIBLE | AV5: ACCIDENTALLY | AW5: INCONVENIENT | AX5: CONCEITED | AY5: QUARRELLED | AZ5: DECEIVED | BA5: PHENOMENON | BB5: SEPARATELY | BC5: ILLEGIBLE | BD5: UNNECESSARY | BE5: DEFINITELY
A7: required | B7: required | C7: required | D7: optional | E7: required | F7: required | G7: required
A8: Test Date (dd/mm/yy) | B8: Date of Birth (dd/mm/yy) | C8: Yr_Lev | D8: Grp | E8: Surname | F8: First_Name | G8: Student_ID | H8: Y | I8: Y | J8: Y | K8: Y | L8: Y | M8: Y | N8: Y | O8: Y | P8: Y | Q8: Y | R8: Y | S8: Y | T8: Y | U8: Y | V8: Y | W8: Y | X8: Y | Y8: Y | Z8: Y | AA8: Y | AB8: Y | AC8: Y | AD8: Y | AE8: Y | AF8: Y | AG8: Y | AH8: Y | AI8: Y | AJ8: Y | AK8: Y | AL8: Y | AM8: Y | AN8: Y | AO8: Y | AP8: Y | AQ8: Y | AR8: Y | AS8: Y | AT8: Y | AU8: Y | AV8: Y | AW8: Y | AX8: Y | AY8: Y | AZ8: Y | BA8: Y | BB8: Y | BC8: Y | BD8: Y | BE8: Y | BF8: Raw Score | BG8: Progress Score | BH8: Spelling Age
A9: 45356 | B9: 40959 | C9: 3 | D9: 3A | E9: Lname1 | F9: Fname1 | G9: XXXXX1 | BF9: =IF(E9="",0,COUNTIF(H9:BE9,"=Y")) -> 0 | BG9: =IF(E9="","",VLOOKUP(BF9,LookUp!$AG$3:$AI$53,2,FALSE)) -> 73 | BH9: =IF(E9="","",VLOOKUP(BF9,LookUp!$AG$3:$AI$53,3,FALSE)) -> <=8:04
A10: 45356 | B10: 40960 | C10: 3 | D10: 3A | E10: Lname2 | F10: Fname2 | G10: XXXXX2 | BF10: =IF(E10="",0,COUNTIF(H10:BE10,"=Y")) -> 0 | BG10: =IF(E10="","",VLOOKUP(BF10,LookUp!$AG$3:$AI$53,2,FALSE)) -> 73 | BH10: =IF(E10="","",VLOOKUP(BF10,LookUp!$AG$3:$AI$53,3,FALSE)) -> <=8:04
A11: 45356 | B11: 40961 | C11: 3 | D11: 3A | E11: Lname3 | F11: Fname3 | G11: XXXXX3 | BF11: =IF(E11="",0,COUNTIF(H11:BE11,"=Y")) -> 0 | BG11: =IF(E11="","",VLOOKUP(BF11,LookUp!$AG$3:$AI$53,2,FALSE)) -> 73 | BH11: =IF(E11="","",VLOOKUP(BF11,LookUp!$AG$3:$AI$53,3,FALSE)) -> <=8:04
A12: 45356 | B12: 40962 | C12: 3 | D12: 3A | E12: Lname4 | F12: Fname4 | G12: XXXXX4 | BF12: =IF(E12="",0,COUNTIF(H12:BE12,"=Y")) -> 0 | BG12: =IF(E12="","",VLOOKUP(BF12,LookUp!$AG$3:$AI$53,2,FALSE)) -> 73 | BH12: =IF(E12="","",VLOOKUP(BF12,LookUp!$AG$3:$AI$53,3,FALSE)) -> <=8:04
A13: 45356 | B13: 40970 | C13: 3 | D13: 3B | E13: ULname13 | F13: UFname13 | G13: UNLISTED | BF13: =IF(E13="",0,COUNTIF(H13:BE13,"=Y")) -> 0 | BG13: =IF(E13="","",VLOOKUP(BF13,LookUp!$AG$3:$AI$53,2,FALSE)) -> 73 | BH13: =IF(E13="","",VLOOKUP(BF13,LookUp!$AG$3:$AI$53,3,FALSE)) -> <=8:04
A14: 45356 | B14: 40963 | C14: 3 | D14: 3A | E14: Lname5 | F14: Fname5 | G14: XXXXX5 | BF14: =IF(E14="",0,COUNTIF(H14:BE14,"=Y")) -> 0 | BG14: =IF(E14="","",VLOOKUP(BF14,LookUp!$AG$3:$AI$53,2,FALSE)) -> 73 | BH14: =IF(E14="","",VLOOKUP(BF14,LookUp!$AG$3:$AI$53,3,FALSE)) -> <=8:04
