Workbook

Sheet Main Menu
B2: PAT-Maths / I can do maths Third Edition Scoring Templates
B4: This series of spreadsheets provide the templates required to enter ACER's PAT-Maths & I can do maths results into the Student Performance Analyser (SPA). Click on the appropriate button (at right) to select the correct Test Booklet proforma to complete. Follow the instructions opposite. | H4: Step 1: Click on the appropriate button (at left) to select the correct Test Booklet proforma to complete. Step 2: For each student, enter the Date (when test was sat), Year Level, Home Group, Name, and Student ID (CASES No. or Student No.). Step 3: For each question, enter their response (their score will be calculated) OR enter their Raw Score OR enter their PAT Score. Step 4: Save and upload into SPA.
B29: Click here to find out more about other tests available from ACER | H29: Click here to find out more about the Student Performance Analyser

Sheet ICDM TBA
A1: I can do maths - Level A
G3: QUESTION No. and ANSWER KEY (Enter the student's response - "Y" if correct; "N" if incorrect )
E4: Question Number | G4: 1 | H4: 2 | I4: 3 | J4: 4 | K4: 5 | L4: 6 | M4: 7 | N4: 8 | O4: 9 | P4: 10 | Q4: 11 | R4: 12 | S4: 13 | T4: 14 | U4: 15 | V4: 16 | W4: 17 | X4: 18 | Y4: 19 | Z4: 20 | AA4: 21 | AB4: 22 | AC4: 23 | AD4: 24 | AE4: 25 | AF4: 26 | AG4: 27 | AH4: 28 | AI4: 29 | AJ4: 30
E5: Item Difficulty | G5: -19 | H5: -22 | I5: -12 | J5: -10 | K5: -8 | L5: -6 | M5: -11 | N5: -20 | O5: -3 | P5: 2 | Q5: 2 | R5: 3 | S5: 5 | T5: -1 | U5: 6 | V5: 14 | W5: 5 | X5: 8 | Y5: 8 | Z5: 17 | AA5: 20 | AB5: 33 | AC5: 16 | AD5: 21 | AE5: 22 | AF5: 26 | AG5: 31 | AH5: 35 | AI5: 40 | AJ5: 44
E6: Skill Assessed | G6: M | H6: N | I6: N | J6: M | K6: M | L6: N | M6: M | N6: N | O6: S | P6: S | Q6: N | R6: S | S6: N | T6: S | U6: S | V6: S | W6: S | X6: N | Y6: N | Z6: M | AA6: M | AB6: M | AC6: M | AD6: M | AE6: N | AF6: N | AG6: S | AH6: M | AI6: N | AJ6: N
A7: required | B7: required | C7: optional | D7: required | E7: required | F7: required
A8: Date (dd/mm/yy) | B8: Yr_Lev | C8: Grp | D8: Surname | E8: First_Name | F8: Student_ID | G8: Y | H8: Y | I8: Y | J8: Y | K8: Y | L8: Y | M8: Y | N8: Y | O8: Y | P8: Y | Q8: Y | R8: Y | S8: Y | T8: Y | U8: Y | V8: Y | W8: Y | X8: Y | Y8: Y | Z8: Y | AA8: Y | AB8: Y | AC8: Y | AD8: Y | AE8: Y | AF8: Y | AG8: Y | AH8: Y | AI8: Y | AJ8: Y | AK8: Raw Score | AL8: PAT Score
A9: 45356 | B9: 3 | C9: 3A | D9: Lname1 | E9: Fname1 | F9: XXXXX1 | AK9: =IF(D9="",0,(IF(G9=$G$8,1,0)+IF(H9=$H$8,1,0)+IF(I9=$I$8,1,0)+IF(J9=$J$8,1,0)+IF(K9=$K$8,1,0)+IF(L9=$L$8,1,0)+IF(M9=$M$8,1,0)+IF(N9=$N$8,1,0)+IF(O9=$O$8,1,0)+IF(P9=$P$8,1,0)+IF(Q9=$Q$8,1,0)+IF(R9=$R$8,1,0)+IF(S9=$S$8,1,0)+IF(T9=$T$8,1,0)+IF(U9=$U$8,1,0)+IF(V9=$V$8,1,0)+IF(W9=$W$8,1,0)+IF(X9=$X$8,1,0)+IF(Y9=$Y$8,1,0)+IF(Z9=$Z$8,1,0)+IF(AA9=$AA$8,1,0)+IF(AB9=$AB$8,1,0)+IF(AC9=$AC$8,1,0)+IF(AD9=$AD$8,1,0)+IF(AE9=$AE$8,1,0)+IF(AF9=$AF$8,1,0)+IF(AG9=$AG$8,1,0)+IF(AH9=$AH$8,1,0)+IF(AI9=$AI$8,1,0)+IF(AJ9=$AJ$8,1,0))) -> 0 | AL9: =IF(D9="","",VLOOKUP(AK9,'PAT Maths'!$B$3:$C$44,2,FALSE)) -> -48
A10: 45356 | B10: 3 | C10: 3A | D10: Lname2 | E10: Fname2 | F10: XXXXX2 | AK10: =IF(D10="",0,(IF(G10=$G$8,1,0)+IF(H10=$H$8,1,0)+IF(I10=$I$8,1,0)+IF(J10=$J$8,1,0)+IF(K10=$K$8,1,0)+IF(L10=$L$8,1,0)+IF(M10=$M$8,1,0)+IF(N10=$N$8,1,0)+IF(O10=$O$8,1,0)+IF(P10=$P$8,1,0)+IF(Q10=$Q$8,1,0)+IF(R10=$R$8,1,0)+IF(S10=$S$8,1,0)+IF(T10=$T$8,1,0)+IF(U10=$U$8,1,0)+IF(V10=$V$8,1,0)+IF(W10=$W$8,1,0)+IF(X10=$X$8,1,0)+IF(Y10=$Y$8,1,0)+IF(Z10=$Z$8,1,0)+IF(AA10=$AA$8,1,0)+IF(AB10=$AB$8,1,0)+IF(AC10=$AC$8,1,0)+IF(AD10=$AD$8,1,0)+IF(AE10=$AE$8,1,0)+IF(AF10=$AF$8,1,0)+IF(AG10=$AG$8,1,0)+IF(AH10=$AH$8,1,0)+IF(AI10=$AI$8,1,0)+IF(AJ10=$AJ$8,1,0))) -> 0 | AL10: =IF(D10="","",VLOOKUP(AK10,'PAT Maths'!$B$3:$C$44,2,FALSE)) -> -48
A11: 45356 | B11: 3 | C11: 3A | D11: Lname3 | E11: Fname3 | F11: XXXXX3 | AK11: =IF(D11="",0,(IF(G11=$G$8,1,0)+IF(H11=$H$8,1,0)+IF(I11=$I$8,1,0)+IF(J11=$J$8,1,0)+IF(K11=$K$8,1,0)+IF(L11=$L$8,1,0)+IF(M11=$M$8,1,0)+IF(N11=$N$8,1,0)+IF(O11=$O$8,1,0)+IF(P11=$P$8,1,0)+IF(Q11=$Q$8,1,0)+IF(R11=$R$8,1,0)+IF(S11=$S$8,1,0)+IF(T11=$T$8,1,0)+IF(U11=$U$8,1,0)+IF(V11=$V$8,1,0)+IF(W11=$W$8,1,0)+IF(X11=$X$8,1,0)+IF(Y11=$Y$8,1,0)+IF(Z11=$Z$8,1,0)+IF(AA11=$AA$8,1,0)+IF(AB11=$AB$8,1,0)+IF(AC11=$AC$8,1,0)+IF(AD11=$AD$8,1,0)+IF(AE11=$AE$8,1,0)+IF(AF11=$AF$8,1,0)+IF(AG11=$AG$8,1,0)+IF(AH11=$AH$8,1,0)+IF(AI11=$AI$8,1,0)+IF(AJ11=$AJ$8,1,0))) -> 0 | AL11: =IF(D11="","",VLOOKUP(AK11,'PAT Maths'!$B$3:$C$44,2,FALSE)) -> -48
A12: 45356 | B12: 3 | C12: 3A | D12: Lname4 | E12: Fname4 | F12: XXXXX4 | AK12: =IF(D12="",0,(IF(G12=$G$8,1,0)+IF(H12=$H$8,1,0)+IF(I12=$I$8,1,0)+IF(J12=$J$8,1,0)+IF(K12=$K$8,1,0)+IF(L12=$L$8,1,0)+IF(M12=$M$8,1,0)+IF(N12=$N$8,1,0)+IF(O12=$O$8,1,0)+IF(P12=$P$8,1,0)+IF(Q12=$Q$8,1,0)+IF(R12=$R$8,1,0)+IF(S12=$S$8,1,0)+IF(T12=$T$8,1,0)+IF(U12=$U$8,1,0)+IF(V12=$V$8,1,0)+IF(W12=$W$8,1,0)+IF(X12=$X$8,1,0)+IF(Y12=$Y$8,1,0)+IF(Z12=$Z$8,1,0)+IF(AA12=$AA$8,1,0)+IF(AB12=$AB$8,1,0)+IF(AC12=$AC$8,1,0)+IF(AD12=$AD$8,1,0)+IF(AE12=$AE$8,1,0)+IF(AF12=$AF$8,1,0)+IF(AG12=$AG$8,1,0)+IF(AH12=$AH$8,1,0)+IF(AI12=$AI$8,1,0)+IF(AJ12=$AJ$8,1,0))) -> 0 | AL12: =IF(D12="","",VLOOKUP(AK12,'PAT Maths'!$B$3:$C$44,2,FALSE)) -> -48
A13: 45356 | B13: 3 | C13: 3B | D13: ULname13 | E13: UFname13 | F13: UNLISTED | AK13: =IF(D13="",0,(IF(G13=$G$8,1,0)+IF(H13=$H$8,1,0)+IF(I13=$I$8,1,0)+IF(J13=$J$8,1,0)+IF(K13=$K$8,1,0)+IF(L13=$L$8,1,0)+IF(M13=$M$8,1,0)+IF(N13=$N$8,1,0)+IF(O13=$O$8,1,0)+IF(P13=$P$8,1,0)+IF(Q13=$Q$8,1,0)+IF(R13=$R$8,1,0)+IF(S13=$S$8,1,0)+IF(T13=$T$8,1,0)+IF(U13=$U$8,1,0)+IF(V13=$V$8,1,0)+IF(W13=$W$8,1,0)+IF(X13=$X$8,1,0)+IF(Y13=$Y$8,1,0)+IF(Z13=$Z$8,1,0)+IF(AA13=$AA$8,1,0)+IF(AB13=$AB$8,1,0)+IF(AC13=$AC$8,1,0)+IF(AD13=$AD$8,1,0)+IF(AE13=$AE$8,1,0)+IF(AF13=$AF$8,1,0)+IF(AG13=$AG$8,1,0)+IF(AH13=$AH$8,1,0)+IF(AI13=$AI$8,1,0)+IF(AJ13=$AJ$8,1,0))) -> 0 | AL13: =IF(D13="","",VLOOKUP(AK13,'PAT Maths'!$B$3:$C$44,2,FALSE)) -> -48
A14: 45356 | B14: 3 | C14: 3A | D14: Lname5 | E14: Fname5 | F14: XXXXX5 | AK14: =IF(D14="",0,(IF(G14=$G$8,1,0)+IF(H14=$H$8,1,0)+IF(I14=$I$8,1,0)+IF(J14=$J$8,1,0)+IF(K14=$K$8,1,0)+IF(L14=$L$8,1,0)+IF(M14=$M$8,1,0)+IF(N14=$N$8,1,0)+IF(O14=$O$8,1,0)+IF(P14=$P$8,1,0)+IF(Q14=$Q$8,1,0)+IF(R14=$R$8,1,0)+IF(S14=$S$8,1,0)+IF(T14=$T$8,1,0)+IF(U14=$U$8,1,0)+IF(V14=$V$8,1,0)+IF(W14=$W$8,1,0)+IF(X14=$X$8,1,0)+IF(Y14=$Y$8,1,0)+IF(Z14=$Z$8,1,0)+IF(AA14=$AA$8,1,0)+IF(AB14=$AB$8,1,0)+IF(AC14=$AC$8,1,0)+IF(AD14=$AD$8,1,0)+IF(AE14=$AE$8,1,0)+IF(AF14=$AF$8,1,0)+IF(AG14=$AG$8,1,0)+IF(AH14=$AH$8,1,0)+IF(AI14=$AI$8,1,0)+IF(AJ14=$AJ$8,1,0))) -> 0 | AL14: =IF(D14="","",VLOOKUP(AK14,'PAT Maths'!$B$3:$C$44,2,FALSE)) -> -48
A15: 45356 | B15: 3 | C15: 3B | D15: Lname6 | E15: Fname6 | F15: XXXXX6 | AK15: =IF(D15="",0,(IF(G15=$G$8,1,0)+IF(H15=$H$8,1,0)+IF(I15=$I$8,1,0)+IF(J15=$J$8,1,0)+IF(K15=$K$8,1,0)+IF(L15=$L$8,1,0)+IF(M15=$M$8,1,0)+IF(N15=$N$8,1,0)+IF(O15=$O$8,1,0)+IF(P15=$P$8,1,0)+IF(Q15=$Q$8,1,0)+IF(R15=$R$8,1,0)+IF(S15=$S$8,1,0)+IF(T15=$T$8,1,0)+IF(U15=$U$8,1,0)+IF(V15=$V$8,1,0)+IF(W15=$W$8,1,0)+IF(X15=$X$8,1,0)+IF(Y15=$Y$8,1,0)+IF(Z15=$Z$8,1,0)+IF(AA15=$AA$8,1,0)+IF(AB15=$AB$8,1,0)+IF(AC15=$AC$8,1,0)+IF(AD15=$AD$8,1,0)+IF(AE15=$AE$8,1,0)+IF(AF15=$AF$8,1,0)+IF(AG15=$AG$8,1,0)+IF(AH15=$AH$8,1,0)+IF(AI15=$AI$8,1,0)+IF(AJ15=$AJ$8,1,0))) -> 0 | AL15: =IF(D15="","",VLOOKUP(AK15,'PAT Maths'!$B$3:$C$44,2,FALSE)) -> -48
A16: 45356 | B16: 3 | C16: 3B | D16: Lname7 | E16: Fname7 | F16: XXXXX7 | AK16: =IF(D16="",0,(IF(G16=$G$8,1,0)+IF(H16=$H$8,1,0)+IF(I16=$I$8,1,0)+IF(J16=$J$8,1,0)+IF(K16=$K$8,1,0)+IF(L16=$L$8,1,0)+IF(M16=$M$8,1,0)+IF(N16=$N$8,1,0)+IF(O16=$O$8,1,0)+IF(P16=$P$8,1,0)+IF(Q16=$Q$8,1,0)+IF(R16=$R$8,1,0)+IF(S16=$S$8,1,0)+IF(T16=$T$8,1,0)+IF(U16=$U$8,1,0)+IF(V16=$V$8,1,0)+IF(W16=$W$8,1,0)+IF(X16=$X$8,1,0)+IF(Y16=$Y$8,1,0)+IF(Z16=$Z$8,1,0)+IF(AA16=$AA$8,1,0)+IF(AB16=$AB$8,1,0)+IF(AC16=$AC$8,1,0)+IF(AD16=$AD$8,1,0)+IF(AE16=$AE$8,1,0)+IF(AF16=$AF$8,1,0)+IF(AG16=$AG$8,1,0)+IF(AH16=$AH$8,1,0)+IF(AI16=$AI$8,1,0)+IF(AJ16=$AJ$8,1,0))) -> 0 | AL16: =IF(D16="","",VLOOKUP(AK16,'PAT Maths'!$B$3:$C$44,2,FALSE)) -> -48
A17: 45356 | B17: 3 | C17: 3B | D17: Lname8 | E17: Fname8 | F17: XXXXX8 | AK17: =IF(D17="",0,(IF(G17=$G$8,1,0)+IF(H17=$H$8,1,0)+IF(I17=$I$8,1,0)+IF(J17=$J$8,1,0)+IF(K17=$K$8,1,0)+IF(L17=$L$8,1,0)+IF(M17=$M$8,1,0)+IF(N17=$N$8,1,0)+IF(O17=$O$8,1,0)+IF(P17=$P$8,1,0)+IF(Q17=$Q$8,1,0)+IF(R17=$R$8,1,0)+IF(S17=$S$8,1,0)+IF(T17=$T$8,1,0)+IF(U17=$U$8,1,0)+IF(V17=$V$8,1,0)+IF(W17=$W$8,1,0)+IF(X17=$X$8,1,0)+IF(Y17=$Y$8,1,0)+IF(Z17=$Z$8,1,0)+IF(AA17=$AA$8,1,0)+IF(AB17=$AB$8,1,0)+IF(AC17=$AC$8,1,0)+IF(AD17=$AD$8,1,0)+IF(AE17=$AE$8,1,0)+IF(AF17=$AF$8,1,0)+IF(AG17=$AG$8,1,0)+IF(AH17=$AH$8,1,0)+IF(AI17=$AI$8,1,0)+IF(AJ17=$AJ$8,1,0))) -> 0 | AL17: =IF(D17="","",VLOOKUP(AK17,'PAT Maths'!$B$3:$C$44,2,FALSE)) -> -48
A18: 45356 | B18: 3 | C18: 3B | D18: Lname9 | E18: Fname9 | F18: XXXXX9 | AK18: =IF(D18="",0,(IF(G18=$G$8,1,0)+IF(H18=$H$8,1,0)+IF(I18=$I$8,1,0)+IF(J18=$J$8,1,0)+IF(K18=$K$8,1,0)+IF(L18=$L$8,1,0)+IF(M18=$M$8,1,0)+IF(N18=$N$8,1,0)+IF(O18=$O$8,1,0)+IF(P18=$P$8,1,0)+IF(Q18=$Q$8,1,0)+IF(R18=$R$8,1,0)+IF(S18=$S$8,1,0)+IF(T18=$T$8,1,0)+IF(U18=$U$8,1,0)+IF(V18=$V$8,1,0)+IF(W18=$W$8,1,0)+IF(X18=$X$8,1,0)+IF(Y18=$Y$8,1,0)+IF(Z18=$Z$8,1,0)+IF(AA18=$AA$8,1,0)+IF(AB18=$AB$8,1,0)+IF(AC18=$AC$8,1,0)+IF(AD18=$AD$8,1,0)+IF(AE18=$AE$8,1,0)+IF(AF18=$AF$8,1,0)+IF(AG18=$AG$8,1,0)+IF(AH18=$AH$8,1,0)+IF(AI18=$AI$8,1,0)+IF(AJ18=$AJ$8,1,0))) -> 0 | AL18: =IF(D18="","",VLOOKUP(AK18,'PAT Maths'!$B$3:$C$44,2,FALSE)) -> -48
A19: 45356 | B19: 3 | C19: 3B | D19: Lname10 | E19: Fname10 | F19: XXXXX10 | AK19: =IF(D19="",0,(IF(G19=$G$8,1,0)+IF(H19=$H$8,1,0)+IF(I19=$I$8,1,0)+IF(J19=$J$8,1,0)+IF(K19=$K$8,1,0)+IF(L19=$L$8,1,0)+IF(M19=$M$8,1,0)+IF(N19=$N$8,1,0)+IF(O19=$O$8,1,0)+IF(P19=$P$8,1,0)+IF(Q19=$Q$8,1,0)+IF(R19=$R$8,1,0)+IF(S19=$S$8,1,0)+IF(T19=$T$8,1,0)+IF(U19=$U$8,1,0)+IF(V19=$V$8,1,0)+IF(W19=$W$8,1,0)+IF(X19=$X$8,1,0)+IF(Y19=$Y$8,1,0)+IF(Z19=$Z$8,1,0)+IF(AA19=$AA$8,1,0)+IF(AB19=$AB$8,1,0)+IF(AC19=$AC$8,1,0)+IF(AD19=$AD$8,1,0)+IF(AE19=$AE$8,1,0)+IF(AF19=$AF$8,1,0)+IF(AG19=$AG$8,1,0)+IF(AH19=$AH$8,1,0)+IF(AI19=$AI$8,1,0)+IF(AJ19=$AJ$8,1,0))) -> 0 | AL19: =IF(D19="","",VLOOKUP(AK19,'PAT Maths'!$B$3:$C$44,2,FALSE)) -> -48
AK20: =IF(D20="",0,(IF(G20=$G$8,1,0)+IF(H20=$H$8,1,0)+IF(I20=$I$8,1,0)+IF(J20=$J$8,1,0)+IF(K20=$K$8,1,0)+IF(L20=$L$8,1,0)+IF(M20=$M$8,1,0)+IF(N20=$N$8,1,0)+IF(O20=$O$8,1,0)+IF(P20=$P$8,1,0)+IF(Q20=$Q$8,1,0)+IF(R20=$R$8,1,0)+IF(S20=$S$8,1,0)+IF(T20=$T$8,1,0)+IF(U20=$U$8,1,0)+IF(V20=$V$8,1,0)+IF(W20=$W$8,1,0)+IF(X20=$X$8,1,0)+IF(Y20=$Y$8,1,0)+IF(Z20=$Z$8,1,0)+IF(AA20=$AA$8,1,0)+IF(AB20=$AB$8,1,0)+IF(AC20=$AC$8,1,0)+IF(AD20=$AD$8,1,0)+IF(AE20=$AE$8,1,0)+IF(AF20=$AF$8,1,0)+IF(AG20=$AG$8,1,0)+IF(AH20=$AH$8,1,0)+IF(AI20=$AI$8,1,0)+IF(AJ20=$AJ$8,1,0))) -> 0 | AL20: =IF(D20="","",VLOOKUP(AK20,'PAT Maths'!$B$3:$C$44,2,FALSE))
AK21: =IF(D21="",0,(IF(G21=$G$8,1,0)+IF(H21=$H$8,1,0)+IF(I21=$I$8,1,0)+IF(J21=$J$8,1,0)+IF(K21=$K$8,1,0)+IF(L21=$L$8,1,0)+IF(M21=$M$8,1,0)+IF(N21=$N$8,1,0)+IF(O21=$O$8,1,0)+IF(P21=$P$8,1,0)+IF(Q21=$Q$8,1,0)+IF(R21=$R$8,1,0)+IF(S21=$S$8,1,0)+IF(T21=$T$8,1,0)+IF(U21=$U$8,1,0)+IF(V21=$V$8,1,0)+IF(W21=$W$8,1,0)+IF(X21=$X$8,1,0)+IF(Y21=$Y$8,1,0)+IF(Z21=$Z$8,1,0)+IF(AA21=$AA$8,1,0)+IF(AB21=$AB$8,1,0)+IF(AC21=$AC$8,1,0)+IF(AD21=$AD$8,1,0)+IF(AE21=$AE$8,1,0)+IF(AF21=$AF$8,1,0)+IF(AG21=$AG$8,1,0)+IF(AH21=$AH$8,1,0)+IF(AI21=$AI$8,1,0)+IF(AJ21=$AJ$8,1,0))) -> 0 | AL21: =IF(D21="","",VLOOKUP(AK21,'PAT Maths'!$B$3:$C$44,2,FALSE))
AK22: =IF(D22="",0,(IF(G22=$G$8,1,0)+IF(H22=$H$8,1,0)+IF(I22=$I$8,1,0)+IF(J22=$J$8,1,0)+IF(K22=$K$8,1,0)+IF(L22=$L$8,1,0)+IF(M22=$M$8,1,0)+IF(N22=$N$8,1,0)+IF(O22=$O$8,1,0)+IF(P22=$P$8,1,0)+IF(Q22=$Q$8,1,0)+IF(R22=$R$8,1,0)+IF(S22=$S$8,1,0)+IF(T22=$T$8,1,0)+IF(U22=$U$8,1,0)+IF(V22=$V$8,1,0)+IF(W22=$W$8,1,0)+IF(X22=$X$8,1,0)+IF(Y22=$Y$8,1,0)+IF(Z22=$Z$8,1,0)+IF(AA22=$AA$8,1,0)+IF(AB22=$AB$8,1,0)+IF(AC22=$AC$8,1,0)+IF(AD22=$AD$8,1,0)+IF(AE22=$AE$8,1,0)+IF(AF22=$AF$8,1,0)+IF(AG22=$AG$8,1,0)+IF(AH22=$AH$8,1,0)+IF(AI22=$AI$8,1,0)+IF(AJ22=$AJ$8,1,0))) -> 0 | AL22: =IF(D22="","",VLOOKUP(AK22,'PAT Maths'!$B$3:$C$44,2,FALSE))
AK23: =IF(D23="",0,(IF(G23=$G$8,1,0)+IF(H23=$H$8,1,0)+IF(I23=$I$8,1,0)+IF(J23=$J$8,1,0)+IF(K23=$K$8,1,0)+IF(L23=$L$8,1,0)+IF(M23=$M$8,1,0)+IF(N23=$N$8,1,0)+IF(O23=$O$8,1,0)+IF(P23=$P$8,1,0)+IF(Q23=$Q$8,1,0)+IF(R23=$R$8,1,0)+IF(S23=$S$8,1,0)+IF(T23=$T$8,1,0)+IF(U23=$U$8,1,0)+IF(V23=$V$8,1,0)+IF(W23=$W$8,1,0)+IF(X23=$X$8,1,0)+IF(Y23=$Y$8,1,0)+IF(Z23=$Z$8,1,0)+IF(AA23=$AA$8,1,0)+IF(AB23=$AB$8,1,0)+IF(AC23=$AC$8,1,0)+IF(AD23=$AD$8,1,0)+IF(AE23=$AE$8,1,0)+IF(AF23=$AF$8,1,0)+IF(AG23=$AG$8,1,0)+IF(AH23=$AH$8,1,0)+IF(AI23=$AI$8,1,0)+IF(AJ23=$AJ$8,1,0))) -> 0 | AL23: =IF(D23="","",VLOOKUP(AK23,'PAT Maths'!$B$3:$C$44,2,FALSE))
AK24: =IF(D24="",0,(IF(G24=$G$8,1,0)+IF(H24=$H$8,1,0)+IF(I24=$I$8,1,0)+IF(J24=$J$8,1,0)+IF(K24=$K$8,1,0)+IF(L24=$L$8,1,0)+IF(M24=$M$8,1,0)+IF(N24=$N$8,1,0)+IF(O24=$O$8,1,0)+IF(P24=$P$8,1,0)+IF(Q24=$Q$8,1,0)+IF(R24=$R$8,1,0)+IF(S24=$S$8,1,0)+IF(T24=$T$8,1,0)+IF(U24=$U$8,1,0)+IF(V24=$V$8,1,0)+IF(W24=$W$8,1,0)+IF(X24=$X$8,1,0)+IF(Y24=$Y$8,1,0)+IF(Z24=$Z$8,1,0)+IF(AA24=$AA$8,1,0)+IF(AB24=$AB$8,1,0)+IF(AC24=$AC$8,1,0)+IF(AD24=$AD$8,1,0)+IF(AE24=$AE$8,1,0)+IF(AF24=$AF$8,1,0)+IF(AG24=$AG$8,1,0)+IF(AH24=$AH$8,1,0)+IF(AI24=$AI$8,1,0)+IF(AJ24=$AJ$8,1,0))) -> 0 | AL24: =IF(D24="","",VLOOKUP(AK24,'PAT Maths'!$B$3:$C$44,2,FALSE))
AK25: =IF(D25="",0,(IF(G25=$G$8,1,0)+IF(H25=$H$8,1,0)+IF(I25=$I$8,1,0)+IF(J25=$J$8,1,0)+IF(K25=$K$8,1,0)+IF(L25=$L$8,1,0)+IF(M25=$M$8,1,0)+IF(N25=$N$8,1,0)+IF(O25=$O$8,1,0)+IF(P25=$P$8,1,0)+IF(Q25=$Q$8,1,0)+IF(R25=$R$8,1,0)+IF(S25=$S$8,1,0)+IF(T25=$T$8,1,0)+IF(U25=$U$8,1,0)+IF(V25=$V$8,1,0)+IF(W25=$W$8,1,0)+IF(X25=$X$8,1,0)+IF(Y25=$Y$8,1,0)+IF(Z25=$Z$8,1,0)+IF(AA25=$AA$8,1,0)+IF(AB25=$AB$8,1,0)+IF(AC25=$AC$8,1,0)+IF(AD25=$AD$8,1,0)+IF(AE25=$AE$8,1,0)+IF(AF25=$AF$8,1,0)+IF(AG25=$AG$8,1,0)+IF(AH25=$AH$8,1,0)+IF(AI25=$AI$8,1,0)+IF(AJ25=$AJ$8,1,0))) -> 0 | AL25: =IF(D25="","",VLOOKUP(AK25,'PAT Maths'!$B$3:$C$44,2,FALSE))
AK26: =IF(D26="",0,(IF(G26=$G$8,1,0)+IF(H26=$H$8,1,0)+IF(I26=$I$8,1,0)+IF(J26=$J$8,1,0)+IF(K26=$K$8,1,0)+IF(L26=$L$8,1,0)+IF(M26=$M$8,1,0)+IF(N26=$N$8,1,0)+IF(O26=$O$8,1,0)+IF(P26=$P$8,1,0)+IF(Q26=$Q$8,1,0)+IF(R26=$R$8,1,0)+IF(S26=$S$8,1,0)+IF(T26=$T$8,1,0)+IF(U26=$U$8,1,0)+IF(V26=$V$8,1,0)+IF(W26=$W$8,1,0)+IF(X26=$X$8,1,0)+IF(Y26=$Y$8,1,0)+IF(Z26=$Z$8,1,0)+IF(AA26=$AA$8,1,0)+IF(AB26=$AB$8,1,0)+IF(AC26=$AC$8,1,0)+IF(AD26=$AD$8,1,0)+IF(AE26=$AE$8,1,0)+IF(AF26=$AF$8,1,0)+IF(AG26=$AG$8,1,0)+IF(AH26=$AH$8,1,0)+IF(AI26=$AI$8,1,0)+IF(AJ26=$AJ$8,1,0))) -> 0 | AL26: =IF(D26="","",VLOOKUP(AK26,'PAT Maths'!$B$3:$C$44,2,FALSE))
AK27: =IF(D27="",0,(IF(G27=$G$8,1,0)+IF(H27=$H$8,1,0)+IF(I27=$I$8,1,0)+IF(J27=$J$8,1,0)+IF(K27=$K$8,1,0)+IF(L27=$L$8,1,0)+IF(M27=$M$8,1,0)+IF(N27=$N$8,1,0)+IF(O27=$O$8,1,0)+IF(P27=$P$8,1,0)+IF(Q27=$Q$8,1,0)+IF(R27=$R$8,1,0)+IF(S27=$S$8,1,0)+IF(T27=$T$8,1,0)+IF(U27=$U$8,1,0)+IF(V27=$V$8,1,0)+IF(W27=$W$8,1,0)+IF(X27=$X$8,1,0)+IF(Y27=$Y$8,1,0)+IF(Z27=$Z$8,1,0)+IF(AA27=$AA$8,1,0)+IF(AB27=$AB$8,1,0)+IF(AC27=$AC$8,1,0)+IF(AD27=$AD$8,1,0)+IF(AE27=$AE$8,1,0)+IF(AF27=$AF$8,1,0)+IF(AG27=$AG$8,1,0)+IF(AH27=$AH$8,1,0)+IF(AI27=$AI$8,1,0)+IF(AJ27=$AJ$8,1,0))) -> 0 | AL27: =IF(D27="","",VLOOKUP(AK27,'PAT Maths'!$B$3:$C$44,2,FALSE))
AK28: =IF(D28="",0,(IF(G28=$G$8,1,0)+IF(H28=$H$8,1,0)+IF(I28=$I$8,1,0)+IF(J28=$J$8,1,0)+IF(K28=$K$8,1,0)+IF(L28=$L$8,1,0)+IF(M28=$M$8,1,0)+IF(N28=$N$8,1,0)+IF(O28=$O$8,1,0)+IF(P28=$P$8,1,0)+IF(Q28=$Q$8,1,0)+IF(R28=$R$8,1,0)+IF(S28=$S$8,1,0)+IF(T28=$T$8,1,0)+IF(U28=$U$8,1,0)+IF(V28=$V$8,1,0)+IF(W28=$W$8,1,0)+IF(X28=$X$8,1,0)+IF(Y28=$Y$8,1,0)+IF(Z28=$Z$8,1,0)+IF(AA28=$AA$8,1,0)+IF(AB28=$AB$8,1,0)+IF(AC28=$AC$8,1,0)+IF(AD28=$AD$8,1,0)+IF(AE28=$AE$8,1,0)+IF(AF28=$AF$8,1,0)+IF(AG28=$AG$8,1,0)+IF(AH28=$AH$8,1,0)+IF(AI28=$AI$8,1,0)+IF(AJ28=$AJ$8,1,0))) -> 0 | AL28: =IF(D28="","",VLOOKUP(AK28,'PAT Maths'!$B$3:$C$44,2,FALSE))
AK29: =IF(D29="",0,(IF(G29=$G$8,1,0)+IF(H29=$H$8,1,0)+IF(I29=$I$8,1,0)+IF(J29=$J$8,1,0)+IF(K29=$K$8,1,0)+IF(L29=$L$8,1,0)+IF(M29=$M$8,1,0)+IF(N29=$N$8,1,0)+IF(O29=$O$8,1,0)+IF(P29=$P$8,1,0)+IF(Q29=$Q$8,1,0)+IF(R29=$R$8,1,0)+IF(S29=$S$8,1,0)+IF(T29=$T$8,1,0)+IF(U29=$U$8,1,0)+IF(V29=$V$8,1,0)+IF(W29=$W$8,1,0)+IF(X29=$X$8,1,0)+IF(Y29=$Y$8,1,0)+IF(Z29=$Z$8,1,0)+IF(AA29=$AA$8,1,0)+IF(AB29=$AB$8,1,0)+IF(AC29=$AC$8,1,0)+IF(AD29=$AD$8,1,0)+IF(AE29=$AE$8,1,0)+IF(AF29=$AF$8,1,0)+IF(AG29=$AG$8,1,0)+IF(AH29=$AH$8,1,0)+IF(AI29=$AI$8,1,0)+IF(AJ29=$AJ$8,1,0))) -> 0 | AL29: =IF(D29="","",VLOOKUP(AK29,'PAT Maths'!$B$3:$C$44,2,FALSE))
AK30: =IF(D30="",0,(IF(G30=$G$8,1,0)+IF(H30=$H$8,1,0)+IF(I30=$I$8,1,0)+IF(J30=$J$8,1,0)+IF(K30=$K$8,1,0)+IF(L30=$L$8,1,0)+IF(M30=$M$8,1,0)+IF(N30=$N$8,1,0)+IF(O30=$O$8,1,0)+IF(P30=$P$8,1,0)+IF(Q30=$Q$8,1,0)+IF(R30=$R$8,1,0)+IF(S30=$S$8,1,0)+IF(T30=$T$8,1,0)+IF(U30=$U$8,1,0)+IF(V30=$V$8,1,0)+IF(W30=$W$8,1,0)+IF(X30=$X$8,1,0)+IF(Y30=$Y$8,1,0)+IF(Z30=$Z$8,1,0)+IF(AA30=$AA$8,1,0)+IF(AB30=$AB$8,1,0)+IF(AC30=$AC$8,1,0)+IF(AD30=$AD$8,1,0)+IF(AE30=$AE$8,1,0)+IF(AF30=$AF$8,1,0)+IF(AG30=$AG$8,1,0)+IF(AH30=$AH$8,1,0)+IF(AI30=$AI$8,1,0)+IF(AJ30=$AJ$8,1,0))) -> 0 | AL30: =IF(D30="","",VLOOKUP(AK30,'PAT Maths'!$B$3:$C$44,2,FALSE))
AK31: =IF(D31="",0,(IF(G31=$G$8,1,0)+IF(H31=$H$8,1,0)+IF(I31=$I$8,1,0)+IF(J31=$J$8,1,0)+IF(K31=$K$8,1,0)+IF(L31=$L$8,1,0)+IF(M31=$M$8,1,0)+IF(N31=$N$8,1,0)+IF(O31=$O$8,1,0)+IF(P31=$P$8,1,0)+IF(Q31=$Q$8,1,0)+IF(R31=$R$8,1,0)+IF(S31=$S$8,1,0)+IF(T31=$T$8,1,0)+IF(U31=$U$8,1,0)+IF(V31=$V$8,1,0)+IF(W31=$W$8,1,0)+IF(X31=$X$8,1,0)+IF(Y31=$Y$8,1,0)+IF(Z31=$Z$8,1,0)+IF(AA31=$AA$8,1,0)+IF(AB31=$AB$8,1,0)+IF(AC31=$AC$8,1,0)+IF(AD31=$AD$8,1,0)+IF(AE31=$AE$8,1,0)+IF(AF31=$AF$8,1,0)+IF(AG31=$AG$8,1,0)+IF(AH31=$AH$8,1,0)+IF(AI31=$AI$8,1,0)+IF(AJ31=$AJ$8,1,0))) -> 0 | AL31: =IF(D31="","",VLOOKUP(AK31,'PAT Maths'!$B$3:$C$44,2,FALSE))
... AK317: =IF(D317="",0,(IF(G317=$G$8,1,0)+IF(H317=$H$8,1,0)+IF(I317=$I$8,1,0)+IF(J317=$J$8,1,0)+IF(K317=$K$8,1,0)+IF(L317=$L$8,1,0)+IF(M317=$M$8,1,0)+IF(N317=$N$8,1,0)+IF(O317=$O$8,1,0)+IF(P317=$P$8,1,0)+IF(Q317=$Q$8,1,0)+IF(R317=$R$8,1,0)+IF(S317=$S$8,1,0)+IF(T317=$T$8,1,0)+IF(U317=$U$8,1,0)+IF(V317=$V$8,1,0)+IF(W317=$W$8,1,0)+IF(X317=$X$8,1,0)+IF(Y317=$Y$8,1,0)+IF(Z317=$Z$8,1,0)+IF(AA317=$AA$8,1,0)+IF(AB317=$AB$8,1,0)+IF(AC317=$AC$8,1,0)+IF(AD317=$AD$8,1,0)+IF(AE317=$AE$8,1,0)+IF(AF317=$AF$8,1,0)+IF(AG317=$AG$8,1,0)+IF(AH317=$AH$8,1,0)+IF(AI317=$AI$8,1,0)+IF(AJ317=$AJ$8,1,0))) -> 0 | AL317: =IF(D317="","",VLOOKUP(AK317,'PAT Maths'!$B$3:$C$44,2,FALSE))

Sheet ICDM TBB
A1: I can do maths - Level B
G3: QUESTION No. and ANSWER KEY (Enter the student's response - "Y" if correct; "N" if incorrect )
E4: Question Number | G4: 1 | H4: 2 | I4: 3 | J4: 4 | K4: 5 | L4: 6 | M4: 7 | N4: 8 | O4: 9 | P4: 10 | Q4: 11 | R4: 12 | S4: 13 | T4: 14 | U4: 15 | V4: 16 | W4: 17 | X4: 18 | Y4: 19 | Z4: 20 | AA4: 21 | AB4: 22 | AC4: 23 | AD4: 24 | AE4: 25 | AF4: 26 | AG4: 27 | AH4: 28 | AI4: 29 | AJ4: 30 | AK4: 31 | AL4: 32 | AM4: 33
E5: Item Difficulty | G5: -16 | H5: -19 | I5: -11 | J5: 3 | K5: -1 | L5: 8 | M5: -6 | N5: 1 | O5: 14 | P5: -1 | Q5: 11 | R5: 2 | S5: 5 | T5: 5 | U5: 15 | V5: 20 | W5: 10 | X5: 18 | Y5: 30 | Z5: 32 | AA5: 34 | AB5: 21 | AC5: 23 | AD5: 27 | AE5: 25 | AF5: 35 | AG5: 47 | AH5: 41 | AI5: 44 | AJ5: 45 | AK5: 46 | AL5: 56 | AM5: 52
E6: Skill Assessed | G6: M | H6: M | I6: M | J6: S | K6: S | L6: N | M6: N | N6: S | O6: S | P6: S | Q6: S | R6: N | S6: N | T6: S | U6: M | V6: M | W6: N | X6: M | Y6: N | Z6: S | AA6: M | AB6: M | AC6: N | AD6: N | AE6: M | AF6: M | AG6: N | AH6: N | AI6: N | AJ6: N | AK6: N | AL6: N | AM6: N
A7: required | B7: required | C7: optional | D7: required | E7: required | F7: required
A8: Date (dd/mm/yy) | B8: Yr_Lev | C8: Grp | D8: Surname | E8: First_Name | F8: Student_ID | G8: Y | H8: Y | I8: Y | J8: Y | K8: Y | L8: Y | M8: Y | N8: Y | O8: Y | P8: Y | Q8: Y | R8: Y | S8: Y | T8: Y | U8: Y | V8: Y | W8: Y | X8: Y | Y8: Y | Z8: Y | AA8: Y | AB8: Y | AC8: Y | AD8: Y | AE8: Y | AF8: Y | AG8: Y | AH8: Y | AI8: Y | AJ8: Y | AK8: Y | AL8: Y | AM8: Y | AN8: Raw Score | AO8: PAT Score
A9: 45356 | B9: 3 | C9: 3A | D9: Lname1 | E9: Fname1 | F9: XXXXX1 | AN9: =IF(D9="",0,(IF(G9=$G$8,1,0)+IF(H9=$H$8,1,0)+IF(I9=$I$8,1,0)+IF(J9=$J$8,1,0)+IF(K9=$K$8,1,0)+IF(L9=$L$8,1,0)+IF(M9=$M$8,1,0)+IF(N9=$N$8,1,0)+IF(O9=$O$8,1,0)+IF(P9=$P$8,1,0)+IF(Q9=$Q$8,1,0)+IF(R9=$R$8,1,0)+IF(S9=$S$8,1,0)+IF(T9=$T$8,1,0)+IF(U9=$U$8,1,0)+IF(V9=$V$8,1,0)+IF(W9=$W$8,1,0)+IF(X9=$X$8,1,0)+IF(Y9=$Y$8,1,0)+IF(Z9=$Z$8,1,0)+IF(AA9=$AA$8,1,0)+IF(AB9=$AB$8,1,0)+IF(AC9=$AC$8,1,0)+IF(AD9=$AD$8,1,0)+IF(AE9=$AE$8,1,0)+IF(AF9=$AF$8,1,0)+IF(AG9=$AG$8,1,0)+IF(AH9=$AH$8,1,0)+IF(AI9=$AI$8,1,0)+IF(AJ9=$AJ$8,1,0)+IF(AK9=$AK$8,1,0)+IF(AL9=$AL$8,1,0)+IF(AM9=$AM$8,1,0))) -> 0 | AO9: =IF(D9="","",VLOOKUP(AN9,'PAT Maths'!$D$3:$E$44,2,FALSE)) -> -42
A10: 45356 | B10: 3 | C10: 3A | D10: Lname2 | E10: Fname2 | F10: XXXXX2 | AN10: =IF(D10="",0,(IF(G10=$G$8,1,0)+IF(H10=$H$8,1,0)+IF(I10=$I$8,1,0)+IF(J10=$J$8,1,0)+IF(K10=$K$8,1,0)+IF(L10=$L$8,1,0)+IF(M10=$M$8,1,0)+IF(N10=$N$8,1,0)+IF(O10=$O$8,1,0)+IF(P10=$P$8,1,0)+IF(Q10=$Q$8,1,0)+IF(R10=$R$8,1,0)+IF(S10=$S$8,1,0)+IF(T10=$T$8,1,0)+IF(U10=$U$8,1,0)+IF(V10=$V$8,1,0)+IF(W10=$W$8,1,0)+IF(X10=$X$8,1,0)+IF(Y10=$Y$8,1,0)+IF(Z10=$Z$8,1,0)+IF(AA10=$AA$8,1,0)+IF(AB10=$AB$8,1,0)+IF(AC10=$AC$8,1,0)+IF(AD10=$AD$8,1,0)+IF(AE10=$AE$8,1,0)+IF(AF10=$AF$8,1,0)+IF(AG10=$AG$8,1,0)+IF(AH10=$AH$8,1,0)+IF(AI10=$AI$8,1,0)+IF(AJ10=$AJ$8,1,0)+IF(AK10=$AK$8,1,0)+IF(AL10=$AL$8,1,0)+IF(AM10=$AM$8,1,0))) -> 0 | AO10: =IF(D10="","",VLOOKUP(AN10,'PAT Maths'!$D$3:$E$44,2,FALSE)) -> -42
A11: 45356 | B11: 3 | C11: 3A | D11: Lname3 | E11: Fname3 | F11: XXXXX3 | AN11: =IF(D11="",0,(IF(G11=$G$8,1,0)+IF(H11=$H$8,1,0)+IF(I11=$I$8,1,0)+IF(J11=$J$8,1,0)+IF(K11=$K$8,1,0)+IF(L11=$L$8,1,0)+IF(M11=$M$8,1,0)+IF(N11=$N$8,1,0)+IF(O11=$O$8,1,0)+IF(P11=$P$8,1,0)+IF(Q11=$Q$8,1,0)+IF(R11=$R$8,1,0)+IF(S11=$S$8,1,0)+IF(T11=$T$8,1,0)+IF(U11=$U$8,1,0)+IF(V11=$V$8,1,0)+IF(W11=$W$8,1,0)+IF(X11=$X$8,1,0)+IF(Y11=$Y$8,1,0)+IF(Z11=$Z$8,1,0)+IF(AA11=$AA$8,1,0)+IF(AB11=$AB$8,1,0)+IF(AC11=$AC$8,1,0)+IF(AD11=$AD$8,1,0)+IF(AE11=$AE$8,1,0)+IF(AF11=$AF$8,1,0)+IF(AG11=$AG$8,1,0)+IF(AH11=$AH$8,1,0)+IF(AI11=$AI$8,1,0)+IF(AJ11=$AJ$8,1,0)+IF(AK11=$AK$8,1,0)+IF(AL11=$AL$8,1,0)+IF(AM11=$AM$8,1,0))) -> 0 | AO11: =IF(D11="","",VLOOKUP(AN11,'PAT Maths'!$D$3:$E$44,2,FALSE)) -> -42
A12: 45356 | B12: 3 | C12: 3A | D12: Lname4 | E12: Fname4 | F12: XXXXX4 | AN12: =IF(D12="",0,(IF(G12=$G$8,1,0)+IF(H12=$H$8,1,0)+IF(I12=$I$8,1,0)+IF(J12=$J$8,1,0)+IF(K12=$K$8,1,0)+IF(L12=$L$8,1,0)+IF(M12=$M$8,1,0)+IF(N12=$N$8,1,0)+IF(O12=$O$8,1,0)+IF(P12=$P$8,1,0)+IF(Q12=$Q$8,1,0)+IF(R12=$R$8,1,0)+IF(S12=$S$8,1,0)+IF(T12=$T$8,1,0)+IF(U12=$U$8,1,0)+IF(V12=$V$8,1,0)+IF(W12=$W$8,1,0)+IF(X12=$X$8,1,0)+IF(Y12=$Y$8,1,0)+IF(Z12=$Z$8,1,0)+IF(AA12=$AA$8,1,0)+IF(AB12=$AB$8,1,0)+IF(AC12=$AC$8,1,0)+IF(AD12=$AD$8,1,0)+IF(AE12=$AE$8,1,0)+IF(AF12=$AF$8,1,0)+IF(AG12=$AG$8,1,0)+IF(AH12=$AH$8,1,0)+IF(AI12=$AI$8,1,0)+IF(AJ12=$AJ$8,1,0)+IF(AK12=$AK$8,1,0)+IF(AL12=$AL$8,1,0)+IF(AM12=$AM$8,1,0))) -> 0 | AO12: =IF(D12="","",VLOOKUP(AN12,'PAT Maths'!$D$3:$E$44,2,FALSE)) -> -42
A13: 45356 | B13: 3 | C13: 3B | D13: ULname13 | E13: UFname13 | F13: UNLISTED | AN13: =IF(D13="",0,(IF(G13=$G$8,1,0)+IF(H13=$H$8,1,0)+IF(I13=$I$8,1,0)+IF(J13=$J$8,1,0)+IF(K13=$K$8,1,0)+IF(L13=$L$8,1,0)+IF(M13=$M$8,1,0)+IF(N13=$N$8,1,0)+IF(O13=$O$8,1,0)+IF(P13=$P$8,1,0)+IF(Q13=$Q$8,1,0)+IF(R13=$R$8,1,0)+IF(S13=$S$8,1,0)+IF(T13=$T$8,1,0)+IF(U13=$U$8,1,0)+IF(V13=$V$8,1,0)+IF(W13=$W$8,1,0)+IF(X13=$X$8,1,0)+IF(Y13=$Y$8,1,0)+IF(Z13=$Z$8,1,0)+IF(AA13=$AA$8,1,0)+IF(AB13=$AB$8,1,0)+IF(AC13=$AC$8,1,0)+IF(AD13=$AD$8,1,0)+IF(AE13=$AE$8,1,0)+IF(AF13=$AF$8,1,0)+IF(AG13=$AG$8,1,0)+IF(AH13=$AH$8,1,0)+IF(AI13=$AI$8,1,0)+IF(AJ13=$AJ$8,1,0)+IF(AK13=$AK$8,1,0)+IF(AL13=$AL$8,1,0)+IF(AM13=$AM$8,1,0))) -> 0 | AO13: =IF(D13="","",VLOOKUP(AN13,'PAT Maths'!$D$3:$E$44,2,FALSE)) -> -42
A14: 45356 | B14: 3 | C14: 3A | D14: Lname5 | E14: Fname5 | F14: XXXXX5 | AN14: =IF(D14="",0,(IF(G14=$G$8,1,0)+IF(H14=$H$8,1,0)+IF(I14=$I$8,1,0)+IF(J14=$J$8,1,0)+IF(K14=$K$8,1,0)+IF(L14=$L$8,1,0)+IF(M14=$M$8,1,0)+IF(N14=$N$8,1,0)+IF(O14=$O$8,1,0)+IF(P14=$P$8,1,0)+IF(Q14=$Q$8,1,0)+IF(R14=$R$8,1,0)+IF(S14=$S$8,1,0)+IF(T14=$T$8,1,0)+IF(U14=$U$8,1,0)+IF(V14=$V$8,1,0)+IF(W14=$W$8,1,0)+IF(X14=$X$8,1,0)+IF(Y14=$Y$8,1,0)+IF(Z14=$Z$8,1,0)+IF(AA14=$AA$8,1,0)+IF(AB14=$AB$8,1,0)+IF(AC14=$AC$8,1,0)+IF(AD14=$AD$8,1,0)+IF(AE14=$AE$8,1,0)+IF(AF14=$AF$8,1,0)+IF(AG14=$AG$8,1,0)+IF(AH14=$AH$8,1,0)+IF(AI14=$AI$8,1,0)+IF(AJ14=$AJ$8,1,0)+IF(AK14=$AK$8,1,0)+IF(AL14=$AL$8,1,0)+IF(AM14=$AM$8,1,0))) -> 0 | AO14: =IF(D14="","",VLOOKUP(AN14,'PAT Maths'!$D$3:$E$44,2,FALSE)) -> -42
A15: 45356 | B15: 3 | C15: 3B | D15: Lname6 | E15: Fname6 | F15: XXXXX6 | AN15: =IF(D15="",0,(IF(G15=$G$8,1,0)+IF(H15=$H$8,1,0)+IF(I15=$I$8,1,0)+IF(J15=$J$8,1,0)+IF(K15=$K$8,1,0)+IF(L15=$L$8,1,0)+IF(M15=$M$8,1,0)+IF(N15=$N$8,1,0)+IF(O15=$O$8,1,0)+IF(P15=$P$8,1,0)+IF(Q15=$Q$8,1,0)+IF(R15=$R$8,1,0)+IF(S15=$S$8,1,0)+IF(T15=$T$8,1,0)+IF(U15=$U$8,1,0)+IF(V15=$V$8,1,0)+IF(W15=$W$8,1,0)+IF(X15=$X$8,1,0)+IF(Y15=$Y$8,1,0)+IF(Z15=$Z$8,1,0)+IF(AA15=$AA$8,1,0)+IF(AB15=$AB$8,1,0)+IF(AC15=$AC$8,1,0)+IF(AD15=$AD$8,1,0)+IF(AE15=$AE$8,1,0)+IF(AF15=$AF$8,1,0)+IF(AG15=$AG$8,1,0)+IF(AH15=$AH$8,1,0)+IF(AI15=$AI$8,1,0)+IF(AJ15=$AJ$8,1,0)+IF(AK15=$AK$8,1,0)+IF(AL15=$AL$8,1,0)+IF(AM15=$AM$8,1,0))) -> 0 | AO15: =IF(D15="","",VLOOKUP(AN15,'PAT Maths'!$D$3:$E$44,2,FALSE)) -> -42
A16: 45356 | B16: 3 | C16: 3B | D16: Lname7 | E16: Fname7 | F16: XXXXX7 | AN16: =IF(D16="",0,(IF(G16=$G$8,1,0)+IF(H16=$H$8,1,0)+IF(I16=$I$8,1,0)+IF(J16=$J$8,1,0)+IF(K16=$K$8,1,0)+IF(L16=$L$8,1,0)+IF(M16=$M$8,1,0)+IF(N16=$N$8,1,0)+IF(O16=$O$8,1,0)+IF(P16=$P$8,1,0)+IF(Q16=$Q$8,1,0)+IF(R16=$R$8,1,0)+IF(S16=$S$8,1,0)+IF(T16=$T$8,1,0)+IF(U16=$U$8,1,0)+IF(V16=$V$8,1,0)+IF(W16=$W$8,1,0)+IF(X16=$X$8,1,0)+IF(Y16=$Y$8,1,0)+IF(Z16=$Z$8,1,0)+IF(AA16=$AA$8,1,0)+IF(AB16=$AB$8,1,0)+IF(AC16=$AC$8,1,0)+IF(AD16=$AD$8,1,0)+IF(AE16=$AE$8,1,0)+IF(AF16=$AF$8,1,0)+IF(AG16=$AG$8,1,0)+IF(AH16=$AH$8,1,0)+IF(AI16=$AI$8,1,0)+IF(AJ16=$AJ$8,1,0)+IF(AK16=$AK$8,1,0)+IF(AL16=$AL$8,1,0)+IF(AM16=$AM$8,1,0))) -> 0 | AO16: =IF(D16="","",VLOOKUP(AN16,'PAT Maths'!$D$3:$E$44,2,FALSE)) -> -42
A17: 45356 | B17: 3 | C17: 3B | D17: Lname8 | E17: Fname8 | F17: XXXXX8 | AN17: =IF(D17="",0,(IF(G17=$G$8,1,0)+IF(H17=$H$8,1,0)+IF(I17=$I$8,1,0)+IF(J17=$J$8,1,0)+IF(K17=$K$8,1,0)+IF(L17=$L$8,1,0)+IF(M17=$M$8,1,0)+IF(N17=$N$8,1,0)+IF(O17=$O$8,1,0)+IF(P17=$P$8,1,0)+IF(Q17=$Q$8,1,0)+IF(R17=$R$8,1,0)+IF(S17=$S$8,1,0)+IF(T17=$T$8,1,0)+IF(U17=$U$8,1,0)+IF(V17=$V$8,1,0)+IF(W17=$W$8,1,0)+IF(X17=$X$8,1,0)+IF(Y17=$Y$8,1,0)+IF(Z17=$Z$8,1,0)+IF(AA17=$AA$8,1,0)+IF(AB17=$AB$8,1,0)+IF(AC17=$AC$8,1,0)+IF(AD17=$AD$8,1,0)+IF(AE17=$AE$8,1,0)+IF(AF17=$AF$8,1,0)+IF(AG17=$AG$8,1,0)+IF(AH17=$AH$8,1,0)+IF(AI17=$AI$8,1,0)+IF(AJ17=$AJ$8,1,0)+IF(AK17=$AK$8,1,0)+IF(AL17=$AL$8,1,0)+IF(AM17=$AM$8,1,0))) -> 0 | AO17: =IF(D17="","",VLOOKUP(AN17,'PAT Maths'!$D$3:$E$44,2,FALSE)) -> -42
A18: 45356 | B18: 3 | C18: 3B | D18: Lname9 | E18: Fname9 | F18: XXXXX9 | AN18: =IF(D18="",0,(IF(G18=$G$8,1,0)+IF(H18=$H$8,1,0)+IF(I18=$I$8,1,0)+IF(J18=$J$8,1,0)+IF(K18=$K$8,1,0)+IF(L18=$L$8,1,0)+IF(M18=$M$8,1,0)+IF(N18=$N$8,1,0)+IF(O18=$O$8,1,0)+IF(P18=$P$8,1,0)+IF(Q18=$Q$8,1,0)+IF(R18=$R$8,1,0)+IF(S18=$S$8,1,0)+IF(T18=$T$8,1,0)+IF(U18=$U$8,1,0)+IF(V18=$V$8,1,0)+IF(W18=$W$8,1,0)+IF(X18=$X$8,1,0)+IF(Y18=$Y$8,1,0)+IF(Z18=$Z$8,1,0)+IF(AA18=$AA$8,1,0)+IF(AB18=$AB$8,1,0)+IF(AC18=$AC$8,1,0)+IF(AD18=$AD$8,1,0)+IF(AE18=$AE$8,1,0)+IF(AF18=$AF$8,1,0)+IF(AG18=$AG$8,1,0)+IF(AH18=$AH$8,1,0)+IF(AI18=$AI$8,1,0)+IF(AJ18=$AJ$8,1,0)+IF(AK18=$AK$8,1,0)+IF(AL18=$AL$8,1,0)+IF(AM18=$AM$8,1,0))) -> 0 | AO18: =IF(D18="","",VLOOKUP(AN18,'PAT Maths'!$D$3:$E$44,2,FALSE)) -> -42
A19: 45356 | B19: 3 | C19: 3B | D19: Lname10 | E19: Fname10 | F19: XXXXX10 | AN19: =IF(D19="",0,(IF(G19=$G$8,1,0)+IF(H19=$H$8,1,0)+IF(I19=$I$8,1,0)+IF(J19=$J$8,1,0)+IF(K19=$K$8,1,0)+IF(L19=$L$8,1,0)+IF(M19=$M$8,1,0)+IF(N19=$N$8,1,0)+IF(O19=$O$8,1,0)+IF(P19=$P$8,1,0)+IF(Q19=$Q$8,1,0)+IF(R19=$R$8,1,0)+IF(S19=$S$8,1,0)+IF(T19=$T$8,1,0)+IF(U19=$U$8,1,0)+IF(V19=$V$8,1,0)+IF(W19=$W$8,1,0)+IF(X19=$X$8,1,0)+IF(Y19=$Y$8,1,0)+IF(Z19=$Z$8,1,0)+IF(AA19=$AA$8,1,0)+IF(AB19=$AB$8,1,0)+IF(AC19=$AC$8,1,0)+IF(AD19=$AD$8,1,0)+IF(AE19=$AE$8,1,0)+IF(AF19=$AF$8,1,0)+IF(AG19=$AG$8,1,0)+IF(AH19=$AH$8,1,0)+IF(AI19=$AI$8,1,0)+IF(AJ19=$AJ$8,1,0)+IF(AK19=$AK$8,1,0)+IF(AL19=$AL$8,1,0)+IF(AM19=$AM$8,1,0))) -> 0 | AO19: =IF(D19="","",VLOOKUP(AN19,'PAT Maths'!$D$3:$E$44,2,FALSE)) -> -42
AN20: =IF(D20="",0,(IF(G20=$G$8,1,0)+IF(H20=$H$8,1,0)+IF(I20=$I$8,1,0)+IF(J20=$J$8,1,0)+IF(K20=$K$8,1,0)+IF(L20=$L$8,1,0)+IF(M20=$M$8,1,0)+IF(N20=$N$8,1,0)+IF(O20=$O$8,1,0)+IF(P20=$P$8,1,0)+IF(Q20=$Q$8,1,0)+IF(R20=$R$8,1,0)+IF(S20=$S$8,1,0)+IF(T20=$T$8,1,0)+IF(U20=$U$8,1,0)+IF(V20=$V$8,1,0)+IF(W20=$W$8,1,0)+IF(X20=$X$8,1,0)+IF(Y20=$Y$8,1,0)+IF(Z20=$Z$8,1,0)+IF(AA20=$AA$8,1,0)+IF(AB20=$AB$8,1,0)+IF(AC20=$AC$8,1,0)+IF(AD20=$AD$8,1,0)+IF(AE20=$AE$8,1,0)+IF(AF20=$AF$8,1,0)+IF(AG20=$AG$8,1,0)+IF(AH20=$AH$8,1,0)+IF(AI20=$AI$8,1,0)+IF(AJ20=$AJ$8,1,0)+IF(AK20=$AK$8,1,0)+IF(AL20=$AL$8,1,0)+IF(AM20=$AM$8,1,0))) -> 0 | AO20: =IF(D20="","",VLOOKUP(AN20,'PAT Maths'!$D$3:$E$44,2,FALSE))
AN21: =IF(D21="",0,(IF(G21=$G$8,1,0)+IF(H21=$H$8,1,0)+IF(I21=$I$8,1,0)+IF(J21=$J$8,1,0)+IF(K21=$K$8,1,0)+IF(L21=$L$8,1,0)+IF(M21=$M$8,1,0)+IF(N21=$N$8,1,0)+IF(O21=$O$8,1,0)+IF(P21=$P$8,1,0)+IF(Q21=$Q$8,1,0)+IF(R21=$R$8,1,0)+IF(S21=$S$8,1,0)+IF(T21=$T$8,1,0)+IF(U21=$U$8,1,0)+IF(V21=$V$8,1,0)+IF(W21=$W$8,1,0)+IF(X21=$X$8,1,0)+IF(Y21=$Y$8,1,0)+IF(Z21=$Z$8,1,0)+IF(AA21=$AA$8,1,0)+IF(AB21=$AB$8,1,0)+IF(AC21=$AC$8,1,0)+IF(AD21=$AD$8,1,0)+IF(AE21=$AE$8,1,0)+IF(AF21=$AF$8,1,0)+IF(AG21=$AG$8,1,0)+IF(AH21=$AH$8,1,0)+IF(AI21=$AI$8,1,0)+IF(AJ21=$AJ$8,1,0)+IF(AK21=$AK$8,1,0)+IF(AL21=$AL$8,1,0)+IF(AM21=$AM$8,1,0))) -> 0 | AO21: =IF(D21="","",VLOOKUP(AN21,'PAT Maths'!$D$3:$E$44,2,FALSE))
AN22: =IF(D22="",0,(IF(G22=$G$8,1,0)+IF(H22=$H$8,1,0)+IF(I22=$I$8,1,0)+IF(J22=$J$8,1,0)+IF(K22=$K$8,1,0)+IF(L22=$L$8,1,0)+IF(M22=$M$8,1,0)+IF(N22=$N$8,1,0)+IF(O22=$O$8,1,0)+IF(P22=$P$8,1,0)+IF(Q22=$Q$8,1,0)+IF(R22=$R$8,1,0)+IF(S22=$S$8,1,0)+IF(T22=$T$8,1,0)+IF(U22=$U$8,1,0)+IF(V22=$V$8,1,0)+IF(W22=$W$8,1,0)+IF(X22=$X$8,1,0)+IF(Y22=$Y$8,1,0)+IF(Z22=$Z$8,1,0)+IF(AA22=$AA$8,1,0)+IF(AB22=$AB$8,1,0)+IF(AC22=$AC$8,1,0)+IF(AD22=$AD$8,1,0)+IF(AE22=$AE$8,1,0)+IF(AF22=$AF$8,1,0)+IF(AG22=$AG$8,1,0)+IF(AH22=$AH$8,1,0)+IF(AI22=$AI$8,1,0)+IF(AJ22=$AJ$8,1,0)+IF(AK22=$AK$8,1,0)+IF(AL22=$AL$8,1,0)+IF(AM22=$AM$8,1,0))) -> 0 | AO22: =IF(D22="","",VLOOKUP(AN22,'PAT Maths'!$D$3:$E$44,2,FALSE))
AN23: =IF(D23="",0,(IF(G23=$G$8,1,0)+IF(H23=$H$8,1,0)+IF(I23=$I$8,1,0)+IF(J23=$J$8,1,0)+IF(K23=$K$8,1,0)+IF(L23=$L$8,1,0)+IF(M23=$M$8,1,0)+IF(N23=$N$8,1,0)+IF(O23=$O$8,1,0)+IF(P23=$P$8,1,0)+IF(Q23=$Q$8,1,0)+IF(R23=$R$8,1,0)+IF(S23=$S$8,1,0)+IF(T23=$T$8,1,0)+IF(U23=$U$8,1,0)+IF(V23=$V$8,1,0)+IF(W23=$W$8,1,0)+IF(X23=$X$8,1,0)+IF(Y23=$Y$8,1,0)+IF(Z23=$Z$8,1,0)+IF(AA23=$AA$8,1,0)+IF(AB23=$AB$8,1,0)+IF(AC23=$AC$8,1,0)+IF(AD23=$AD$8,1,0)+IF(AE23=$AE$8,1,0)+IF(AF23=$AF$8,1,0)+IF(AG23=$AG$8,1,0)+IF(AH23=$AH$8,1,0)+IF(AI23=$AI$8,1,0)+IF(AJ23=$AJ$8,1,0)+IF(AK23=$AK$8,1,0)+IF(AL23=$AL$8,1,0)+IF(AM23=$AM$8,1,0))) -> 0 | AO23: =IF(D23="","",VLOOKUP(AN23,'PAT Maths'!$D$3:$E$44,2,FALSE))
AN24: =IF(D24="",0,(IF(G24=$G$8,1,0)+IF(H24=$H$8,1,0)+IF(I24=$I$8,1,0)+IF(J24=$J$8,1,0)+IF(K24=$K$8,1,0)+IF(L24=$L$8,1,0)+IF(M24=$M$8,1,0)+IF(N24=$N$8,1,0)+IF(O24=$O$8,1,0)+IF(P24=$P$8,1,0)+IF(Q24=$Q$8,1,0)+IF(R24=$R$8,1,0)+IF(S24=$S$8,1,0)+IF(T24=$T$8,1,0)+IF(U24=$U$8,1,0)+IF(V24=$V$8,1,0)+IF(W24=$W$8,1,0)+IF(X24=$X$8,1,0)+IF(Y24=$Y$8,1,0)+IF(Z24=$Z$8,1,0)+IF(AA24=$AA$8,1,0)+IF(AB24=$AB$8,1,0)+IF(AC24=$AC$8,1,0)+IF(AD24=$AD$8,1,0)+IF(AE24=$AE$8,1,0)+IF(AF24=$AF$8,1,0)+IF(AG24=$AG$8,1,0)+IF(AH24=$AH$8,1,0)+IF(AI24=$AI$8,1,0)+IF(AJ24=$AJ$8,1,0)+IF(AK24=$AK$8,1,0)+IF(AL24=$AL$8,1,0)+IF(AM24=$AM$8,1,0))) -> 0 | AO24: =IF(D24="","",VLOOKUP(AN24,'PAT Maths'!$D$3:$E$44,2,FALSE))
AN25: =IF(D25="",0,(IF(G25=$G$8,1,0)+IF(H25=$H$8,1,0)+IF(I25=$I$8,1,0)+IF(J25=$J$8,1,0)+IF(K25=$K$8,1,0)+IF(L25=$L$8,1,0)+IF(M25=$M$8,1,0)+IF(N25=$N$8,1,0)+IF(O25=$O$8,1,0)+IF(P25=$P$8,1,0)+IF(Q25=$Q$8,1,0)+IF(R25=$R$8,1,0)+IF(S25=$S$8,1,0)+IF(T25=$T$8,1,0)+IF(U25=$U$8,1,0)+IF(V25=$V$8,1,0)+IF(W25=$W$8,1,0)+IF(X25=$X$8,1,0)+IF(Y25=$Y$8,1,0)+IF(Z25=$Z$8,1,0)+IF(AA25=$AA$8,1,0)+IF(AB25=$AB$8,1,0)+IF(AC25=$AC$8,1,0)+IF(AD25=$AD$8,1,0)+IF(AE25=$AE$8,1,0)+IF(AF25=$AF$8,1,0)+IF(AG25=$AG$8,1,0)+IF(AH25=$AH$8,1,0)+IF(AI25=$AI$8,1,0)+IF(AJ25=$AJ$8,1,0)+IF(AK25=$AK$8,1,0)+IF(AL25=$AL$8,1,0)+IF(AM25=$AM$8,1,0))) -> 0 | AO25: =IF(D25="","",VLOOKUP(AN25,'PAT Maths'!$D$3:$E$44,2,FALSE))
AN26: =IF(D26="",0,(IF(G26=$G$8,1,0)+IF(H26=$H$8,1,0)+IF(I26=$I$8,1,0)+IF(J26=$J$8,1,0)+IF(K26=$K$8,1,0)+IF(L26=$L$8,1,0)+IF(M26=$M$8,1,0)+IF(N26=$N$8,1,0)+IF(O26=$O$8,1,0)+IF(P26=$P$8,1,0)+IF(Q26=$Q$8,1,0)+IF(R26=$R$8,1,0)+IF(S26=$S$8,1,0)+IF(T26=$T$8,1,0)+IF(U26=$U$8,1,0)+IF(V26=$V$8,1,0)+IF(W26=$W$8,1,0)+IF(X26=$X$8,1,0)+IF(Y26=$Y$8,1,0)+IF(Z26=$Z$8,1,0)+IF(AA26=$AA$8,1,0)+IF(AB26=$AB$8,1,0)+IF(AC26=$AC$8,1,0)+IF(AD26=$AD$8,1,0)+IF(AE26=$AE$8,1,0)+IF(AF26=$AF$8,1,0)+IF(AG26=$AG$8,1,0)+IF(AH26=$AH$8,1,0)+IF(AI26=$AI$8,1,0)+IF(AJ26=$AJ$8,1,0)+IF(AK26=$AK$8,1,0)+IF(AL26=$AL$8,1,0)+IF(AM26=$AM$8,1,0))) -> 0 | AO26: =IF(D26="","",VLOOKUP(AN26,'PAT Maths'!$D$3:$E$44,2,FALSE))
AN27: =IF(D27="",0,(IF(G27=$G$8,1,0)+IF(H27=$H$8,1,0)+IF(I27=$I$8,1,0)+IF(J27=$J$8,1,0)+IF(K27=$K$8,1,0)+IF(L27=$L$8,1,0)+IF(M27=$M$8,1,0)+IF(N27=$N$8,1,0)+IF(O27=$O$8,1,0)+IF(P27=$P$8,1,0)+IF(Q27=$Q$8,1,0)+IF(R27=$R$8,1,0)+IF(S27=$S$8,1,0)+IF(T27=$T$8,1,0)+IF(U27=$U$8,1,0)+IF(V27=$V$8,1,0)+IF(W27=$W$8,1,0)+IF(X27=$X$8,1,0)+IF(Y27=$Y$8,1,0)+IF(Z27=$Z$8,1,0)+IF(AA27=$AA$8,1,0)+IF(AB27=$AB$8,1,0)+IF(AC27=$AC$8,1,0)+IF(AD27=$AD$8,1,0)+IF(AE27=$AE$8,1,0)+IF(AF27=$AF$8,1,0)+IF(AG27=$AG$8,1,0)+IF(AH27=$AH$8,1,0)+IF(AI27=$AI$8,1,0)+IF(AJ27=$AJ$8,1,0)+IF(AK27=$AK$8,1,0)+IF(AL27=$AL$8,1,0)+IF(AM27=$AM$8,1,0))) -> 0 | AO27: =IF(D27="","",VLOOKUP(AN27,'PAT Maths'!$D$3:$E$44,2,FALSE))
AN28: =IF(D28="",0,(IF(G28=$G$8,1,0)+IF(H28=$H$8,1,0)+IF(I28=$I$8,1,0)+IF(J28=$J$8,1,0)+IF(K28=$K$8,1,0)+IF(L28=$L$8,1,0)+IF(M28=$M$8,1,0)+IF(N28=$N$8,1,0)+IF(O28=$O$8,1,0)+IF(P28=$P$8,1,0)+IF(Q28=$Q$8,1,0)+IF(R28=$R$8,1,0)+IF(S28=$S$8,1,0)+IF(T28=$T$8,1,0)+IF(U28=$U$8,1,0)+IF(V28=$V$8,1,0)+IF(W28=$W$8,1,0)+IF(X28=$X$8,1,0)+IF(Y28=$Y$8,1,0)+IF(Z28=$Z$8,1,0)+IF(AA28=$AA$8,1,0)+IF(AB28=$AB$8,1,0)+IF(AC28=$AC$8,1,0)+IF(AD28=$AD$8,1,0)+IF(AE28=$AE$8,1,0)+IF(AF28=$AF$8,1,0)+IF(AG28=$AG$8,1,0)+IF(AH28=$AH$8,1,0)+IF(AI28=$AI$8,1,0)+IF(AJ28=$AJ$8,1,0)+IF(AK28=$AK$8,1,0)+IF(AL28=$AL$8,1,0)+IF(AM28=$AM$8,1,0))) -> 0 | AO28: =IF(D28="","",VLOOKUP(AN28,'PAT Maths'!$D$3:$E$44,2,FALSE))
AN29: =IF(D29="",0,(IF(G29=$G$8,1,0)+IF(H29=$H$8,1,0)+IF(I29=$I$8,1,0)+IF(J29=$J$8,1,0)+IF(K29=$K$8,1,0)+IF(L29=$L$8,1,0)+IF(M29=$M$8,1,0)+IF(N29=$N$8,1,0)+IF(O29=$O$8,1,0)+IF(P29=$P$8,1,0)+IF(Q29=$Q$8,1,0)+IF(R29=$R$8,1,0)+IF(S29=$S$8,1,0)+IF(T29=$T$8,1,0)+IF(U29=$U$8,1,0)+IF(V29=$V$8,1,0)+IF(W29=$W$8,1,0)+IF(X29=$X$8,1,0)+IF(Y29=$Y$8,1,0)+IF(Z29=$Z$8,1,0)+IF(AA29=$AA$8,1,0)+IF(AB29=$AB$8,1,0)+IF(AC29=$AC$8,1,0)+IF(AD29=$AD$8,1,0)+IF(AE29=$AE$8,1,0)+IF(AF29=$AF$8,1,0)+IF(AG29=$AG$8,1,0)+IF(AH29=$AH$8,1,0)+IF(AI29=$AI$8,1,0)+IF(AJ29=$AJ$8,1,0)+IF(AK29=$AK$8,1,0)+IF(AL29=$AL$8,1,0)+IF(AM29=$AM$8,1,0))) -> 0 | AO29: =IF(D29="","",VLOOKUP(AN29,'PAT Maths'!$D$3:$E$44,2,FALSE))
AN30: =IF(D30="",0,(IF(G30=$G$8,1,0)+IF(H30=$H$8,1,0)+IF(I30=$I$8,1,0)+IF(J30=$J$8,1,0)+IF(K30=$K$8,1,0)+IF(L30=$L$8,1,0)+IF(M30=$M$8,1,0)+IF(N30=$N$8,1,0)+IF(O30=$O$8,1,0)+IF(P30=$P$8,1,0)+IF(Q30=$Q$8,1,0)+IF(R30=$R$8,1,0)+IF(S30=$S$8,1,0)+IF(T30=$T$8,1,0)+IF(U30=$U$8,1,0)+IF(V30=$V$8,1,0)+IF(W30=$W$8,1,0)+IF(X30=$X$8,1,0)+IF(Y30=$Y$8,1,0)+IF(Z30=$Z$8,1,0)+IF(AA30=$AA$8,1,0)+IF(AB30=$AB$8,1,0)+IF(AC30=$AC$8,1,0)+IF(AD30=$AD$8,1,0)+IF(AE30=$AE$8,1,0)+IF(AF30=$AF$8,1,0)+IF(AG30=$AG$8,1,0)+IF(AH30=$AH$8,1,0)+IF(AI30=$AI$8,1,0)+IF(AJ30=$AJ$8,1,0)+IF(AK30=$AK$8,1,0)+IF(AL30=$AL$8,1,0)+IF(AM30=$AM$8,1,0))) -> 0 | AO30: =IF(D30="","",VLOOKUP(AN30,'PAT Maths'!$D$3:$E$44,2,FALSE))
AN31: =IF(D31="",0,(IF(G31=$G$8,1,0)+IF(H31=$H$8,1,0)+IF(I31=$I$8,1,0)+IF(J31=$J$8,1,0)+IF(K31=$K$8,1,0)+IF(L31=$L$8,1,0)+IF(M31=$M$8,1,0)+IF(N31=$N$8,1,0)+IF(O31=$O$8,1,0)+IF(P31=$P$8,1,0)+IF(Q31=$Q$8,1,0)+IF(R31=$R$8,1,0)+IF(S31=$S$8,1,0)+IF(T31=$T$8,1,0)+IF(U31=$U$8,1,0)+IF(V31=$V$8,1,0)+IF(W31=$W$8,1,0)+IF(X31=$X$8,1,0)+IF(Y31=$Y$8,1,0)+IF(Z31=$Z$8,1,0)+IF(AA31=$AA$8,1,0)+IF(AB31=$AB$8,1,0)+IF(AC31=$AC$8,1,0)+IF(AD31=$AD$8,1,0)+IF(AE31=$AE$8,1,0)+IF(AF31=$AF$8,1,0)+IF(AG31=$AG$8,1,0)+IF(AH31=$AH$8,1,0)+IF(AI31=$AI$8,1,0)+IF(AJ31=$AJ$8,1,0)+IF(AK31=$AK$8,1,0)+IF(AL31=$AL$8,1,0)+IF(AM31=$AM$8,1,0))) -> 0 | AO31: =IF(D31="","",VLOOKUP(AN31,'PAT Maths'!$D$3:$E$44,2,FALSE))
... AN425: =IF(D425="",0,(IF(G425=$G$8,1,0)+IF(H425=$H$8,1,0)+IF(I425=$I$8,1,0)+IF(J425=$J$8,1,0)+IF(K425=$K$8,1,0)+IF(L425=$L$8,1,0)+IF(M425=$M$8,1,0)+IF(N425=$N$8,1,0)+IF(O425=$O$8,1,0)+IF(P425=$P$8,1,0)+IF(Q425=$Q$8,1,0)+IF(R425=$R$8,1,0)+IF(S425=$S$8,1,0)+IF(T425=$T$8,1,0)+IF(U425=$U$8,1,0)+IF(V425=$V$8,1,0)+IF(W425=$W$8,1,0)+IF(X425=$X$8,1,0)+IF(Y425=$Y$8,1,0)+IF(Z425=$Z$8,1,0)+IF(AA425=$AA$8,1,0)+IF(AB425=$AB$8,1,0)+IF(AC425=$AC$8,1,0)+IF(AD425=$AD$8,1,0)+IF(AE425=$AE$8,1,0)+IF(AF425=$AF$8,1,0)+IF(AG425=$AG$8,1,0)+IF(AH425=$AH$8,1,0)+IF(AI425=$AI$8,1,0)+IF(AJ425=$AJ$8,1,0)+IF(AK425=$AK$8,1,0)+IF(AL425=$AL$8,1,0)+IF(AM425=$AM$8,1,0))) -> 0 | AO425: =IF(D425="","",VLOOKUP(AN425,'PAT Maths'!$D$3:$E$44,2,FALSE))

Sheet PATM TBA
A1: PAT-Maths - Test Booklet A
G3: QUESTION No. and ANSWER KEY (Enter the student's response - "A" or "B" or "C" or "D" or "E")
E4: Question Number | G4: 1 | H4: 2 | I4: 3 | J4: 4 | K4: 5 | L4: 6 | M4: 7 | N4: 8 | O4: 9 | P4: 10 | Q4: 11 | R4: 12 | S4: 13 | T4: 14 | U4: 15 | V4: 16 | W4: 17 | X4: 18 | Y4: 19 | Z4: 20
E5: Item Difficulty | G5: 22 | H5: 25 | I5: 27 | J5: 20 | K5: 24 | L5: 25 | M5: 17 | N5: 29 | O5: 28 | P5: 26 | Q5: 23 | R5: 13 | S5: 18 | T5: 19 | U5: 18 | V5: 29 | W5: 40 | X5: 19 | Y5: 23 | Z5: 22
E6: Skill Assessed | G6: NC | H6: NC | I6: NC | J6: NC | K6: NC | L6: NC | M6: NC | N6: NC | O6: NC | P6: NC | Q6: NC | R6: S | S6: S | T6: S | U6: M | V6: M | W6: M | X6: CD | Y6: CD | Z6: CD
A7: required | B7: required | C7: optional | D7: required | E7: required | F7: required
A8: Date (dd/mm/yy) | B8: Yr_Lev | C8: Grp | D8: Surname | E8: First_Name | F8: Student_ID | G8: C | H8: D | I8: B | J8: E | K8: C | L8: C | M8: A | N8: E | O8: A | P8: C | Q8: D | R8: D | S8: A | T8: B | U8: C | V8: B | W8: B | X8: E | Y8: C | Z8: A | AA8: Raw Score | AB8: PAT Score
A9: 45356 | B9: 3 | C9: 3A | D9: Lname1 | E9: Fname1 | F9: XXXXX1 | AA9: =IF(D9="",0,(IF(G9=$G$8,1,0)+IF(H9=$H$8,1,0)+IF(I9=$I$8,1,0)+IF(J9=$J$8,1,0)+IF(K9=$K$8,1,0)+IF(L9=$L$8,1,0)+IF(M9=$M$8,1,0)+IF(N9=$N$8,1,0)+IF(O9=$O$8,1,0)+IF(P9=$P$8,1,0)+IF(Q9=$Q$8,1,0)+IF(R9=$R$8,1,0)+IF(S9=$S$8,1,0)+IF(T9=$T$8,1,0)+IF(U9=$U$8,1,0)+IF(V9=$V$8,1,0)+IF(W9=$W$8,1,0)+IF(X9=$X$8,1,0)+IF(Y9=$Y$8,1,0)+IF(Z9=$Z$8,1,0))) -> 0 | AB9: =IF(D9="","",VLOOKUP(AA9,'PAT Maths'!$F$3:$G$44,2,FALSE)) -> –17.7
A10: 45356 | B10: 3 | C10: 3A | D10: Lname2 | E10: Fname2 | F10: XXXXX2 | AA10: =IF(D10="",0,(IF(G10=$G$8,1,0)+IF(H10=$H$8,1,0)+IF(I10=$I$8,1,0)+IF(J10=$J$8,1,0)+IF(K10=$K$8,1,0)+IF(L10=$L$8,1,0)+IF(M10=$M$8,1,0)+IF(N10=$N$8,1,0)+IF(O10=$O$8,1,0)+IF(P10=$P$8,1,0)+IF(Q10=$Q$8,1,0)+IF(R10=$R$8,1,0)+IF(S10=$S$8,1,0)+IF(T10=$T$8,1,0)+IF(U10=$U$8,1,0)+IF(V10=$V$8,1,0)+IF(W10=$W$8,1,0)+IF(X10=$X$8,1,0)+IF(Y10=$Y$8,1,0)+IF(Z10=$Z$8,1,0))) -> 0 | AB10: =IF(D10="","",VLOOKUP(AA10,'PAT Maths'!$F$3:$G$44,2,FALSE)) -> –17.7
A11: 45356 | B11: 3 | C11: 3A | D11: Lname3 | E11: Fname3 | F11: XXXXX3 | AA11: =IF(D11="",0,(IF(G11=$G$8,1,0)+IF(H11=$H$8,1,0)+IF(I11=$I$8,1,0)+IF(J11=$J$8,1,0)+IF(K11=$K$8,1,0)+IF(L11=$L$8,1,0)+IF(M11=$M$8,1,0)+IF(N11=$N$8,1,0)+IF(O11=$O$8,1,0)+IF(P11=$P$8,1,0)+IF(Q11=$Q$8,1,0)+IF(R11=$R$8,1,0)+IF(S11=$S$8,1,0)+IF(T11=$T$8,1,0)+IF(U11=$U$8,1,0)+IF(V11=$V$8,1,0)+IF(W11=$W$8,1,0)+IF(X11=$X$8,1,0)+IF(Y11=$Y$8,1,0)+IF(Z11=$Z$8,1,0))) -> 0 | AB11: =IF(D11="","",VLOOKUP(AA11,'PAT Maths'!$F$3:$G$44,2,FALSE)) -> –17.7
A12: 45356 | B12: 3 | C12: 3A | D12: Lname4 | E12: Fname4 | F12: XXXXX4 | AA12: =IF(D12="",0,(IF(G12=$G$8,1,0)+IF(H12=$H$8,1,0)+IF(I12=$I$8,1,0)+IF(J12=$J$8,1,0)+IF(K12=$K$8,1,0)+IF(L12=$L$8,1,0)+IF(M12=$M$8,1,0)+IF(N12=$N$8,1,0)+IF(O12=$O$8,1,0)+IF(P12=$P$8,1,0)+IF(Q12=$Q$8,1,0)+IF(R12=$R$8,1,0)+IF(S12=$S$8,1,0)+IF(T12=$T$8,1,0)+IF(U12=$U$8,1,0)+IF(V12=$V$8,1,0)+IF(W12=$W$8,1,0)+IF(X12=$X$8,1,0)+IF(Y12=$Y$8,1,0)+IF(Z12=$Z$8,1,0))) -> 0 | AB12: =IF(D12="","",VLOOKUP(AA12,'PAT Maths'!$F$3:$G$44,2,FALSE)) -> –17.7
A13: 45356 | B13: 3 | C13: 3B | D13: ULname13 | E13: UFname13 | F13: UNLISTED | AA13: =IF(D13="",0,(IF(G13=$G$8,1,0)+IF(H13=$H$8,1,0)+IF(I13=$I$8,1,0)+IF(J13=$J$8,1,0)+IF(K13=$K$8,1,0)+IF(L13=$L$8,1,0)+IF(M13=$M$8,1,0)+IF(N13=$N$8,1,0)+IF(O13=$O$8,1,0)+IF(P13=$P$8,1,0)+IF(Q13=$Q$8,1,0)+IF(R13=$R$8,1,0)+IF(S13=$S$8,1,0)+IF(T13=$T$8,1,0)+IF(U13=$U$8,1,0)+IF(V13=$V$8,1,0)+IF(W13=$W$8,1,0)+IF(X13=$X$8,1,0)+IF(Y13=$Y$8,1,0)+IF(Z13=$Z$8,1,0))) -> 0 | AB13: =IF(D13="","",VLOOKUP(AA13,'PAT Maths'!$F$3:$G$44,2,FALSE)) -> –17.7
A14: 45356 | B14: 3 | C14: 3A | D14: Lname5 | E14: Fname5 | F14: XXXXX5 | AA14: =IF(D14="",0,(IF(G14=$G$8,1,0)+IF(H14=$H$8,1,0)+IF(I14=$I$8,1,0)+IF(J14=$J$8,1,0)+IF(K14=$K$8,1,0)+IF(L14=$L$8,1,0)+IF(M14=$M$8,1,0)+IF(N14=$N$8,1,0)+IF(O14=$O$8,1,0)+IF(P14=$P$8,1,0)+IF(Q14=$Q$8,1,0)+IF(R14=$R$8,1,0)+IF(S14=$S$8,1,0)+IF(T14=$T$8,1,0)+IF(U14=$U$8,1,0)+IF(V14=$V$8,1,0)+IF(W14=$W$8,1,0)+IF(X14=$X$8,1,0)+IF(Y14=$Y$8,1,0)+IF(Z14=$Z$8,1,0))) -> 0 | AB14: =IF(D14="","",VLOOKUP(AA14,'PAT Maths'!$F$3:$G$44,2,FALSE)) -> –17.7
A15: 45356 | B15: 3 | C15: 3B | D15: Lname6 | E15: Fname6 | F15: XXXXX6 | AA15: =IF(D15="",0,(IF(G15=$G$8,1,0)+IF(H15=$H$8,1,0)+IF(I15=$I$8,1,0)+IF(J15=$J$8,1,0)+IF(K15=$K$8,1,0)+IF(L15=$L$8,1,0)+IF(M15=$M$8,1,0)+IF(N15=$N$8,1,0)+IF(O15=$O$8,1,0)+IF(P15=$P$8,1,0)+IF(Q15=$Q$8,1,0)+IF(R15=$R$8,1,0)+IF(S15=$S$8,1,0)+IF(T15=$T$8,1,0)+IF(U15=$U$8,1,0)+IF(V15=$V$8,1,0)+IF(W15=$W$8,1,0)+IF(X15=$X$8,1,0)+IF(Y15=$Y$8,1,0)+IF(Z15=$Z$8,1,0))) -> 0 | AB15: =IF(D15="","",VLOOKUP(AA15,'PAT Maths'!$F$3:$G$44,2,FALSE)) -> –17.7
A16: 45356 | B16: 3 | C16: 3B | D16: Lname7 | E16: Fname7 | F16: XXXXX7 | AA16: =IF(D16="",0,(IF(G16=$G$8,1,0)+IF(H16=$H$8,1,0)+IF(I16=$I$8,1,0)+IF(J16=$J$8,1,0)+IF(K16=$K$8,1,0)+IF(L16=$L$8,1,0)+IF(M16=$M$8,1,0)+IF(N16=$N$8,1,0)+IF(O16=$O$8,1,0)+IF(P16=$P$8,1,0)+IF(Q16=$Q$8,1,0)+IF(R16=$R$8,1,0)+IF(S16=$S$8,1,0)+IF(T16=$T$8,1,0)+IF(U16=$U$8,1,0)+IF(V16=$V$8,1,0)+IF(W16=$W$8,1,0)+IF(X16=$X$8,1,0)+IF(Y16=$Y$8,1,0)+IF(Z16=$Z$8,1,0))) -> 0 | AB16: =IF(D16="","",VLOOKUP(AA16,'PAT Maths'!$F$3:$G$44,2,FALSE)) -> –17.7
A17: 45356 | B17: 3 | C17: 3B | D17: Lname8 | E17: Fname8 | F17: XXXXX8 | AA17: =IF(D17="",0,(IF(G17=$G$8,1,0)+IF(H17=$H$8,1,0)+IF(I17=$I$8,1,0)+IF(J17=$J$8,1,0)+IF(K17=$K$8,1,0)+IF(L17=$L$8,1,0)+IF(M17=$M$8,1,0)+IF(N17=$N$8,1,0)+IF(O17=$O$8,1,0)+IF(P17=$P$8,1,0)+IF(Q17=$Q$8,1,0)+IF(R17=$R$8,1,0)+IF(S17=$S$8,1,0)+IF(T17=$T$8,1,0)+IF(U17=$U$8,1,0)+IF(V17=$V$8,1,0)+IF(W17=$W$8,1,0)+IF(X17=$X$8,1,0)+IF(Y17=$Y$8,1,0)+IF(Z17=$Z$8,1,0))) -> 0 | AB17: =IF(D17="","",VLOOKUP(AA17,'PAT Maths'!$F$3:$G$44,2,FALSE)) -> –17.7
A18: 45356 | B18: 3 | C18: 3B | D18: Lname9 | E18: Fname9 | F18: XXXXX9 | AA18: =IF(D18="",0,(IF(G18=$G$8,1,0)+IF(H18=$H$8,1,0)+IF(I18=$I$8,1,0)+IF(J18=$J$8,1,0)+IF(K18=$K$8,1,0)+IF(L18=$L$8,1,0)+IF(M18=$M$8,1,0)+IF(N18=$N$8,1,0)+IF(O18=$O$8,1,0)+IF(P18=$P$8,1,0)+IF(Q18=$Q$8,1,0)+IF(R18=$R$8,1,0)+IF(S18=$S$8,1,0)+IF(T18=$T$8,1,0)+IF(U18=$U$8,1,0)+IF(V18=$V$8,1,0)+IF(W18=$W$8,1,0)+IF(X18=$X$8,1,0)+IF(Y18=$Y$8,1,0)+IF(Z18=$Z$8,1,0))) -> 0 | AB18: =IF(D18="","",VLOOKUP(AA18,'PAT Maths'!$F$3:$G$44,2,FALSE)) -> –17.7
A19: 45356 | B19: 3 | C19: 3B | D19: Lname10 | E19: Fname10 | F19: XXXXX10 | AA19: =IF(D19="",0,(IF(G19=$G$8,1,0)+IF(H19=$H$8,1,0)+IF(I19=$I$8,1,0)+IF(J19=$J$8,1,0)+IF(K19=$K$8,1,0)+IF(L19=$L$8,1,0)+IF(M19=$M$8,1,0)+IF(N19=$N$8,1,0)+IF(O19=$O$8,1,0)+IF(P19=$P$8,1,0)+IF(Q19=$Q$8,1,0)+IF(R19=$R$8,1,0)+IF(S19=$S$8,1,0)+IF(T19=$T$8,1,0)+IF(U19=$U$8,1,0)+IF(V19=$V$8,1,0)+IF(W19=$W$8,1,0)+IF(X19=$X$8,1,0)+IF(Y19=$Y$8,1,0)+IF(Z19=$Z$8,1,0))) -> 0 | AB19: =IF(D19="","",VLOOKUP(AA19,'PAT Maths'!$F$3:$G$44,2,FALSE)) -> –17.7
AA20: =IF(D20="",0,(IF(G20=$G$8,1,0)+IF(H20=$H$8,1,0)+IF(I20=$I$8,1,0)+IF(J20=$J$8,1,0)+IF(K20=$K$8,1,0)+IF(L20=$L$8,1,0)+IF(M20=$M$8,1,0)+IF(N20=$N$8,1,0)+IF(O20=$O$8,1,0)+IF(P20=$P$8,1,0)+IF(Q20=$Q$8,1,0)+IF(R20=$R$8,1,0)+IF(S20=$S$8,1,0)+IF(T20=$T$8,1,0)+IF(U20=$U$8,1,0)+IF(V20=$V$8,1,0)+IF(W20=$W$8,1,0)+IF(X20=$X$8,1,0)+IF(Y20=$Y$8,1,0)+IF(Z20=$Z$8,1,0))) -> 0 | AB20: =IF(D20="","",VLOOKUP(AA20,'PAT Maths'!$F$3:$G$44,2,FALSE))
AA21: =IF(D21="",0,(IF(G21=$G$8,1,0)+IF(H21=$H$8,1,0)+IF(I21=$I$8,1,0)+IF(J21=$J$8,1,0)+IF(K21=$K$8,1,0)+IF(L21=$L$8,1,0)+IF(M21=$M$8,1,0)+IF(N21=$N$8,1,0)+IF(O21=$O$8,1,0)+IF(P21=$P$8,1,0)+IF(Q21=$Q$8,1,0)+IF(R21=$R$8,1,0)+IF(S21=$S$8,1,0)+IF(T21=$T$8,1,0)+IF(U21=$U$8,1,0)+IF(V21=$V$8,1,0)+IF(W21=$W$8,1,0)+IF(X21=$X$8,1,0)+IF(Y21=$Y$8,1,0)+IF(Z21=$Z$8,1,0))) -> 0 | AB21: =IF(D21="","",VLOOKUP(AA21,'PAT Maths'!$F$3:$G$44,2,FALSE))
AA22: =IF(D22="",0,(IF(G22=$G$8,1,0)+IF(H22=$H$8,1,0)+IF(I22=$I$8,1,0)+IF(J22=$J$8,1,0)+IF(K22=$K$8,1,0)+IF(L22=$L$8,1,0)+IF(M22=$M$8,1,0)+IF(N22=$N$8,1,0)+IF(O22=$O$8,1,0)+IF(P22=$P$8,1,0)+IF(Q22=$Q$8,1,0)+IF(R22=$R$8,1,0)+IF(S22=$S$8,1,0)+IF(T22=$T$8,1,0)+IF(U22=$U$8,1,0)+IF(V22=$V$8,1,0)+IF(W22=$W$8,1,0)+IF(X22=$X$8,1,0)+IF(Y22=$Y$8,1,0)+IF(Z22=$Z$8,1,0))) -> 0 | AB22: =IF(D22="","",VLOOKUP(AA22,'PAT Maths'!$F$3:$G$44,2,FALSE))
AA23: =IF(D23="",0,(IF(G23=$G$8,1,0)+IF(H23=$H$8,1,0)+IF(I23=$I$8,1,0)+IF(J23=$J$8,1,0)+IF(K23=$K$8,1,0)+IF(L23=$L$8,1,0)+IF(M23=$M$8,1,0)+IF(N23=$N$8,1,0)+IF(O23=$O$8,1,0)+IF(P23=$P$8,1,0)+IF(Q23=$Q$8,1,0)+IF(R23=$R$8,1,0)+IF(S23=$S$8,1,0)+IF(T23=$T$8,1,0)+IF(U23=$U$8,1,0)+IF(V23=$V$8,1,0)+IF(W23=$W$8,1,0)+IF(X23=$X$8,1,0)+IF(Y23=$Y$8,1,0)+IF(Z23=$Z$8,1,0))) -> 0 | AB23: =IF(D23="","",VLOOKUP(AA23,'PAT Maths'!$F$3:$G$44,2,FALSE))
AA24: =IF(D24="",0,(IF(G24=$G$8,1,0)+IF(H24=$H$8,1,0)+IF(I24=$I$8,1,0)+IF(J24=$J$8,1,0)+IF(K24=$K$8,1,0)+IF(L24=$L$8,1,0)+IF(M24=$M$8,1,0)+IF(N24=$N$8,1,0)+IF(O24=$O$8,1,0)+IF(P24=$P$8,1,0)+IF(Q24=$Q$8,1,0)+IF(R24=$R$8,1,0)+IF(S24=$S$8,1,0)+IF(T24=$T$8,1,0)+IF(U24=$U$8,1,0)+IF(V24=$V$8,1,0)+IF(W24=$W$8,1,0)+IF(X24=$X$8,1,0)+IF(Y24=$Y$8,1,0)+IF(Z24=$Z$8,1,0))) -> 0 | AB24: =IF(D24="","",VLOOKUP(AA24,'PAT Maths'!$F$3:$G$44,2,FALSE))
AA25: =IF(D25="",0,(IF(G25=$G$8,1,0)+IF(H25=$H$8,1,0)+IF(I25=$I$8,1,0)+IF(J25=$J$8,1,0)+IF(K25=$K$8,1,0)+IF(L25=$L$8,1,0)+IF(M25=$M$8,1,0)+IF(N25=$N$8,1,0)+IF(O25=$O$8,1,0)+IF(P25=$P$8,1,0)+IF(Q25=$Q$8,1,0)+IF(R25=$R$8,1,0)+IF(S25=$S$8,1,0)+IF(T25=$T$8,1,0)+IF(U25=$U$8,1,0)+IF(V25=$V$8,1,0)+IF(W25=$W$8,1,0)+IF(X25=$X$8,1,0)+IF(Y25=$Y$8,1,0)+IF(Z25=$Z$8,1,0))) -> 0 | AB25: =IF(D25="","",VLOOKUP(AA25,'PAT Maths'!$F$3:$G$44,2,FALSE))
AA26: =IF(D26="",0,(IF(G26=$G$8,1,0)+IF(H26=$H$8,1,0)+IF(I26=$I$8,1,0)+IF(J26=$J$8,1,0)+IF(K26=$K$8,1,0)+IF(L26=$L$8,1,0)+IF(M26=$M$8,1,0)+IF(N26=$N$8,1,0)+IF(O26=$O$8,1,0)+IF(P26=$P$8,1,0)+IF(Q26=$Q$8,1,0)+IF(R26=$R$8,1,0)+IF(S26=$S$8,1,0)+IF(T26=$T$8,1,0)+IF(U26=$U$8,1,0)+IF(V26=$V$8,1,0)+IF(W26=$W$8,1,0)+IF(X26=$X$8,1,0)+IF(Y26=$Y$8,1,0)+IF(Z26=$Z$8,1,0))) -> 0 | AB26: =IF(D26="","",VLOOKUP(AA26,'PAT Maths'!$F$3:$G$44,2,FALSE))
AA27: =IF(D27="",0,(IF(G27=$G$8,1,0)+IF(H27=$H$8,1,0)+IF(I27=$I$8,1,0)+IF(J27=$J$8,1,0)+IF(K27=$K$8,1,0)+IF(L27=$L$8,1,0)+IF(M27=$M$8,1,0)+IF(N27=$N$8,1,0)+IF(O27=$O$8,1,0)+IF(P27=$P$8,1,0)+IF(Q27=$Q$8,1,0)+IF(R27=$R$8,1,0)+IF(S27=$S$8,1,0)+IF(T27=$T$8,1,0)+IF(U27=$U$8,1,0)+IF(V27=$V$8,1,0)+IF(W27=$W$8,1,0)+IF(X27=$X$8,1,0)+IF(Y27=$Y$8,1,0)+IF(Z27=$Z$8,1,0))) -> 0 | AB27: =IF(D27="","",VLOOKUP(AA27,'PAT Maths'!$F$3:$G$44,2,FALSE))
AA28: =IF(D28="",0,(IF(G28=$G$8,1,0)+IF(H28=$H$8,1,0)+IF(I28=$I$8,1,0)+IF(J28=$J$8,1,0)+IF(K28=$K$8,1,0)+IF(L28=$L$8,1,0)+IF(M28=$M$8,1,0)+IF(N28=$N$8,1,0)+IF(O28=$O$8,1,0)+IF(P28=$P$8,1,0)+IF(Q28=$Q$8,1,0)+IF(R28=$R$8,1,0)+IF(S28=$S$8,1,0)+IF(T28=$T$8,1,0)+IF(U28=$U$8,1,0)+IF(V28=$V$8,1,0)+IF(W28=$W$8,1,0)+IF(X28=$X$8,1,0)+IF(Y28=$Y$8,1,0)+IF(Z28=$Z$8,1,0))) -> 0 | AB28: =IF(D28="","",VLOOKUP(AA28,'PAT Maths'!$F$3:$G$44,2,FALSE))
AA29: =IF(D29="",0,(IF(G29=$G$8,1,0)+IF(H29=$H$8,1,0)+IF(I29=$I$8,1,0)+IF(J29=$J$8,1,0)+IF(K29=$K$8,1,0)+IF(L29=$L$8,1,0)+IF(M29=$M$8,1,0)+IF(N29=$N$8,1,0)+IF(O29=$O$8,1,0)+IF(P29=$P$8,1,0)+IF(Q29=$Q$8,1,0)+IF(R29=$R$8,1,0)+IF(S29=$S$8,1,0)+IF(T29=$T$8,1,0)+IF(U29=$U$8,1,0)+IF(V29=$V$8,1,0)+IF(W29=$W$8,1,0)+IF(X29=$X$8,1,0)+IF(Y29=$Y$8,1,0)+IF(Z29=$Z$8,1,0))) -> 0 | AB29: =IF(D29="","",VLOOKUP(AA29,'PAT Maths'!$F$3:$G$44,2,FALSE))
AA30: =IF(D30="",0,(IF(G30=$G$8,1,0)+IF(H30=$H$8,1,0)+IF(I30=$I$8,1,0)+IF(J30=$J$8,1,0)+IF(K30=$K$8,1,0)+IF(L30=$L$8,1,0)+IF(M30=$M$8,1,0)+IF(N30=$N$8,1,0)+IF(O30=$O$8,1,0)+IF(P30=$P$8,1,0)+IF(Q30=$Q$8,1,0)+IF(R30=$R$8,1,0)+IF(S30=$S$8,1,0)+IF(T30=$T$8,1,0)+IF(U30=$U$8,1,0)+IF(V30=$V$8,1,0)+IF(W30=$W$8,1,0)+IF(X30=$X$8,1,0)+IF(Y30=$Y$8,1,0)+IF(Z30=$Z$8,1,0))) -> 0 | AB30: =IF(D30="","",VLOOKUP(AA30,'PAT Maths'!$F$3:$G$44,2,FALSE))
AA31: =IF(D31="",0,(IF(G31=$G$8,1,0)+IF(H31=$H$8,1,0)+IF(I31=$I$8,1,0)+IF(J31=$J$8,1,0)+IF(K31=$K$8,1,0)+IF(L31=$L$8,1,0)+IF(M31=$M$8,1,0)+IF(N31=$N$8,1,0)+IF(O31=$O$8,1,0)+IF(P31=$P$8,1,0)+IF(Q31=$Q$8,1,0)+IF(R31=$R$8,1,0)+IF(S31=$S$8,1,0)+IF(T31=$T$8,1,0)+IF(U31=$U$8,1,0)+IF(V31=$V$8,1,0)+IF(W31=$W$8,1,0)+IF(X31=$X$8,1,0)+IF(Y31=$Y$8,1,0)+IF(Z31=$Z$8,1,0))) -> 0 | AB31: =IF(D31="","",VLOOKUP(AA31,'PAT Maths'!$F$3:$G$44,2,FALSE))
... AA416: =IF(D416="",0,(IF(G416=$G$8,1,0)+IF(H416=$H$8,1,0)+IF(I416=$I$8,1,0)+IF(J416=$J$8,1,0)+IF(K416=$K$8,1,0)+IF(L416=$L$8,1,0)+IF(M416=$M$8,1,0)+IF(N416=$N$8,1,0)+IF(O416=$O$8,1,0)+IF(P416=$P$8,1,0)+IF(Q416=$Q$8,1,0)+IF(R416=$R$8,1,0)+IF(S416=$S$8,1,0)+IF(T416=$T$8,1,0)+IF(U416=$U$8,1,0)+IF(V416=$V$8,1,0)+IF(W416=$W$8,1,0)+IF(X416=$X$8,1,0)+IF(Y416=$Y$8,1,0)+IF(Z416=$Z$8,1,0))) -> 0 | AB416: =IF(D416="","",VLOOKUP(AA416,'PAT Maths'!$F$3:$G$44,2,FALSE))

Sheet PATM TB1
A1: PAT-Maths - Test Booklet 1
G3: QUESTION No. and ANSWER KEY (Enter the student's response - "A" or "B" or "C" or "D" or "E")
E4: Question Number | G4: 1 | H4: 2 | I4: 3 | J4: 4 | K4: 5 | L4: 6 | M4: 7 | N4: 8 | O4: 9 | P4: 10 | Q4: 11 | R4: 12 | S4: 13 | T4: 14 | U4: 15 | V4: 16 | W4: 17 | X4: 18 | Y4: 19 | Z4: 20 | AA4: 21 | AB4: 22 | AC4: 23 | AD4: 24 | AE4: 25 | AF4: 26 | AG4: 27 | AH4: 28 | AI4: 29 | AJ4: 30 | AK4: 31 | AL4: 32 | AM4: 33 | AN4: 34 | AO4: 35
E5: Item Difficulty | G5: 29 | H5: 29 | I5: 29 | J5: 31 | K5: 30 | L5: 31 | M5: 32 | N5: 31 | O5: 36 | P5: 39 | Q5: 20 | R5: 35 | S5: 35 | T5: 40 | U5: 37 | V5: 29 | W5: 27 | X5: 15 | Y5: 23 | Z5: 22 | AA5: 35 | AB5: 33 | AC5: 38 | AD5: 19 | AE5: 37 | AF5: 30 | AG5: 21 | AH5: 37 | AI5: 31 | AJ5: 46 | AK5: 29 | AL5: 28 | AM5: 30 | AN5: 32 | AO5: 28
E6: Skill Assessed | G6: NC | H6: NC | I6: NC | J6: NC | K6: NC | L6: NC | M6: NC | N6: NC | O6: NC | P6: NC | Q6: NC | R6: NC | S6: NC | T6: NC | U6: NC | V6: S | W6: S | X6: S | Y6: S | Z6: S | AA6: M | AB6: M | AC6: M | AD6: M | AE6: M | AF6: CD | AG6: CD | AH6: CD | AI6: CD | AJ6: CD | AK6: N | AL6: N | AM6: N | AN6: N | AO6: N
A7: required | B7: required | C7: optional | D7: required | E7: required | F7: required
A8: Date (dd/mm/yy) | B8: Yr_Lev | C8: Grp | D8: Surname | E8: First_Name | F8: Student_ID | G8: D | H8: B | I8: C | J8: D | K8: C | L8: B | M8: B | N8: E | O8: E | P8: C | Q8: B | R8: B | S8: B | T8: E | U8: A | V8: D | W8: D | X8: A | Y8: E | Z8: A | AA8: D | AB8: A | AC8: B | AD8: A | AE8: C | AF8: B | AG8: A | AH8: C | AI8: B | AJ8: D | AK8: C | AL8: D | AM8: D | AN8: D | AO8: C | AP8: Raw Score | AQ8: PAT Score
A9: 45356 | B9: 3 | C9: 3A | D9: Lname1 | E9: Fname1 | F9: XXXXX1 | AP9: =IF(D9="",0,(IF(G9=$G$8,1,0)+IF(H9=$H$8,1,0)+IF(I9=$I$8,1,0)+IF(J9=$J$8,1,0)+IF(K9=$K$8,1,0)+IF(L9=$L$8,1,0)+IF(M9=$M$8,1,0)+IF(N9=$N$8,1,0)+IF(O9=$O$8,1,0)+IF(P9=$P$8,1,0)+IF(Q9=$Q$8,1,0)+IF(R9=$R$8,1,0)+IF(S9=$S$8,1,0)+IF(T9=$T$8,1,0)+IF(U9=$U$8,1,0)+IF(V9=$V$8,1,0)+IF(W9=$W$8,1,0)+IF(X9=$X$8,1,0)+IF(Y9=$Y$8,1,0)+IF(Z9=$Z$8,1,0)+IF(AA9=$AA$8,1,0)+IF(AB9=$AB$8,1,0)+IF(AC9=$AC$8,1,0)+IF(AD9=$AD$8,1,0)+IF(AE9=$AE$8,1,0)+IF(AF9=$AF$8,1,0)+IF(AG9=$AG$8,1,0)+IF(AH9=$AH$8,1,0)+IF(AI9=$AI$8,1,0)+IF(AJ9=$AJ$8,1,0)+IF(AK9=$AK$8,1,0)+IF(AL9=$AL$8,1,0)+IF(AM9=$AM$8,1,0)+IF(AN9=$AN$8,1,0)+IF(AO9=$AO$8,1,0))) -> 0 | AQ9: =IF(D9="","",VLOOKUP(AP9,'PAT Maths'!$H$3:$I$44,2,FALSE)) -> –16.8
A10: 45356 | B10: 3 | C10: 3A | D10: Lname2 | E10: Fname2 | F10: XXXXX2 | AP10: =IF(D10="",0,(IF(G10=$G$8,1,0)+IF(H10=$H$8,1,0)+IF(I10=$I$8,1,0)+IF(J10=$J$8,1,0)+IF(K10=$K$8,1,0)+IF(L10=$L$8,1,0)+IF(M10=$M$8,1,0)+IF(N10=$N$8,1,0)+IF(O10=$O$8,1,0)+IF(P10=$P$8,1,0)+IF(Q10=$Q$8,1,0)+IF(R10=$R$8,1,0)+IF(S10=$S$8,1,0)+IF(T10=$T$8,1,0)+IF(U10=$U$8,1,0)+IF(V10=$V$8,1,0)+IF(W10=$W$8,1,0)+IF(X10=$X$8,1,0)+IF(Y10=$Y$8,1,0)+IF(Z10=$Z$8,1,0)+IF(AA10=$AA$8,1,0)+IF(AB10=$AB$8,1,0)+IF(AC10=$AC$8,1,0)+IF(AD10=$AD$8,1,0)+IF(AE10=$AE$8,1,0)+IF(AF10=$AF$8,1,0)+IF(AG10=$AG$8,1,0)+IF(AH10=$AH$8,1,0)+IF(AI10=$AI$8,1,0)+IF(AJ10=$AJ$8,1,0)+IF(AK10=$AK$8,1,0)+IF(AL10=$AL$8,1,0)+IF(AM10=$AM$8,1,0)+IF(AN10=$AN$8,1,0)+IF(AO10=$AO$8,1,0))) -> 0 | AQ10: =IF(D10="","",VLOOKUP(AP10,'PAT Maths'!$H$3:$I$44,2,FALSE)) -> –16.8
A11: 45356 | B11: 3 | C11: 3A | D11: Lname3 | E11: Fname3 | F11: XXXXX3 | AP11: =IF(D11="",0,(IF(G11=$G$8,1,0)+IF(H11=$H$8,1,0)+IF(I11=$I$8,1,0)+IF(J11=$J$8,1,0)+IF(K11=$K$8,1,0)+IF(L11=$L$8,1,0)+IF(M11=$M$8,1,0)+IF(N11=$N$8,1,0)+IF(O11=$O$8,1,0)+IF(P11=$P$8,1,0)+IF(Q11=$Q$8,1,0)+IF(R11=$R$8,1,0)+IF(S11=$S$8,1,0)+IF(T11=$T$8,1,0)+IF(U11=$U$8,1,0)+IF(V11=$V$8,1,0)+IF(W11=$W$8,1,0)+IF(X11=$X$8,1,0)+IF(Y11=$Y$8,1,0)+IF(Z11=$Z$8,1,0)+IF(AA11=$AA$8,1,0)+IF(AB11=$AB$8,1,0)+IF(AC11=$AC$8,1,0)+IF(AD11=$AD$8,1,0)+IF(AE11=$AE$8,1,0)+IF(AF11=$AF$8,1,0)+IF(AG11=$AG$8,1,0)+IF(AH11=$AH$8,1,0)+IF(AI11=$AI$8,1,0)+IF(AJ11=$AJ$8,1,0)+IF(AK11=$AK$8,1,0)+IF(AL11=$AL$8,1,0)+IF(AM11=$AM$8,1,0)+IF(AN11=$AN$8,1,0)+IF(AO11=$AO$8,1,0))) -> 0 | AQ11: =IF(D11="","",VLOOKUP(AP11,'PAT Maths'!$H$3:$I$44,2,FALSE)) -> –16.8
A12: 45356 | B12: 3 | C12: 3A | D12: Lname4 | E12: Fname4 | F12: XXXXX4 | AP12: =IF(D12="",0,(IF(G12=$G$8,1,0)+IF(H12=$H$8,1,0)+IF(I12=$I$8,1,0)+IF(J12=$J$8,1,0)+IF(K12=$K$8,1,0)+IF(L12=$L$8,1,0)+IF(M12=$M$8,1,0)+IF(N12=$N$8,1,0)+IF(O12=$O$8,1,0)+IF(P12=$P$8,1,0)+IF(Q12=$Q$8,1,0)+IF(R12=$R$8,1,0)+IF(S12=$S$8,1,0)+IF(T12=$T$8,1,0)+IF(U12=$U$8,1,0)+IF(V12=$V$8,1,0)+IF(W12=$W$8,1,0)+IF(X12=$X$8,1,0)+IF(Y12=$Y$8,1,0)+IF(Z12=$Z$8,1,0)+IF(AA12=$AA$8,1,0)+IF(AB12=$AB$8,1,0)+IF(AC12=$AC$8,1,0)+IF(AD12=$AD$8,1,0)+IF(AE12=$AE$8,1,0)+IF(AF12=$AF$8,1,0)+IF(AG12=$AG$8,1,0)+IF(AH12=$AH$8,1,0)+IF(AI12=$AI$8,1,0)+IF(AJ12=$AJ$8,1,0)+IF(AK12=$AK$8,1,0)+IF(AL12=$AL$8,1,0)+IF(AM12=$AM$8,1,0)+IF(AN12=$AN$8,1,0)+IF(AO12=$AO$8,1,0))) -> 0 | AQ12: =IF(D12="","",VLOOKUP(AP12,'PAT Maths'!$H$3:$I$44,2,FALSE)) -> –16.8
A13: 45356 | B13: 3 | C13: 3B | D13: ULname13 | E13: UFname13 | F13: UNLISTED | AP13: =IF(D13="",0,(IF(G13=$G$8,1,0)+IF(H13=$H$8,1,0)+IF(I13=$I$8,1,0)+IF(J13=$J$8,1,0)+IF(K13=$K$8,1,0)+IF(L13=$L$8,1,0)+IF(M13=$M$8,1,0)+IF(N13=$N$8,1,0)+IF(O13=$O$8,1,0)+IF(P13=$P$8,1,0)+IF(Q13=$Q$8,1,0)+IF(R13=$R$8,1,0)+IF(S13=$S$8,1,0)+IF(T13=$T$8,1,0)+IF(U13=$U$8,1,0)+IF(V13=$V$8,1,0)+IF(W13=$W$8,1,0)+IF(X13=$X$8,1,0)+IF(Y13=$Y$8,1,0)+IF(Z13=$Z$8,1,0)+IF(AA13=$AA$8,1,0)+IF(AB13=$AB$8,1,0)+IF(AC13=$AC$8,1,0)+IF(AD13=$AD$8,1,0)+IF(AE13=$AE$8,1,0)+IF(AF13=$AF$8,1,0)+IF(AG13=$AG$8,1,0)+IF(AH13=$AH$8,1,0)+IF(AI13=$AI$8,1,0)+IF(AJ13=$AJ$8,1,0)+IF(AK13=$AK$8,1,0)+IF(AL13=$AL$8,1,0)+IF(AM13=$AM$8,1,0)+IF(AN13=$AN$8,1,0)+IF(AO13=$AO$8,1,0))) -> 0 | AQ13: =IF(D13="","",VLOOKUP(AP13,'PAT Maths'!$H$3:$I$44,2,FALSE)) -> –16.8
A14: 45356 | B14: 3 | C14: 3A | D14: Lname5 | E14: Fname5 | F14: XXXXX5 | AP14: =IF(D14="",0,(IF(G14=$G$8,1,0)+IF(H14=$H$8,1,0)+IF(I14=$I$8,1,0)+IF(J14=$J$8,1,0)+IF(K14=$K$8,1,0)+IF(L14=$L$8,1,0)+IF(M14=$M$8,1,0)+IF(N14=$N$8,1,0)+IF(O14=$O$8,1,0)+IF(P14=$P$8,1,0)+IF(Q14=$Q$8,1,0)+IF(R14=$R$8,1,0)+IF(S14=$S$8,1,0)+IF(T14=$T$8,1,0)+IF(U14=$U$8,1,0)+IF(V14=$V$8,1,0)+IF(W14=$W$8,1,0)+IF(X14=$X$8,1,0)+IF(Y14=$Y$8,1,0)+IF(Z14=$Z$8,1,0)+IF(AA14=$AA$8,1,0)+IF(AB14=$AB$8,1,0)+IF(AC14=$AC$8,1,0)+IF(AD14=$AD$8,1,0)+IF(AE14=$AE$8,1,0)+IF(AF14=$AF$8,1,0)+IF(AG14=$AG$8,1,0)+IF(AH14=$AH$8,1,0)+IF(AI14=$AI$8,1,0)+IF(AJ14=$AJ$8,1,0)+IF(AK14=$AK$8,1,0)+IF(AL14=$AL$8,1,0)+IF(AM14=$AM$8,1,0)+IF(AN14=$AN$8,1,0)+IF(AO14=$AO$8,1,0))) -> 0 | AQ14: =IF(D14="","",VLOOKUP(AP14,'PAT Maths'!$H$3:$I$44,2,FALSE)) -> –16.8
A15: 45356 | B15: 3 | C15: 3B | D15: Lname6 | E15: Fname6 | F15: XXXXX6 | AP15: =IF(D15="",0,(IF(G15=$G$8,1,0)+IF(H15=$H$8,1,0)+IF(I15=$I$8,1,0)+IF(J15=$J$8,1,0)+IF(K15=$K$8,1,0)+IF(L15=$L$8,1,0)+IF(M15=$M$8,1,0)+IF(N15=$N$8,1,0)+IF(O15=$O$8,1,0)+IF(P15=$P$8,1,0)+IF(Q15=$Q$8,1,0)+IF(R15=$R$8,1,0)+IF(S15=$S$8,1,0)+IF(T15=$T$8,1,0)+IF(U15=$U$8,1,0)+IF(V15=$V$8,1,0)+IF(W15=$W$8,1,0)+IF(X15=$X$8,1,0)+IF(Y15=$Y$8,1,0)+IF(Z15=$Z$8,1,0)+IF(AA15=$AA$8,1,0)+IF(AB15=$AB$8,1,0)+IF(AC15=$AC$8,1,0)+IF(AD15=$AD$8,1,0)+IF(AE15=$AE$8,1,0)+IF(AF15=$AF$8,1,0)+IF(AG15=$AG$8,1,0)+IF(AH15=$AH$8,1,0)+IF(AI15=$AI$8,1,0)+IF(AJ15=$AJ$8,1,0)+IF(AK15=$AK$8,1,0)+IF(AL15=$AL$8,1,0)+IF(AM15=$AM$8,1,0)+IF(AN15=$AN$8,1,0)+IF(AO15=$AO$8,1,0))) -> 0 | AQ15: =IF(D15="","",VLOOKUP(AP15,'PAT Maths'!$H$3:$I$44,2,FALSE)) -> –16.8
A16: 45356 | B16: 3 | C16: 3B | D16: Lname7 | E16: Fname7 | F16: XXXXX7 | AP16: =IF(D16="",0,(IF(G16=$G$8,1,0)+IF(H16=$H$8,1,0)+IF(I16=$I$8,1,0)+IF(J16=$J$8,1,0)+IF(K16=$K$8,1,0)+IF(L16=$L$8,1,0)+IF(M16=$M$8,1,0)+IF(N16=$N$8,1,0)+IF(O16=$O$8,1,0)+IF(P16=$P$8,1,0)+IF(Q16=$Q$8,1,0)+IF(R16=$R$8,1,0)+IF(S16=$S$8,1,0)+IF(T16=$T$8,1,0)+IF(U16=$U$8,1,0)+IF(V16=$V$8,1,0)+IF(W16=$W$8,1,0)+IF(X16=$X$8,1,0)+IF(Y16=$Y$8,1,0)+IF(Z16=$Z$8,1,0)+IF(AA16=$AA$8,1,0)+IF(AB16=$AB$8,1,0)+IF(AC16=$AC$8,1,0)+IF(AD16=$AD$8,1,0)+IF(AE16=$AE$8,1,0)+IF(AF16=$AF$8,1,0)+IF(AG16=$AG$8,1,0)+IF(AH16=$AH$8,1,0)+IF(AI16=$AI$8,1,0)+IF(AJ16=$AJ$8,1,0)+IF(AK16=$AK$8,1,0)+IF(AL16=$AL$8,1,0)+IF(AM16=$AM$8,1,0)+IF(AN16=$AN$8,1,0)+IF(AO16=$AO$8,1,0))) -> 0 | AQ16: =IF(D16="","",VLOOKUP(AP16,'PAT Maths'!$H$3:$I$44,2,FALSE)) -> –16.8
A17: 45356 | B17: 3 | C17: 3B | D17: Lname8 | E17: Fname8 | F17: XXXXX8 | AP17: =IF(D17="",0,(IF(G17=$G$8,1,0)+IF(H17=$H$8,1,0)+IF(I17=$I$8,1,0)+IF(J17=$J$8,1,0)+IF(K17=$K$8,1,0)+IF(L17=$L$8,1,0)+IF(M17=$M$8,1,0)+IF(N17=$N$8,1,0)+IF(O17=$O$8,1,0)+IF(P17=$P$8,1,0)+IF(Q17=$Q$8,1,0)+IF(R17=$R$8,1,0)+IF(S17=$S$8,1,0)+IF(T17=$T$8,1,0)+IF(U17=$U$8,1,0)+IF(V17=$V$8,1,0)+IF(W17=$W$8,1,0)+IF(X17=$X$8,1,0)+IF(Y17=$Y$8,1,0)+IF(Z17=$Z$8,1,0)+IF(AA17=$AA$8,1,0)+IF(AB17=$AB$8,1,0)+IF(AC17=$AC$8,1,0)+IF(AD17=$AD$8,1,0)+IF(AE17=$AE$8,1,0)+IF(AF17=$AF$8,1,0)+IF(AG17=$AG$8,1,0)+IF(AH17=$AH$8,1,0)+IF(AI17=$AI$8,1,0)+IF(AJ17=$AJ$8,1,0)+IF(AK17=$AK$8,1,0)+IF(AL17=$AL$8,1,0)+IF(AM17=$AM$8,1,0)+IF(AN17=$AN$8,1,0)+IF(AO17=$AO$8,1,0))) -> 0 | AQ17: =IF(D17="","",VLOOKUP(AP17,'PAT Maths'!$H$3:$I$44,2,FALSE)) -> –16.8
A18: 45356 | B18: 3 | C18: 3B | D18: Lname9 | E18: Fname9 | F18: XXXXX9 | AP18: =IF(D18="",0,(IF(G18=$G$8,1,0)+IF(H18=$H$8,1,0)+IF(I18=$I$8,1,0)+IF(J18=$J$8,1,0)+IF(K18=$K$8,1,0)+IF(L18=$L$8,1,0)+IF(M18=$M$8,1,0)+IF(N18=$N$8,1,0)+IF(O18=$O$8,1,0)+IF(P18=$P$8,1,0)+IF(Q18=$Q$8,1,0)+IF(R18=$R$8,1,0)+IF(S18=$S$8,1,0)+IF(T18=$T$8,1,0)+IF(U18=$U$8,1,0)+IF(V18=$V$8,1,0)+IF(W18=$W$8,1,0)+IF(X18=$X$8,1,0)+IF(Y18=$Y$8,1,0)+IF(Z18=$Z$8,1,0)+IF(AA18=$AA$8,1,0)+IF(AB18=$AB$8,1,0)+IF(AC18=$AC$8,1,0)+IF(AD18=$AD$8,1,0)+IF(AE18=$AE$8,1,0)+IF(AF18=$AF$8,1,0)+IF(AG18=$AG$8,1,0)+IF(AH18=$AH$8,1,0)+IF(AI18=$AI$8,1,0)+IF(AJ18=$AJ$8,1,0)+IF(AK18=$AK$8,1,0)+IF(AL18=$AL$8,1,0)+IF(AM18=$AM$8,1,0)+IF(AN18=$AN$8,1,0)+IF(AO18=$AO$8,1,0))) -> 0 | AQ18: =IF(D18="","",VLOOKUP(AP18,'PAT Maths'!$H$3:$I$44,2,FALSE)) -> –16.8
