Workbook

Sheet Main Menu
B2: Marie Clay Observation Survey Tasks Scoring Templates
B4: This series of spreadsheets provide the templates required to enter Marie Clay Observation Survey Task results into the Student Performance Analyser (SPA). Click on the appropriate button (at right) to select the correct task proforma to complete. Follow the instructions opposite. | H4: Step 1: Click on the appropriate button (at left) to select the correct task proforma to complete. Step 2: For each student, enter the Date (when test was sat), Date of Birth, Year Level, Home Group, Name, and Student ID (CASES No. or Student No.). Step 3: For each question, enter their response with a Y (for answered correctly) or N (for answered incorrectly) (their score will then be calculated) OR enter their Raw Score Step 4: Save and upload into SPA.
H29: Click here to find out more about the Student Performance Analyser

Sheet Concepts of Print
F1: Concepts Of Print
K3: Question No., Skills Assessed and Answer Key AND Instructions: Mark either a 'Y' or a 'N' against each of the questions and fill in the required fields. The template will then calculate the total number of questions correct and a stanine score for the child.
K4: =COUNTIF(K$9:K$503,K$8) -> 8 | L4: =COUNTIF(L$9:L$503,L$8) -> 8 | M4: =COUNTIF(M$9:M$503,M$8) -> 8 | N4: =COUNTIF(N$9:N$503,N$8) -> 8 | O4: =COUNTIF(O$9:O$503,O$8) -> 9 | P4: =COUNTIF(P$9:P$503,P$8) -> 9 | Q4: =COUNTIF(Q$9:Q$503,Q$8) -> 8 | R4: =COUNTIF(R$9:R$503,R$8) -> 9 | ... AH4: =COUNTIF(AH$9:AH$503,AH$8) -> 0
K5: 1 | L5: 2 | M5: 3 | N5: 4 | O5: 5 | P5: 6 | Q5: 7 | R5: 8 | S5: 9 | T5: 10 | U5: 11 | V5: 12 | W5: 13 | X5: 14 | Y5: 15 | Z5: 16 | AA5: 17 | AB5: 18 | AC5: 19 | AD5: 20 | AE5: 21 | AF5: 22 | AG5: 23 | AH5: 24
K6: Front of book Orientation of book | L6: Print contains message Concept that print, not pictures, carries the message | M6: Where to start Directional rules | N6: Which way to go Moves left to right on any line | O6: Return sweep to left Return sweep | P6: Word-by-mouth matching Word-by-word pointing | Q6: First and last concept Concept of first and last | R6: Bottom of picture Inversion of picture | S6: Begins ‘The’ (Sand) Response to inverted print | T6: Line order altered Line sequence | U6: Left page before right A left page is read before a right page. | V6: One change in word order Sequence | W6: One change in letter order Letter order (changes to first or last letters) | X6: One change in letter order Re-ordering letters within a word | Y6: Meaning of a question mark Punctuation | Z6: Meaning of full stop (period) Punctuation | AA6: Meaning of comma Punctuation | AB6: Meaning of quotation marks Punctuation | AC6: Locate: m h (Sand); t b (Stones); Capital and lower case letters | AD6: Reversible words ‘was’, ‘no’ Words that contain the same letters in a different order | AE6: One letter: two letters Letter concepts | AF6: One word: two words Word Concept | AG6: First and last letter of word First and last letter concepts | AH6: Capital letter capital letter concepts
A7: required | B7: required | C7: required | E7: required | F7: required | G7: required | H7: required
A8: Date (dd/mm/yy) | B8: DOB | C8: Yr_Lev | D8: HG | E8: Surname | F8: First_Name | G8: Student ID | H8: Book Read (Sand,Stone, Shoes,Moon) | I8: Total Score | J8: Stanine Score | K8: Y | L8: Y | M8: Y | N8: Y | O8: Y | P8: Y | Q8: Y | R8: Y | S8: Y | T8: Y | U8: Y | V8: Y | W8: Y | X8: Y | Y8: Y | Z8: Y | AA8: Y | AB8: Y | AC8: Y | AD8: Y | AE8: Y | AF8: Y | AG8: Y | AH8: Y | AI8: =COUNTIF(K8:AH8,"y") -> 24 | AJ8: (Total) | AL8: Age at test
A9: 45950 | B9: 40959 | C9: 3 | E9: Lname1 | F9: Fname1 | G9: XXXXX1 | H9: Sand | I9: =IF(E9="","",COUNTIF(K9:AH9,"y")) -> 23 | J9: =IF(I9="","",IF(AND(AL9<=66),VLOOKUP(I9,'COP Look Up'!$A$13:$B$21,2,TRUE),IF(AND(AL9>=67,AL9<=72),VLOOKUP(I9,'COP Look Up'!$E$13:$F$21,2,TRUE),IF(AND(AL9>=73,AL9<=78),VLOOKUP(I9,'COP Look Up'!$I$13:$J$21,2,TRUE),IF(AND(AL9>=79),VLOOKUP(I9,'COP Look Up'!$M$13:$N$20,2,TRUE),""))))) -> 7 | K9: y | L9: y | M9: y | N9: y | O9: y | P9: y | Q9: y | R9: y | S9: y | T9: y | U9: y | V9: y | W9: y | X9: y | Y9: y | Z9: y | AA9: y | AB9: y | AC9: y | AD9: y | AE9: y | AF9: y | AG9: y | AL9: =IF(E9="","",DATEDIF(B9,A9,"m")) -> 164
A10: 45950 | B10: 40960 | C10: 3 | E10: Lname2 | F10: Fname2 | G10: XXXXX2 | H10: Sand | I10: =IF(E10="","",COUNTIF(K10:AH10,"y")) -> 19 | J10: =IF(I10="","",IF(AND(AL10<=66),VLOOKUP(I10,'COP Look Up'!$A$13:$B$21,2,TRUE),IF(AND(AL10>=67,AL10<=72),VLOOKUP(I10,'COP Look Up'!$E$13:$F$21,2,TRUE),IF(AND(AL10>=73,AL10<=78),VLOOKUP(I10,'COP Look Up'!$I$13:$J$21,2,TRUE),IF(AND(AL10>=79),VLOOKUP(I10,'COP Look Up'!$M$13:$N$20,2,TRUE),""))))) -> 5 | K10: y | L10: y | M10: y | N10: y | O10: y | P10: y | Q10: y | R10: y | S10: y | T10: y | U10: y | V10: y | W10: y | X10: y | Y10: y | Z10: y | AA10: y | AB10: y | AC10: y | AL10: =IF(E10="","",DATEDIF(B10,A10,"m")) -> 163
A11: 45950 | B11: 40961 | C11: 3 | E11: Lname3 | F11: Fname3 | G11: XXXXX3 | H11: Sand | I11: =IF(E11="","",COUNTIF(K11:AH11,"y")) -> 21 | J11: =IF(I11="","",IF(AND(AL11<=66),VLOOKUP(I11,'COP Look Up'!$A$13:$B$21,2,TRUE),IF(AND(AL11>=67,AL11<=72),VLOOKUP(I11,'COP Look Up'!$E$13:$F$21,2,TRUE),IF(AND(AL11>=73,AL11<=78),VLOOKUP(I11,'COP Look Up'!$I$13:$J$21,2,TRUE),IF(AND(AL11>=79),VLOOKUP(I11,'COP Look Up'!$M$13:$N$20,2,TRUE),""))))) -> 6 | K11: y | L11: y | M11: y | N11: y | O11: y | P11: y | Q11: y | R11: y | S11: y | T11: y | U11: y | V11: y | W11: y | X11: y | Y11: y | Z11: y | AA11: y | AB11: y | AC11: y | AD11: y | AE11: y | AL11: =IF(E11="","",DATEDIF(B11,A11,"m")) -> 163
A12: 45950 | B12: 40962 | C12: 3 | E12: Lname4 | F12: Fname4 | G12: XXXXX4 | H12: Sand | I12: =IF(E12="","",COUNTIF(K12:AH12,"y")) -> 21 | J12: =IF(I12="","",IF(AND(AL12<=66),VLOOKUP(I12,'COP Look Up'!$A$13:$B$21,2,TRUE),IF(AND(AL12>=67,AL12<=72),VLOOKUP(I12,'COP Look Up'!$E$13:$F$21,2,TRUE),IF(AND(AL12>=73,AL12<=78),VLOOKUP(I12,'COP Look Up'!$I$13:$J$21,2,TRUE),IF(AND(AL12>=79),VLOOKUP(I12,'COP Look Up'!$M$13:$N$20,2,TRUE),""))))) -> 6 | K12: y | L12: y | M12: y | N12: y | O12: y | P12: y | Q12: y | R12: y | S12: y | T12: y | U12: y | V12: y | W12: y | X12: y | Y12: y | Z12: y | AA12: y | AB12: y | AC12: y | AD12: y | AE12: y | AL12: =IF(E12="","",DATEDIF(B12,A12,"m")) -> 163
A13: 45950 | B13: 40970 | C13: 3 | E13: ULname13 | F13: UFname13 | G13: UNLISTED | H13: Sand | I13: =IF(E13="","",COUNTIF(K13:AH13,"y")) -> 21 | J13: =IF(I13="","",IF(AND(AL13<=66),VLOOKUP(I13,'COP Look Up'!$A$13:$B$21,2,TRUE),IF(AND(AL13>=67,AL13<=72),VLOOKUP(I13,'COP Look Up'!$E$13:$F$21,2,TRUE),IF(AND(AL13>=73,AL13<=78),VLOOKUP(I13,'COP Look Up'!$I$13:$J$21,2,TRUE),IF(AND(AL13>=79),VLOOKUP(I13,'COP Look Up'!$M$13:$N$20,2,TRUE),""))))) -> 6 | K13: y | L13: y | M13: y | N13: y | O13: y | P13: y | Q13: y | R13: y | S13: y | T13: y | U13: y | V13: y | W13: y | X13: y | Y13: y | Z13: y | AA13: y | AB13: y | AC13: y | AD13: y | AE13: y | AL13: =IF(E13="","",DATEDIF(B13,A13,"m")) -> 163
A14: 45950 | B14: 40963 | C14: 3 | E14: Lname5 | F14: Fname5 | G14: XXXXX5 | H14: Sand | I14: =IF(E14="","",COUNTIF(K14:AH14,"y")) -> 0 | J14: =IF(I14="","",IF(AND(AL14<=66),VLOOKUP(I14,'COP Look Up'!$A$13:$B$21,2,TRUE),IF(AND(AL14>=67,AL14<=72),VLOOKUP(I14,'COP Look Up'!$E$13:$F$21,2,TRUE),IF(AND(AL14>=73,AL14<=78),VLOOKUP(I14,'COP Look Up'!$I$13:$J$21,2,TRUE),IF(AND(AL14>=79),VLOOKUP(I14,'COP Look Up'!$M$13:$N$20,2,TRUE),""))))) -> 1 | AL14: =IF(E14="","",DATEDIF(B14,A14,"m")) -> 163
A15: 45950 | B15: 40964 | C15: 3 | E15: Lname6 | F15: Fname6 | G15: XXXXX6 | H15: Sand | I15: =IF(E15="","",COUNTIF(K15:AH15,"y")) -> 20 | J15: =IF(I15="","",IF(AND(AL15<=66),VLOOKUP(I15,'COP Look Up'!$A$13:$B$21,2,TRUE),IF(AND(AL15>=67,AL15<=72),VLOOKUP(I15,'COP Look Up'!$E$13:$F$21,2,TRUE),IF(AND(AL15>=73,AL15<=78),VLOOKUP(I15,'COP Look Up'!$I$13:$J$21,2,TRUE),IF(AND(AL15>=79),VLOOKUP(I15,'COP Look Up'!$M$13:$N$20,2,TRUE),""))))) -> 5 | K15: y | L15: y | M15: y | N15: y | O15: y | P15: y | Q15: y | R15: y | S15: y | T15: y | U15: y | V15: y | W15: y | X15: y | Y15: y | Z15: y | AA15: y | AB15: y | AC15: y | AD15: y | AL15: =IF(E15="","",DATEDIF(B15,A15,"m")) -> 163
A16: 45950 | B16: 40965 | C16: 3 | E16: Lname7 | F16: Fname7 | G16: XXXXX7 | H16: Sand | I16: =IF(E16="","",COUNTIF(K16:AH16,"y")) -> 4 | J16: =IF(I16="","",IF(AND(AL16<=66),VLOOKUP(I16,'COP Look Up'!$A$13:$B$21,2,TRUE),IF(AND(AL16>=67,AL16<=72),VLOOKUP(I16,'COP Look Up'!$E$13:$F$21,2,TRUE),IF(AND(AL16>=73,AL16<=78),VLOOKUP(I16,'COP Look Up'!$I$13:$J$21,2,TRUE),IF(AND(AL16>=79),VLOOKUP(I16,'COP Look Up'!$M$13:$N$20,2,TRUE),""))))) -> 1 | K16: n | L16: n | M16: n | N16: n | O16: y | P16: y | Q16: n | R16: y | S16: y | T16: n | U16: n | V16: n | W16: n | X16: n | Y16: n | Z16: n | AA16: n | AB16: n | AC16: n | AD16: n | AL16: =IF(E16="","",DATEDIF(B16,A16,"m")) -> 163
A17: 45950 | B17: 40966 | C17: 3 | E17: Lname8 | F17: Fname8 | G17: XXXXX8 | H17: Sand | I17: =IF(E17="","",COUNTIF(K17:AH17,"y")) -> 20 | J17: =IF(I17="","",IF(AND(AL17<=66),VLOOKUP(I17,'COP Look Up'!$A$13:$B$21,2,TRUE),IF(AND(AL17>=67,AL17<=72),VLOOKUP(I17,'COP Look Up'!$E$13:$F$21,2,TRUE),IF(AND(AL17>=73,AL17<=78),VLOOKUP(I17,'COP Look Up'!$I$13:$J$21,2,TRUE),IF(AND(AL17>=79),VLOOKUP(I17,'COP Look Up'!$M$13:$N$20,2,TRUE),""))))) -> 5 | K17: y | L17: y | M17: y | N17: y | O17: y | P17: y | Q17: y | R17: y | S17: y | T17: y | U17: y | V17: y | W17: y | X17: y | Y17: y | Z17: y | AA17: y | AB17: y | AC17: y | AD17: y | AL17: =IF(E17="","",DATEDIF(B17,A17,"m")) -> 163
A18: 45950 | B18: 40967 | C18: 3 | E18: Lname9 | F18: Fname9 | G18: XXXXX9 | H18: Sand | I18: =IF(E18="","",COUNTIF(K18:AH18,"y")) -> 20 | J18: =IF(I18="","",IF(AND(AL18<=66),VLOOKUP(I18,'COP Look Up'!$A$13:$B$21,2,TRUE),IF(AND(AL18>=67,AL18<=72),VLOOKUP(I18,'COP Look Up'!$E$13:$F$21,2,TRUE),IF(AND(AL18>=73,AL18<=78),VLOOKUP(I18,'COP Look Up'!$I$13:$J$21,2,TRUE),IF(AND(AL18>=79),VLOOKUP(I18,'COP Look Up'!$M$13:$N$20,2,TRUE),""))))) -> 5 | K18: y | L18: y | M18: y | N18: y | O18: y | P18: y | Q18: y | R18: y | S18: y | T18: y | U18: y | V18: y | W18: y | X18: y | Y18: y | Z18: y | AA18: y | AB18: y | AC18: y | AD18: y | AL18: =IF(E18="","",DATEDIF(B18,A18,"m")) -> 163
A19: 45950 | B19: 40968 | C19: 3 | E19: Lname10 | F19: Fname10 | G19: XXXXX10 | I19: =IF(E19="","",COUNTIF(K19:AH19,"y")) -> 0 | J19: =IF(I19="","",IF(AND(AL19<=66),VLOOKUP(I19,'COP Look Up'!$A$13:$B$21,2,TRUE),IF(AND(AL19>=67,AL19<=72),VLOOKUP(I19,'COP Look Up'!$E$13:$F$21,2,TRUE),IF(AND(AL19>=73,AL19<=78),VLOOKUP(I19,'COP Look Up'!$I$13:$J$21,2,TRUE),IF(AND(AL19>=79),VLOOKUP(I19,'COP Look Up'!$M$13:$N$20,2,TRUE),""))))) -> 1 | AL19: =IF(E19="","",DATEDIF(B19,A19,"m")) -> 163
I20: =IF(E20="","",COUNTIF(K20:AH20,"y")) | J20: =IF(I20="","",IF(AND(AL20<=66),VLOOKUP(I20,'COP Look Up'!$A$13:$B$21,2,TRUE),IF(AND(AL20>=67,AL20<=72),VLOOKUP(I20,'COP Look Up'!$E$13:$F$21,2,TRUE),IF(AND(AL20>=73,AL20<=78),VLOOKUP(I20,'COP Look Up'!$I$13:$J$21,2,TRUE),IF(AND(AL20>=79),VLOOKUP(I20,'COP Look Up'!$M$13:$N$20,2,TRUE),""))))) | AL20: =IF(E20="","",DATEDIF(B20,A20,"m"))
I21: =IF(E21="","",COUNTIF(K21:AH21,"y")) | J21: =IF(I21="","",IF(AND(AL21<=66),VLOOKUP(I21,'COP Look Up'!$A$13:$B$21,2,TRUE),IF(AND(AL21>=67,AL21<=72),VLOOKUP(I21,'COP Look Up'!$E$13:$F$21,2,TRUE),IF(AND(AL21>=73,AL21<=78),VLOOKUP(I21,'COP Look Up'!$I$13:$J$21,2,TRUE),IF(AND(AL21>=79),VLOOKUP(I21,'COP Look Up'!$M$13:$N$20,2,TRUE),""))))) | AL21: =IF(E21="","",DATEDIF(B21,A21,"m"))
I22: =IF(E22="","",COUNTIF(K22:AH22,"y")) | J22: =IF(I22="","",IF(AND(AL22<=66),VLOOKUP(I22,'COP Look Up'!$A$13:$B$21,2,TRUE),IF(AND(AL22>=67,AL22<=72),VLOOKUP(I22,'COP Look Up'!$E$13:$F$21,2,TRUE),IF(AND(AL22>=73,AL22<=78),VLOOKUP(I22,'COP Look Up'!$I$13:$J$21,2,TRUE),IF(AND(AL22>=79),VLOOKUP(I22,'COP Look Up'!$M$13:$N$20,2,TRUE),""))))) | AL22: =IF(E22="","",DATEDIF(B22,A22,"m"))
I23: =IF(E23="","",COUNTIF(K23:AH23,"y")) | J23: =IF(I23="","",IF(AND(AL23<=66),VLOOKUP(I23,'COP Look Up'!$A$13:$B$21,2,TRUE),IF(AND(AL23>=67,AL23<=72),VLOOKUP(I23,'COP Look Up'!$E$13:$F$21,2,TRUE),IF(AND(AL23>=73,AL23<=78),VLOOKUP(I23,'COP Look Up'!$I$13:$J$21,2,TRUE),IF(AND(AL23>=79),VLOOKUP(I23,'COP Look Up'!$M$13:$N$20,2,TRUE),""))))) | AL23: =IF(E23="","",DATEDIF(B23,A23,"m"))
I24: =IF(E24="","",COUNTIF(K24:AH24,"y")) | J24: =IF(I24="","",IF(AND(AL24<=66),VLOOKUP(I24,'COP Look Up'!$A$13:$B$21,2,TRUE),IF(AND(AL24>=67,AL24<=72),VLOOKUP(I24,'COP Look Up'!$E$13:$F$21,2,TRUE),IF(AND(AL24>=73,AL24<=78),VLOOKUP(I24,'COP Look Up'!$I$13:$J$21,2,TRUE),IF(AND(AL24>=79),VLOOKUP(I24,'COP Look Up'!$M$13:$N$20,2,TRUE),""))))) | AL24: =IF(E24="","",DATEDIF(B24,A24,"m"))
I25: =IF(E25="","",COUNTIF(K25:AH25,"y")) | J25: =IF(I25="","",IF(AND(AL25<=66),VLOOKUP(I25,'COP Look Up'!$A$13:$B$21,2,TRUE),IF(AND(AL25>=67,AL25<=72),VLOOKUP(I25,'COP Look Up'!$E$13:$F$21,2,TRUE),IF(AND(AL25>=73,AL25<=78),VLOOKUP(I25,'COP Look Up'!$I$13:$J$21,2,TRUE),IF(AND(AL25>=79),VLOOKUP(I25,'COP Look Up'!$M$13:$N$20,2,TRUE),""))))) | AL25: =IF(E25="","",DATEDIF(B25,A25,"m"))
I26: =IF(E26="","",COUNTIF(K26:AH26,"y")) | J26: =IF(I26="","",IF(AND(AL26<=66),VLOOKUP(I26,'COP Look Up'!$A$13:$B$21,2,TRUE),IF(AND(AL26>=67,AL26<=72),VLOOKUP(I26,'COP Look Up'!$E$13:$F$21,2,TRUE),IF(AND(AL26>=73,AL26<=78),VLOOKUP(I26,'COP Look Up'!$I$13:$J$21,2,TRUE),IF(AND(AL26>=79),VLOOKUP(I26,'COP Look Up'!$M$13:$N$20,2,TRUE),""))))) | AL26: =IF(E26="","",DATEDIF(B26,A26,"m"))
I27: =IF(E27="","",COUNTIF(K27:AH27,"y")) | J27: =IF(I27="","",IF(AND(AL27<=66),VLOOKUP(I27,'COP Look Up'!$A$13:$B$21,2,TRUE),IF(AND(AL27>=67,AL27<=72),VLOOKUP(I27,'COP Look Up'!$E$13:$F$21,2,TRUE),IF(AND(AL27>=73,AL27<=78),VLOOKUP(I27,'COP Look Up'!$I$13:$J$21,2,TRUE),IF(AND(AL27>=79),VLOOKUP(I27,'COP Look Up'!$M$13:$N$20,2,TRUE),""))))) | AL27: =IF(E27="","",DATEDIF(B27,A27,"m"))
I28: =IF(E28="","",COUNTIF(K28:AH28,"y")) | J28: =IF(I28="","",IF(AND(AL28<=66),VLOOKUP(I28,'COP Look Up'!$A$13:$B$21,2,TRUE),IF(AND(AL28>=67,AL28<=72),VLOOKUP(I28,'COP Look Up'!$E$13:$F$21,2,TRUE),IF(AND(AL28>=73,AL28<=78),VLOOKUP(I28,'COP Look Up'!$I$13:$J$21,2,TRUE),IF(AND(AL28>=79),VLOOKUP(I28,'COP Look Up'!$M$13:$N$20,2,TRUE),""))))) | AL28: =IF(E28="","",DATEDIF(B28,A28,"m"))
I29: =IF(E29="","",COUNTIF(K29:AH29,"y")) | J29: =IF(I29="","",IF(AND(AL29<=66),VLOOKUP(I29,'COP Look Up'!$A$13:$B$21,2,TRUE),IF(AND(AL29>=67,AL29<=72),VLOOKUP(I29,'COP Look Up'!$E$13:$F$21,2,TRUE),IF(AND(AL29>=73,AL29<=78),VLOOKUP(I29,'COP Look Up'!$I$13:$J$21,2,TRUE),IF(AND(AL29>=79),VLOOKUP(I29,'COP Look Up'!$M$13:$N$20,2,TRUE),""))))) | AL29: =IF(E29="","",DATEDIF(B29,A29,"m"))
I30: =IF(E30="","",COUNTIF(K30:AH30,"y")) | J30: =IF(I30="","",IF(AND(AL30<=66),VLOOKUP(I30,'COP Look Up'!$A$13:$B$21,2,TRUE),IF(AND(AL30>=67,AL30<=72),VLOOKUP(I30,'COP Look Up'!$E$13:$F$21,2,TRUE),IF(AND(AL30>=73,AL30<=78),VLOOKUP(I30,'COP Look Up'!$I$13:$J$21,2,TRUE),IF(AND(AL30>=79),VLOOKUP(I30,'COP Look Up'!$M$13:$N$20,2,TRUE),""))))) | AL30: =IF(E30="","",DATEDIF(B30,A30,"m"))
I31: =IF(E31="","",COUNTIF(K31:AH31,"y")) | J31: =IF(I31="","",IF(AND(AL31<=66),VLOOKUP(I31,'COP Look Up'!$A$13:$B$21,2,TRUE),IF(AND(AL31>=67,AL31<=72),VLOOKUP(I31,'COP Look Up'!$E$13:$F$21,2,TRUE),IF(AND(AL31>=73,AL31<=78),VLOOKUP(I31,'COP Look Up'!$I$13:$J$21,2,TRUE),IF(AND(AL31>=79),VLOOKUP(I31,'COP Look Up'!$M$13:$N$20,2,TRUE),""))))) | AL31: =IF(E31="","",DATEDIF(B31,A31,"m"))
... I500: =IF(E500="","",COUNTIF(K500:AH500,"y")) | J500: =IF(I500="","",IF(AND(AL500<=66),VLOOKUP(I500,'COP Look Up'!$A$13:$B$21,2,TRUE),IF(AND(AL500>=67,AL500<=72),VLOOKUP(I500,'COP Look Up'!$E$13:$F$21,2,TRUE),IF(AND(AL500>=73,AL500<=78),VLOOKUP(I500,'COP Look Up'!$I$13:$J$21,2,TRUE),IF(AND(AL500>=79),VLOOKUP(I500,'COP Look Up'!$M$13:$N$20,2,TRUE),""))))) | AL500: =IF(E500="","",DATEDIF(B500,A500,"m"))

Sheet COP Look Up
A9: Concepts of Print
A11: Concepts of Print 5.00-5.5 years <=66 months | E11: Concepts of Print 5.51-6.00 years 67-72 months | I11: Concepts of Print 6.01-6.5 years 73-78 months | M11: Concepts of Print 6.51-7 years >=79 months
A12: Test Score | B12: Stanine Group | E12: Test Score | F12: Stanine Group | I12: Test Score | J12: Stanine Group | M12: Test Score | N12: Stanine Group
A13: 0 | B13: 1 | E13: 0 | F13: 1 | I13: 0 | J13: 1 | M13: 0 | N13: 1
A14: 8 | B14: 2 | E14: 9 | F14: 2 | I14: 12 | J14: 2 | M14: 14 | N14: 2
A15: 10 | B15: 3 | E15: 12 | F15: 3 | I15: 15 | J15: 3 | M15: 16 | N15: 3
A16: 12 | B16: 4 | E16: 14 | F16: 4 | I16: 17 | J16: 4 | M16: 18 | N16: 4
A17: 14 | B17: 5 | E17: 16 | F17: 5 | I17: 18 | J17: 5 | M17: 19 | N17: 5
A18: 15 | B18: 6 | E18: 18 | F18: 6 | I18: 20 | J18: 6 | M18: 21 | N18: 6
A19: 17 | B19: 7 | E19: 19 | F19: 7 | I19: 21 | J19: 7 | M19: 22 | N19: 7
A20: 19 | B20: 8 | E20: 21 | F20: 8 | I20: 23 | J20: 8 | M20: 24 | N20: 8-9
A21: 20 | B21: 9 | E21: 23 | F21: 9 | I21: 24 | J21: 9

Sheet Letter ID
F1: Letter ID
J3: Question No., Letter and Answer Key Record a 'Y' where the child responds correctly either by naming the letter, providing the sound the letter makes or suggesting a word beginning with that letter. Marie Clay considers any of these responses from the child as correct as the child is able to distingish the letter. If the child can not identify the letter record an 'N'. Additionally fill in the required fields. The template will then calculate a total score and a stanine score for the child.
H4: Question Number | J4: AND Instructions: | K4: 2 | L4: 3 | M4: 4 | N4: 5 | O4: 6 | P4: 7 | Q4: 8 | R4: 9 | S4: 10 | T4: 11 | U4: 12 | V4: 13 | W4: 14 | X4: 15 | Y4: 16 | Z4: 17 | AA4: 18 | AB4: 19 | AC4: 20 | AD4: 21 | AE4: 22 | AF4: 23 | AG4: 24 | AH4: 25 | AI4: 26 | AJ4: 27 | AK4: 28 | AL4: 29 | AM4: 30 | AN4: 31 | AO4: 32 | AP4: 33 | AQ4: 34 | AR4: 35 | AS4: 36 | AT4: 37 | AU4: 38 | AV4: 39 | AW4: 40 | AX4: 41 | AY4: 42 | AZ4: 43 | BA4: 44 | BB4: 45 | BC4: 46 | BD4: 47 | BE4: 48 | BF4: 49 | BG4: 50 | BH4: 51 | BI4: 52 | BJ4: 53 | BK4: 54
H5: Letter asked | J5: A | K5: F | L5: K | M5: P | N5: W | O5: Z | P5: B | Q5: H | R5: O | S5: J | T5: U | U5: C | V5: Y | W5: L | X5: Q | Y5: M | Z5: D | AA5: N | AB5: S | AC5: X | AD5: I | AE5: E | AF5: G | AG5: R | AH5: V | AI5: T | AJ5: a | AK5: f | AL5: k | AM5: p | AN5: w | AO5: z | AP5: b | AQ5: h | AR5: o | AS5: j | AT5: u | AU5: a | AV5: c | AW5: y | AX5: l | AY5: q | AZ5: m | BA5: d | BB5: n | BC5: s | BD5: x | BE5: i | BF5: e | BG5: g | BH5: r | BI5: v | BJ5: t | BK5: g
A6: required | B6: required | C6: required | E6: required | F6: required | G6: required
A7: Date (dd/mm/yy) | B7: DOB | C7: Yr_Lev | D7: HG | E7: Surname | F7: First_Name | G7: Student ID | H7: Total Score | I7: Stanine Score | J7: Y | K7: Y | L7: Y | M7: Y | N7: Y | O7: Y | P7: Y | Q7: Y | R7: Y | S7: Y | T7: Y | U7: Y | V7: Y | W7: Y | X7: Y | Y7: Y | Z7: Y | AA7: Y | AB7: Y | AC7: Y | AD7: Y | AE7: Y | AF7: Y | AG7: Y | AH7: Y | AI7: Y | AJ7: Y | AK7: Y | AL7: Y | AM7: Y | AN7: Y | AO7: Y | AP7: Y | AQ7: Y | AR7: Y | AS7: Y | AT7: Y | AU7: Y | AV7: Y | AW7: Y | AX7: Y | AY7: Y | AZ7: Y | BA7: Y | BB7: Y | BC7: Y | BD7: Y | BE7: Y | BF7: Y | BG7: Y | BH7: Y | BI7: Y | BJ7: Y | BK7: Y | BL7: =COUNTIF(J7:BK7,"y") -> 54 | BM7: (Total) | BV7: Age at test
A8: 45950 | B8: 40959 | C8: 3 | E8: Lname1 | F8: Fname1 | G8: XXXXX1 | H8: =IF(E8="","",COUNTIF(J8:BK8,"y")) -> 0 | I8: =IF(E8="","",IF(AND(BV8<=66),VLOOKUP(H8,'LetterID Look Up'!$A$13:$B$20,2,TRUE),IF(AND(BV8>=67,BV8<=72),VLOOKUP(H8,'LetterID Look Up'!$E$13:$F$19,2,TRUE),IF(AND(BV8>=73,BV8<=78),VLOOKUP(H8,'LetterID Look Up'!$I$13:$J$19,2,TRUE),IF(AND(BV8>=79),VLOOKUP(H8,'LetterID Look Up'!$M$13:$N$17,2,TRUE),""))))) -> 1 | BV8: =IF(E8="","",DATEDIF(B8,A8,"m")) -> 164
A9: 45950 | B9: 40960 | C9: 3 | E9: Lname2 | F9: Fname2 | G9: XXXXX2 | H9: =IF(E9="","",COUNTIF(J9:BK9,"y")) -> 0 | I9: =IF(E9="","",IF(AND(BV9<=66),VLOOKUP(H9,'LetterID Look Up'!$A$13:$B$20,2,TRUE),IF(AND(BV9>=67,BV9<=72),VLOOKUP(H9,'LetterID Look Up'!$E$13:$F$19,2,TRUE),IF(AND(BV9>=73,BV9<=78),VLOOKUP(H9,'LetterID Look Up'!$I$13:$J$19,2,TRUE),IF(AND(BV9>=79),VLOOKUP(H9,'LetterID Look Up'!$M$13:$N$17,2,TRUE),""))))) -> 1 | BV9: =IF(E9="","",DATEDIF(B9,A9,"m")) -> 163
A10: 45950 | B10: 40961 | C10: 3 | E10: Lname3 | F10: Fname3 | G10: XXXXX3 | H10: =IF(E10="","",COUNTIF(J10:BK10,"y")) -> 0 | I10: =IF(E10="","",IF(AND(BV10<=66),VLOOKUP(H10,'LetterID Look Up'!$A$13:$B$20,2,TRUE),IF(AND(BV10>=67,BV10<=72),VLOOKUP(H10,'LetterID Look Up'!$E$13:$F$19,2,TRUE),IF(AND(BV10>=73,BV10<=78),VLOOKUP(H10,'LetterID Look Up'!$I$13:$J$19,2,TRUE),IF(AND(BV10>=79),VLOOKUP(H10,'LetterID Look Up'!$M$13:$N$17,2,TRUE),""))))) -> 1 | BV10: =IF(E10="","",DATEDIF(B10,A10,"m")) -> 163
A11: 45950 | B11: 40962 | C11: 3 | E11: Lname4 | F11: Fname4 | G11: XXXXX4 | H11: =IF(E11="","",COUNTIF(J11:BK11,"y")) -> 0 | I11: =IF(E11="","",IF(AND(BV11<=66),VLOOKUP(H11,'LetterID Look Up'!$A$13:$B$20,2,TRUE),IF(AND(BV11>=67,BV11<=72),VLOOKUP(H11,'LetterID Look Up'!$E$13:$F$19,2,TRUE),IF(AND(BV11>=73,BV11<=78),VLOOKUP(H11,'LetterID Look Up'!$I$13:$J$19,2,TRUE),IF(AND(BV11>=79),VLOOKUP(H11,'LetterID Look Up'!$M$13:$N$17,2,TRUE),""))))) -> 1 | BV11: =IF(E11="","",DATEDIF(B11,A11,"m")) -> 163
A12: 45950 | B12: 40970 | C12: 3 | E12: ULname13 | F12: UFname13 | G12: UNLISTED | H12: =IF(E12="","",COUNTIF(J12:BK12,"y")) -> 0 | I12: =IF(E12="","",IF(AND(BV12<=66),VLOOKUP(H12,'LetterID Look Up'!$A$13:$B$20,2,TRUE),IF(AND(BV12>=67,BV12<=72),VLOOKUP(H12,'LetterID Look Up'!$E$13:$F$19,2,TRUE),IF(AND(BV12>=73,BV12<=78),VLOOKUP(H12,'LetterID Look Up'!$I$13:$J$19,2,TRUE),IF(AND(BV12>=79),VLOOKUP(H12,'LetterID Look Up'!$M$13:$N$17,2,TRUE),""))))) -> 1 | BV12: =IF(E12="","",DATEDIF(B12,A12,"m")) -> 163
A13: 45950 | B13: 40963 | C13: 3 | E13: Lname5 | F13: Fname5 | G13: XXXXX5 | H13: =IF(E13="","",COUNTIF(J13:BK13,"y")) -> 0 | I13: =IF(E13="","",IF(AND(BV13<=66),VLOOKUP(H13,'LetterID Look Up'!$A$13:$B$20,2,TRUE),IF(AND(BV13>=67,BV13<=72),VLOOKUP(H13,'LetterID Look Up'!$E$13:$F$19,2,TRUE),IF(AND(BV13>=73,BV13<=78),VLOOKUP(H13,'LetterID Look Up'!$I$13:$J$19,2,TRUE),IF(AND(BV13>=79),VLOOKUP(H13,'LetterID Look Up'!$M$13:$N$17,2,TRUE),""))))) -> 1 | BV13: =IF(E13="","",DATEDIF(B13,A13,"m")) -> 163
A14: 45950 | B14: 40964 | C14: 3 | E14: Lname6 | F14: Fname6 | G14: XXXXX6 | H14: =IF(E14="","",COUNTIF(J14:BK14,"y")) -> 0 | I14: =IF(E14="","",IF(AND(BV14<=66),VLOOKUP(H14,'LetterID Look Up'!$A$13:$B$20,2,TRUE),IF(AND(BV14>=67,BV14<=72),VLOOKUP(H14,'LetterID Look Up'!$E$13:$F$19,2,TRUE),IF(AND(BV14>=73,BV14<=78),VLOOKUP(H14,'LetterID Look Up'!$I$13:$J$19,2,TRUE),IF(AND(BV14>=79),VLOOKUP(H14,'LetterID Look Up'!$M$13:$N$17,2,TRUE),""))))) -> 1 | BV14: =IF(E14="","",DATEDIF(B14,A14,"m")) -> 163
A15: 45950 | B15: 40965 | C15: 3 | E15: Lname7 | F15: Fname7 | G15: XXXXX7 | H15: =IF(E15="","",COUNTIF(J15:BK15,"y")) -> 0 | I15: =IF(E15="","",IF(AND(BV15<=66),VLOOKUP(H15,'LetterID Look Up'!$A$13:$B$20,2,TRUE),IF(AND(BV15>=67,BV15<=72),VLOOKUP(H15,'LetterID Look Up'!$E$13:$F$19,2,TRUE),IF(AND(BV15>=73,BV15<=78),VLOOKUP(H15,'LetterID Look Up'!$I$13:$J$19,2,TRUE),IF(AND(BV15>=79),VLOOKUP(H15,'LetterID Look Up'!$M$13:$N$17,2,TRUE),""))))) -> 1 | BV15: =IF(E15="","",DATEDIF(B15,A15,"m")) -> 163
A16: 45950 | B16: 40966 | C16: 3 | E16: Lname8 | F16: Fname8 | G16: XXXXX8 | H16: =IF(E16="","",COUNTIF(J16:BK16,"y")) -> 0 | I16: =IF(E16="","",IF(AND(BV16<=66),VLOOKUP(H16,'LetterID Look Up'!$A$13:$B$20,2,TRUE),IF(AND(BV16>=67,BV16<=72),VLOOKUP(H16,'LetterID Look Up'!$E$13:$F$19,2,TRUE),IF(AND(BV16>=73,BV16<=78),VLOOKUP(H16,'LetterID Look Up'!$I$13:$J$19,2,TRUE),IF(AND(BV16>=79),VLOOKUP(H16,'LetterID Look Up'!$M$13:$N$17,2,TRUE),""))))) -> 1 | BV16: =IF(E16="","",DATEDIF(B16,A16,"m")) -> 163
A17: 45950 | B17: 40967 | C17: 3 | E17: Lname9 | F17: Fname9 | G17: XXXXX9 | H17: =IF(E17="","",COUNTIF(J17:BK17,"y")) -> 0 | I17: =IF(E17="","",IF(AND(BV17<=66),VLOOKUP(H17,'LetterID Look Up'!$A$13:$B$20,2,TRUE),IF(AND(BV17>=67,BV17<=72),VLOOKUP(H17,'LetterID Look Up'!$E$13:$F$19,2,TRUE),IF(AND(BV17>=73,BV17<=78),VLOOKUP(H17,'LetterID Look Up'!$I$13:$J$19,2,TRUE),IF(AND(BV17>=79),VLOOKUP(H17,'LetterID Look Up'!$M$13:$N$17,2,TRUE),""))))) -> 1 | BV17: =IF(E17="","",DATEDIF(B17,A17,"m")) -> 163
A18: 45950 | B18: 40968 | C18: 3 | E18: Lname10 | F18: Fname10 | G18: XXXXX10 | H18: =IF(E18="","",COUNTIF(J18:BK18,"y")) -> 0 | I18: =IF(E18="","",IF(AND(BV18<=66),VLOOKUP(H18,'LetterID Look Up'!$A$13:$B$20,2,TRUE),IF(AND(BV18>=67,BV18<=72),VLOOKUP(H18,'LetterID Look Up'!$E$13:$F$19,2,TRUE),IF(AND(BV18>=73,BV18<=78),VLOOKUP(H18,'LetterID Look Up'!$I$13:$J$19,2,TRUE),IF(AND(BV18>=79),VLOOKUP(H18,'LetterID Look Up'!$M$13:$N$17,2,TRUE),""))))) -> 1 | BV18: =IF(E18="","",DATEDIF(B18,A18,"m")) -> 163
H19: =IF(E19="","",COUNTIF(J19:BK19,"y")) | I19: =IF(E19="","",IF(AND(BV19<=66),VLOOKUP(H19,'LetterID Look Up'!$A$13:$B$20,2,TRUE),IF(AND(BV19>=67,BV19<=72),VLOOKUP(H19,'LetterID Look Up'!$E$13:$F$19,2,TRUE),IF(AND(BV19>=73,BV19<=78),VLOOKUP(H19,'LetterID Look Up'!$I$13:$J$19,2,TRUE),IF(AND(BV19>=79),VLOOKUP(H19,'LetterID Look Up'!$M$13:$N$17,2,TRUE),""))))) | BV19: =IF(E19="","",DATEDIF(B19,A19,"m"))
H20: =IF(E20="","",COUNTIF(J20:BK20,"y")) | I20: =IF(E20="","",IF(AND(BV20<=66),VLOOKUP(H20,'LetterID Look Up'!$A$13:$B$20,2,TRUE),IF(AND(BV20>=67,BV20<=72),VLOOKUP(H20,'LetterID Look Up'!$E$13:$F$19,2,TRUE),IF(AND(BV20>=73,BV20<=78),VLOOKUP(H20,'LetterID Look Up'!$I$13:$J$19,2,TRUE),IF(AND(BV20>=79),VLOOKUP(H20,'LetterID Look Up'!$M$13:$N$17,2,TRUE),""))))) | BV20: =IF(E20="","",DATEDIF(B20,A20,"m"))
H21: =IF(E21="","",COUNTIF(J21:BK21,"y")) | I21: =IF(E21="","",IF(AND(BV21<=66),VLOOKUP(H21,'LetterID Look Up'!$A$13:$B$20,2,TRUE),IF(AND(BV21>=67,BV21<=72),VLOOKUP(H21,'LetterID Look Up'!$E$13:$F$19,2,TRUE),IF(AND(BV21>=73,BV21<=78),VLOOKUP(H21,'LetterID Look Up'!$I$13:$J$19,2,TRUE),IF(AND(BV21>=79),VLOOKUP(H21,'LetterID Look Up'!$M$13:$N$17,2,TRUE),""))))) | BV21: =IF(E21="","",DATEDIF(B21,A21,"m"))
H22: =IF(E22="","",COUNTIF(J22:BK22,"y")) | I22: =IF(E22="","",IF(AND(BV22<=66),VLOOKUP(H22,'LetterID Look Up'!$A$13:$B$20,2,TRUE),IF(AND(BV22>=67,BV22<=72),VLOOKUP(H22,'LetterID Look Up'!$E$13:$F$19,2,TRUE),IF(AND(BV22>=73,BV22<=78),VLOOKUP(H22,'LetterID Look Up'!$I$13:$J$19,2,TRUE),IF(AND(BV22>=79),VLOOKUP(H22,'LetterID Look Up'!$M$13:$N$17,2,TRUE),""))))) | BV22: =IF(E22="","",DATEDIF(B22,A22,"m"))
H23: =IF(E23="","",COUNTIF(J23:BK23,"y")) | I23: =IF(E23="","",IF(AND(BV23<=66),VLOOKUP(H23,'LetterID Look Up'!$A$13:$B$20,2,TRUE),IF(AND(BV23>=67,BV23<=72),VLOOKUP(H23,'LetterID Look Up'!$E$13:$F$19,2,TRUE),IF(AND(BV23>=73,BV23<=78),VLOOKUP(H23,'LetterID Look Up'!$I$13:$J$19,2,TRUE),IF(AND(BV23>=79),VLOOKUP(H23,'LetterID Look Up'!$M$13:$N$17,2,TRUE),""))))) | BV23: =IF(E23="","",DATEDIF(B23,A23,"m"))
H24: =IF(E24="","",COUNTIF(J24:BK24,"y")) | I24: =IF(E24="","",IF(AND(BV24<=66),VLOOKUP(H24,'LetterID Look Up'!$A$13:$B$20,2,TRUE),IF(AND(BV24>=67,BV24<=72),VLOOKUP(H24,'LetterID Look Up'!$E$13:$F$19,2,TRUE),IF(AND(BV24>=73,BV24<=78),VLOOKUP(H24,'LetterID Look Up'!$I$13:$J$19,2,TRUE),IF(AND(BV24>=79),VLOOKUP(H24,'LetterID Look Up'!$M$13:$N$17,2,TRUE),""))))) | BV24: =IF(E24="","",DATEDIF(B24,A24,"m"))
H25: =IF(E25="","",COUNTIF(J25:BK25,"y")) | I25: =IF(E25="","",IF(AND(BV25<=66),VLOOKUP(H25,'LetterID Look Up'!$A$13:$B$20,2,TRUE),IF(AND(BV25>=67,BV25<=72),VLOOKUP(H25,'LetterID Look Up'!$E$13:$F$19,2,TRUE),IF(AND(BV25>=73,BV25<=78),VLOOKUP(H25,'LetterID Look Up'!$I$13:$J$19,2,TRUE),IF(AND(BV25>=79),VLOOKUP(H25,'LetterID Look Up'!$M$13:$N$17,2,TRUE),""))))) | BV25: =IF(E25="","",DATEDIF(B25,A25,"m"))
H26: =IF(E26="","",COUNTIF(J26:BK26,"y")) | I26: =IF(E26="","",IF(AND(BV26<=66),VLOOKUP(H26,'LetterID Look Up'!$A$13:$B$20,2,TRUE),IF(AND(BV26>=67,BV26<=72),VLOOKUP(H26,'LetterID Look Up'!$E$13:$F$19,2,TRUE),IF(AND(BV26>=73,BV26<=78),VLOOKUP(H26,'LetterID Look Up'!$I$13:$J$19,2,TRUE),IF(AND(BV26>=79),VLOOKUP(H26,'LetterID Look Up'!$M$13:$N$17,2,TRUE),""))))) | BV26: =IF(E26="","",DATEDIF(B26,A26,"m"))
H27: =IF(E27="","",COUNTIF(J27:BK27,"y")) | I27: =IF(E27="","",IF(AND(BV27<=66),VLOOKUP(H27,'LetterID Look Up'!$A$13:$B$20,2,TRUE),IF(AND(BV27>=67,BV27<=72),VLOOKUP(H27,'LetterID Look Up'!$E$13:$F$19,2,TRUE),IF(AND(BV27>=73,BV27<=78),VLOOKUP(H27,'LetterID Look Up'!$I$13:$J$19,2,TRUE),IF(AND(BV27>=79),VLOOKUP(H27,'LetterID Look Up'!$M$13:$N$17,2,TRUE),""))))) | BV27: =IF(E27="","",DATEDIF(B27,A27,"m"))
H28: =IF(E28="","",COUNTIF(J28:BK28,"y")) | I28: =IF(E28="","",IF(AND(BV28<=66),VLOOKUP(H28,'LetterID Look Up'!$A$13:$B$20,2,TRUE),IF(AND(BV28>=67,BV28<=72),VLOOKUP(H28,'LetterID Look Up'!$E$13:$F$19,2,TRUE),IF(AND(BV28>=73,BV28<=78),VLOOKUP(H28,'LetterID Look Up'!$I$13:$J$19,2,TRUE),IF(AND(BV28>=79),VLOOKUP(H28,'LetterID Look Up'!$M$13:$N$17,2,TRUE),""))))) | BV28: =IF(E28="","",DATEDIF(B28,A28,"m"))
H29: =IF(E29="","",COUNTIF(J29:BK29,"y")) | I29: =IF(E29="","",IF(AND(BV29<=66),VLOOKUP(H29,'LetterID Look Up'!$A$13:$B$20,2,TRUE),IF(AND(BV29>=67,BV29<=72),VLOOKUP(H29,'LetterID Look Up'!$E$13:$F$19,2,TRUE),IF(AND(BV29>=73,BV29<=78),VLOOKUP(H29,'LetterID Look Up'!$I$13:$J$19,2,TRUE),IF(AND(BV29>=79),VLOOKUP(H29,'LetterID Look Up'!$M$13:$N$17,2,TRUE),""))))) | BV29: =IF(E29="","",DATEDIF(B29,A29,"m"))
H30: =IF(E30="","",COUNTIF(J30:BK30,"y")) | I30: =IF(E30="","",IF(AND(BV30<=66),VLOOKUP(H30,'LetterID Look Up'!$A$13:$B$20,2,TRUE),IF(AND(BV30>=67,BV30<=72),VLOOKUP(H30,'LetterID Look Up'!$E$13:$F$19,2,TRUE),IF(AND(BV30>=73,BV30<=78),VLOOKUP(H30,'LetterID Look Up'!$I$13:$J$19,2,TRUE),IF(AND(BV30>=79),VLOOKUP(H30,'LetterID Look Up'!$M$13:$N$17,2,TRUE),""))))) | BV30: =IF(E30="","",DATEDIF(B30,A30,"m"))
... H500: =IF(E500="","",COUNTIF(J500:BK500,"y")) | I500: =IF(E500="","",IF(AND(BV500<=66),VLOOKUP(H500,'LetterID Look Up'!$A$13:$B$20,2,TRUE),IF(AND(BV500>=67,BV500<=72),VLOOKUP(H500,'LetterID Look Up'!$E$13:$F$19,2,TRUE),IF(AND(BV500>=73,BV500<=78),VLOOKUP(H500,'LetterID Look Up'!$I$13:$J$19,2,TRUE),IF(AND(BV500>=79),VLOOKUP(H500,'LetterID Look Up'!$M$13:$N$17,2,TRUE),""))))) | BV500: =IF(E500="","",DATEDIF(B500,A500,"m"))

Sheet LetterID Look Up
A9: Letter ID
A11: Letter ID 5.00-5.5 years <=66 months | E11: Letter ID 5.51-6.00 years 67-72 months | I11: Letter ID 6.01-6.5 years 73-78 months | M11: Letter ID 6.51-7 years >=79 months
A12: Test Score | B12: Stanine Group | E12: Test Score | F12: Stanine Group | I12: Test Score | J12: Stanine Group | M12: Test Score | N12: Stanine Group
A13: 0 | B13: 1 | E13: 0 | F13: 1 | I13: 0 | J13: 1 | M13: 0 | N13: 1
A14: 4 | B14: 2 | E14: 11 | F14: 2 | I14: 35 | J14: 2 | M14: 41 | N14: 2
A15: 13 | B15: 3 | E15: 36 | F15: 3 | I15: 49 | J15: 3 | M15: 51 | N15: 3
A16: 28 | B16: 4 | E16: 47 | F16: 4 | I16: 51 | J16: 4 | M16: 53 | N16: 4-5
A17: 43 | B17: 5 | E17: 52 | F17: 5 | I17: 52 | J17: 5 | M17: 54 | N17: 6-9
A18: 50 | B18: 6 | E18: 53 | F18: 6 | I18: 53 | J18: 6
A19: 53 | B19: 7 | E19: 54 | F19: 7-9 | I19: 54 | J19: 7-9
A20: 54 | B20: 8-9

Sheet Hearing & Recording Sounds
F1: Hearing & Recording Sounds
F3: Instructions: Record the child's total score within the yellow portion of the template along with the required fields. The template will then calculate a stanine score for the child.
A4: required | B4: required | C4: required | E4: required | F4: required | G4: required | H4: required | I4: required
A5: Test_Date (dd/mm/yy) | B5: DOB | C5: Yr_Lev | D5: HG | E5: Surname | F5: First_Name | G5: Student ID | H5: Form (A,B,C,D,E) | I5: Total Score | J5: Stanine Score | U5: Age at Test in Months
A6: 45950 | B6: 40959 | C6: 3 | E6: Lname1 | F6: Fname1 | G6: XXXXX1 | J6: =IF(E6="","",IF(AND(U6<=66),VLOOKUP(I6,'H&R Look Up'!$A$13:$B$21,2,TRUE),IF(AND(U6>=67,U6<=72),VLOOKUP(I6,'H&R Look Up'!$E$13:$F$20,2,TRUE),IF(AND(U6>=73,U6<=78),VLOOKUP(I6,'H&R Look Up'!$I$13:$J$19,2,TRUE),IF(AND(U6>=79),VLOOKUP(I6,'H&R Look Up'!$M$13:$N$18,2,TRUE),""))))) -> 1 | S6: =IF(P6="","",COUNTIF(#REF!,"y")) | T6: =IF(P6="","",IF(AND(CE6<=2008),VLOOKUP(S6,'H&R Look Up'!$A$13:$B$20,2,TRUE),IF(AND(CE6>2009,CE6<=2191),VLOOKUP(S6,'H&R Look Up'!$E$13:$F$19,2,TRUE),IF(AND(CE6>2192,CE6<=2374),VLOOKUP(S6,'H&R Look Up'!$I$13:$J$19,2,TRUE),IF(AND(CE6>2375,CE6>=2556),VLOOKUP(S6,'H&R Look Up'!$M$13:$N$17,2,TRUE),""))))) | U6: =IF(E6="","",DATEDIF(B6,A6,"m")) -> 164
A7: 45950 | B7: 40960 | C7: 3 | E7: Lname2 | F7: Fname2 | G7: XXXXX2 | J7: =IF(E7="","",IF(AND(U7<=66),VLOOKUP(I7,'H&R Look Up'!$A$13:$B$21,2,TRUE),IF(AND(U7>=67,U7<=72),VLOOKUP(I7,'H&R Look Up'!$E$13:$F$20,2,TRUE),IF(AND(U7>=73,U7<=78),VLOOKUP(I7,'H&R Look Up'!$I$13:$J$19,2,TRUE),IF(AND(U7>=79),VLOOKUP(I7,'H&R Look Up'!$M$13:$N$18,2,TRUE),""))))) -> 1 | S7: =IF(P7="","",COUNTIF(U7:BT7,"y")) | T7: =IF(P7="","",IF(AND(CE7<=2008),VLOOKUP(S7,'H&R Look Up'!$A$13:$B$20,2,TRUE),IF(AND(CE7>2009,CE7<=2191),VLOOKUP(S7,'H&R Look Up'!$E$13:$F$19,2,TRUE),IF(AND(CE7>2192,CE7<=2374),VLOOKUP(S7,'H&R Look Up'!$I$13:$J$19,2,TRUE),IF(AND(CE7>2375,CE7>=2556),VLOOKUP(S7,'H&R Look Up'!$M$13:$N$17,2,TRUE),""))))) | U7: =IF(E7="","",DATEDIF(B7,A7,"m")) -> 163
A8: 45950 | B8: 40961 | C8: 3 | E8: Lname3 | F8: Fname3 | G8: XXXXX3 | J8: =IF(E8="","",IF(AND(U8<=66),VLOOKUP(I8,'H&R Look Up'!$A$13:$B$21,2,TRUE),IF(AND(U8>=67,U8<=72),VLOOKUP(I8,'H&R Look Up'!$E$13:$F$20,2,TRUE),IF(AND(U8>=73,U8<=78),VLOOKUP(I8,'H&R Look Up'!$I$13:$J$19,2,TRUE),IF(AND(U8>=79),VLOOKUP(I8,'H&R Look Up'!$M$13:$N$18,2,TRUE),""))))) -> 1 | S8: =IF(P8="","",COUNTIF(U8:BT8,"y")) | T8: =IF(P8="","",IF(AND(CE8<=2008),VLOOKUP(S8,'H&R Look Up'!$A$13:$B$20,2,TRUE),IF(AND(CE8>2009,CE8<=2191),VLOOKUP(S8,'H&R Look Up'!$E$13:$F$19,2,TRUE),IF(AND(CE8>2192,CE8<=2374),VLOOKUP(S8,'H&R Look Up'!$I$13:$J$19,2,TRUE),IF(AND(CE8>2375,CE8>=2556),VLOOKUP(S8,'H&R Look Up'!$M$13:$N$17,2,TRUE),""))))) | U8: =IF(E8="","",DATEDIF(B8,A8,"m")) -> 163
A9: 45950 | B9: 40962 | C9: 3 | E9: Lname4 | F9: Fname4 | G9: XXXXX4 | J9: =IF(E9="","",IF(AND(U9<=66),VLOOKUP(I9,'H&R Look Up'!$A$13:$B$21,2,TRUE),IF(AND(U9>=67,U9<=72),VLOOKUP(I9,'H&R Look Up'!$E$13:$F$20,2,TRUE),IF(AND(U9>=73,U9<=78),VLOOKUP(I9,'H&R Look Up'!$I$13:$J$19,2,TRUE),IF(AND(U9>=79),VLOOKUP(I9,'H&R Look Up'!$M$13:$N$18,2,TRUE),""))))) -> 1 | S9: =IF(P9="","",COUNTIF(U9:BT9,"y")) | T9: =IF(P9="","",IF(AND(CE9<=2008),VLOOKUP(S9,'H&R Look Up'!$A$13:$B$20,2,TRUE),IF(AND(CE9>2009,CE9<=2191),VLOOKUP(S9,'H&R Look Up'!$E$13:$F$19,2,TRUE),IF(AND(CE9>2192,CE9<=2374),VLOOKUP(S9,'H&R Look Up'!$I$13:$J$19,2,TRUE),IF(AND(CE9>2375,CE9>=2556),VLOOKUP(S9,'H&R Look Up'!$M$13:$N$17,2,TRUE),""))))) | U9: =IF(E9="","",DATEDIF(B9,A9,"m")) -> 163
A10: 45950 | B10: 40970 | C10: 3 | E10: ULname13 | F10: UFname13 | G10: UNLISTED | J10: =IF(E10="","",IF(AND(U10<=66),VLOOKUP(I10,'H&R Look Up'!$A$13:$B$21,2,TRUE),IF(AND(U10>=67,U10<=72),VLOOKUP(I10,'H&R Look Up'!$E$13:$F$20,2,TRUE),IF(AND(U10>=73,U10<=78),VLOOKUP(I10,'H&R Look Up'!$I$13:$J$19,2,TRUE),IF(AND(U10>=79),VLOOKUP(I10,'H&R Look Up'!$M$13:$N$18,2,TRUE),""))))) -> 1 | S10: =IF(P10="","",COUNTIF(U10:BT10,"y")) | T10: =IF(P10="","",IF(AND(CE10<=2008),VLOOKUP(S10,'H&R Look Up'!$A$13:$B$20,2,TRUE),IF(AND(CE10>2009,CE10<=2191),VLOOKUP(S10,'H&R Look Up'!$E$13:$F$19,2,TRUE),IF(AND(CE10>2192,CE10<=2374),VLOOKUP(S10,'H&R Look Up'!$I$13:$J$19,2,TRUE),IF(AND(CE10>2375,CE10>=2556),VLOOKUP(S10,'H&R Look Up'!$M$13:$N$17,2,TRUE),""))))) | U10: =IF(E10="","",DATEDIF(B10,A10,"m")) -> 163
A11: 45950 | B11: 40963 | C11: 3 | E11: Lname5 | F11: Fname5 | G11: XXXXX5 | J11: =IF(E11="","",IF(AND(U11<=66),VLOOKUP(I11,'H&R Look Up'!$A$13:$B$21,2,TRUE),IF(AND(U11>=67,U11<=72),VLOOKUP(I11,'H&R Look Up'!$E$13:$F$20,2,TRUE),IF(AND(U11>=73,U11<=78),VLOOKUP(I11,'H&R Look Up'!$I$13:$J$19,2,TRUE),IF(AND(U11>=79),VLOOKUP(I11,'H&R Look Up'!$M$13:$N$18,2,TRUE),""))))) -> 1 | S11: =IF(P11="","",COUNTIF(U11:BT11,"y")) | T11: =IF(P11="","",IF(AND(CE11<=2008),VLOOKUP(S11,'H&R Look Up'!$A$13:$B$20,2,TRUE),IF(AND(CE11>2009,CE11<=2191),VLOOKUP(S11,'H&R Look Up'!$E$13:$F$19,2,TRUE),IF(AND(CE11>2192,CE11<=2374),VLOOKUP(S11,'H&R Look Up'!$I$13:$J$19,2,TRUE),IF(AND(CE11>2375,CE11>=2556),VLOOKUP(S11,'H&R Look Up'!$M$13:$N$17,2,TRUE),""))))) | U11: =IF(E11="","",DATEDIF(B11,A11,"m")) -> 163
A12: 45950 | B12: 40964 | C12: 3 | E12: Lname6 | F12: Fname6 | G12: XXXXX6 | J12: =IF(E12="","",IF(AND(U12<=66),VLOOKUP(I12,'H&R Look Up'!$A$13:$B$21,2,TRUE),IF(AND(U12>=67,U12<=72),VLOOKUP(I12,'H&R Look Up'!$E$13:$F$20,2,TRUE),IF(AND(U12>=73,U12<=78),VLOOKUP(I12,'H&R Look Up'!$I$13:$J$19,2,TRUE),IF(AND(U12>=79),VLOOKUP(I12,'H&R Look Up'!$M$13:$N$18,2,TRUE),""))))) -> 1 | S12: =IF(P12="","",COUNTIF(U12:BT12,"y")) | T12: =IF(P12="","",IF(AND(CE12<=2008),VLOOKUP(S12,'H&R Look Up'!$A$13:$B$20,2,TRUE),IF(AND(CE12>2009,CE12<=2191),VLOOKUP(S12,'H&R Look Up'!$E$13:$F$19,2,TRUE),IF(AND(CE12>2192,CE12<=2374),VLOOKUP(S12,'H&R Look Up'!$I$13:$J$19,2,TRUE),IF(AND(CE12>2375,CE12>=2556),VLOOKUP(S12,'H&R Look Up'!$M$13:$N$17,2,TRUE),""))))) | U12: =IF(E12="","",DATEDIF(B12,A12,"m")) -> 163
A13: 45950 | B13: 40965 | C13: 3 | E13: Lname7 | F13: Fname7 | G13: XXXXX7 | J13: =IF(E13="","",IF(AND(U13<=66),VLOOKUP(I13,'H&R Look Up'!$A$13:$B$21,2,TRUE),IF(AND(U13>=67,U13<=72),VLOOKUP(I13,'H&R Look Up'!$E$13:$F$20,2,TRUE),IF(AND(U13>=73,U13<=78),VLOOKUP(I13,'H&R Look Up'!$I$13:$J$19,2,TRUE),IF(AND(U13>=79),VLOOKUP(I13,'H&R Look Up'!$M$13:$N$18,2,TRUE),""))))) -> 1 | S13: =IF(P13="","",COUNTIF(U13:BT13,"y")) | T13: =IF(P13="","",IF(AND(CE13<=2008),VLOOKUP(S13,'H&R Look Up'!$A$13:$B$20,2,TRUE),IF(AND(CE13>2009,CE13<=2191),VLOOKUP(S13,'H&R Look Up'!$E$13:$F$19,2,TRUE),IF(AND(CE13>2192,CE13<=2374),VLOOKUP(S13,'H&R Look Up'!$I$13:$J$19,2,TRUE),IF(AND(CE13>2375,CE13>=2556),VLOOKUP(S13,'H&R Look Up'!$M$13:$N$17,2,TRUE),""))))) | U13: =IF(E13="","",DATEDIF(B13,A13,"m")) -> 163
A14: 45950 | B14: 40966 | C14: 3 | E14: Lname8 | F14: Fname8 | G14: XXXXX8 | J14: =IF(E14="","",IF(AND(U14<=66),VLOOKUP(I14,'H&R Look Up'!$A$13:$B$21,2,TRUE),IF(AND(U14>=67,U14<=72),VLOOKUP(I14,'H&R Look Up'!$E$13:$F$20,2,TRUE),IF(AND(U14>=73,U14<=78),VLOOKUP(I14,'H&R Look Up'!$I$13:$J$19,2,TRUE),IF(AND(U14>=79),VLOOKUP(I14,'H&R Look Up'!$M$13:$N$18,2,TRUE),""))))) -> 1 | S14: =IF(P14="","",COUNTIF(U14:BT14,"y")) | T14: =IF(P14="","",IF(AND(CE14<=2008),VLOOKUP(S14,'H&R Look Up'!$A$13:$B$20,2,TRUE),IF(AND(CE14>2009,CE14<=2191),VLOOKUP(S14,'H&R Look Up'!$E$13:$F$19,2,TRUE),IF(AND(CE14>2192,CE14<=2374),VLOOKUP(S14,'H&R Look Up'!$I$13:$J$19,2,TRUE),IF(AND(CE14>2375,CE14>=2556),VLOOKUP(S14,'H&R Look Up'!$M$13:$N$17,2,TRUE),""))))) | U14: =IF(E14="","",DATEDIF(B14,A14,"m")) -> 163
A15: 45950 | B15: 40967 | C15: 3 | E15: Lname9 | F15: Fname9 | G15: XXXXX9 | J15: =IF(E15="","",IF(AND(U15<=66),VLOOKUP(I15,'H&R Look Up'!$A$13:$B$21,2,TRUE),IF(AND(U15>=67,U15<=72),VLOOKUP(I15,'H&R Look Up'!$E$13:$F$20,2,TRUE),IF(AND(U15>=73,U15<=78),VLOOKUP(I15,'H&R Look Up'!$I$13:$J$19,2,TRUE),IF(AND(U15>=79),VLOOKUP(I15,'H&R Look Up'!$M$13:$N$18,2,TRUE),""))))) -> 1 | S15: =IF(P15="","",COUNTIF(U15:BT15,"y")) | T15: =IF(P15="","",IF(AND(CE15<=2008),VLOOKUP(S15,'H&R Look Up'!$A$13:$B$20,2,TRUE),IF(AND(CE15>2009,CE15<=2191),VLOOKUP(S15,'H&R Look Up'!$E$13:$F$19,2,TRUE),IF(AND(CE15>2192,CE15<=2374),VLOOKUP(S15,'H&R Look Up'!$I$13:$J$19,2,TRUE),IF(AND(CE15>2375,CE15>=2556),VLOOKUP(S15,'H&R Look Up'!$M$13:$N$17,2,TRUE),""))))) | U15: =IF(E15="","",DATEDIF(B15,A15,"m")) -> 163
A16: 45950 | B16: 40968 | C16: 3 | E16: Lname10 | F16: Fname10 | G16: XXXXX10 | J16: =IF(E16="","",IF(AND(U16<=66),VLOOKUP(I16,'H&R Look Up'!$A$13:$B$21,2,TRUE),IF(AND(U16>=67,U16<=72),VLOOKUP(I16,'H&R Look Up'!$E$13:$F$20,2,TRUE),IF(AND(U16>=73,U16<=78),VLOOKUP(I16,'H&R Look Up'!$I$13:$J$19,2,TRUE),IF(AND(U16>=79),VLOOKUP(I16,'H&R Look Up'!$M$13:$N$18,2,TRUE),""))))) -> 1 | S16: =IF(P16="","",COUNTIF(U16:BT16,"y")) | T16: =IF(P16="","",IF(AND(CE16<=2008),VLOOKUP(S16,'H&R Look Up'!$A$13:$B$20,2,TRUE),IF(AND(CE16>2009,CE16<=2191),VLOOKUP(S16,'H&R Look Up'!$E$13:$F$19,2,TRUE),IF(AND(CE16>2192,CE16<=2374),VLOOKUP(S16,'H&R Look Up'!$I$13:$J$19,2,TRUE),IF(AND(CE16>2375,CE16>=2556),VLOOKUP(S16,'H&R Look Up'!$M$13:$N$17,2,TRUE),""))))) | U16: =IF(E16="","",DATEDIF(B16,A16,"m")) -> 163
J17: =IF(E17="","",IF(AND(U17<=66),VLOOKUP(I17,'H&R Look Up'!$A$13:$B$21,2,TRUE),IF(AND(U17>=67,U17<=72),VLOOKUP(I17,'H&R Look Up'!$E$13:$F$20,2,TRUE),IF(AND(U17>=73,U17<=78),VLOOKUP(I17,'H&R Look Up'!$I$13:$J$19,2,TRUE),IF(AND(U17>=79),VLOOKUP(I17,'H&R Look Up'!$M$13:$N$18,2,TRUE),""))))) | S17: =IF(P17="","",COUNTIF(U17:BT17,"y")) | T17: =IF(P17="","",IF(AND(CE17<=2008),VLOOKUP(S17,'H&R Look Up'!$A$13:$B$20,2,TRUE),IF(AND(CE17>2009,CE17<=2191),VLOOKUP(S17,'H&R Look Up'!$E$13:$F$19,2,TRUE),IF(AND(CE17>2192,CE17<=2374),VLOOKUP(S17,'H&R Look Up'!$I$13:$J$19,2,TRUE),IF(AND(CE17>2375,CE17>=2556),VLOOKUP(S17,'H&R Look Up'!$M$13:$N$17,2,TRUE),""))))) | U17: =IF(E17="","",DATEDIF(B17,A17,"m"))
J18: =IF(E18="","",IF(AND(U18<=66),VLOOKUP(I18,'H&R Look Up'!$A$13:$B$21,2,TRUE),IF(AND(U18>=67,U18<=72),VLOOKUP(I18,'H&R Look Up'!$E$13:$F$20,2,TRUE),IF(AND(U18>=73,U18<=78),VLOOKUP(I18,'H&R Look Up'!$I$13:$J$19,2,TRUE),IF(AND(U18>=79),VLOOKUP(I18,'H&R Look Up'!$M$13:$N$18,2,TRUE),""))))) | U18: =IF(E18="","",DATEDIF(B18,A18,"m"))
J19: =IF(E19="","",IF(AND(U19<=66),VLOOKUP(I19,'H&R Look Up'!$A$13:$B$21,2,TRUE),IF(AND(U19>=67,U19<=72),VLOOKUP(I19,'H&R Look Up'!$E$13:$F$20,2,TRUE),IF(AND(U19>=73,U19<=78),VLOOKUP(I19,'H&R Look Up'!$I$13:$J$19,2,TRUE),IF(AND(U19>=79),VLOOKUP(I19,'H&R Look Up'!$M$13:$N$18,2,TRUE),""))))) | U19: =IF(E19="","",DATEDIF(B19,A19,"m"))
J20: =IF(E20="","",IF(AND(U20<=66),VLOOKUP(I20,'H&R Look Up'!$A$13:$B$21,2,TRUE),IF(AND(U20>=67,U20<=72),VLOOKUP(I20,'H&R Look Up'!$E$13:$F$20,2,TRUE),IF(AND(U20>=73,U20<=78),VLOOKUP(I20,'H&R Look Up'!$I$13:$J$19,2,TRUE),IF(AND(U20>=79),VLOOKUP(I20,'H&R Look Up'!$M$13:$N$18,2,TRUE),""))))) | U20: =IF(E20="","",DATEDIF(B20,A20,"m"))
J21: =IF(E21="","",IF(AND(U21<=66),VLOOKUP(I21,'H&R Look Up'!$A$13:$B$21,2,TRUE),IF(AND(U21>=67,U21<=72),VLOOKUP(I21,'H&R Look Up'!$E$13:$F$20,2,TRUE),IF(AND(U21>=73,U21<=78),VLOOKUP(I21,'H&R Look Up'!$I$13:$J$19,2,TRUE),IF(AND(U21>=79),VLOOKUP(I21,'H&R Look Up'!$M$13:$N$18,2,TRUE),""))))) | U21: =IF(E21="","",DATEDIF(B21,A21,"m"))
J22: =IF(E22="","",IF(AND(U22<=66),VLOOKUP(I22,'H&R Look Up'!$A$13:$B$21,2,TRUE),IF(AND(U22>=67,U22<=72),VLOOKUP(I22,'H&R Look Up'!$E$13:$F$20,2,TRUE),IF(AND(U22>=73,U22<=78),VLOOKUP(I22,'H&R Look Up'!$I$13:$J$19,2,TRUE),IF(AND(U22>=79),VLOOKUP(I22,'H&R Look Up'!$M$13:$N$18,2,TRUE),""))))) | U22: =IF(E22="","",DATEDIF(B22,A22,"m"))
J23: =IF(E23="","",IF(AND(U23<=66),VLOOKUP(I23,'H&R Look Up'!$A$13:$B$21,2,TRUE),IF(AND(U23>=67,U23<=72),VLOOKUP(I23,'H&R Look Up'!$E$13:$F$20,2,TRUE),IF(AND(U23>=73,U23<=78),VLOOKUP(I23,'H&R Look Up'!$I$13:$J$19,2,TRUE),IF(AND(U23>=79),VLOOKUP(I23,'H&R Look Up'!$M$13:$N$18,2,TRUE),""))))) | U23: =IF(E23="","",DATEDIF(B23,A23,"m"))
J24: =IF(E24="","",IF(AND(U24<=66),VLOOKUP(I24,'H&R Look Up'!$A$13:$B$21,2,TRUE),IF(AND(U24>=67,U24<=72),VLOOKUP(I24,'H&R Look Up'!$E$13:$F$20,2,TRUE),IF(AND(U24>=73,U24<=78),VLOOKUP(I24,'H&R Look Up'!$I$13:$J$19,2,TRUE),IF(AND(U24>=79),VLOOKUP(I24,'H&R Look Up'!$M$13:$N$18,2,TRUE),""))))) | U24: =IF(E24="","",DATEDIF(B24,A24,"m"))
J25: =IF(E25="","",IF(AND(U25<=66),VLOOKUP(I25,'H&R Look Up'!$A$13:$B$21,2,TRUE),IF(AND(U25>=67,U25<=72),VLOOKUP(I25,'H&R Look Up'!$E$13:$F$20,2,TRUE),IF(AND(U25>=73,U25<=78),VLOOKUP(I25,'H&R Look Up'!$I$13:$J$19,2,TRUE),IF(AND(U25>=79),VLOOKUP(I25,'H&R Look Up'!$M$13:$N$18,2,TRUE),""))))) | U25: =IF(E25="","",DATEDIF(B25,A25,"m"))
J26: =IF(E26="","",IF(AND(U26<=66),VLOOKUP(I26,'H&R Look Up'!$A$13:$B$21,2,TRUE),IF(AND(U26>=67,U26<=72),VLOOKUP(I26,'H&R Look Up'!$E$13:$F$20,2,TRUE),IF(AND(U26>=73,U26<=78),VLOOKUP(I26,'H&R Look Up'!$I$13:$J$19,2,TRUE),IF(AND(U26>=79),VLOOKUP(I26,'H&R Look Up'!$M$13:$N$18,2,TRUE),""))))) | U26: =IF(E26="","",DATEDIF(B26,A26,"m"))
J27: =IF(E27="","",IF(AND(U27<=66),VLOOKUP(I27,'H&R Look Up'!$A$13:$B$21,2,TRUE),IF(AND(U27>=67,U27<=72),VLOOKUP(I27,'H&R Look Up'!$E$13:$F$20,2,TRUE),IF(AND(U27>=73,U27<=78),VLOOKUP(I27,'H&R Look Up'!$I$13:$J$19,2,TRUE),IF(AND(U27>=79),VLOOKUP(I27,'H&R Look Up'!$M$13:$N$18,2,TRUE),""))))) | U27: =IF(E27="","",DATEDIF(B27,A27,"m"))
J28: =IF(E28="","",IF(AND(U28<=66),VLOOKUP(I28,'H&R Look Up'!$A$13:$B$21,2,TRUE),IF(AND(U28>=67,U28<=72),VLOOKUP(I28,'H&R Look Up'!$E$13:$F$20,2,TRUE),IF(AND(U28>=73,U28<=78),VLOOKUP(I28,'H&R Look Up'!$I$13:$J$19,2,TRUE),IF(AND(U28>=79),VLOOKUP(I28,'H&R Look Up'!$M$13:$N$18,2,TRUE),""))))) | U28: =IF(E28="","",DATEDIF(B28,A28,"m"))
J29: =IF(E29="","",IF(AND(U29<=66),VLOOKUP(I29,'H&R Look Up'!$A$13:$B$21,2,TRUE),IF(AND(U29>=67,U29<=72),VLOOKUP(I29,'H&R Look Up'!$E$13:$F$20,2,TRUE),IF(AND(U29>=73,U29<=78),VLOOKUP(I29,'H&R Look Up'!$I$13:$J$19,2,TRUE),IF(AND(U29>=79),VLOOKUP(I29,'H&R Look Up'!$M$13:$N$18,2,TRUE),""))))) | U29: =IF(E29="","",DATEDIF(B29,A29,"m"))
... J500: =IF(E500="","",IF(AND(U500<=66),VLOOKUP(I500,'H&R Look Up'!$A$13:$B$21,2,TRUE),IF(AND(U500>=67,U500<=72),VLOOKUP(I500,'H&R Look Up'!$E$13:$F$20,2,TRUE),IF(AND(U500>=73,U500<=78),VLOOKUP(I500,'H&R Look Up'!$I$13:$J$19,2,TRUE),IF(AND(U500>=79),VLOOKUP(I500,'H&R Look Up'!$M$13:$N$18,2,TRUE),""))))) | U500: =IF(E500="","",DATEDIF(B500,A500,"m"))

Sheet H&R Look Up
A9: Hearing & Recording Sounds
A11: Hearing & Recording Sounds 5.00-5.5 years <=66 months | E11: Hearing & Recording Sounds 5.51-6.00 years 67-72 months | I11: Hearing & Recording Sounds 6.01-6.5 years 73-78 months | M11: Hearing & Recording Sounds6.51-7 years >=79 months
A12: Test Score | B12: Stanine Group | E12: Test Score | F12: Stanine Group | I12: Test Score | J12: Stanine Group | M12: Test Score | N12: Stanine Group
A13: 0 | B13: 1 | E13: 0 | F13: 1 | I13: 0 | J13: 1 | M13: 0 | N13: 1
A14: 1 | B14: 2 | E14: 2 | F14: 2 | I14: 9 | J14: 2 | M14: 15 | N14: 2
A15: 2 | B15: 3 | E15: 8 | F15: 3 | I15: 20 | J15: 3 | M15: 29 | N15: 3
A16: 5 | B16: 4 | E16: 16 | F16: 4 | I16: 28 | J16: 4 | M16: 33 | N16: 4
A17: 12 | B17: 5 | E17: 23 | F17: 5 | I17: 33 | J17: 5 | M17: 36 | N17: 5
A18: 19 | B18: 6 | E18: 30 | F18: 6 | I18: 36 | J18: 6 | M18: 37 | N18: 6-9
A19: 27 | B19: 7 | E19: 34 | F19: 7 | I19: 37 | J19: 7-9
A20: 34 | B20: 8 | E20: 37 | F20: 8-9
A21: 37 | B21: 9

Sheet Word_Reading_List A
F1: Word Reading List A
J3: Question No., Word and Answer Key Fill in the required fields and mark either a 'Y' or a 'N' against each of the words. The template will then calculate the total number of words correct and a stanine score for the child.
H4: Question Number | J4: 1 | K4: 2 | L4: 3 | M4: 4 | N4: 5 | O4: 6 | P4: 7 | Q4: 8 | R4: 9 | S4: 10 | T4: 11 | U4: 12 | V4: 13 | W4: 14 | X4: 15
H5: List A Words | J5: I | K5: Mother | L5: are | M5: here | N5: me | O5: shouted | P5: am | Q5: with | R5: car | S5: children | T5: help | U5: not | V5: too | W5: meet | X5: away
A6: required | B6: required | C6: required | E6: required | F6: required | G6: required
A7: Date (dd/mm/yy) | B7: DOB | C7: Yr_Lev | D7: HG | E7: Surname | F7: First_Name | G7: Student ID | H7: Total Score | I7: Stanine Score | J7: Y | K7: Y | L7: Y | M7: Y | N7: Y | O7: Y | P7: Y | Q7: Y | R7: Y | S7: Y | T7: Y | U7: Y | V7: Y | W7: Y | X7: Y | Y7: =COUNTIF(J7:X7,"y") -> 15 | Z7: (Total) | AI7: Age at test
A8: 45950 | B8: 40959 | C8: 3 | E8: Lname1 | F8: Fname1 | G8: XXXXX1 | H8: =IF(E8="","",COUNTIF(J8:X8,"y")) -> 0 | I8: =IF(H8="","",IF(AND(AI8<=66),VLOOKUP(H8,'WordRead Look Up'!$A$13:$B$20,2,TRUE),IF(AND(AI8>=67,AI8<=72),VLOOKUP(H8,'WordRead Look Up'!$E$13:$F$20,2,TRUE),IF(AND(AI8>=73,AI8<=78),VLOOKUP(H8,'WordRead Look Up'!$I$13:$J$18,2,TRUE),IF(AND(AI8>=79),VLOOKUP(H8,'WordRead Look Up'!$M$13:$N$18,2,TRUE),""))))) -> 1 | AI8: =IF(E8="","",DATEDIF(B8,A8,"m")) -> 164
A9: 45950 | B9: 40960 | C9: 3 | E9: Lname2 | F9: Fname2 | G9: XXXXX2 | H9: =IF(E9="","",COUNTIF(J9:X9,"y")) -> 0 | I9: =IF(H9="","",IF(AND(AI9<=66),VLOOKUP(H9,'WordRead Look Up'!$A$13:$B$20,2,TRUE),IF(AND(AI9>=67,AI9<=72),VLOOKUP(H9,'WordRead Look Up'!$E$13:$F$20,2,TRUE),IF(AND(AI9>=73,AI9<=78),VLOOKUP(H9,'WordRead Look Up'!$I$13:$J$18,2,TRUE),IF(AND(AI9>=79),VLOOKUP(H9,'WordRead Look Up'!$M$13:$N$18,2,TRUE),""))))) -> 1 | AI9: =IF(E9="","",DATEDIF(B9,A9,"m")) -> 163
A10: 45950 | B10: 40961 | C10: 3 | E10: Lname3 | F10: Fname3 | G10: XXXXX3 | H10: =IF(E10="","",COUNTIF(J10:X10,"y")) -> 0 | I10: =IF(H10="","",IF(AND(AI10<=66),VLOOKUP(H10,'WordRead Look Up'!$A$13:$B$20,2,TRUE),IF(AND(AI10>=67,AI10<=72),VLOOKUP(H10,'WordRead Look Up'!$E$13:$F$20,2,TRUE),IF(AND(AI10>=73,AI10<=78),VLOOKUP(H10,'WordRead Look Up'!$I$13:$J$18,2,TRUE),IF(AND(AI10>=79),VLOOKUP(H10,'WordRead Look Up'!$M$13:$N$18,2,TRUE),""))))) -> 1 | AI10: =IF(E10="","",DATEDIF(B10,A10,"m")) -> 163
A11: 45950 | B11: 40962 | C11: 3 | E11: Lname4 | F11: Fname4 | G11: XXXXX4 | H11: =IF(E11="","",COUNTIF(J11:X11,"y")) -> 0 | I11: =IF(H11="","",IF(AND(AI11<=66),VLOOKUP(H11,'WordRead Look Up'!$A$13:$B$20,2,TRUE),IF(AND(AI11>=67,AI11<=72),VLOOKUP(H11,'WordRead Look Up'!$E$13:$F$20,2,TRUE),IF(AND(AI11>=73,AI11<=78),VLOOKUP(H11,'WordRead Look Up'!$I$13:$J$18,2,TRUE),IF(AND(AI11>=79),VLOOKUP(H11,'WordRead Look Up'!$M$13:$N$18,2,TRUE),""))))) -> 1 | AI11: =IF(E11="","",DATEDIF(B11,A11,"m")) -> 163
A12: 45950 | B12: 40970 | C12: 3 | E12: ULname13 | F12: UFname13 | G12: UNLISTED | H12: =IF(E12="","",COUNTIF(J12:X12,"y")) -> 0 | I12: =IF(H12="","",IF(AND(AI12<=66),VLOOKUP(H12,'WordRead Look Up'!$A$13:$B$20,2,TRUE),IF(AND(AI12>=67,AI12<=72),VLOOKUP(H12,'WordRead Look Up'!$E$13:$F$20,2,TRUE),IF(AND(AI12>=73,AI12<=78),VLOOKUP(H12,'WordRead Look Up'!$I$13:$J$18,2,TRUE),IF(AND(AI12>=79),VLOOKUP(H12,'WordRead Look Up'!$M$13:$N$18,2,TRUE),""))))) -> 1 | AI12: =IF(E12="","",DATEDIF(B12,A12,"m")) -> 163
A13: 45950 | B13: 40963 | C13: 3 | E13: Lname5 | F13: Fname5 | G13: XXXXX5 | H13: =IF(E13="","",COUNTIF(J13:X13,"y")) -> 0 | I13: =IF(H13="","",IF(AND(AI13<=66),VLOOKUP(H13,'WordRead Look Up'!$A$13:$B$20,2,TRUE),IF(AND(AI13>=67,AI13<=72),VLOOKUP(H13,'WordRead Look Up'!$E$13:$F$20,2,TRUE),IF(AND(AI13>=73,AI13<=78),VLOOKUP(H13,'WordRead Look Up'!$I$13:$J$18,2,TRUE),IF(AND(AI13>=79),VLOOKUP(H13,'WordRead Look Up'!$M$13:$N$18,2,TRUE),""))))) -> 1 | AI13: =IF(E13="","",DATEDIF(B13,A13,"m")) -> 163
A14: 45950 | B14: 40964 | C14: 3 | E14: Lname6 | F14: Fname6 | G14: XXXXX6 | H14: =IF(E14="","",COUNTIF(J14:X14,"y")) -> 0 | I14: =IF(H14="","",IF(AND(AI14<=66),VLOOKUP(H14,'WordRead Look Up'!$A$13:$B$20,2,TRUE),IF(AND(AI14>=67,AI14<=72),VLOOKUP(H14,'WordRead Look Up'!$E$13:$F$20,2,TRUE),IF(AND(AI14>=73,AI14<=78),VLOOKUP(H14,'WordRead Look Up'!$I$13:$J$18,2,TRUE),IF(AND(AI14>=79),VLOOKUP(H14,'WordRead Look Up'!$M$13:$N$18,2,TRUE),""))))) -> 1 | AI14: =IF(E14="","",DATEDIF(B14,A14,"m")) -> 163
A15: 45950 | B15: 40965 | C15: 3 | E15: Lname7 | F15: Fname7 | G15: XXXXX7 | H15: =IF(E15="","",COUNTIF(J15:X15,"y")) -> 0 | I15: =IF(H15="","",IF(AND(AI15<=66),VLOOKUP(H15,'WordRead Look Up'!$A$13:$B$20,2,TRUE),IF(AND(AI15>=67,AI15<=72),VLOOKUP(H15,'WordRead Look Up'!$E$13:$F$20,2,TRUE),IF(AND(AI15>=73,AI15<=78),VLOOKUP(H15,'WordRead Look Up'!$I$13:$J$18,2,TRUE),IF(AND(AI15>=79),VLOOKUP(H15,'WordRead Look Up'!$M$13:$N$18,2,TRUE),""))))) -> 1 | AI15: =IF(E15="","",DATEDIF(B15,A15,"m")) -> 163
A16: 45950 | B16: 40966 | C16: 3 | E16: Lname8 | F16: Fname8 | G16: XXXXX8 | H16: =IF(E16="","",COUNTIF(J16:X16,"y")) -> 0 | I16: =IF(H16="","",IF(AND(AI16<=66),VLOOKUP(H16,'WordRead Look Up'!$A$13:$B$20,2,TRUE),IF(AND(AI16>=67,AI16<=72),VLOOKUP(H16,'WordRead Look Up'!$E$13:$F$20,2,TRUE),IF(AND(AI16>=73,AI16<=78),VLOOKUP(H16,'WordRead Look Up'!$I$13:$J$18,2,TRUE),IF(AND(AI16>=79),VLOOKUP(H16,'WordRead Look Up'!$M$13:$N$18,2,TRUE),""))))) -> 1 | AI16: =IF(E16="","",DATEDIF(B16,A16,"m")) -> 163
A17: 45950 | B17: 40967 | C17: 3 | E17: Lname9 | F17: Fname9 | G17: XXXXX9 | H17: =IF(E17="","",COUNTIF(J17:X17,"y")) -> 0 | I17: =IF(H17="","",IF(AND(AI17<=66),VLOOKUP(H17,'WordRead Look Up'!$A$13:$B$20,2,TRUE),IF(AND(AI17>=67,AI17<=72),VLOOKUP(H17,'WordRead Look Up'!$E$13:$F$20,2,TRUE),IF(AND(AI17>=73,AI17<=78),VLOOKUP(H17,'WordRead Look Up'!$I$13:$J$18,2,TRUE),IF(AND(AI17>=79),VLOOKUP(H17,'WordRead Look Up'!$M$13:$N$18,2,TRUE),""))))) -> 1 | AI17: =IF(E17="","",DATEDIF(B17,A17,"m")) -> 163
A18: 45950 | B18: 40968 | C18: 3 | E18: Lname10 | F18: Fname10 | G18: XXXXX10 | H18: =IF(E18="","",COUNTIF(J18:X18,"y")) -> 0 | I18: =IF(H18="","",IF(AND(AI18<=66),VLOOKUP(H18,'WordRead Look Up'!$A$13:$B$20,2,TRUE),IF(AND(AI18>=67,AI18<=72),VLOOKUP(H18,'WordRead Look Up'!$E$13:$F$20,2,TRUE),IF(AND(AI18>=73,AI18<=78),VLOOKUP(H18,'WordRead Look Up'!$I$13:$J$18,2,TRUE),IF(AND(AI18>=79),VLOOKUP(H18,'WordRead Look Up'!$M$13:$N$18,2,TRUE),""))))) -> 1 | AI18: =IF(E18="","",DATEDIF(B18,A18,"m")) -> 163
H19: =IF(E19="","",COUNTIF(J19:X19,"y")) | I19: =IF(H19="","",IF(AND(AI19<=66),VLOOKUP(H19,'WordRead Look Up'!$A$13:$B$20,2,TRUE),IF(AND(AI19>=67,AI19<=72),VLOOKUP(H19,'WordRead Look Up'!$E$13:$F$20,2,TRUE),IF(AND(AI19>=73,AI19<=78),VLOOKUP(H19,'WordRead Look Up'!$I$13:$J$18,2,TRUE),IF(AND(AI19>=79),VLOOKUP(H19,'WordRead Look Up'!$M$13:$N$18,2,TRUE),""))))) | AG19: =IF(AD19="","",COUNTIF(AI19:CH19,"y")) | AH19: =IF(AD19="","",IF(AND(CS19<=2008),VLOOKUP(AG19,'WordRead Look Up'!$A$13:$B$20,2,TRUE),IF(AND(CS19>2009,CS19<=2191),VLOOKUP(AG19,'WordRead Look Up'!$E$13:$F$19,2,TRUE),IF(AND(CS19>2192,CS19<=2374),VLOOKUP(AG19,'WordRead Look Up'!$I$13:$J$19,2,TRUE),IF(AND(CS19>2375,CS19>=2556),VLOOKUP(AG19,'WordRead Look Up'!$M$13:$N$17,2,TRUE),""))))) | AI19: =IF(E19="","",DATEDIF(B19,A19,"m"))
H20: =IF(E20="","",COUNTIF(J20:X20,"y")) | I20: =IF(H20="","",IF(AND(AI20<=66),VLOOKUP(H20,'WordRead Look Up'!$A$13:$B$20,2,TRUE),IF(AND(AI20>=67,AI20<=72),VLOOKUP(H20,'WordRead Look Up'!$E$13:$F$20,2,TRUE),IF(AND(AI20>=73,AI20<=78),VLOOKUP(H20,'WordRead Look Up'!$I$13:$J$18,2,TRUE),IF(AND(AI20>=79),VLOOKUP(H20,'WordRead Look Up'!$M$13:$N$18,2,TRUE),""))))) | AI20: =IF(E20="","",DATEDIF(B20,A20,"m"))
H21: =IF(E21="","",COUNTIF(J21:X21,"y")) | I21: =IF(H21="","",IF(AND(AI21<=66),VLOOKUP(H21,'WordRead Look Up'!$A$13:$B$20,2,TRUE),IF(AND(AI21>=67,AI21<=72),VLOOKUP(H21,'WordRead Look Up'!$E$13:$F$20,2,TRUE),IF(AND(AI21>=73,AI21<=78),VLOOKUP(H21,'WordRead Look Up'!$I$13:$J$18,2,TRUE),IF(AND(AI21>=79),VLOOKUP(H21,'WordRead Look Up'!$M$13:$N$18,2,TRUE),""))))) | AI21: =IF(E21="","",DATEDIF(B21,A21,"m"))
H22: =IF(E22="","",COUNTIF(J22:X22,"y")) | I22: =IF(H22="","",IF(AND(AI22<=66),VLOOKUP(H22,'WordRead Look Up'!$A$13:$B$20,2,TRUE),IF(AND(AI22>=67,AI22<=72),VLOOKUP(H22,'WordRead Look Up'!$E$13:$F$20,2,TRUE),IF(AND(AI22>=73,AI22<=78),VLOOKUP(H22,'WordRead Look Up'!$I$13:$J$18,2,TRUE),IF(AND(AI22>=79),VLOOKUP(H22,'WordRead Look Up'!$M$13:$N$18,2,TRUE),""))))) | AI22: =IF(E22="","",DATEDIF(B22,A22,"m"))
H23: =IF(E23="","",COUNTIF(J23:X23,"y")) | I23: =IF(H23="","",IF(AND(AI23<=66),VLOOKUP(H23,'WordRead Look Up'!$A$13:$B$20,2,TRUE),IF(AND(AI23>=67,AI23<=72),VLOOKUP(H23,'WordRead Look Up'!$E$13:$F$20,2,TRUE),IF(AND(AI23>=73,AI23<=78),VLOOKUP(H23,'WordRead Look Up'!$I$13:$J$18,2,TRUE),IF(AND(AI23>=79),VLOOKUP(H23,'WordRead Look Up'!$M$13:$N$18,2,TRUE),""))))) | AI23: =IF(E23="","",DATEDIF(B23,A23,"m"))
H24: =IF(E24="","",COUNTIF(J24:X24,"y")) | I24: =IF(H24="","",IF(AND(AI24<=66),VLOOKUP(H24,'WordRead Look Up'!$A$13:$B$20,2,TRUE),IF(AND(AI24>=67,AI24<=72),VLOOKUP(H24,'WordRead Look Up'!$E$13:$F$20,2,TRUE),IF(AND(AI24>=73,AI24<=78),VLOOKUP(H24,'WordRead Look Up'!$I$13:$J$18,2,TRUE),IF(AND(AI24>=79),VLOOKUP(H24,'WordRead Look Up'!$M$13:$N$18,2,TRUE),""))))) | AI24: =IF(E24="","",DATEDIF(B24,A24,"m"))
H25: =IF(E25="","",COUNTIF(J25:X25,"y")) | I25: =IF(H25="","",IF(AND(AI25<=66),VLOOKUP(H25,'WordRead Look Up'!$A$13:$B$20,2,TRUE),IF(AND(AI25>=67,AI25<=72),VLOOKUP(H25,'WordRead Look Up'!$E$13:$F$20,2,TRUE),IF(AND(AI25>=73,AI25<=78),VLOOKUP(H25,'WordRead Look Up'!$I$13:$J$18,2,TRUE),IF(AND(AI25>=79),VLOOKUP(H25,'WordRead Look Up'!$M$13:$N$18,2,TRUE),""))))) | AI25: =IF(E25="","",DATEDIF(B25,A25,"m"))
H26: =IF(E26="","",COUNTIF(J26:X26,"y")) | I26: =IF(H26="","",IF(AND(AI26<=66),VLOOKUP(H26,'WordRead Look Up'!$A$13:$B$20,2,TRUE),IF(AND(AI26>=67,AI26<=72),VLOOKUP(H26,'WordRead Look Up'!$E$13:$F$20,2,TRUE),IF(AND(AI26>=73,AI26<=78),VLOOKUP(H26,'WordRead Look Up'!$I$13:$J$18,2,TRUE),IF(AND(AI26>=79),VLOOKUP(H26,'WordRead Look Up'!$M$13:$N$18,2,TRUE),""))))) | AI26: =IF(E26="","",DATEDIF(B26,A26,"m"))
H27: =IF(E27="","",COUNTIF(J27:X27,"y")) | I27: =IF(H27="","",IF(AND(AI27<=66),VLOOKUP(H27,'WordRead Look Up'!$A$13:$B$20,2,TRUE),IF(AND(AI27>=67,AI27<=72),VLOOKUP(H27,'WordRead Look Up'!$E$13:$F$20,2,TRUE),IF(AND(AI27>=73,AI27<=78),VLOOKUP(H27,'WordRead Look Up'!$I$13:$J$18,2,TRUE),IF(AND(AI27>=79),VLOOKUP(H27,'WordRead Look Up'!$M$13:$N$18,2,TRUE),""))))) | AI27: =IF(E27="","",DATEDIF(B27,A27,"m"))
H28: =IF(E28="","",COUNTIF(J28:X28,"y")) | I28: =IF(H28="","",IF(AND(AI28<=66),VLOOKUP(H28,'WordRead Look Up'!$A$13:$B$20,2,TRUE),IF(AND(AI28>=67,AI28<=72),VLOOKUP(H28,'WordRead Look Up'!$E$13:$F$20,2,TRUE),IF(AND(AI28>=73,AI28<=78),VLOOKUP(H28,'WordRead Look Up'!$I$13:$J$18,2,TRUE),IF(AND(AI28>=79),VLOOKUP(H28,'WordRead Look Up'!$M$13:$N$18,2,TRUE),""))))) | AI28: =IF(E28="","",DATEDIF(B28,A28,"m"))
H29: =IF(E29="","",COUNTIF(J29:X29,"y")) | I29: =IF(H29="","",IF(AND(AI29<=66),VLOOKUP(H29,'WordRead Look Up'!$A$13:$B$20,2,TRUE),IF(AND(AI29>=67,AI29<=72),VLOOKUP(H29,'WordRead Look Up'!$E$13:$F$20,2,TRUE),IF(AND(AI29>=73,AI29<=78),VLOOKUP(H29,'WordRead Look Up'!$I$13:$J$18,2,TRUE),IF(AND(AI29>=79),VLOOKUP(H29,'WordRead Look Up'!$M$13:$N$18,2,TRUE),""))))) | AI29: =IF(E29="","",DATEDIF(B29,A29,"m"))
H30: =IF(E30="","",COUNTIF(J30:X30,"y")) | I30: =IF(H30="","",IF(AND(AI30<=66),VLOOKUP(H30,'WordRead Look Up'!$A$13:$B$20,2,TRUE),IF(AND(AI30>=67,AI30<=72),VLOOKUP(H30,'WordRead Look Up'!$E$13:$F$20,2,TRUE),IF(AND(AI30>=73,AI30<=78),VLOOKUP(H30,'WordRead Look Up'!$I$13:$J$18,2,TRUE),IF(AND(AI30>=79),VLOOKUP(H30,'WordRead Look Up'!$M$13:$N$18,2,TRUE),""))))) | AI30: =IF(E30="","",DATEDIF(B30,A30,"m"))
H31: =IF(E31="","",COUNTIF(J31:X31,"y")) | I31: =IF(H31="","",IF(AND(AI31<=66),VLOOKUP(H31,'WordRead Look Up'!$A$13:$B$20,2,TRUE),IF(AND(AI31>=67,AI31<=72),VLOOKUP(H31,'WordRead Look Up'!$E$13:$F$20,2,TRUE),IF(AND(AI31>=73,AI31<=78),VLOOKUP(H31,'WordRead Look Up'!$I$13:$J$18,2,TRUE),IF(AND(AI31>=79),VLOOKUP(H31,'WordRead Look Up'!$M$13:$N$18,2,TRUE),""))))) | AI31: =IF(E31="","",DATEDIF(B31,A31,"m"))
... H500: =IF(E500="","",COUNTIF(J500:X500,"y")) | I500: =IF(H500="","",IF(AND(AI500<=66),VLOOKUP(H500,'WordRead Look Up'!$A$13:$B$20,2,TRUE),IF(AND(AI500>=67,AI500<=72),VLOOKUP(H500,'WordRead Look Up'!$E$13:$F$20,2,TRUE),IF(AND(AI500>=73,AI500<=78),VLOOKUP(H500,'WordRead Look Up'!$I$13:$J$18,2,TRUE),IF(AND(AI500>=79),VLOOKUP(H500,'WordRead Look Up'!$M$13:$N$18,2,TRUE),""))))) | AI500: =IF(E500="","",DATEDIF(B500,A500,"m"))

Sheet Word_Reading_List B
F1: Word Reading List B
J3: Question No., Word and Answer Key Fill in the required fields and mark either a 'Y' or a 'N' against each of the words. The template will then calculate the total number of words correct and a stanine score for the child.
H4: Question Number | J4: 1 | K4: 2 | L4: 3 | M4: 4 | N4: 5 | O4: 6 | P4: 7 | Q4: 8 | R4: 9 | S4: 10 | T4: 11 | U4: 12 | V4: 13 | W4: 14 | X4: 15
H5: List B Words | J5: and | K5: to | L5: will | M5: look | N5: he | O5: up | P5: like | Q5: in | R5: where | S5: Mr | T5: going | U5: big | V5: go | W5: let | X5: on
A6: required | B6: required | C6: required | E6: required | F6: required | G6: required
A7: Date (dd/mm/yy) | B7: DOB | C7: Yr_Lev | D7: HG | E7: Surname | F7: First_Name | G7: Student ID | H7: Total Score | I7: Stanine Score | J7: Y | K7: Y | L7: Y | M7: Y | N7: Y | O7: Y | P7: Y | Q7: Y | R7: Y | S7: Y | T7: Y | U7: Y | V7: Y | W7: Y | X7: Y | Y7: =COUNTIF(J7:X7,"y") -> 15 | Z7: (Total) | AI7: Age at test
A8: 45950 | B8: 40959 | C8: 3 | E8: Lname1 | F8: Fname1 | G8: XXXXX1 | H8: =IF(E8="","",COUNTIF(J8:X8,"y")) -> 0 | I8: =IF(H8="","",IF(AND(AI8<=66),VLOOKUP(H8,'WordRead Look Up'!$A$13:$B$20,2,TRUE),IF(AND(AI8>=67,AI8<=72),VLOOKUP(H8,'WordRead Look Up'!$E$13:$F$20,2,TRUE),IF(AND(AI8>=73,AI8<=78),VLOOKUP(H8,'WordRead Look Up'!$I$13:$J$18,2,TRUE),IF(AND(AI8>=79),VLOOKUP(H8,'WordRead Look Up'!$M$13:$N$18,2,TRUE),""))))) -> 1 | AI8: =IF(E8="","",DATEDIF(B8,A8,"m")) -> 164
