Workbook

Sheet Main Menu
B2: TORCH Third Edition Scoring Templates
B4: This series of spreadsheets provide the templates required to enter ACER's TORCH 3rd Ed. (Tests of Reading Comprehension) results into the Student Performance Analyser (SPA). Click on the appropriate button (at right) to select the correct Test Booklet proforma to complete. Follow the instructions opposite. | H4: Step 1: Click on the appropriate button (at left) to select the correct Test Booklet proforma to complete. Step 2: For each student, enter the Date (when test was sat), Year Level, Home Group, Name, and Student ID (CASES No. or Student No.). Step 3: For each question, enter their response (their score will be calculated) OR enter their Raw Score OR enter their PAT Score. Step 4: Save and upload into SPA.
B40: Click here to find out more about other tests available from ACER | H40: Click here to find out more about the Student Performance Analyser

Sheet Rock Pools
A1: TORCH - Rock Pools | AK1: Item Type Key
A2: 3rd Edition
AK3: Locate
G4: QUESTION No. and ANSWER KEY (Enter the student's response - "Y" if correct, "N" if incorrect) | AK4: 1 | AL4: Directly stated: verbatim
E5: Question Number | G5: 1 | H5: 2 | I5: 3 | J5: 4 | K5: 5 | L5: 6 | M5: 7 | N5: 8 | O5: 9 | P5: 10 | Q5: 11 | R5: 12 | S5: 13 | T5: 14 | U5: 15 | V5: 16 | W5: 17 | X5: 18 | Y5: 19 | Z5: 20 | AA5: 21 | AB5: 22 | AC5: 23 | AD5: 24 | AE5: 25 | AF5: 26 | AG5: 27 | AK5: 2 | AL5: Directly stated: rephrased, reworded
E6: Item Difficulty | G6: 36 | H6: 33 | I6: 34 | J6: 34 | K6: 42 | L6: 49 | M6: 41 | N6: 42 | O6: 40 | P6: 39 | Q6: 32 | R6: 35 | S6: 34 | T6: 49 | U6: 41 | V6: 40 | W6: 43 | X6: 39 | Y6: 35 | Z6: 34 | AA6: 25 | AB6: 40 | AC6: 45 | AD6: 47 | AE6: 50 | AF6: 52 | AG6: 53 | AK6: Locate, interpret and infer
E7: Item Category | G7: Locate, Interpret and Infer | H7: Locate | I7: Locate | J7: Locate, Interpret and Infer | K7: Locate, Interpret and Infer | L7: Locate, Interpret and Infer | M7: Locate, Interpret and Infer | N7: Locate | O7: Locate | P7: Locate | Q7: Locate, Interpret and Infer | R7: Locate | S7: Locate | T7: Locate | U7: Locate | V7: Locate | W7: Locate | X7: Locate | Y7: Locate | Z7: Locate | AA7: Locate, Interpret and Infer | AB7: Locate | AC7: Locate, Interpret and Infer | AD7: Locate | AE7: Locate | AF7: Locate | AG7: Locate | AK7: 3 | AL7: Directly stated: across text
AK8: 4 | AL8: Directly stated: embedded
AK9: 5 | AL9: Inference: simple, explicit references
AK10: Interpret, infer and use
AK11: 6 | AL11: Inference: complex, multiple references, cultural values, writer's intention
E12: Item Type | G12: 3 | H12: 2 | I12: 2 | J12: 3 | K12: 3 | L12: 3 | M12: 5 | N12: 2 | O12: 1 | P12: 2 | Q12: 4 | R12: 2 | S12: 1 | T12: 2 | U12: 2 | V12: 2 | W12: 2 | X12: 2 | Y12: 2 | Z12: 1 | AA12: 5 | AB12: 2 | AC12: 4 | AD12: 2 | AE12: 2 | AF12: 2 | AG12: 2
A14: Date (dd/mm/yy) | B14: Yr_Lev | C14: HG | D14: Surname | E14: First_Name | F14: Student_ID | G14: Y | H14: Y | I14: Y | J14: Y | K14: Y | L14: Y | M14: Y | N14: Y | O14: Y | P14: Y | Q14: Y | R14: Y | S14: Y | T14: Y | U14: Y | V14: Y | W14: Y | X14: Y | Y14: Y | Z14: Y | AA14: Y | AB14: Y | AC14: Y | AD14: Y | AE14: Y | AF14: Y | AG14: Y | AH14: Raw Score | AI14: TORCH Score
A15: 45356 | B15: 3 | C15: 3A | D15: Lname1 | E15: Fname1 | F15: XXXXX1 | AH15: =IF(D15="",0,COUNTIF(G15:AG15,"Y")) -> 0 | AI15: =IF(D15="","",VLOOKUP(AH15,TorchTables!$E$1:$F$28,2,FALSE)) -> 9
A16: 45356 | B16: 3 | C16: 3A | D16: Lname2 | E16: Fname2 | F16: XXXXX2 | AH16: =IF(D16="",0,COUNTIF(G16:AG16,"Y")) -> 0 | AI16: =IF(D16="","",VLOOKUP(AH16,TorchTables!$E$1:$F$28,2,FALSE)) -> 9
A17: 45356 | B17: 3 | C17: 3A | D17: Lname3 | E17: Fname3 | F17: XXXXX3 | AH17: =IF(D17="",0,COUNTIF(G17:AG17,"Y")) -> 0 | AI17: =IF(D17="","",VLOOKUP(AH17,TorchTables!$E$1:$F$28,2,FALSE)) -> 9
A18: 45356 | B18: 3 | C18: 3A | D18: Lname4 | E18: Fname4 | F18: XXXXX4 | AH18: =IF(D18="",0,COUNTIF(G18:AG18,"Y")) -> 0 | AI18: =IF(D18="","",VLOOKUP(AH18,TorchTables!$E$1:$F$28,2,FALSE)) -> 9
A19: 45356 | B19: 3 | C19: 3B | D19: ULname13 | E19: UFname13 | F19: UNLISTED | AH19: =IF(D19="",0,COUNTIF(G19:AG19,"Y")) -> 0 | AI19: =IF(D19="","",VLOOKUP(AH19,TorchTables!$E$1:$F$28,2,FALSE)) -> 9
A20: 45356 | B20: 3 | C20: 3A | D20: Lname5 | E20: Fname5 | F20: XXXXX5 | AH20: =IF(D20="",0,COUNTIF(G20:AG20,"Y")) -> 0 | AI20: =IF(D20="","",VLOOKUP(AH20,TorchTables!$E$1:$F$28,2,FALSE)) -> 9
A21: 45356 | B21: 3 | C21: 3B | D21: Lname6 | E21: Fname6 | F21: XXXXX6 | AH21: =IF(D21="",0,COUNTIF(G21:AG21,"Y")) -> 0 | AI21: =IF(D21="","",VLOOKUP(AH21,TorchTables!$E$1:$F$28,2,FALSE)) -> 9
A22: 45356 | B22: 3 | C22: 3B | D22: Lname7 | E22: Fname7 | F22: XXXXX7 | AH22: =IF(D22="",0,COUNTIF(G22:AG22,"Y")) -> 0 | AI22: =IF(D22="","",VLOOKUP(AH22,TorchTables!$E$1:$F$28,2,FALSE)) -> 9
A23: 45356 | B23: 3 | C23: 3B | D23: Lname8 | E23: Fname8 | F23: XXXXX8 | AH23: =IF(D23="",0,COUNTIF(G23:AG23,"Y")) -> 0 | AI23: =IF(D23="","",VLOOKUP(AH23,TorchTables!$E$1:$F$28,2,FALSE)) -> 9
A24: 45356 | B24: 3 | C24: 3B | D24: Lname9 | E24: Fname9 | F24: XXXXX9 | AH24: =IF(D24="",0,COUNTIF(G24:AG24,"Y")) -> 0 | AI24: =IF(D24="","",VLOOKUP(AH24,TorchTables!$E$1:$F$28,2,FALSE)) -> 9
A25: 45356 | B25: 3 | C25: 3B | D25: Lname10 | E25: Fname10 | F25: XXXXX10 | AH25: =IF(D25="",0,COUNTIF(G25:AG25,"Y")) -> 0 | AI25: =IF(D25="","",VLOOKUP(AH25,TorchTables!$E$1:$F$28,2,FALSE)) -> 9
AH26: =IF(D26="",0,COUNTIF(G26:AG26,"Y")) -> 0 | AI26: =IF(D26="","",VLOOKUP(AH26,TorchTables!$E$1:$F$28,2,FALSE))
AH27: =IF(D27="",0,COUNTIF(G27:AG27,"Y")) -> 0 | AI27: =IF(D27="","",VLOOKUP(AH27,TorchTables!$E$1:$F$28,2,FALSE))
AH28: =IF(D28="",0,COUNTIF(G28:AG28,"Y")) -> 0 | AI28: =IF(D28="","",VLOOKUP(AH28,TorchTables!$E$1:$F$28,2,FALSE))
AH29: =IF(D29="",0,COUNTIF(G29:AG29,"Y")) -> 0 | AI29: =IF(D29="","",VLOOKUP(AH29,TorchTables!$E$1:$F$28,2,FALSE))
AH30: =IF(D30="",0,COUNTIF(G30:AG30,"Y")) -> 0 | AI30: =IF(D30="","",VLOOKUP(AH30,TorchTables!$E$1:$F$28,2,FALSE))
AH31: =IF(D31="",0,COUNTIF(G31:AG31,"Y")) -> 0 | AI31: =IF(D31="","",VLOOKUP(AH31,TorchTables!$E$1:$F$28,2,FALSE))
AH32: =IF(D32="",0,COUNTIF(G32:AG32,"Y")) -> 0 | AI32: =IF(D32="","",VLOOKUP(AH32,TorchTables!$E$1:$F$28,2,FALSE))
AH33: =IF(D33="",0,COUNTIF(G33:AG33,"Y")) -> 0 | AI33: =IF(D33="","",VLOOKUP(AH33,TorchTables!$E$1:$F$28,2,FALSE))
AH34: =IF(D34="",0,COUNTIF(G34:AG34,"Y")) -> 0 | AI34: =IF(D34="","",VLOOKUP(AH34,TorchTables!$E$1:$F$28,2,FALSE))
AH35: =IF(D35="",0,COUNTIF(G35:AG35,"Y")) -> 0 | AI35: =IF(D35="","",VLOOKUP(AH35,TorchTables!$E$1:$F$28,2,FALSE))
AH36: =IF(D36="",0,COUNTIF(G36:AG36,"Y")) -> 0 | AI36: =IF(D36="","",VLOOKUP(AH36,TorchTables!$E$1:$F$28,2,FALSE))
AH37: =IF(D37="",0,COUNTIF(G37:AG37,"Y")) -> 0 | AI37: =IF(D37="","",VLOOKUP(AH37,TorchTables!$E$1:$F$28,2,FALSE))
... AH509: =IF(D509="",0,COUNTIF(G509:AG509,"Y")) -> 0 | AI509: =IF(D509="","",VLOOKUP(AH509,TorchTables!$E$1:$F$28,2,FALSE))

Sheet Lizards
A1: TORCH - Lizards Love Eggs | AD1: Item Type Key
A2: 3rd Edition
AD3: Locate
G4: QUESTION No. and ANSWER KEY (Enter the student's response - "Y" if correct, "N" if incorrect) | AD4: 1 | AE4: Directly stated: verbatim
E5: Question Number | G5: 1 | H5: 2 | I5: 3 | J5: 4 | K5: 5 | L5: 6 | M5: 7 | N5: 8 | O5: 9 | P5: 10 | Q5: 11 | R5: 12 | S5: 13 | T5: 14 | U5: 15 | V5: 16 | W5: 17 | X5: 18 | Y5: 19 | Z5: 20 | AD5: 2 | AE5: Directly stated: rephrased, reworded
E6: Item Difficulty | G6: 21 | H6: 26 | I6: 8 | J6: 17 | K6: 22 | L6: 29 | M6: 22 | N6: 36 | O6: 30 | P6: 40 | Q6: 32 | R6: 46 | S6: 48 | T6: 31 | U6: 34 | V6: 28 | W6: 30 | X6: 30 | Y6: 35 | Z6: 20 | AD6: Locate, interpret and infer
E7: Item Category | G7: Locate | H7: Locate, Interpret and Infer | I7: Locate, Interpret and Infer | J7: Locate, Interpret and Infer | K7: Locate, Interpret and Infer | L7: Locate | M7: Locate | N7: Locate, Interpret and Infer | O7: Locate, Interpret and Infer | P7: Locate, Interpret and Infer | Q7: Locate, Interpret and Infer | R7: Locate, Interpret and Infer | S7: Locate, Interpret and Infer | T7: Locate, Interpret and Infer | U7: Locate, Interpret and Infer | V7: Locate, Interpret and Infer | W7: Locate, Interpret and Infer | X7: Locate | Y7: Locate, Interpret and Infer | Z7: Locate | AD7: 3 | AE7: Directly stated: across text
AD8: 4 | AE8: Directly stated: embedded
AD9: 5 | AE9: Inference: simple, explicit references
AD10: Interpret, infer and use
AD11: 6 | AE11: Inference: complex, multiple references, cultural values, writer's intention
E12: Item Type | G12: 2 | H12: 5 | I12: 3 | J12: 3 | K12: 5 | L12: 1 | M12: 2 | N12: 5 | O12: 5 | P12: 5 | Q12: 5 | R12: 5 | S12: 3 | T12: 5 | U12: 3 | V12: 3 | W12: 3 | X12: 2 | Y12: 5 | Z12: 2
A14: Date (dd/mm/yy) | B14: Yr_Lev | C14: HG | D14: Surname | E14: First_Name | F14: Student_ID | G14: Y | H14: Y | I14: Y | J14: Y | K14: Y | L14: Y | M14: Y | N14: Y | O14: Y | P14: Y | Q14: Y | R14: Y | S14: Y | T14: Y | U14: Y | V14: Y | W14: Y | X14: Y | Y14: Y | Z14: Y | AA14: Raw Score | AB14: TORCH Score
A15: 45356 | B15: 3 | C15: 3A | D15: Lname1 | E15: Fname1 | F15: XXXXX1 | AA15: =IF(D15="",0,COUNTIF(G15:Z15,"Y")) -> 0 | AB15: =IF(D15="","",VLOOKUP(AA15,TorchTables!$A$1:$B$21,2,FALSE)) -> -3.3
A16: 45356 | B16: 3 | C16: 3A | D16: Lname2 | E16: Fname2 | F16: XXXXX2 | AA16: =IF(D16="",0,COUNTIF(G16:Z16,"Y")) -> 0 | AB16: =IF(D16="","",VLOOKUP(AA16,TorchTables!$A$1:$B$21,2,FALSE)) -> -3.3
A17: 45356 | B17: 3 | C17: 3A | D17: Lname3 | E17: Fname3 | F17: XXXXX3 | AA17: =IF(D17="",0,COUNTIF(G17:Z17,"Y")) -> 0 | AB17: =IF(D17="","",VLOOKUP(AA17,TorchTables!$A$1:$B$21,2,FALSE)) -> -3.3
A18: 45356 | B18: 3 | C18: 3A | D18: Lname4 | E18: Fname4 | F18: XXXXX4 | AA18: =IF(D18="",0,COUNTIF(G18:Z18,"Y")) -> 0 | AB18: =IF(D18="","",VLOOKUP(AA18,TorchTables!$A$1:$B$21,2,FALSE)) -> -3.3
A19: 45356 | B19: 3 | C19: 3B | D19: ULname13 | E19: UFname13 | F19: UNLISTED | AA19: =IF(D19="",0,COUNTIF(G19:Z19,"Y")) -> 0 | AB19: =IF(D19="","",VLOOKUP(AA19,TorchTables!$A$1:$B$21,2,FALSE)) -> -3.3
A20: 45356 | B20: 3 | C20: 3A | D20: Lname5 | E20: Fname5 | F20: XXXXX5 | AA20: =IF(D20="",0,COUNTIF(G20:Z20,"Y")) -> 0 | AB20: =IF(D20="","",VLOOKUP(AA20,TorchTables!$A$1:$B$21,2,FALSE)) -> -3.3
A21: 45356 | B21: 3 | C21: 3B | D21: Lname6 | E21: Fname6 | F21: XXXXX6 | AA21: =IF(D21="",0,COUNTIF(G21:Z21,"Y")) -> 0 | AB21: =IF(D21="","",VLOOKUP(AA21,TorchTables!$A$1:$B$21,2,FALSE)) -> -3.3
A22: 45356 | B22: 3 | C22: 3B | D22: Lname7 | E22: Fname7 | F22: XXXXX7 | AA22: =IF(D22="",0,COUNTIF(G22:Z22,"Y")) -> 0 | AB22: =IF(D22="","",VLOOKUP(AA22,TorchTables!$A$1:$B$21,2,FALSE)) -> -3.3
A23: 45356 | B23: 3 | C23: 3B | D23: Lname8 | E23: Fname8 | F23: XXXXX8 | AA23: =IF(D23="",0,COUNTIF(G23:Z23,"Y")) -> 0 | AB23: =IF(D23="","",VLOOKUP(AA23,TorchTables!$A$1:$B$21,2,FALSE)) -> -3.3
A24: 45356 | B24: 3 | C24: 3B | D24: Lname9 | E24: Fname9 | F24: XXXXX9 | AA24: =IF(D24="",0,COUNTIF(G24:Z24,"Y")) -> 0 | AB24: =IF(D24="","",VLOOKUP(AA24,TorchTables!$A$1:$B$21,2,FALSE)) -> -3.3
A25: 45356 | B25: 3 | C25: 3B | D25: Lname10 | E25: Fname10 | F25: XXXXX10 | AA25: =IF(D25="",0,COUNTIF(G25:Z25,"Y")) -> 0 | AB25: =IF(D25="","",VLOOKUP(AA25,TorchTables!$A$1:$B$21,2,FALSE)) -> -3.3
AA26: =IF(D26="",0,COUNTIF(G26:Z26,"Y")) -> 0 | AB26: =IF(D26="","",VLOOKUP(AA26,TorchTables!$A$1:$B$21,2,FALSE))
AA27: =IF(D27="",0,COUNTIF(G27:Z27,"Y")) -> 0 | AB27: =IF(D27="","",VLOOKUP(AA27,TorchTables!$A$1:$B$21,2,FALSE))
AA28: =IF(D28="",0,COUNTIF(G28:Z28,"Y")) -> 0 | AB28: =IF(D28="","",VLOOKUP(AA28,TorchTables!$A$1:$B$21,2,FALSE))
AA29: =IF(D29="",0,COUNTIF(G29:Z29,"Y")) -> 0 | AB29: =IF(D29="","",VLOOKUP(AA29,TorchTables!$A$1:$B$21,2,FALSE))
AA30: =IF(D30="",0,COUNTIF(G30:Z30,"Y")) -> 0 | AB30: =IF(D30="","",VLOOKUP(AA30,TorchTables!$A$1:$B$21,2,FALSE))
AA31: =IF(D31="",0,COUNTIF(G31:Z31,"Y")) -> 0 | AB31: =IF(D31="","",VLOOKUP(AA31,TorchTables!$A$1:$B$21,2,FALSE))
AA32: =IF(D32="",0,COUNTIF(G32:Z32,"Y")) -> 0 | AB32: =IF(D32="","",VLOOKUP(AA32,TorchTables!$A$1:$B$21,2,FALSE))
AA33: =IF(D33="",0,COUNTIF(G33:Z33,"Y")) -> 0 | AB33: =IF(D33="","",VLOOKUP(AA33,TorchTables!$A$1:$B$21,2,FALSE))
AA34: =IF(D34="",0,COUNTIF(G34:Z34,"Y")) -> 0 | AB34: =IF(D34="","",VLOOKUP(AA34,TorchTables!$A$1:$B$21,2,FALSE))
AA35: =IF(D35="",0,COUNTIF(G35:Z35,"Y")) -> 0 | AB35: =IF(D35="","",VLOOKUP(AA35,TorchTables!$A$1:$B$21,2,FALSE))
AA36: =IF(D36="",0,COUNTIF(G36:Z36,"Y")) -> 0 | AB36: =IF(D36="","",VLOOKUP(AA36,TorchTables!$A$1:$B$21,2,FALSE))
AA37: =IF(D37="",0,COUNTIF(G37:Z37,"Y")) -> 0 | AB37: =IF(D37="","",VLOOKUP(AA37,TorchTables!$A$1:$B$21,2,FALSE))
... AA509: =IF(D509="",0,COUNTIF(G509:Z509,"Y")) -> 0 | AB509: =IF(D509="","",VLOOKUP(AA509,TorchTables!$A$1:$B$21,2,FALSE))

Sheet Gorillas
A1: TORCH - How Gorillas Communicate | AL1: Item Type Key
A2: 3rd Edition | AL2: Locate
AL3: Locate
G4: QUESTION No. and ANSWER KEY (Enter the student's response - "Y" if correct, "N" if incorrect) | AL4: 1 | AM4: Directly stated: verbatim
E5: Question Number | G5: 1 | H5: 2 | I5: 3 | J5: 4 | K5: 5 | L5: 6 | M5: 7 | N5: 8 | O5: 9 | P5: 10 | Q5: 11 | R5: 12 | S5: 13 | T5: 14 | U5: 15 | V5: 16 | W5: 17 | X5: 18 | Y5: 19 | Z5: 20 | AA5: 21 | AB5: 22 | AC5: 23 | AD5: 24 | AE5: 25 | AF5: 26 | AG5: 27 | AH5: 28 | AL5: 2 | AM5: Directly stated: rephrased, reworded
E6: Item Difficulty | G6: 45 | H6: 25 | I6: 21 | J6: 40 | K6: 32 | L6: 35 | M6: 29 | N6: 28 | O6: 30 | P6: 38 | Q6: 39 | R6: 34 | S6: 40 | T6: 38 | U6: 30 | V6: 37 | W6: 39 | X6: 50 | Y6: 64 | Z6: 61 | AA6: 28 | AB6: 40 | AC6: 30 | AD6: 34 | AE6: 30 | AF6: 19 | AG6: 44 | AH6: 41 | AL6: Locate, interpret and infer
E7: Item Category | G7: Locate | H7: Locate | I7: Locate, Interpret and Infer | J7: Locate, Interpret and Infer | K7: Locate, Interpret and Infer | L7: Locate | M7: Locate | N7: Locate, Interpret and Infer | O7: Locate | P7: Locate | Q7: Locate | R7: Locate, Interpret and Infer | S7: Locate, Interpret and Infer | T7: Interpret, Infer and Use | U7: Locate | V7: Locate, Interpret and Infer | W7: Locate | X7: Locate | Y7: Locate, Interpret and Infer | Z7: Locate | AA7: Locate | AB7: Locate | AC7: Locate | AD7: Locate, Interpret and Infer | AE7: Locate | AF7: Locate | AG7: Locate, Interpret and Infer | AH7: Locate | AL7: 3 | AM7: Directly stated: across text
AL8: 4 | AM8: Directly stated: embedded
AL9: 5 | AM9: Inference: simple, explicit references
AL10: Interpret, infer and use
AL11: 6 | AM11: Inference: complex, multiple references, cultural values, writer's intention
E12: Item Type | G12: 2 | H12: 2 | I12: 3 | J12: 5 | K12: 5 | L12: 2 | M12: 2 | N12: 5 | O12: 2 | P12: 1 | Q12: 1 | R12: 5 | S12: 5 | T12: 6 | U12: 1 | V12: 3 | W12: 2 | X12: 1 | Y12: 5 | Z12: 2 | AA12: 2 | AB12: 2 | AC12: 2 | AD12: 3 | AE12: 2 | AF12: 2 | AG12: 5 | AH12: 2
A14: Date (dd/mm/yy) | B14: Yr_Lev | C14: HG | D14: Surname | E14: First_Name | F14: Student_ID | G14: Y | H14: Y | I14: Y | J14: Y | K14: Y | L14: Y | M14: Y | N14: Y | O14: Y | P14: Y | Q14: Y | R14: Y | S14: Y | T14: Y | U14: Y | V14: Y | W14: Y | X14: Y | Y14: Y | Z14: Y | AA14: Y | AB14: Y | AC14: Y | AD14: Y | AE14: Y | AF14: Y | AG14: Y | AH14: Y | AI14: Raw Score | AJ14: TORCH Score
A15: 45356 | B15: 3 | C15: 3A | D15: Lname1 | E15: Fname1 | F15: XXXXX1 | AI15: =IF(D15="",0,COUNTIF(G15:AH15,"Y")) -> 0 | AJ15: =IF(D15="","",VLOOKUP(AI15,TorchTables!$C$1:$D$29,2,FALSE)) -> 3
A16: 45356 | B16: 3 | C16: 3A | D16: Lname2 | E16: Fname2 | F16: XXXXX2 | AI16: =IF(D16="",0,COUNTIF(G16:AH16,"Y")) -> 0 | AJ16: =IF(D16="","",VLOOKUP(AI16,TorchTables!$C$1:$D$29,2,FALSE)) -> 3
A17: 45356 | B17: 3 | C17: 3A | D17: Lname3 | E17: Fname3 | F17: XXXXX3 | AI17: =IF(D17="",0,COUNTIF(G17:AH17,"Y")) -> 0 | AJ17: =IF(D17="","",VLOOKUP(AI17,TorchTables!$C$1:$D$29,2,FALSE)) -> 3
A18: 45356 | B18: 3 | C18: 3A | D18: Lname4 | E18: Fname4 | F18: XXXXX4 | AI18: =IF(D18="",0,COUNTIF(G18:AH18,"Y")) -> 0 | AJ18: =IF(D18="","",VLOOKUP(AI18,TorchTables!$C$1:$D$29,2,FALSE)) -> 3
A19: 45356 | B19: 3 | C19: 3B | D19: ULname13 | E19: UFname13 | F19: UNLISTED | AI19: =IF(D19="",0,COUNTIF(G19:AH19,"Y")) -> 0 | AJ19: =IF(D19="","",VLOOKUP(AI19,TorchTables!$C$1:$D$29,2,FALSE)) -> 3
A20: 45356 | B20: 3 | C20: 3A | D20: Lname5 | E20: Fname5 | F20: XXXXX5 | AI20: =IF(D20="",0,COUNTIF(G20:AH20,"Y")) -> 0 | AJ20: =IF(D20="","",VLOOKUP(AI20,TorchTables!$C$1:$D$29,2,FALSE)) -> 3
A21: 45356 | B21: 3 | C21: 3B | D21: Lname6 | E21: Fname6 | F21: XXXXX6 | AI21: =IF(D21="",0,COUNTIF(G21:AH21,"Y")) -> 0 | AJ21: =IF(D21="","",VLOOKUP(AI21,TorchTables!$C$1:$D$29,2,FALSE)) -> 3
A22: 45356 | B22: 3 | C22: 3B | D22: Lname7 | E22: Fname7 | F22: XXXXX7 | AI22: =IF(D22="",0,COUNTIF(G22:AH22,"Y")) -> 0 | AJ22: =IF(D22="","",VLOOKUP(AI22,TorchTables!$C$1:$D$29,2,FALSE)) -> 3
A23: 45356 | B23: 3 | C23: 3B | D23: Lname8 | E23: Fname8 | F23: XXXXX8 | AI23: =IF(D23="",0,COUNTIF(G23:AH23,"Y")) -> 0 | AJ23: =IF(D23="","",VLOOKUP(AI23,TorchTables!$C$1:$D$29,2,FALSE)) -> 3
A24: 45356 | B24: 3 | C24: 3B | D24: Lname9 | E24: Fname9 | F24: XXXXX9 | AI24: =IF(D24="",0,COUNTIF(G24:AH24,"Y")) -> 0 | AJ24: =IF(D24="","",VLOOKUP(AI24,TorchTables!$C$1:$D$29,2,FALSE)) -> 3
A25: 45356 | B25: 3 | C25: 3B | D25: Lname10 | E25: Fname10 | F25: XXXXX10 | AI25: =IF(D25="",0,COUNTIF(G25:AH25,"Y")) -> 0 | AJ25: =IF(D25="","",VLOOKUP(AI25,TorchTables!$C$1:$D$29,2,FALSE)) -> 3
AI26: =IF(D26="",0,COUNTIF(G26:AH26,"Y")) -> 0 | AJ26: =IF(D26="","",VLOOKUP(AI26,TorchTables!$C$1:$D$29,2,FALSE))
AI27: =IF(D27="",0,COUNTIF(G27:AH27,"Y")) -> 0 | AJ27: =IF(D27="","",VLOOKUP(AI27,TorchTables!$C$1:$D$29,2,FALSE))
AI28: =IF(D28="",0,COUNTIF(G28:AH28,"Y")) -> 0 | AJ28: =IF(D28="","",VLOOKUP(AI28,TorchTables!$C$1:$D$29,2,FALSE))
AI29: =IF(D29="",0,COUNTIF(G29:AH29,"Y")) -> 0 | AJ29: =IF(D29="","",VLOOKUP(AI29,TorchTables!$C$1:$D$29,2,FALSE))
AI30: =IF(D30="",0,COUNTIF(G30:AH30,"Y")) -> 0 | AJ30: =IF(D30="","",VLOOKUP(AI30,TorchTables!$C$1:$D$29,2,FALSE))
AI31: =IF(D31="",0,COUNTIF(G31:AH31,"Y")) -> 0 | AJ31: =IF(D31="","",VLOOKUP(AI31,TorchTables!$C$1:$D$29,2,FALSE))
AI32: =IF(D32="",0,COUNTIF(G32:AH32,"Y")) -> 0 | AJ32: =IF(D32="","",VLOOKUP(AI32,TorchTables!$C$1:$D$29,2,FALSE))
AI33: =IF(D33="",0,COUNTIF(G33:AH33,"Y")) -> 0 | AJ33: =IF(D33="","",VLOOKUP(AI33,TorchTables!$C$1:$D$29,2,FALSE))
AI34: =IF(D34="",0,COUNTIF(G34:AH34,"Y")) -> 0 | AJ34: =IF(D34="","",VLOOKUP(AI34,TorchTables!$C$1:$D$29,2,FALSE))
AI35: =IF(D35="",0,COUNTIF(G35:AH35,"Y")) -> 0 | AJ35: =IF(D35="","",VLOOKUP(AI35,TorchTables!$C$1:$D$29,2,FALSE))
AI36: =IF(D36="",0,COUNTIF(G36:AH36,"Y")) -> 0 | AJ36: =IF(D36="","",VLOOKUP(AI36,TorchTables!$C$1:$D$29,2,FALSE))
AI37: =IF(D37="",0,COUNTIF(G37:AH37,"Y")) -> 0 | AJ37: =IF(D37="","",VLOOKUP(AI37,TorchTables!$C$1:$D$29,2,FALSE))
... AI509: =IF(D509="",0,COUNTIF(G509:AH509,"Y")) -> 0 | AJ509: =IF(D509="","",VLOOKUP(AI509,TorchTables!$C$1:$D$29,2,FALSE))

Sheet Audrey
A1: TORCH - Audrey and the Visitor | AK1: Item Type Key
A2: 3rd Edition
AK3: Locate
G4: QUESTION No. and ANSWER KEY (Enter the student's response - "Y" if correct, "N" if incorrect) | AK4: 1 | AL4: Directly stated: verbatim
E5: Question Number | G5: 1 | H5: 2 | I5: 3 | J5: 4 | K5: 5 | L5: 6 | M5: 7 | N5: 8 | O5: 9 | P5: 10 | Q5: 11 | R5: 12 | S5: 13 | T5: 14 | U5: 15 | V5: 16 | W5: 17 | X5: 18 | Y5: 19 | Z5: 20 | AA5: 21 | AB5: 22 | AC5: 23 | AD5: 24 | AE5: 25 | AF5: 26 | AG5: 27 | AK5: 2 | AL5: Directly stated: rephrased, reworded
E6: Item Difficulty | G6: 30 | H6: 24 | I6: 41 | J6: 37 | K6: 30 | L6: 28 | M6: 39 | N6: 52 | O6: 41 | P6: 50 | Q6: 40 | R6: 55 | S6: 45 | T6: 30 | U6: 39 | V6: 40 | W6: 35 | X6: 36 | Y6: 39 | Z6: 46 | AA6: 51 | AB6: 38 | AC6: 46 | AD6: 31 | AE6: 52 | AF6: 52 | AG6: 34 | AK6: Locate, interpret and infer
E7: Item Category | G7: Locate, Interpret and Infer | H7: Locate | I7: Locate | J7: Locate | K7: Locate | L7: Locate | M7: Locate, Interpret and Infer | N7: Locate, Interpret and Infer | O7: Locate | P7: Locate, Interpret and Infer | Q7: Locate | R7: Locate, Interpret and Infer | S7: Locate | T7: Locate | U7: Locate | V7: Locate | W7: Locate | X7: Locate, Interpret and Infer | Y7: Locate | Z7: Locate, Interpret and Infer | AA7: Locate | AB7: Locate | AC7: Interpret, Infer and Use | AD7: Locate | AE7: Locate | AF7: Interpret, Infer and Use | AG7: Locate, Interpret and Infer | AK7: 3 | AL7: Directly stated: across text
AK8: 4 | AL8: Directly stated: embedded
AK9: 5 | AL9: Inference: simple, explicit references
AK10: Interpret, infer and use
AK11: 6 | AL11: Inference: complex, multiple references, cultural values, writer's intention
E12: Item Type | G12: 4 | H12: 2 | I12: 2 | J12: 2 | K12: 2 | L12: 2 | M12: 5 | N12: 4 | O12: 2 | P12: 5 | Q12: 1 | R12: 4 | S12: 1 | T12: 1 | U12: 2 | V12: 1 | W12: 1 | X12: 5 | Y12: 2 | Z12: 4 | AA12: 2 | AB12: 2 | AC12: 6 | AD12: 2 | AE12: 2 | AF12: 6 | AG12: 4
A14: Date (dd/mm/yy) | B14: Yr_Lev | C14: HG | D14: Surname | E14: First_Name | F14: Student_ID | G14: Y | H14: Y | I14: Y | J14: Y | K14: Y | L14: Y | M14: Y | N14: Y | O14: Y | P14: Y | Q14: Y | R14: Y | S14: Y | T14: Y | U14: Y | V14: Y | W14: Y | X14: Y | Y14: Y | Z14: Y | AA14: Y | AB14: Y | AC14: Y | AD14: Y | AE14: Y | AF14: Y | AG14: Y | AH14: Raw Score | AI14: TORCH Score
A15: 45356 | B15: 3 | C15: 3A | D15: Lname1 | E15: Fname1 | F15: XXXXX1 | AH15: =IF(D15="",0,COUNTIF(G15:AG15,"Y")) -> 0 | AI15: =IF(D15="","",VLOOKUP(AH15,TorchTables!$G$1:$H$28,2,FALSE)) -> 7.5
A16: 45356 | B16: 3 | C16: 3A | D16: Lname2 | E16: Fname2 | F16: XXXXX2 | AH16: =IF(D16="",0,COUNTIF(G16:AG16,"Y")) -> 0 | AI16: =IF(D16="","",VLOOKUP(AH16,TorchTables!$G$1:$H$28,2,FALSE)) -> 7.5
A17: 45356 | B17: 3 | C17: 3A | D17: Lname3 | E17: Fname3 | F17: XXXXX3 | AH17: =IF(D17="",0,COUNTIF(G17:AG17,"Y")) -> 0 | AI17: =IF(D17="","",VLOOKUP(AH17,TorchTables!$G$1:$H$28,2,FALSE)) -> 7.5
A18: 45356 | B18: 3 | C18: 3A | D18: Lname4 | E18: Fname4 | F18: XXXXX4 | AH18: =IF(D18="",0,COUNTIF(G18:AG18,"Y")) -> 0 | AI18: =IF(D18="","",VLOOKUP(AH18,TorchTables!$G$1:$H$28,2,FALSE)) -> 7.5
A19: 45356 | B19: 3 | C19: 3B | D19: ULname13 | E19: UFname13 | F19: UNLISTED | AH19: =IF(D19="",0,COUNTIF(G19:AG19,"Y")) -> 0 | AI19: =IF(D19="","",VLOOKUP(AH19,TorchTables!$G$1:$H$28,2,FALSE)) -> 7.5
A20: 45356 | B20: 3 | C20: 3A | D20: Lname5 | E20: Fname5 | F20: XXXXX5 | AH20: =IF(D20="",0,COUNTIF(G20:AG20,"Y")) -> 0 | AI20: =IF(D20="","",VLOOKUP(AH20,TorchTables!$G$1:$H$28,2,FALSE)) -> 7.5
A21: 45356 | B21: 3 | C21: 3B | D21: Lname6 | E21: Fname6 | F21: XXXXX6 | AH21: =IF(D21="",0,COUNTIF(G21:AG21,"Y")) -> 0 | AI21: =IF(D21="","",VLOOKUP(AH21,TorchTables!$G$1:$H$28,2,FALSE)) -> 7.5
A22: 45356 | B22: 3 | C22: 3B | D22: Lname7 | E22: Fname7 | F22: XXXXX7 | AH22: =IF(D22="",0,COUNTIF(G22:AG22,"Y")) -> 0 | AI22: =IF(D22="","",VLOOKUP(AH22,TorchTables!$G$1:$H$28,2,FALSE)) -> 7.5
A23: 45356 | B23: 3 | C23: 3B | D23: Lname8 | E23: Fname8 | F23: XXXXX8 | AH23: =IF(D23="",0,COUNTIF(G23:AG23,"Y")) -> 0 | AI23: =IF(D23="","",VLOOKUP(AH23,TorchTables!$G$1:$H$28,2,FALSE)) -> 7.5
A24: 45356 | B24: 3 | C24: 3B | D24: Lname9 | E24: Fname9 | F24: XXXXX9 | AH24: =IF(D24="",0,COUNTIF(G24:AG24,"Y")) -> 0 | AI24: =IF(D24="","",VLOOKUP(AH24,TorchTables!$G$1:$H$28,2,FALSE)) -> 7.5
A25: 45356 | B25: 3 | C25: 3B | D25: Lname10 | E25: Fname10 | F25: XXXXX10 | AH25: =IF(D25="",0,COUNTIF(G25:AG25,"Y")) -> 0 | AI25: =IF(D25="","",VLOOKUP(AH25,TorchTables!$G$1:$H$28,2,FALSE)) -> 7.5
AH26: =IF(D26="",0,COUNTIF(G26:AG26,"Y")) -> 0 | AI26: =IF(D26="","",VLOOKUP(AH26,TorchTables!$G$1:$H$28,2,FALSE))
AH27: =IF(D27="",0,COUNTIF(G27:AG27,"Y")) -> 0 | AI27: =IF(D27="","",VLOOKUP(AH27,TorchTables!$G$1:$H$28,2,FALSE))
AH28: =IF(D28="",0,COUNTIF(G28:AG28,"Y")) -> 0 | AI28: =IF(D28="","",VLOOKUP(AH28,TorchTables!$G$1:$H$28,2,FALSE))
AH29: =IF(D29="",0,COUNTIF(G29:AG29,"Y")) -> 0 | AI29: =IF(D29="","",VLOOKUP(AH29,TorchTables!$G$1:$H$28,2,FALSE))
AH30: =IF(D30="",0,COUNTIF(G30:AG30,"Y")) -> 0 | AI30: =IF(D30="","",VLOOKUP(AH30,TorchTables!$G$1:$H$28,2,FALSE))
AH31: =IF(D31="",0,COUNTIF(G31:AG31,"Y")) -> 0 | AI31: =IF(D31="","",VLOOKUP(AH31,TorchTables!$G$1:$H$28,2,FALSE))
AH32: =IF(D32="",0,COUNTIF(G32:AG32,"Y")) -> 0 | AI32: =IF(D32="","",VLOOKUP(AH32,TorchTables!$G$1:$H$28,2,FALSE))
AH33: =IF(D33="",0,COUNTIF(G33:AG33,"Y")) -> 0 | AI33: =IF(D33="","",VLOOKUP(AH33,TorchTables!$G$1:$H$28,2,FALSE))
AH34: =IF(D34="",0,COUNTIF(G34:AG34,"Y")) -> 0 | AI34: =IF(D34="","",VLOOKUP(AH34,TorchTables!$G$1:$H$28,2,FALSE))
AH35: =IF(D35="",0,COUNTIF(G35:AG35,"Y")) -> 0 | AI35: =IF(D35="","",VLOOKUP(AH35,TorchTables!$G$1:$H$28,2,FALSE))
AH36: =IF(D36="",0,COUNTIF(G36:AG36,"Y")) -> 0 | AI36: =IF(D36="","",VLOOKUP(AH36,TorchTables!$G$1:$H$28,2,FALSE))
AH37: =IF(D37="",0,COUNTIF(G37:AG37,"Y")) -> 0 | AI37: =IF(D37="","",VLOOKUP(AH37,TorchTables!$G$1:$H$28,2,FALSE))
... AH509: =IF(D509="",0,COUNTIF(G509:AG509,"Y")) -> 0 | AI509: =IF(D509="","",VLOOKUP(AH509,TorchTables!$G$1:$H$28,2,FALSE))

Sheet Matches
A1: TORCH - Matches | AB1: Item Type Key
A2: 3rd Edition
AB3: Locate
G4: QUESTION No. and ANSWER KEY (Enter the student's response - "Y" if correct, "N" if incorrect) | AB4: 1 | AC4: Directly stated: verbatim
E5: Question Number | G5: 1 | H5: 2 | I5: 3 | J5: 4 | K5: 5 | L5: 6 | M5: 7 | N5: 8 | O5: 9 | P5: 10 | Q5: 11 | R5: 12 | S5: 13 | T5: 14 | U5: 15 | V5: 16 | W5: 17 | X5: 18 | Y5: 19 | AB5: 2 | AC5: Directly stated: rephrased, reworded
E6: Item Difficulty | G6: 31 | H6: 42 | I6: 52 | J6: 47 | K6: 43 | L6: 49 | M6: 50 | N6: 48 | O6: 47 | P6: 55 | Q6: 54 | R6: 54 | S6: 46 | T6: 56 | U6: 58 | V6: 47 | W6: 46 | X6: 55 | Y6: 38 | AB6: Locate, interpret and infer
E7: Item Category | G7: Locate, Interpret and Infer | H7: Locate, Interpret and Infer | I7: Locate, Interpret and Infer | J7: Locate, Interpret and Infer | K7: Locate, Interpret and Infer | L7: Locate, Interpret and Infer | M7: Locate, Interpret and Infer | N7: Locate, Interpret and Infer | O7: Locate, Interpret and Infer | P7: Locate, Interpret and Infer | Q7: Locate, Interpret and Infer | R7: Locate, Interpret and Infer | S7: Locate, Interpret and Infer | T7: Locate, Interpret and Infer | U7: Locate, Interpret and Infer | V7: Locate, Interpret and Infer | W7: Locate, Interpret and Infer | X7: Locate, Interpret and Infer | Y7: Locate, Interpret and Infer | AB7: 3 | AC7: Directly stated: across text
AB8: 4 | AC8: Directly stated: embedded
AB9: 5 | AC9: Inference: simple, explicit references
AB10: Interpret, infer and use
AB11: 6 | AC11: Inference: complex, multiple references, cultural values, writer's intention
E12: Item Type | G12: 3 | H12: 3 | I12: 4 | J12: 3 | K12: 4 | L12: 4 | M12: 3 | N12: 3 | O12: 3 | P12: 4 | Q12: 4 | R12: 4 | S12: 4 | T12: 5 | U12: 5 | V12: 3 | W12: 3 | X12: 5 | Y12: 5
A14: Date (dd/mm/yy) | B14: Yr_Lev | C14: HG | D14: Surname | E14: First_Name | F14: Student_ID | G14: Y | H14: Y | I14: Y | J14: Y | K14: Y | L14: Y | M14: Y | N14: Y | O14: Y | P14: Y | Q14: Y | R14: Y | S14: Y | T14: Y | U14: Y | V14: Y | W14: Y | X14: Y | Y14: Y | Z14: Raw Score | AA14: TORCH Score
A15: 45356 | B15: 3 | C15: 3A | D15: Lname1 | E15: Fname1 | F15: XXXXX1 | Z15: =IF(D15="",0,COUNTIF(G15:Y15,"Y")) -> 0 | AA15: =IF(D15="","",VLOOKUP(Z15,TorchTables!$I$1:$J$20,2,FALSE)) -> 18.6
A16: 45356 | B16: 3 | C16: 3A | D16: Lname2 | E16: Fname2 | F16: XXXXX2 | Z16: =IF(D16="",0,COUNTIF(G16:Y16,"Y")) -> 0 | AA16: =IF(D16="","",VLOOKUP(Z16,TorchTables!$I$1:$J$20,2,FALSE)) -> 18.6
A17: 45356 | B17: 3 | C17: 3A | D17: Lname3 | E17: Fname3 | F17: XXXXX3 | Z17: =IF(D17="",0,COUNTIF(G17:Y17,"Y")) -> 0 | AA17: =IF(D17="","",VLOOKUP(Z17,TorchTables!$I$1:$J$20,2,FALSE)) -> 18.6
A18: 45356 | B18: 3 | C18: 3A | D18: Lname4 | E18: Fname4 | F18: XXXXX4 | Z18: =IF(D18="",0,COUNTIF(G18:Y18,"Y")) -> 0 | AA18: =IF(D18="","",VLOOKUP(Z18,TorchTables!$I$1:$J$20,2,FALSE)) -> 18.6
A19: 45356 | B19: 3 | C19: 3B | D19: ULname13 | E19: UFname13 | F19: UNLISTED | Z19: =IF(D19="",0,COUNTIF(G19:Y19,"Y")) -> 0 | AA19: =IF(D19="","",VLOOKUP(Z19,TorchTables!$I$1:$J$20,2,FALSE)) -> 18.6
A20: 45356 | B20: 3 | C20: 3A | D20: Lname5 | E20: Fname5 | F20: XXXXX5 | Z20: =IF(D20="",0,COUNTIF(G20:Y20,"Y")) -> 0 | AA20: =IF(D20="","",VLOOKUP(Z20,TorchTables!$I$1:$J$20,2,FALSE)) -> 18.6
A21: 45356 | B21: 3 | C21: 3B | D21: Lname6 | E21: Fname6 | F21: XXXXX6 | Z21: =IF(D21="",0,COUNTIF(G21:Y21,"Y")) -> 0 | AA21: =IF(D21="","",VLOOKUP(Z21,TorchTables!$I$1:$J$20,2,FALSE)) -> 18.6
A22: 45356 | B22: 3 | C22: 3B | D22: Lname7 | E22: Fname7 | F22: XXXXX7 | Z22: =IF(D22="",0,COUNTIF(G22:Y22,"Y")) -> 0 | AA22: =IF(D22="","",VLOOKUP(Z22,TorchTables!$I$1:$J$20,2,FALSE)) -> 18.6
A23: 45356 | B23: 3 | C23: 3B | D23: Lname8 | E23: Fname8 | F23: XXXXX8 | Z23: =IF(D23="",0,COUNTIF(G23:Y23,"Y")) -> 0 | AA23: =IF(D23="","",VLOOKUP(Z23,TorchTables!$I$1:$J$20,2,FALSE)) -> 18.6
A24: 45356 | B24: 3 | C24: 3B | D24: Lname9 | E24: Fname9 | F24: XXXXX9 | Z24: =IF(D24="",0,COUNTIF(G24:Y24,"Y")) -> 0 | AA24: =IF(D24="","",VLOOKUP(Z24,TorchTables!$I$1:$J$20,2,FALSE)) -> 18.6
A25: 45356 | B25: 3 | C25: 3B | D25: Lname10 | E25: Fname10 | F25: XXXXX10 | Z25: =IF(D25="",0,COUNTIF(G25:Y25,"Y")) -> 0 | AA25: =IF(D25="","",VLOOKUP(Z25,TorchTables!$I$1:$J$20,2,FALSE)) -> 18.6
Z26: =IF(D26="",0,COUNTIF(G26:Y26,"Y")) -> 0 | AA26: =IF(D26="","",VLOOKUP(Z26,TorchTables!$I$1:$J$20,2,FALSE))
Z27: =IF(D27="",0,COUNTIF(G27:Y27,"Y")) -> 0 | AA27: =IF(D27="","",VLOOKUP(Z27,TorchTables!$I$1:$J$20,2,FALSE))
Z28: =IF(D28="",0,COUNTIF(G28:Y28,"Y")) -> 0 | AA28: =IF(D28="","",VLOOKUP(Z28,TorchTables!$I$1:$J$20,2,FALSE))
Z29: =IF(D29="",0,COUNTIF(G29:Y29,"Y")) -> 0 | AA29: =IF(D29="","",VLOOKUP(Z29,TorchTables!$I$1:$J$20,2,FALSE))
Z30: =IF(D30="",0,COUNTIF(G30:Y30,"Y")) -> 0 | AA30: =IF(D30="","",VLOOKUP(Z30,TorchTables!$I$1:$J$20,2,FALSE))
Z31: =IF(D31="",0,COUNTIF(G31:Y31,"Y")) -> 0 | AA31: =IF(D31="","",VLOOKUP(Z31,TorchTables!$I$1:$J$20,2,FALSE))
Z32: =IF(D32="",0,COUNTIF(G32:Y32,"Y")) -> 0 | AA32: =IF(D32="","",VLOOKUP(Z32,TorchTables!$I$1:$J$20,2,FALSE))
Z33: =IF(D33="",0,COUNTIF(G33:Y33,"Y")) -> 0 | AA33: =IF(D33="","",VLOOKUP(Z33,TorchTables!$I$1:$J$20,2,FALSE))
Z34: =IF(D34="",0,COUNTIF(G34:Y34,"Y")) -> 0 | AA34: =IF(D34="","",VLOOKUP(Z34,TorchTables!$I$1:$J$20,2,FALSE))
Z35: =IF(D35="",0,COUNTIF(G35:Y35,"Y")) -> 0 | AA35: =IF(D35="","",VLOOKUP(Z35,TorchTables!$I$1:$J$20,2,FALSE))
Z36: =IF(D36="",0,COUNTIF(G36:Y36,"Y")) -> 0 | AA36: =IF(D36="","",VLOOKUP(Z36,TorchTables!$I$1:$J$20,2,FALSE))
Z37: =IF(D37="",0,COUNTIF(G37:Y37,"Y")) -> 0 | AA37: =IF(D37="","",VLOOKUP(Z37,TorchTables!$I$1:$J$20,2,FALSE))
... Z509: =IF(D509="",0,COUNTIF(G509:Y509,"Y")) -> 0 | AA509: =IF(D509="","",VLOOKUP(Z509,TorchTables!$I$1:$J$20,2,FALSE))

Sheet Bones
A1: TORCH - Misery Bones | AL1: Item Type Key
A2: 3rd Edition
AL3: Locate
G4: QUESTION No. and ANSWER KEY (Enter the student's response - "Y" if correct, "N" if incorrect) | AL4: 1 | AM4: Directly stated: verbatim
E5: Question Number | G5: 1 | H5: 2 | I5: 3 | J5: 4 | K5: 5 | L5: 6 | M5: 7 | N5: 8 | O5: 9 | P5: 10 | Q5: 11 | R5: 12 | S5: 13 | T5: 14 | U5: 15 | V5: 16 | W5: 17 | X5: 18 | Y5: 19 | Z5: 20 | AA5: 21 | AB5: 22 | AC5: 23 | AD5: 24 | AE5: 25 | AF5: 26 | AG5: 27 | AH5: 28 | AL5: 2 | AM5: Directly stated: rephrased, reworded
E6: Item Difficulty | G6: 39 | H6: 38 | I6: 54 | J6: 49 | K6: 60 | L6: 52 | M6: 46 | N6: 43 | O6: 51 | P6: 52 | Q6: 51 | R6: 56 | S6: 61 | T6: 42 | U6: 49 | V6: 43 | W6: 44 | X6: 57 | Y6: 62 | Z6: 57 | AA6: 47 | AB6: 46 | AC6: 70 | AD6: 69 | AE6: 56 | AF6: 55 | AG6: 51 | AH6: 62 | AL6: Locate, interpret and infer
E7: Item Category | G7: Locate, Interpret and Infer | H7: Locate, Interpret and Infer | I7: Interpret, Infer and Use | J7: Interpret, Infer and Use | K7: Locate | L7: Locate | M7: Locate | N7: Locate | O7: Locate | P7: Locate | Q7: Locate, Interpret and Infer | R7: Locate, Interpret and Infer | S7: Locate | T7: Locate | U7: Locate | V7: Locate | W7: Locate | X7: Locate, Interpret and Infer | Y7: Locate | Z7: Locate | AA7: Locate, Interpret and Infer | AB7: Locate | AC7: Locate, Interpret and Infer | AD7: Locate, Interpret and Infer | AE7: Locate | AF7: Locate, Interpret and Infer | AG7: Interpret, Infer and Use | AH7: Interpret, Infer and Use | AL7: 3 | AM7: Directly stated: across text
AL8: 4 | AM8: Directly stated: embedded
AL9: 5 | AM9: Inference: simple, explicit references
AL10: Interpret, infer and use
AL11: 6 | AM11: Inference: complex, multiple references, cultural values, writer's intention
E12: Item Type | G12: 4 | H12: 4 | I12: 6 | J12: 6 | K12: 2 | L12: 2 | M12: 2 | N12: 2 | O12: 2 | P12: 2 | Q12: 5 | R12: 5 | S12: 2 | T12: 2 | U12: 2 | V12: 2 | W12: 2 | X12: 5 | Y12: 2 | Z12: 2 | AA12: 3 | AB12: 2 | AC12: 5 | AD12: 4 | AE12: 2 | AF12: 5 | AG12: 6 | AH12: 6
A14: Date (dd/mm/yy) | B14: Yr_Lev | C14: HG | D14: Surname | E14: First_Name | F14: Student_ID | G14: Y | H14: Y | I14: Y | J14: Y | K14: Y | L14: Y | M14: Y | N14: Y | O14: Y | P14: Y | Q14: Y | R14: Y | S14: Y | T14: Y | U14: Y | V14: Y | W14: Y | X14: Y | Y14: Y | Z14: Y | AA14: Y | AB14: Y | AC14: Y | AD14: Y | AE14: Y | AF14: Y | AG14: Y | AH14: Y | AI14: Raw Score | AJ14: TORCH Score
A15: 45356 | B15: 3 | C15: 3A | D15: Lname1 | E15: Fname1 | F15: XXXXX1 | AI15: =IF(D15="",0,COUNTIF(G15:AH15,"Y")) -> 0 | AJ15: =IF(D15="","",VLOOKUP(AI15,TorchTables!$Q$1:$R$29,2,FALSE)) -> 19.8
A16: 45356 | B16: 3 | C16: 3A | D16: Lname2 | E16: Fname2 | F16: XXXXX2 | AI16: =IF(D16="",0,COUNTIF(G16:AH16,"Y")) -> 0 | AJ16: =IF(D16="","",VLOOKUP(AI16,TorchTables!$Q$1:$R$29,2,FALSE)) -> 19.8
A17: 45356 | B17: 3 | C17: 3A | D17: Lname3 | E17: Fname3 | F17: XXXXX3 | AI17: =IF(D17="",0,COUNTIF(G17:AH17,"Y")) -> 0 | AJ17: =IF(D17="","",VLOOKUP(AI17,TorchTables!$Q$1:$R$29,2,FALSE)) -> 19.8
A18: 45356 | B18: 3 | C18: 3A | D18: Lname4 | E18: Fname4 | F18: XXXXX4 | AI18: =IF(D18="",0,COUNTIF(G18:AH18,"Y")) -> 0 | AJ18: =IF(D18="","",VLOOKUP(AI18,TorchTables!$Q$1:$R$29,2,FALSE)) -> 19.8
A19: 45356 | B19: 3 | C19: 3B | D19: ULname13 | E19: UFname13 | F19: UNLISTED | AI19: =IF(D19="",0,COUNTIF(G19:AH19,"Y")) -> 0 | AJ19: =IF(D19="","",VLOOKUP(AI19,TorchTables!$Q$1:$R$29,2,FALSE)) -> 19.8
A20: 45356 | B20: 3 | C20: 3A | D20: Lname5 | E20: Fname5 | F20: XXXXX5 | AI20: =IF(D20="",0,COUNTIF(G20:AH20,"Y")) -> 0 | AJ20: =IF(D20="","",VLOOKUP(AI20,TorchTables!$Q$1:$R$29,2,FALSE)) -> 19.8
A21: 45356 | B21: 3 | C21: 3B | D21: Lname6 | E21: Fname6 | F21: XXXXX6 | AI21: =IF(D21="",0,COUNTIF(G21:AH21,"Y")) -> 0 | AJ21: =IF(D21="","",VLOOKUP(AI21,TorchTables!$Q$1:$R$29,2,FALSE)) -> 19.8
A22: 45356 | B22: 3 | C22: 3B | D22: Lname7 | E22: Fname7 | F22: XXXXX7 | AI22: =IF(D22="",0,COUNTIF(G22:AH22,"Y")) -> 0 | AJ22: =IF(D22="","",VLOOKUP(AI22,TorchTables!$Q$1:$R$29,2,FALSE)) -> 19.8
A23: 45356 | B23: 3 | C23: 3B | D23: Lname8 | E23: Fname8 | F23: XXXXX8 | AI23: =IF(D23="",0,COUNTIF(G23:AH23,"Y")) -> 0 | AJ23: =IF(D23="","",VLOOKUP(AI23,TorchTables!$Q$1:$R$29,2,FALSE)) -> 19.8
A24: 45356 | B24: 3 | C24: 3B | D24: Lname9 | E24: Fname9 | F24: XXXXX9 | AI24: =IF(D24="",0,COUNTIF(G24:AH24,"Y")) -> 0 | AJ24: =IF(D24="","",VLOOKUP(AI24,TorchTables!$Q$1:$R$29,2,FALSE)) -> 19.8
A25: 45356 | B25: 3 | C25: 3B | D25: Lname10 | E25: Fname10 | F25: XXXXX10 | AI25: =IF(D25="",0,COUNTIF(G25:AH25,"Y")) -> 0 | AJ25: =IF(D25="","",VLOOKUP(AI25,TorchTables!$Q$1:$R$29,2,FALSE)) -> 19.8
AI26: =IF(D26="",0,COUNTIF(G26:AH26,"Y")) -> 0 | AJ26: =IF(D26="","",VLOOKUP(AI26,TorchTables!$Q$1:$R$29,2,FALSE))
AI27: =IF(D27="",0,COUNTIF(G27:AH27,"Y")) -> 0 | AJ27: =IF(D27="","",VLOOKUP(AI27,TorchTables!$Q$1:$R$29,2,FALSE))
AI28: =IF(D28="",0,COUNTIF(G28:AH28,"Y")) -> 0 | AJ28: =IF(D28="","",VLOOKUP(AI28,TorchTables!$Q$1:$R$29,2,FALSE))
AI29: =IF(D29="",0,COUNTIF(G29:AH29,"Y")) -> 0 | AJ29: =IF(D29="","",VLOOKUP(AI29,TorchTables!$Q$1:$R$29,2,FALSE))
AI30: =IF(D30="",0,COUNTIF(G30:AH30,"Y")) -> 0 | AJ30: =IF(D30="","",VLOOKUP(AI30,TorchTables!$Q$1:$R$29,2,FALSE))
AI31: =IF(D31="",0,COUNTIF(G31:AH31,"Y")) -> 0 | AJ31: =IF(D31="","",VLOOKUP(AI31,TorchTables!$Q$1:$R$29,2,FALSE))
AI32: =IF(D32="",0,COUNTIF(G32:AH32,"Y")) -> 0 | AJ32: =IF(D32="","",VLOOKUP(AI32,TorchTables!$Q$1:$R$29,2,FALSE))
AI33: =IF(D33="",0,COUNTIF(G33:AH33,"Y")) -> 0 | AJ33: =IF(D33="","",VLOOKUP(AI33,TorchTables!$Q$1:$R$29,2,FALSE))
AI34: =IF(D34="",0,COUNTIF(G34:AH34,"Y")) -> 0 | AJ34: =IF(D34="","",VLOOKUP(AI34,TorchTables!$Q$1:$R$29,2,FALSE))
AI35: =IF(D35="",0,COUNTIF(G35:AH35,"Y")) -> 0 | AJ35: =IF(D35="","",VLOOKUP(AI35,TorchTables!$Q$1:$R$29,2,FALSE))
AI36: =IF(D36="",0,COUNTIF(G36:AH36,"Y")) -> 0 | AJ36: =IF(D36="","",VLOOKUP(AI36,TorchTables!$Q$1:$R$29,2,FALSE))
AI37: =IF(D37="",0,COUNTIF(G37:AH37,"Y")) -> 0 | AJ37: =IF(D37="","",VLOOKUP(AI37,TorchTables!$Q$1:$R$29,2,FALSE))
... AI509: =IF(D509="",0,COUNTIF(G509:AH509,"Y")) -> 0 | AJ509: =IF(D509="","",VLOOKUP(AI509,TorchTables!$Q$1:$R$29,2,FALSE))

Sheet Mall
A1: TORCH - In the Mall | AK1: Item Type Key
A2: 3rd Edition
AK3: Locate
G4: QUESTION No. and ANSWER KEY (Enter the student's response - "Y" if correct, "N" if incorrect) | AK4: 1 | AL4: Directly stated: verbatim
E5: Question Number | G5: 1 | H5: 2 | I5: 3 | J5: 4 | K5: 5 | L5: 6 | M5: 7 | N5: 8 | O5: 9 | P5: 10 | Q5: 11 | R5: 12 | S5: 13 | T5: 14 | U5: 15 | V5: 16 | W5: 17 | X5: 18 | Y5: 19 | Z5: 20 | AA5: 21 | AB5: 22 | AC5: 23 | AD5: 24 | AE5: 25 | AF5: 26 | AG5: 27 | AK5: 2 | AL5: Directly stated: rephrased, reworded
E6: Item Difficulty | G6: 50 | H6: 49 | I6: 33 | J6: 32 | K6: 43 | L6: 51 | M6: 60 | N6: 45 | O6: 46 | P6: 52 | Q6: 23 | R6: 57 | S6: 45 | T6: 45 | U6: 56 | V6: 56 | W6: 55 | X6: 58 | Y6: 51 | Z6: 66 | AA6: 36 | AB6: 44 | AC6: 50 | AD6: 47 | AE6: 53 | AF6: 60 | AG6: 57 | AK6: Locate, interpret and infer
E7: Item Category | G7: Locate | H7: Interpret, Infer and Use | I7: Locate | J7: Locate | K7: Locate | L7: Locate, Interpret and Infer | M7: Locate, Interpret and Infer | N7: Locate | O7: Locate, Interpret and Infer | P7: Locate, Interpret and Infer | Q7: Locate | R7: Locate, Interpret and Infer | S7: Locate | T7: Locate | U7: Locate | V7: Locate, Interpret and Infer | W7: Interpret, Infer and Use | X7: Locate | Y7: Locate | Z7: Interpret, Infer and Use | AA7: Locate | AB7: Locate, Interpret and Infer | AC7: Interpret, Infer and Use | AD7: Locate, Interpret and Infer | AE7: Locate | AF7: Locate | AG7: Locate | AK7: 3 | AL7: Directly stated: across text
AK8: 4 | AL8: Directly stated: embedded
AK9: 5 | AL9: Inference: simple, explicit references
AK10: Interpret, infer and use
AK11: 6 | AL11: Inference: complex, multiple references, cultural values, writer's intention
E12: Item Type | G12: 2 | H12: 6 | I12: 2 | J12: 2 | K12: 2 | L12: 5 | M12: 5 | N12: 2 | O12: 5 | P12: 4 | Q12: 2 | R12: 4 | S12: 2 | T12: 1 | U12: 2 | V12: 4 | W12: 6 | X12: 1 | Y12: 2 | Z12: 6 | AA12: 1 | AB12: 4 | AC12: 6 | AD12: 4 | AE12: 2 | AF12: 2 | AG12: 2
A14: Date (dd/mm/yy) | B14: Yr_Lev | C14: HG | D14: Surname | E14: First_Name | F14: Student_ID | G14: Y | H14: Y | I14: Y | J14: Y | K14: Y | L14: Y | M14: Y | N14: Y | O14: Y | P14: Y | Q14: Y | R14: Y | S14: Y | T14: Y | U14: Y | V14: Y | W14: Y | X14: Y | Y14: Y | Z14: Y | AA14: Y | AB14: Y | AC14: Y | AD14: Y | AE14: Y | AF14: Y | AG14: Y | AH14: Raw Score | AI14: TORCH Score
A15: 45356 | B15: 3 | C15: 3A | D15: Lname1 | E15: Fname1 | F15: XXXXX1 | AH15: =IF(D15="",0,COUNTIF(G15:AG15,"Y")) -> 0 | AI15: =IF(D15="","",VLOOKUP(AH15,TorchTables!$K$1:$L$28,2,FALSE)) -> 12.3
A16: 45356 | B16: 3 | C16: 3A | D16: Lname2 | E16: Fname2 | F16: XXXXX2 | AH16: =IF(D16="",0,COUNTIF(G16:AG16,"Y")) -> 0 | AI16: =IF(D16="","",VLOOKUP(AH16,TorchTables!$K$1:$L$28,2,FALSE)) -> 12.3
A17: 45356 | B17: 3 | C17: 3A | D17: Lname3 | E17: Fname3 | F17: XXXXX3 | AH17: =IF(D17="",0,COUNTIF(G17:AG17,"Y")) -> 0 | AI17: =IF(D17="","",VLOOKUP(AH17,TorchTables!$K$1:$L$28,2,FALSE)) -> 12.3
A18: 45356 | B18: 3 | C18: 3A | D18: Lname4 | E18: Fname4 | F18: XXXXX4 | AH18: =IF(D18="",0,COUNTIF(G18:AG18,"Y")) -> 0 | AI18: =IF(D18="","",VLOOKUP(AH18,TorchTables!$K$1:$L$28,2,FALSE)) -> 12.3
A19: 45356 | B19: 3 | C19: 3B | D19: ULname13 | E19: UFname13 | F19: UNLISTED | AH19: =IF(D19="",0,COUNTIF(G19:AG19,"Y")) -> 0 | AI19: =IF(D19="","",VLOOKUP(AH19,TorchTables!$K$1:$L$28,2,FALSE)) -> 12.3
A20: 45356 | B20: 3 | C20: 3A | D20: Lname5 | E20: Fname5 | F20: XXXXX5 | AH20: =IF(D20="",0,COUNTIF(G20:AG20,"Y")) -> 0 | AI20: =IF(D20="","",VLOOKUP(AH20,TorchTables!$K$1:$L$28,2,FALSE)) -> 12.3
A21: 45356 | B21: 3 | C21: 3B | D21: Lname6 | E21: Fname6 | F21: XXXXX6 | AH21: =IF(D21="",0,COUNTIF(G21:AG21,"Y")) -> 0 | AI21: =IF(D21="","",VLOOKUP(AH21,TorchTables!$K$1:$L$28,2,FALSE)) -> 12.3
A22: 45356 | B22: 3 | C22: 3B | D22: Lname7 | E22: Fname7 | F22: XXXXX7 | AH22: =IF(D22="",0,COUNTIF(G22:AG22,"Y")) -> 0 | AI22: =IF(D22="","",VLOOKUP(AH22,TorchTables!$K$1:$L$28,2,FALSE)) -> 12.3
A23: 45356 | B23: 3 | C23: 3B | D23: Lname8 | E23: Fname8 | F23: XXXXX8 | AH23: =IF(D23="",0,COUNTIF(G23:AG23,"Y")) -> 0 | AI23: =IF(D23="","",VLOOKUP(AH23,TorchTables!$K$1:$L$28,2,FALSE)) -> 12.3
A24: 45356 | B24: 3 | C24: 3B | D24: Lname9 | E24: Fname9 | F24: XXXXX9 | AH24: =IF(D24="",0,COUNTIF(G24:AG24,"Y")) -> 0 | AI24: =IF(D24="","",VLOOKUP(AH24,TorchTables!$K$1:$L$28,2,FALSE)) -> 12.3
A25: 45356 | B25: 3 | C25: 3B | D25: Lname10 | E25: Fname10 | F25: XXXXX10 | AH25: =IF(D25="",0,COUNTIF(G25:AG25,"Y")) -> 0 | AI25: =IF(D25="","",VLOOKUP(AH25,TorchTables!$K$1:$L$28,2,FALSE)) -> 12.3
AH26: =IF(D26="",0,COUNTIF(G26:AG26,"Y")) -> 0 | AI26: =IF(D26="","",VLOOKUP(AH26,TorchTables!$K$1:$L$28,2,FALSE))
AH27: =IF(D27="",0,COUNTIF(G27:AG27,"Y")) -> 0 | AI27: =IF(D27="","",VLOOKUP(AH27,TorchTables!$K$1:$L$28,2,FALSE))
AH28: =IF(D28="",0,COUNTIF(G28:AG28,"Y")) -> 0 | AI28: =IF(D28="","",VLOOKUP(AH28,TorchTables!$K$1:$L$28,2,FALSE))
AH29: =IF(D29="",0,COUNTIF(G29:AG29,"Y")) -> 0 | AI29: =IF(D29="","",VLOOKUP(AH29,TorchTables!$K$1:$L$28,2,FALSE))
AH30: =IF(D30="",0,COUNTIF(G30:AG30,"Y")) -> 0 | AI30: =IF(D30="","",VLOOKUP(AH30,TorchTables!$K$1:$L$28,2,FALSE))
AH31: =IF(D31="",0,COUNTIF(G31:AG31,"Y")) -> 0 | AI31: =IF(D31="","",VLOOKUP(AH31,TorchTables!$K$1:$L$28,2,FALSE))
AH32: =IF(D32="",0,COUNTIF(G32:AG32,"Y")) -> 0 | AI32: =IF(D32="","",VLOOKUP(AH32,TorchTables!$K$1:$L$28,2,FALSE))
AH33: =IF(D33="",0,COUNTIF(G33:AG33,"Y")) -> 0 | AI33: =IF(D33="","",VLOOKUP(AH33,TorchTables!$K$1:$L$28,2,FALSE))
AH34: =IF(D34="",0,COUNTIF(G34:AG34,"Y")) -> 0 | AI34: =IF(D34="","",VLOOKUP(AH34,TorchTables!$K$1:$L$28,2,FALSE))
AH35: =IF(D35="",0,COUNTIF(G35:AG35,"Y")) -> 0 | AI35: =IF(D35="","",VLOOKUP(AH35,TorchTables!$K$1:$L$28,2,FALSE))
AH36: =IF(D36="",0,COUNTIF(G36:AG36,"Y")) -> 0 | AI36: =IF(D36="","",VLOOKUP(AH36,TorchTables!$K$1:$L$28,2,FALSE))
AH37: =IF(D37="",0,COUNTIF(G37:AG37,"Y")) -> 0 | AI37: =IF(D37="","",VLOOKUP(AH37,TorchTables!$K$1:$L$28,2,FALSE))
... AH509: =IF(D509="",0,COUNTIF(G509:AG509,"Y")) -> 0 | AI509: =IF(D509="","",VLOOKUP(AH509,TorchTables!$K$1:$L$28,2,FALSE))

Sheet Glass
A1: TORCH - Window Glass | AK1: Item Type Key
A2: 3rd Edition
AK3: Locate
G4: QUESTION No. and ANSWER KEY (Enter the student's response - "Y" if correct, "N" if incorrect) | AK4: 1 | AL4: Directly stated: verbatim
E5: Question Number | G5: 1 | H5: 2 | I5: 3 | J5: 4 | K5: 5 | L5: 6 | M5: 7 | N5: 8 | O5: 9 | P5: 10 | Q5: 11 | R5: 12 | S5: 13 | T5: 14 | U5: 15 | V5: 16 | W5: 17 | X5: 18 | Y5: 19 | Z5: 20 | AA5: 21 | AB5: 22 | AC5: 23 | AD5: 24 | AE5: 25 | AF5: 26 | AG5: 27 | AK5: 2 | AL5: Directly stated: rephrased, reworded
E6: Item Difficulty | G6: 32 | H6: 46 | I6: 47 | J6: 38 | K6: 44 | L6: 53 | M6: 47 | N6: 64 | O6: 59 | P6: 63 | Q6: 42 | R6: 50 | S6: 55 | T6: 57 | U6: 55 | V6: 43 | W6: 55 | X6: 43 | Y6: 44 | Z6: 40 | AA6: 55 | AB6: 61 | AC6: 62 | AD6: 47 | AE6: 36 | AF6: 46 | AG6: 54 | AK6: Locate, interpret and infer
E7: Item Category | G7: Locate | H7: Locate | I7: Locate | J7: Locate | K7: Locate | L7: Locate | M7: Locate | N7: Locate, Interpret and Infer | O7: Locate, Interpret and Infer | P7: Locate, Interpret and Infer | Q7: Locate, Interpret and Infer | R7: Locate | S7: Locate | T7: Locate | U7: Locate, Interpret and Infer | V7: Locate, Interpret and Infer | W7: Locate, Interpret and Infer | X7: Locate, Interpret and Infer | Y7: Locate | Z7: Locate, Interpret and Infer | AA7: Locate | AB7: Locate, Interpret and Infer | AC7: Locate, Interpret and Infer | AD7: Locate | AE7: Locate, Interpret and Infer | AF7: Locate | AG7: Locate, Interpret and Infer | AK7: 3 | AL7: Directly stated: across text
AK8: 4 | AL8: Directly stated: embedded
AK9: 5 | AL9: Inference: simple, explicit references
AK10: Interpret, infer and use
AK11: 6 | AL11: Inference: complex, multiple references, cultural values, writer's intention
E12: Item Type | G12: 1 | H12: 2 | I12: 2 | J12: 1 | K12: 2 | L12: 2 | M12: 2 | N12: 4 | O12: 4 | P12: 4 | Q12: 4 | R12: 2 | S12: 2 | T12: 2 | U12: 4 | V12: 4 | W12: 4 | X12: 4 | Y12: 2 | Z12: 4 | AA12: 2 | AB12: 4 | AC12: 3 | AD12: 2 | AE12: 4 | AF12: 2 | AG12: 4
A14: Date (dd/mm/yy) | B14: Yr_Lev | C14: HG | D14: Surname | E14: First_Name | F14: Student_ID | G14: Y | H14: Y | I14: Y | J14: Y | K14: Y | L14: Y | M14: Y | N14: Y | O14: Y | P14: Y | Q14: Y | R14: Y | S14: Y | T14: Y | U14: Y | V14: Y | W14: Y | X14: Y | Y14: Y | Z14: Y | AA14: Y | AB14: Y | AC14: Y | AD14: Y | AE14: Y | AF14: Y | AG14: Y | AH14: Raw Score | AI14: TORCH Score
AH15: =IF(D15="",0,COUNTIF(G15:AG15,"Y")) -> 0 | AI15: =IF(D15="","",VLOOKUP(AH15,TorchTables!$M$1:$N$28,2,FALSE))
AH16: =IF(D16="",0,COUNTIF(G16:AG16,"Y")) -> 0 | AI16: =IF(D16="","",VLOOKUP(AH16,TorchTables!$M$1:$N$28,2,FALSE))
AH17: =IF(D17="",0,COUNTIF(G17:AG17,"Y")) -> 0 | AI17: =IF(D17="","",VLOOKUP(AH17,TorchTables!$M$1:$N$28,2,FALSE))
AH18: =IF(D18="",0,COUNTIF(G18:AG18,"Y")) -> 0 | AI18: =IF(D18="","",VLOOKUP(AH18,TorchTables!$M$1:$N$28,2,FALSE))
AH19: =IF(D19="",0,COUNTIF(G19:AG19,"Y")) -> 0 | AI19: =IF(D19="","",VLOOKUP(AH19,TorchTables!$M$1:$N$28,2,FALSE))
AH20: =IF(D20="",0,COUNTIF(G20:AG20,"Y")) -> 0 | AI20: =IF(D20="","",VLOOKUP(AH20,TorchTables!$M$1:$N$28,2,FALSE))
AH21: =IF(D21="",0,COUNTIF(G21:AG21,"Y")) -> 0 | AI21: =IF(D21="","",VLOOKUP(AH21,TorchTables!$M$1:$N$28,2,FALSE))
AH22: =IF(D22="",0,COUNTIF(G22:AG22,"Y")) -> 0 | AI22: =IF(D22="","",VLOOKUP(AH22,TorchTables!$M$1:$N$28,2,FALSE))
AH23: =IF(D23="",0,COUNTIF(G23:AG23,"Y")) -> 0 | AI23: =IF(D23="","",VLOOKUP(AH23,TorchTables!$M$1:$N$28,2,FALSE))
AH24: =IF(D24="",0,COUNTIF(G24:AG24,"Y")) -> 0 | AI24: =IF(D24="","",VLOOKUP(AH24,TorchTables!$M$1:$N$28,2,FALSE))
AH25: =IF(D25="",0,COUNTIF(G25:AG25,"Y")) -> 0 | AI25: =IF(D25="","",VLOOKUP(AH25,TorchTables!$M$1:$N$28,2,FALSE))
AH26: =IF(D26="",0,COUNTIF(G26:AG26,"Y")) -> 0 | AI26: =IF(D26="","",VLOOKUP(AH26,TorchTables!$M$1:$N$28,2,FALSE))
... AH509: =IF(D509="",0,COUNTIF(G509:AG509,"Y")) -> 0 | AI509: =IF(D509="","",VLOOKUP(AH509,TorchTables!$M$1:$N$28,2,FALSE))

Sheet Crying
A1: TORCH - She's Crying | AF1: Item Type Key
A2: 3rd Edition
AF3: Locate
G4: QUESTION No. and ANSWER KEY (Enter the student's response - "Y" if correct, "N" if incorrect) | AF4: 1 | AG4: Directly stated: verbatim
E5: Question Number | G5: 1 | H5: 2 | I5: 3 | J5: 4 | K5: 5 | L5: 6 | M5: 7 | N5: 8 | O5: 9 | P5: 10 | Q5: 11 | R5: 12 | S5: 13 | T5: 14 | U5: 15 | V5: 16 | W5: 17 | X5: 18 | Y5: 19 | Z5: 20 | AA5: 21 | AB5: 22 | AF5: 2 | AG5: Directly stated: rephrased, reworded
E6: Item Difficulty | G6: 29 | H6: 41 | I6: 35 | J6: 50 | K6: 43 | L6: 50 | M6: 50 | N6: 34 | O6: 41 | P6: 63 | Q6: 48 | R6: 53 | S6: 63 | T6: 55 | U6: 65 | V6: 52 | W6: 45 | X6: 54 | Y6: 56 | Z6: 46 | AA6: 54 | AB6: 67 | AF6: Locate, interpret and infer
E7: Item Category | G7: Locate | H7: Locate | I7: Locate | J7: Locate, Interpret and Infer | K7: Locate | L7: Locate, Interpret and Infer | M7: Locate | N7: Locate | O7: Locate, Interpret and Infer | P7: Locate, Interpret and Infer | Q7: Locate, Interpret and Infer | R7: Locate, Interpret and Infer | S7: Locate, Interpret and Infer | T7: Locate, Interpret and Infer | U7: Locate, Interpret and Infer | V7: Locate, Interpret and Infer | W7: Locate, Interpret and Infer | X7: Locate, Interpret and Infer | Y7: Locate, Interpret and Infer | Z7: Locate | AA7: Locate, Interpret and Infer | AB7: Locate, Interpret and Infer | AF7: 3 | AG7: Directly stated: across text
AF8: 4 | AG8: Directly stated: embedded
AF9: 5 | AG9: Inference: simple, explicit references
AF10: Interpret, infer and use
AF11: 6 | AG11: Inference: complex, multiple references, cultural values, writer's intention
E12: Item Type | G12: 2 | H12: 2 | I12: 2 | J12: 3 | K12: 2 | L12: 3 | M12: 2 | N12: 2 | O12: 4 | P12: 4 | Q12: 4 | R12: 4 | S12: 4 | T12: 3 | U12: 5 | V12: 3 | W12: 3 | X12: 4 | Y12: 4 | Z12: 2 | AA12: 3 | AB12: 3
A14: Date (dd/mm/yy) | B14: Yr_Lev | C14: HG | D14: Surname | E14: First_Name | F14: Student_ID | G14: Y | H14: Y | I14: Y | J14: Y | K14: Y | L14: Y | M14: Y | N14: Y | O14: Y | P14: Y | Q14: Y | R14: Y | S14: Y | T14: Y | U14: Y | V14: Y | W14: Y | X14: Y | Y14: Y | Z14: Y | AA14: Y | AB14: Y | AC14: Raw Score | AD14: TORCH Score
A15: 45356 | B15: 3 | C15: 3A | D15: Lname1 | E15: Fname1 | F15: XXXXX1 | AC15: =IF(D15="",0,COUNTIF(G15:AB15,"Y")) -> 0 | AD15: =IF(D15="","",VLOOKUP(AC15,TorchTables!$O$1:$P$23,2,FALSE)) -> 16.3
A16: 45356 | B16: 3 | C16: 3A | D16: Lname2 | E16: Fname2 | F16: XXXXX2 | AC16: =IF(D16="",0,COUNTIF(G16:AB16,"Y")) -> 0 | AD16: =IF(D16="","",VLOOKUP(AC16,TorchTables!$O$1:$P$23,2,FALSE)) -> 16.3
A17: 45356 | B17: 3 | C17: 3A | D17: Lname3 | E17: Fname3 | F17: XXXXX3 | AC17: =IF(D17="",0,COUNTIF(G17:AB17,"Y")) -> 0 | AD17: =IF(D17="","",VLOOKUP(AC17,TorchTables!$O$1:$P$23,2,FALSE)) -> 16.3
A18: 45356 | B18: 3 | C18: 3A | D18: Lname4 | E18: Fname4 | F18: XXXXX4 | AC18: =IF(D18="",0,COUNTIF(G18:AB18,"Y")) -> 0 | AD18: =IF(D18="","",VLOOKUP(AC18,TorchTables!$O$1:$P$23,2,FALSE)) -> 16.3
A19: 45356 | B19: 3 | C19: 3B | D19: ULname13 | E19: UFname13 | F19: UNLISTED | AC19: =IF(D19="",0,COUNTIF(G19:AB19,"Y")) -> 0 | AD19: =IF(D19="","",VLOOKUP(AC19,TorchTables!$O$1:$P$23,2,FALSE)) -> 16.3
A20: 45356 | B20: 3 | C20: 3A | D20: Lname5 | E20: Fname5 | F20: XXXXX5 | AC20: =IF(D20="",0,COUNTIF(G20:AB20,"Y")) -> 0 | AD20: =IF(D20="","",VLOOKUP(AC20,TorchTables!$O$1:$P$23,2,FALSE)) -> 16.3
A21: 45356 | B21: 3 | C21: 3B | D21: Lname6 | E21: Fname6 | F21: XXXXX6 | AC21: =IF(D21="",0,COUNTIF(G21:AB21,"Y")) -> 0 | AD21: =IF(D21="","",VLOOKUP(AC21,TorchTables!$O$1:$P$23,2,FALSE)) -> 16.3
A22: 45356 | B22: 3 | C22: 3B | D22: Lname7 | E22: Fname7 | F22: XXXXX7 | AC22: =IF(D22="",0,COUNTIF(G22:AB22,"Y")) -> 0 | AD22: =IF(D22="","",VLOOKUP(AC22,TorchTables!$O$1:$P$23,2,FALSE)) -> 16.3
A23: 45356 | B23: 3 | C23: 3B | D23: Lname8 | E23: Fname8 | F23: XXXXX8 | AC23: =IF(D23="",0,COUNTIF(G23:AB23,"Y")) -> 0 | AD23: =IF(D23="","",VLOOKUP(AC23,TorchTables!$O$1:$P$23,2,FALSE)) -> 16.3
A24: 45356 | B24: 3 | C24: 3B | D24: Lname9 | E24: Fname9 | F24: XXXXX9 | AC24: =IF(D24="",0,COUNTIF(G24:AB24,"Y")) -> 0 | AD24: =IF(D24="","",VLOOKUP(AC24,TorchTables!$O$1:$P$23,2,FALSE)) -> 16.3
A25: 45356 | B25: 3 | C25: 3B | D25: Lname10 | E25: Fname10 | F25: XXXXX10 | AC25: =IF(D25="",0,COUNTIF(G25:AB25,"Y")) -> 0 | AD25: =IF(D25="","",VLOOKUP(AC25,TorchTables!$O$1:$P$23,2,FALSE)) -> 16.3
AC26: =IF(D26="",0,COUNTIF(G26:AB26,"Y")) -> 0 | AD26: =IF(D26="","",VLOOKUP(AC26,TorchTables!$O$1:$P$23,2,FALSE))
AC27: =IF(D27="",0,COUNTIF(G27:AB27,"Y")) -> 0 | AD27: =IF(D27="","",VLOOKUP(AC27,TorchTables!$O$1:$P$23,2,FALSE))
AC28: =IF(D28="",0,COUNTIF(G28:AB28,"Y")) -> 0 | AD28: =IF(D28="","",VLOOKUP(AC28,TorchTables!$O$1:$P$23,2,FALSE))
AC29: =IF(D29="",0,COUNTIF(G29:AB29,"Y")) -> 0 | AD29: =IF(D29="","",VLOOKUP(AC29,TorchTables!$O$1:$P$23,2,FALSE))
AC30: =IF(D30="",0,COUNTIF(G30:AB30,"Y")) -> 0 | AD30: =IF(D30="","",VLOOKUP(AC30,TorchTables!$O$1:$P$23,2,FALSE))
AC31: =IF(D31="",0,COUNTIF(G31:AB31,"Y")) -> 0 | AD31: =IF(D31="","",VLOOKUP(AC31,TorchTables!$O$1:$P$23,2,FALSE))
AC32: =IF(D32="",0,COUNTIF(G32:AB32,"Y")) -> 0 | AD32: =IF(D32="","",VLOOKUP(AC32,TorchTables!$O$1:$P$23,2,FALSE))
AC33: =IF(D33="",0,COUNTIF(G33:AB33,"Y")) -> 0 | AD33: =IF(D33="","",VLOOKUP(AC33,TorchTables!$O$1:$P$23,2,FALSE))
AC34: =IF(D34="",0,COUNTIF(G34:AB34,"Y")) -> 0 | AD34: =IF(D34="","",VLOOKUP(AC34,TorchTables!$O$1:$P$23,2,FALSE))
AC35: =IF(D35="",0,COUNTIF(G35:AB35,"Y")) -> 0 | AD35: =IF(D35="","",VLOOKUP(AC35,TorchTables!$O$1:$P$23,2,FALSE))
AC36: =IF(D36="",0,COUNTIF(G36:AB36,"Y")) -> 0 | AD36: =IF(D36="","",VLOOKUP(AC36,TorchTables!$O$1:$P$23,2,FALSE))
AC37: =IF(D37="",0,COUNTIF(G37:AB37,"Y")) -> 0 | AD37: =IF(D37="","",VLOOKUP(AC37,TorchTables!$O$1:$P$23,2,FALSE))
... AC509: =IF(D509="",0,COUNTIF(G509:AB509,"Y")) -> 0 | AD509: =IF(D509="","",VLOOKUP(AC509,TorchTables!$O$1:$P$23,2,FALSE))

Sheet RoboCup
A1: TORCH - RoboCup | AK1: Item Type Key
A2: 3rd Edition
AK3: Locate
G4: QUESTION No. and ANSWER KEY (Enter the student's response - "Y" if correct, "N" if incorrect) | AK4: 1 | AL4: Directly stated: verbatim
E5: Question Number | G5: 1 | H5: 2 | I5: 3 | J5: 4 | K5: 5 | L5: 6 | M5: 7 | N5: 8 | O5: 9 | P5: 10 | Q5: 11 | R5: 12 | S5: 13 | T5: 14 | U5: 15 | V5: 16 | W5: 17 | X5: 18 | Y5: 19 | Z5: 20 | AA5: 21 | AB5: 22 | AC5: 23 | AD5: 24 | AE5: 25 | AF5: 26 | AK5: 2 | AL5: Directly stated: rephrased, reworded
E6: Item Difficulty | G6: 35 | H6: 44 | I6: 45 | J6: 44 | K6: 68 | L6: 55 | M6: 63 | N6: 56 | O6: 46 | P6: 56 | Q6: 44 | R6: 64 | S6: 68 | T6: 68 | U6: 59 | V6: 53 | W6: 52 | X6: 52 | Y6: 43 | Z6: 69 | AA6: 65 | AB6: 65 | AC6: 48 | AD6: 49 | AE6: 57 | AF6: 56 | AK6: Locate, interpret and infer
E7: Item Category | G7: Locate | H7: Locate | I7: Locate, Interpret and Infer | J7: Locate | K7: Locate | L7: Locate, Interpret and Infer | M7: Locate | N7: Locate | O7: Locate | P7: Locate | Q7: Locate | R7: Locate | S7: Locate, Interpret and Infer | T7: Locate | U7: Locate | V7: Locate | W7: Locate | X7: Locate, Interpret and Infer | Y7: Locate, Interpret and Infer | Z7: Interpret, Infer and Use | AA7: Locate | AB7: Locate, Interpret and Infer | AC7: Locate, Interpret and Infer | AD7: Locate, Interpret and Infer | AE7: Locate | AF7: Locate | AK7: 3 | AL7: Directly stated: across text
AK8: 4 | AL8: Directly stated: embedded
AK9: 5 | AL9: Inference: simple, explicit references
AK10: Interpret, infer and use
AK11: 6 | AL11: Inference: complex, multiple references, cultural values, writer's intention
E12: Item Type | G12: 1 | H12: 1 | I12: 4 | J12: 2 | K12: 1 | L12: 4 | M12: 2 | N12: 2 | O12: 2 | P12: 2 | Q12: 1 | R12: 2 | S12: 4 | T12: 2 | U12: 2 | V12: 2 | W12: 2 | X12: 4 | Y12: 4 | Z12: 6 | AA12: 2 | AB12: 4 | AC12: 4 | AD12: 5 | AE12: 2 | AF12: 2
A14: Date (dd/mm/yy) | B14: Yr_Lev | C14: HG | D14: Surname | E14: First_Name | F14: Student_ID | G14: Y | H14: Y | I14: Y | J14: Y | K14: Y | L14: Y | M14: Y | N14: Y | O14: Y | P14: Y | Q14: Y | R14: Y | S14: Y | T14: Y | U14: Y | V14: Y | W14: Y | X14: Y | Y14: Y | Z14: Y | AA14: Y | AB14: Y | AC14: Y | AD14: Y | AE14: Y | AF14: Y | AG14: Raw Score | AH14: TORCH Score
A15: 45356 | B15: 3 | C15: 3A | D15: Lname1 | E15: Fname1 | F15: XXXXX1 | AG15: =IF(D15="",0,COUNTIF(G15:AF15,"Y")) -> 0 | AH15: =IF(D15="","",VLOOKUP(AG15,TorchTables!$S$1:$T$27,2,FALSE)) -> 21
A16: 45356 | B16: 3 | C16: 3A | D16: Lname2 | E16: Fname2 | F16: XXXXX2 | AG16: =IF(D16="",0,COUNTIF(G16:AF16,"Y")) -> 0 | AH16: =IF(D16="","",VLOOKUP(AG16,TorchTables!$S$1:$T$27,2,FALSE)) -> 21
A17: 45356 | B17: 3 | C17: 3A | D17: Lname3 | E17: Fname3 | F17: XXXXX3 | AG17: =IF(D17="",0,COUNTIF(G17:AF17,"Y")) -> 0 | AH17: =IF(D17="","",VLOOKUP(AG17,TorchTables!$S$1:$T$27,2,FALSE)) -> 21
A18: 45356 | B18: 3 | C18: 3A | D18: Lname4 | E18: Fname4 | F18: XXXXX4 | AG18: =IF(D18="",0,COUNTIF(G18:AF18,"Y")) -> 0 | AH18: =IF(D18="","",VLOOKUP(AG18,TorchTables!$S$1:$T$27,2,FALSE)) -> 21
A19: 45356 | B19: 3 | C19: 3B | D19: ULname13 | E19: UFname13 | F19: UNLISTED | AG19: =IF(D19="",0,COUNTIF(G19:AF19,"Y")) -> 0 | AH19: =IF(D19="","",VLOOKUP(AG19,TorchTables!$S$1:$T$27,2,FALSE)) -> 21
A20: 45356 | B20: 3 | C20: 3A | D20: Lname5 | E20: Fname5 | F20: XXXXX5 | AG20: =IF(D20="",0,COUNTIF(G20:AF20,"Y")) -> 0 | AH20: =IF(D20="","",VLOOKUP(AG20,TorchTables!$S$1:$T$27,2,FALSE)) -> 21
A21: 45356 | B21: 3 | C21: 3B | D21: Lname6 | E21: Fname6 | F21: XXXXX6 | AG21: =IF(D21="",0,COUNTIF(G21:AF21,"Y")) -> 0 | AH21: =IF(D21="","",VLOOKUP(AG21,TorchTables!$S$1:$T$27,2,FALSE)) -> 21
A22: 45356 | B22: 3 | C22: 3B | D22: Lname7 | E22: Fname7 | F22: XXXXX7 | AG22: =IF(D22="",0,COUNTIF(G22:AF22,"Y")) -> 0 | AH22: =IF(D22="","",VLOOKUP(AG22,TorchTables!$S$1:$T$27,2,FALSE)) -> 21
A23: 45356 | B23: 3 | C23: 3B | D23: Lname8 | E23: Fname8 | F23: XXXXX8 | AG23: =IF(D23="",0,COUNTIF(G23:AF23,"Y")) -> 0 | AH23: =IF(D23="","",VLOOKUP(AG23,TorchTables!$S$1:$T$27,2,FALSE)) -> 21
A24: 45356 | B24: 3 | C24: 3B | D24: Lname9 | E24: Fname9 | F24: XXXXX9 | AG24: =IF(D24="",0,COUNTIF(G24:AF24,"Y")) -> 0 | AH24: =IF(D24="","",VLOOKUP(AG24,TorchTables!$S$1:$T$27,2,FALSE)) -> 21
A25: 45356 | B25: 3 | C25: 3B | D25: Lname10 | E25: Fname10 | F25: XXXXX10 | AG25: =IF(D25="",0,COUNTIF(G25:AF25,"Y")) -> 0 | AH25: =IF(D25="","",VLOOKUP(AG25,TorchTables!$S$1:$T$27,2,FALSE)) -> 21
AG26: =IF(D26="",0,COUNTIF(G26:AF26,"Y")) -> 0 | AH26: =IF(D26="","",VLOOKUP(AG26,TorchTables!$S$1:$T$27,2,FALSE))
AG27: =IF(D27="",0,COUNTIF(G27:AF27,"Y")) -> 0 | AH27: =IF(D27="","",VLOOKUP(AG27,TorchTables!$S$1:$T$27,2,FALSE))
AG28: =IF(D28="",0,COUNTIF(G28:AF28,"Y")) -> 0 | AH28: =IF(D28="","",VLOOKUP(AG28,TorchTables!$S$1:$T$27,2,FALSE))
AG29: =IF(D29="",0,COUNTIF(G29:AF29,"Y")) -> 0 | AH29: =IF(D29="","",VLOOKUP(AG29,TorchTables!$S$1:$T$27,2,FALSE))
AG30: =IF(D30="",0,COUNTIF(G30:AF30,"Y")) -> 0 | AH30: =IF(D30="","",VLOOKUP(AG30,TorchTables!$S$1:$T$27,2,FALSE))
AG31: =IF(D31="",0,COUNTIF(G31:AF31,"Y")) -> 0 | AH31: =IF(D31="","",VLOOKUP(AG31,TorchTables!$S$1:$T$27,2,FALSE))
AG32: =IF(D32="",0,COUNTIF(G32:AF32,"Y")) -> 0 | AH32: =IF(D32="","",VLOOKUP(AG32,TorchTables!$S$1:$T$27,2,FALSE))
AG33: =IF(D33="",0,COUNTIF(G33:AF33,"Y")) -> 0 | AH33: =IF(D33="","",VLOOKUP(AG33,TorchTables!$S$1:$T$27,2,FALSE))
AG34: =IF(D34="",0,COUNTIF(G34:AF34,"Y")) -> 0 | AH34: =IF(D34="","",VLOOKUP(AG34,TorchTables!$S$1:$T$27,2,FALSE))
AG35: =IF(D35="",0,COUNTIF(G35:AF35,"Y")) -> 0 | AH35: =IF(D35="","",VLOOKUP(AG35,TorchTables!$S$1:$T$27,2,FALSE))
AG36: =IF(D36="",0,COUNTIF(G36:AF36,"Y")) -> 0 | AH36: =IF(D36="","",VLOOKUP(AG36,TorchTables!$S$1:$T$27,2,FALSE))
AG37: =IF(D37="",0,COUNTIF(G37:AF37,"Y")) -> 0 | AH37: =IF(D37="","",VLOOKUP(AG37,TorchTables!$S$1:$T$27,2,FALSE))
... AG509: =IF(D509="",0,COUNTIF(G509:AF509,"Y")) -> 0 | AH509: =IF(D509="","",VLOOKUP(AG509,TorchTables!$S$1:$T$27,2,FALSE))

Sheet Rages
A1: TORCH - The Rages of Mrs Torrens | AJ1: Item Type Key
A2: 3rd Edition
AJ3: Locate
G4: QUESTION No. and ANSWER KEY (Enter the student's response - "Y" if correct, "N" if incorrect) | AJ4: 1 | AK4: Directly stated: verbatim
E5: Question Number | G5: 1 | H5: 2 | I5: 3 | J5: 4 | K5: 5 | L5: 6 | M5: 7 | N5: 8 | O5: 9 | P5: 10 | Q5: 11 | R5: 12 | S5: 13 | T5: 14 | U5: 15 | V5: 16 | W5: 17 | X5: 18 | Y5: 19 | Z5: 20 | AA5: 21 | AB5: 22 | AC5: 23 | AD5: 24 | AE5: 25 | AJ5: 2 | AK5: Directly stated: rephrased, reworded
E6: Item Difficulty | G6: 36 | H6: 49 | I6: 67 | J6: 56 | K6: 60 | L6: 77 | M6: 67 | N6: 65 | O6: 59 | P6: 60 | Q6: 59 | R6: 36 | S6: 61 | T6: 49 | U6: 49 | V6: 63 | W6: 47 | X6: 63 | Y6: 56 | Z6: 60 | AA6: 52 | AB6: 58 | AC6: 59 | AD6: 49 | AE6: 52 | AJ6: Locate, interpret and infer
E7: Item Category | G7: Locate | H7: Locate | I7: Locate, Interpret and Infer | J7: Locate, Interpret and Infer | K7: Locate, Interpret and Infer | L7: Interpret, Infer and Use | M7: Locate, Interpret and Infer | N7: Locate, Interpret and Infer | O7: Locate, Interpret and Infer | P7: Locate, Interpret and Infer | Q7: Locate, Interpret and Infer | R7: Locate | S7: Locate | T7: Locate | U7: Locate | V7: Locate | W7: Locate | X7: Locate, Interpret and Infer | Y7: Locate, Interpret and Infer | Z7: Locate, Interpret and Infer | AA7: Locate, Interpret and Infer | AB7: Locate, Interpret and Infer | AC7: Interpret, Infer and Use | AD7: Locate | AE7: Locate | AJ7: 3 | AK7: Directly stated: across text
AJ8: 4 | AK8: Directly stated: embedded
AJ9: 5 | AK9: Inference: simple, explicit references
AJ10: Interpret, infer and use
