Workbook

Sheet Main Menu
B2: Acadience Reading (2021) K-6 Assessment Scoring Template
B4: This spreadsheet provides the template required to enter results into the Student Performance Analyser (SPA) for an Acadience Reading K-6 assessment. Step 1: Click on the appropriate tab below for the year level you wish to enter data for. Step 2: For each student, enter the Year Level, Name, Student ID, Gender, DOB & Home Group Step 3: Input test round so test results can be analysed using correct benchmarks in SPA. PLEASE NOTE: The values of shaded cells are automatically calculated by a formula. Please do not paste data directly into these cells. Step 4: Save the template to your computer or a school shared-drive. Step 5: Upload the saved template to SPA. (The school can choose to create one template per grade or year level or one template for the whole school.)
B24: Please Note:
B25: According to the Acadience guidelines "The Acadience Reading measures that are used to calculate the [Reading Composite Score] RCS vary by grade and time of year. As such, the RCS is not comparable across different grades and does not provide a direct measure of growth across grades. For grades K through 2, the RCS is also not comparable across different times of year and should not be used as an indicator of growth within a grade." Therefore, SPA will not calculate RCS growth in Foundation, Year 1 or Year 2 data. However, we will calculate within year RCS growth for Year 3,4,5,& 6 data.
B31: The Maze Adjusted Score is a modified score that compensates for student guessing. To calculate the Adjusted Score, use the following formula: Maze Adjusted Score = number of correct responses – (number of incorrect responses ÷ 2). The result of the formula should then be rounded to the nearest whole number. Half-points (0.5) should be rounded up. The minimum Maze Adjusted Score is 0. Do not record a negative number.

Sheet Foundation
A1: Acadience Reading (2021) K-6 Assessment
A4: Required | B4: Required | C4: Required | D4: Required | E4: Optional | F4: Required | G4: Optional | H4: complete all columns or leave blank | L4: complete all columns or leave blank | R4: complete all columns or leave blank
H5: Beginning | L5: Middle | R5: End
P6: Nonsense Word Fluency (NWF) | U6: Nonsense Word Fluency (NWF)
A7: Year Level | B7: Surname | C7: First Name | D7: Student ID | E7: Gender | F7: DOB (dd/mm/yy) | G7: Class | H7: Test Date (dd/mm/yy) | I7: First Sound Fluency (FSF) Score | J7: Letter Name Fluency (LNF) Score | K7: Composite Score | L7: Test Date (dd/mm/yy) | M7: First Sound Fluency (FSF) Score | N7: Letter Name Fluency (LNF) Score | O7: Phonemic Segmentation Fluency (PSF) Score | P7: Correct Letter Sounds (NWF-CLS) Score | Q7: Composite Score | R7: Test Date (dd/mm/yy) | S7: Letter Name Fluency (LNF) Score | T7: Phonemic Segmentation Fluency (PSF) Score | U7: Correct Letter Sounds (NWF-CLS) Score | V7: Composite Score
A8: 3 | B8: Lname1 | C8: Fname1 | D8: XXXXX1 | E8: Female | F8: 40959 | G8: 3A | H8: 45376 | I8: 0 | J8: 0 | K8: 0 | L8: 45441 | M8: 0 | N8: 1 | O8: 0 | P8: 0 | Q8: 1 | R8: 45580 | S8: 2 | T8: 0 | U8: 0 | V8: 2
A9: 3 | B9: Lname2 | C9: Fname2 | D9: XXXXX2 | E9: Male | F9: 40960 | G9: 3A | H9: 45376 | I9: 0 | J9: 0 | K9: 0 | L9: 45441 | M9: 7 | N9: 7 | O9: 2 | P9: 2 | Q9: 18 | R9: 45580 | S9: 19 | T9: 12 | U9: 10 | V9: 41
A10: 3 | B10: Lname3 | C10: Fname3 | D10: XXXXX3 | E10: Female | F10: 40961 | G10: 3A | H10: 45376 | I10: 0 | J10: 1 | K10: 1 | L10: 45441 | M10: 16 | N10: 14 | O10: 8 | P10: 6 | Q10: 44 | R10: 45580 | S10: 28 | T10: 28 | U10: 17 | V10: 73
A11: 3 | B11: Lname4 | C11: Fname4 | D11: XXXXX4 | E11: Female | F11: 40962 | G11: 3A | H11: 45376 | I11: 1 | J11: 2 | K11: 3 | L11: 45441 | M11: 22 | N11: 20 | O11: 11 | P11: 10 | Q11: 63 | R11: 45580 | S11: 33 | T11: 36 | U11: 20 | V11: 89
A12: 3 | B12: ULname13 | C12: UFname13 | D12: UNLISTED | E12: Male | F12: 40970 | G12: 3B | H12: 45376 | I12: 1 | J12: 3 | K12: 4 | L12: 45441 | M12: 26 | N12: 24 | O12: 15 | P12: 13 | Q12: 78 | R12: 45580 | S12: 37 | T12: 41 | U12: 23 | V12: 101
A13: 3 | B13: Lname5 | C13: Fname5 | D13: XXXXX5 | E13: Male | F13: 40963 | G13: 3A | H13: 45376 | I13: 1 | J13: 4 | K13: 5 | L13: 45441 | M13: 29 | N13: 27 | O13: 19 | P13: 15 | Q13: 90 | R13: 45580 | S13: 40 | T13: 44 | U13: 26 | V13: 110
A14: 3 | B14: Lname6 | C14: Fname6 | D14: XXXXX6 | E14: Female | F14: 40964 | G14: 3B | H14: 45376 | I14: 2 | J14: 6 | K14: 8 | L14: 45441 | M14: 32 | N14: 30 | O14: 25 | P14: 17 | Q14: 104 | R14: 45580 | S14: 43 | T14: 46 | U14: 28 | V14: 117
A15: 3 | B15: Lname7 | C15: Fname7 | D15: XXXXX7 | E15: Male | F15: 40965 | G15: 3B | H15: 45376 | I15: 5 | J15: 8 | K15: 13 | L15: 45441 | M15: 35 | N15: 32 | O15: 30 | P15: 19 | Q15: 116 | R15: 45580 | S15: 45 | T15: 49 | U15: 30 | V15: 124
A16: 3 | B16: Lname8 | C16: Fname8 | D16: XXXXX8 | E16: Female | F16: 40966 | G16: 3B | H16: 45376 | I16: 7 | J16: 11 | K16: 18 | L16: 45441 | M16: 37 | N16: 35 | O16: 34 | P16: 21 | Q16: 127 | R16: 45580 | S16: 48 | T16: 51 | U16: 32 | V16: 131
A17: 3 | B17: Lname9 | C17: Fname9 | D17: XXXXX9 | E17: Female | F17: 40967 | G17: 3B | H17: 45376 | I17: 10 | J17: 14 | K17: 24 | L17: 45441 | M17: 39 | N17: 38 | O17: 38 | P17: 23 | Q17: 138 | R17: 45580 | S17: 50 | T17: 52 | U17: 34 | V17: 136
A18: 3 | B18: Lname10 | C18: Fname10 | D18: XXXXX10 | E18: Female | F18: 40968 | G18: 3B | H18: 45376 | I18: 12 | J18: 16 | K18: 28 | L18: 45441 | M18: 41 | N18: 39 | O18: 41 | P18: 25 | Q18: 146 | R18: 45580 | S18: 52 | T18: 54 | U18: 36 | V18: 142
K19: =IF($B19="","",SUM($I19:$J19)) | Q19: =IF($L19="","",SUM($M19:$P19)) | V19: =IF($R19="","",SUM($S19:$U19))
K20: =IF($B20="","",SUM($I20:$J20)) | Q20: =IF($L20="","",SUM($M20:$P20)) | V20: =IF($R20="","",SUM($S20:$U20))
K21: =IF($B21="","",SUM($I21:$J21)) | Q21: =IF($L21="","",SUM($M21:$P21)) | V21: =IF($R21="","",SUM($S21:$U21))
K22: =IF($B22="","",SUM($I22:$J22)) | Q22: =IF($L22="","",SUM($M22:$P22)) | V22: =IF($R22="","",SUM($S22:$U22))
K23: =IF($B23="","",SUM($I23:$J23)) | Q23: =IF($L23="","",SUM($M23:$P23)) | V23: =IF($R23="","",SUM($S23:$U23))
K24: =IF($B24="","",SUM($I24:$J24)) | Q24: =IF($L24="","",SUM($M24:$P24)) | V24: =IF($R24="","",SUM($S24:$U24))
K25: =IF($B25="","",SUM($I25:$J25)) | Q25: =IF($L25="","",SUM($M25:$P25)) | V25: =IF($R25="","",SUM($S25:$U25))
K26: =IF($B26="","",SUM($I26:$J26)) | Q26: =IF($L26="","",SUM($M26:$P26)) | V26: =IF($R26="","",SUM($S26:$U26))
K27: =IF($B27="","",SUM($I27:$J27)) | Q27: =IF($L27="","",SUM($M27:$P27)) | V27: =IF($R27="","",SUM($S27:$U27))
K28: =IF($B28="","",SUM($I28:$J28)) | Q28: =IF($L28="","",SUM($M28:$P28)) | V28: =IF($R28="","",SUM($S28:$U28))
K29: =IF($B29="","",SUM($I29:$J29)) | Q29: =IF($L29="","",SUM($M29:$P29)) | V29: =IF($R29="","",SUM($S29:$U29))
K30: =IF($B30="","",SUM($I30:$J30)) | Q30: =IF($L30="","",SUM($M30:$P30)) | V30: =IF($R30="","",SUM($S30:$U30))
... K397: =IF($B397="","",SUM($I397:$J397)) | Q397: =IF($L397="","",SUM($M397:$P397)) | V397: =IF($R397="","",SUM($S397:$U397))

Sheet Year 1
A1: Acadience Reading (2021) K-6 Assessment | I1: NOTE: Beginning Testing: A score recorded in the Whole Words Read (NWF-WWR) Score column will display in SPA. However, note that these values are not used to calculate a composite score. Middle/End Testing: Scores recorded in the Correct Letter Sounds (NWF-CLS) (END testing) & Retell Score (MIDDLE & END testing) columns will display in SPA. However, note that these values are not used to calculate a composite score.
H3: complete all columns or leave blank | N3: complete all columns or leave blank | U3: complete all columns or leave blank
A4: Required | B4: Required | C4: Required | D4: Required | E4: Optional | F4: Required | G4: Optional | H4: Required | I4: Required | J4: Required | K4: Required | L4: Optional | N4: Required | O4: Required | P4: Required | Q4: Required | R4: Optional | S4: Required | U4: Required | V4: Optional | W4: Required | X4: Required | Y4: Optional | Z4: Required | AA4: Optional
H5: Beginning | N5: Middle | U5: End
K6: Nonsense Word Fluency (NWF) | O6: Nonsense Word Fluency (NWF) | Q6: Oral Reading Fluency (ORF) | V6: Nonsense Word Fluency (NWF) | X6: Oral Reading Fluency (ORF) | AE6: Middle | AF6: End
A7: Year Level | B7: Surname | C7: First Name | D7: Student ID | E7: Gender | F7: DOB (dd/mm/yy) | G7: Class | H7: Test Date (dd/mm/yy) | I7: Letter Name Fluency (LNF) Score | J7: Phonemic Segmentation Fluency (PSF) Score | K7: Correct Letter Sounds (NWF-CLS) Score | L7: Whole Words Read (NWF-WWR) Score | M7: Composite Score | N7: Test Date (dd/mm/yy) | O7: Correct Letter Sounds (NWF-CLS) Score | P7: Whole Words Read (NWF-WWR) Score | Q7: Words Read Correctly (ORF-WRC) Score | R7: ORF-Errors | S7: Accuracy Percent (ORF-AP) | T7: Composite Score | U7: Test Date (dd/mm/yy) | V7: Correct Letter Sounds (NWF-CLS) Score | W7: Whole Words Read (NWF-WWR) Score | X7: Words Read Correctly (ORF-WRC) Score | Y7: ORF-Errors | Z7: Accuracy Percent (ORF-AP) | AA7: Retell | AB7: Composite Score | AE7: Accuracy Value (ORF-AV) | AF7: Accuracy Value (ORF-AV)
A8: 3 | B8: Lname1 | C8: Fname1 | D8: XXXXX1 | E8: Female | F8: 40959 | G8: 3A | H8: 45376 | I8: 2 | J8: 0 | K8: 0 | L8: 0 | M8: 2 | N8: 45441 | O8: 3 | P8: 0 | Q8: 1 | R8: 1 | S8: 0.5 | T8: 30 | U8: 45580 | V8: 6 | W8: 0 | X8: 1 | Y8: 1 | Z8: 0.5 | AA8: 0 | AB8: 1 | AE8: =IF($S8="","",VLOOKUP($S8,'ORF Accuracy Value LookUp'!$A$4:$B$104,2,TRUE)) -> 2 | AF8: =IF($Z8="","",VLOOKUP($Z8,'ORF Accuracy Value LookUp'!$D$4:$E$104,2,TRUE)) -> 0
A9: 3 | B9: Lname2 | C9: Fname2 | D9: XXXXX2 | E9: Male | F9: 40960 | G9: 3A | H9: 45376 | I9: 16 | J9: 8 | K9: 6 | L9: 0 | M9: 30 | N9: 45441 | O9: 19 | P9: 0 | Q9: 5 | R9: 3 | S9: 0.625 | T9: 68 | U9: 45580 | V9: 25 | W9: 1 | X9: 8 | Y9: 3 | Z9: 0.72727273 | AA9: 1 | AB9: 31 | AE9: =IF($S9="","",VLOOKUP($S9,'ORF Accuracy Value LookUp'!$A$4:$B$104,2,TRUE)) -> 26 | AF9: =IF($Z9="","",VLOOKUP($Z9,'ORF Accuracy Value LookUp'!$D$4:$E$104,2,TRUE)) -> 21
A10: 3 | B10: Lname3 | C10: Fname3 | D10: XXXXX3 | E10: Female | F10: 40961 | G10: 3A | H10: 45376 | I10: 23 | J10: 20 | K10: 13 | L10: 0 | M10: 56 | N10: 45441 | O10: 25 | P10: 1 | Q10: 8 | R10: 3 | S10: 0.72727273 | T10: 78 | U10: 45580 | V10: 33 | W10: 4 | X10: 14 | Y10: 3 | Z10: 0.82352941 | AA10: 5 | AB10: 73 | AE10: =IF($S10="","",VLOOKUP($S10,'ORF Accuracy Value LookUp'!$A$4:$B$104,2,TRUE)) -> 44 | AF10: =IF($Z10="","",VLOOKUP($Z10,'ORF Accuracy Value LookUp'!$D$4:$E$104,2,TRUE)) -> 51
A11: 3 | B11: Lname4 | C11: Fname4 | D11: XXXXX4 | E11: Female | F11: 40962 | G11: 3A | H11: 45376 | I11: 27 | J11: 28 | K11: 16 | L11: 0 | M11: 71 | N11: 45441 | O11: 30 | P11: 2 | Q11: 11 | R11: 4 | S11: 0.73333333 | T11: 105 | U11: 45580 | V11: 39 | W11: 7 | X11: 20 | Y11: 4 | Z11: 0.83333333 | AA11: 9 | AB11: 91 | AE11: =IF($S11="","",VLOOKUP($S11,'ORF Accuracy Value LookUp'!$A$4:$B$104,2,TRUE)) -> 44 | AF11: =IF($Z11="","",VLOOKUP($Z11,'ORF Accuracy Value LookUp'!$D$4:$E$104,2,TRUE)) -> 57
A12: 3 | B12: ULname13 | C12: UFname13 | D12: UNLISTED | E12: Male | F12: 40970 | G12: 3B | H12: 45376 | I12: 31 | J12: 32 | K12: 19 | L12: 1 | M12: 82 | N12: 45441 | O12: 34 | P12: 4 | Q12: 13 | R12: 3 | S12: 0.8125 | T12: 113 | U12: 45580 | V12: 44 | W12: 10 | X12: 26 | Y12: 3 | Z12: 0.89655172 | AA12: 11 | AB12: 121 | AE12: =IF($S12="","",VLOOKUP($S12,'ORF Accuracy Value LookUp'!$A$4:$B$104,2,TRUE)) -> 62 | AF12: =IF($Z12="","",VLOOKUP($Z12,'ORF Accuracy Value LookUp'!$D$4:$E$104,2,TRUE)) -> 75
A13: 3 | B13: Lname5 | C13: Fname5 | D13: XXXXX5 | E13: Male | F13: 40963 | G13: 3A | H13: 45376 | I13: 34 | J13: 35 | K13: 21 | L13: 1 | M13: 90 | N13: 45441 | O13: 38 | P13: 6 | Q13: 16 | R13: 4 | S13: 0.8 | T13: 146 | U13: 45580 | V13: 49 | W13: 12 | X13: 31 | Y13: 4 | Z13: 0.88571429 | AA13: 13 | AB13: 124 | AE13: =IF($S13="","",VLOOKUP($S13,'ORF Accuracy Value LookUp'!$A$4:$B$104,2,TRUE)) -> 62 | AF13: =IF($Z13="","",VLOOKUP($Z13,'ORF Accuracy Value LookUp'!$D$4:$E$104,2,TRUE)) -> 69
A14: 3 | B14: Lname6 | C14: Fname6 | D14: XXXXX6 | E14: Female | F14: 40964 | G14: 3B | H14: 45376 | I14: 36 | J14: 38 | K14: 23 | L14: 1 | M14: 97 | N14: 45441 | O14: 41 | P14: 8 | Q14: 18 | R14: 1 | S14: 0.94736842 | T14: 147 | U14: 45580 | V14: 53 | W14: 14 | X14: 36 | Y14: 1 | Z14: 0.97297297 | AA14: 15 | AB14: 163 | AE14: =IF($S14="","",VLOOKUP($S14,'ORF Accuracy Value LookUp'!$A$4:$B$104,2,TRUE)) -> 86 | AF14: =IF($Z14="","",VLOOKUP($Z14,'ORF Accuracy Value LookUp'!$D$4:$E$104,2,TRUE)) -> 99
A15: 3 | B15: Lname7 | C15: Fname7 | D15: XXXXX7 | E15: Male | F15: 40965 | G15: 3B | H15: 45376 | I15: 39 | J15: 40 | K15: 25 | L15: 1 | M15: 104 | N15: 45441 | O15: 44 | P15: 10 | Q15: 20 | R15: 2 | S15: 0.90909091 | T15: 136 | U15: 45580 | V15: 58 | W15: 16 | X15: 42 | Y15: 2 | Z15: 0.95454545 | AA15: 17 | AB15: 167 | AE15: =IF($S15="","",VLOOKUP($S15,'ORF Accuracy Value LookUp'!$A$4:$B$104,2,TRUE)) -> 80 | AF15: =IF($Z15="","",VLOOKUP($Z15,'ORF Accuracy Value LookUp'!$D$4:$E$104,2,TRUE)) -> 93
A16: 3 | B16: Lname8 | C16: Fname8 | D16: XXXXX8 | E16: Female | F16: 40966 | G16: 3B | H16: 45376 | I16: 41 | J16: 42 | K16: 27 | L16: 1 | M16: 110 | N16: 45441 | O16: 47 | P16: 12 | Q16: 23 | R16: 5 | S16: 0.82142857 | T16: 138 | U16: 45580 | V16: 63 | W16: 18 | X16: 48 | Y16: 5 | Z16: 0.90566038 | AA16: 18 | AB16: 159 | AE16: =IF($S16="","",VLOOKUP($S16,'ORF Accuracy Value LookUp'!$A$4:$B$104,2,TRUE)) -> 62 | AF16: =IF($Z16="","",VLOOKUP($Z16,'ORF Accuracy Value LookUp'!$D$4:$E$104,2,TRUE)) -> 75
A17: 3 | B17: Lname9 | C17: Fname9 | D17: XXXXX9 | E17: Female | F17: 40967 | G17: 3B | H17: 45376 | I17: 43 | J17: 44 | K17: 29 | L17: 2 | M17: 116 | N17: 45441 | O17: 51 | P17: 13 | Q17: 25 | R17: 7 | S17: 0.78125 | T17: 139 | U17: 45580 | V17: 68 | W17: 20 | X17: 54 | Y17: 7 | Z17: 0.8852459 | AA17: 20 | AB17: 163 | AE17: =IF($S17="","",VLOOKUP($S17,'ORF Accuracy Value LookUp'!$A$4:$B$104,2,TRUE)) -> 56 | AF17: =IF($Z17="","",VLOOKUP($Z17,'ORF Accuracy Value LookUp'!$D$4:$E$104,2,TRUE)) -> 69
A18: 3 | B18: Lname10 | C18: Fname10 | D18: XXXXX10 | E18: Female | F18: 40968 | G18: 3B | H18: 45376 | I18: 44 | J18: 46 | K18: 32 | L18: 2 | M18: 122 | N18: 45441 | O18: 55 | P18: 15 | Q18: 28 | R18: 9 | S18: 0.75675676 | T18: 190 | U18: 45580 | V18: 73 | W18: 22 | X18: 59 | Y18: 9 | Z18: 0.86764706 | AA18: 21 | AB18: 166 | AE18: =IF($S18="","",VLOOKUP($S18,'ORF Accuracy Value LookUp'!$A$4:$B$104,2,TRUE)) -> 50 | AF18: =IF($Z18="","",VLOOKUP($Z18,'ORF Accuracy Value LookUp'!$D$4:$E$104,2,TRUE)) -> 63
M19: =IF($B19="","",SUM($I19:$K19)) | S19: =IF($Q19="","",SUM($Q19/($Q19+$R19))) | T19: =IF($N19="","",SUM($O19:$Q19,$AE20)) | Z19: =IF($X19="","",SUM($X19/($X19+$Y19))) | AB19: =IF($U19="","",SUM(($W19*2)+$X19+$AF19)) | AE19: =IF($S19="","",VLOOKUP($S19,'ORF Accuracy Value LookUp'!$A$4:$B$104,2,TRUE)) | AF19: =IF($Z19="","",VLOOKUP($Z19,'ORF Accuracy Value LookUp'!$D$4:$E$104,2,TRUE))
M20: =IF($B20="","",SUM($I20:$K20)) | S20: =IF($Q20="","",SUM($Q20/($Q20+$R20))) | T20: =IF($N20="","",SUM($O20:$Q20,$AE21)) | Z20: =IF($X20="","",SUM($X20/($X20+$Y20))) | AB20: =IF($U20="","",SUM(($W20*2)+$X20+$AF20)) | AE20: =IF($S20="","",VLOOKUP($S20,'ORF Accuracy Value LookUp'!$A$4:$B$104,2,TRUE)) | AF20: =IF($Z20="","",VLOOKUP($Z20,'ORF Accuracy Value LookUp'!$D$4:$E$104,2,TRUE))
M21: =IF($B21="","",SUM($I21:$K21)) | S21: =IF($Q21="","",SUM($Q21/($Q21+$R21))) | T21: =IF($N21="","",SUM($O21:$Q21,$AE22)) | Z21: =IF($X21="","",SUM($X21/($X21+$Y21))) | AB21: =IF($U21="","",SUM(($W21*2)+$X21+$AF21)) | AE21: =IF($S21="","",VLOOKUP($S21,'ORF Accuracy Value LookUp'!$A$4:$B$104,2,TRUE)) | AF21: =IF($Z21="","",VLOOKUP($Z21,'ORF Accuracy Value LookUp'!$D$4:$E$104,2,TRUE))
M22: =IF($B22="","",SUM($I22:$K22)) | S22: =IF($Q22="","",SUM($Q22/($Q22+$R22))) | T22: =IF($N22="","",SUM($O22:$Q22,$AE23)) | Z22: =IF($X22="","",SUM($X22/($X22+$Y22))) | AB22: =IF($U22="","",SUM(($W22*2)+$X22+$AF22)) | AE22: =IF($S22="","",VLOOKUP($S22,'ORF Accuracy Value LookUp'!$A$4:$B$104,2,TRUE)) | AF22: =IF($Z22="","",VLOOKUP($Z22,'ORF Accuracy Value LookUp'!$D$4:$E$104,2,TRUE))
M23: =IF($B23="","",SUM($I23:$K23)) | S23: =IF($Q23="","",SUM($Q23/($Q23+$R23))) | T23: =IF($N23="","",SUM($O23:$Q23,$AE24)) | Z23: =IF($X23="","",SUM($X23/($X23+$Y23))) | AB23: =IF($U23="","",SUM(($W23*2)+$X23+$AF23)) | AE23: =IF($S23="","",VLOOKUP($S23,'ORF Accuracy Value LookUp'!$A$4:$B$104,2,TRUE)) | AF23: =IF($Z23="","",VLOOKUP($Z23,'ORF Accuracy Value LookUp'!$D$4:$E$104,2,TRUE))
M24: =IF($B24="","",SUM($I24:$K24)) | S24: =IF($Q24="","",SUM($Q24/($Q24+$R24))) | T24: =IF($N24="","",SUM($O24:$Q24,$AE25)) | Z24: =IF($X24="","",SUM($X24/($X24+$Y24))) | AB24: =IF($U24="","",SUM(($W24*2)+$X24+$AF24)) | AE24: =IF($S24="","",VLOOKUP($S24,'ORF Accuracy Value LookUp'!$A$4:$B$104,2,TRUE)) | AF24: =IF($Z24="","",VLOOKUP($Z24,'ORF Accuracy Value LookUp'!$D$4:$E$104,2,TRUE))
M25: =IF($B25="","",SUM($I25:$K25)) | S25: =IF($Q25="","",SUM($Q25/($Q25+$R25))) | T25: =IF($N25="","",SUM($O25:$Q25,$AE26)) | Z25: =IF($X25="","",SUM($X25/($X25+$Y25))) | AB25: =IF($U25="","",SUM(($W25*2)+$X25+$AF25)) | AE25: =IF($S25="","",VLOOKUP($S25,'ORF Accuracy Value LookUp'!$A$4:$B$104,2,TRUE)) | AF25: =IF($Z25="","",VLOOKUP($Z25,'ORF Accuracy Value LookUp'!$D$4:$E$104,2,TRUE))
M26: =IF($B26="","",SUM($I26:$K26)) | S26: =IF($Q26="","",SUM($Q26/($Q26+$R26))) | T26: =IF($N26="","",SUM($O26:$Q26,$AE27)) | Z26: =IF($X26="","",SUM($X26/($X26+$Y26))) | AB26: =IF($U26="","",SUM(($W26*2)+$X26+$AF26)) | AE26: =IF($S26="","",VLOOKUP($S26,'ORF Accuracy Value LookUp'!$A$4:$B$104,2,TRUE)) | AF26: =IF($Z26="","",VLOOKUP($Z26,'ORF Accuracy Value LookUp'!$D$4:$E$104,2,TRUE))
M27: =IF($B27="","",SUM($I27:$K27)) | S27: =IF($Q27="","",SUM($Q27/($Q27+$R27))) | T27: =IF($N27="","",SUM($O27:$Q27,$AE28)) | Z27: =IF($X27="","",SUM($X27/($X27+$Y27))) | AB27: =IF($U27="","",SUM(($W27*2)+$X27+$AF27)) | AE27: =IF($S27="","",VLOOKUP($S27,'ORF Accuracy Value LookUp'!$A$4:$B$104,2,TRUE)) | AF27: =IF($Z27="","",VLOOKUP($Z27,'ORF Accuracy Value LookUp'!$D$4:$E$104,2,TRUE))
M28: =IF($B28="","",SUM($I28:$K28)) | S28: =IF($Q28="","",SUM($Q28/($Q28+$R28))) | T28: =IF($N28="","",SUM($O28:$Q28,$AE29)) | Z28: =IF($X28="","",SUM($X28/($X28+$Y28))) | AB28: =IF($U28="","",SUM(($W28*2)+$X28+$AF28)) | AE28: =IF($S28="","",VLOOKUP($S28,'ORF Accuracy Value LookUp'!$A$4:$B$104,2,TRUE)) | AF28: =IF($Z28="","",VLOOKUP($Z28,'ORF Accuracy Value LookUp'!$D$4:$E$104,2,TRUE))
M29: =IF($B29="","",SUM($I29:$K29)) | S29: =IF($Q29="","",SUM($Q29/($Q29+$R29))) | T29: =IF($N29="","",SUM($O29:$Q29,$AE30)) | Z29: =IF($X29="","",SUM($X29/($X29+$Y29))) | AB29: =IF($U29="","",SUM(($W29*2)+$X29+$AF29)) | AE29: =IF($S29="","",VLOOKUP($S29,'ORF Accuracy Value LookUp'!$A$4:$B$104,2,TRUE)) | AF29: =IF($Z29="","",VLOOKUP($Z29,'ORF Accuracy Value LookUp'!$D$4:$E$104,2,TRUE))
M30: =IF($B30="","",SUM($I30:$K30)) | S30: =IF($Q30="","",SUM($Q30/($Q30+$R30))) | T30: =IF($N30="","",SUM($O30:$Q30,$AE31)) | Z30: =IF($X30="","",SUM($X30/($X30+$Y30))) | AB30: =IF($U30="","",SUM(($W30*2)+$X30+$AF30)) | AE30: =IF($S30="","",VLOOKUP($S30,'ORF Accuracy Value LookUp'!$A$4:$B$104,2,TRUE)) | AF30: =IF($Z30="","",VLOOKUP($Z30,'ORF Accuracy Value LookUp'!$D$4:$E$104,2,TRUE))
... M395: =IF($B395="","",SUM($I395:$K395)) | S395: =IF($Q395="","",SUM($Q395/($Q395+$R395))) | T395: =IF($N395="","",SUM($O395:$Q395,$AE396)) | Z395: =IF($X395="","",SUM($X395/($X395+$Y395))) | AB395: =IF($U395="","",SUM(($W395*2)+$X395+$AF395)) | AE395: =IF($S395="","",VLOOKUP($S395,'ORF Accuracy Value LookUp'!$A$4:$B$104,2,TRUE)) | AF395: =IF($Z395="","",VLOOKUP($Z395,'ORF Accuracy Value LookUp'!$D$4:$E$104,2,TRUE))

Sheet Year 2
A1: Acadience Reading (2021) K-6 Assessment | I1: NOTE: Beginning Testing: Scores recorded in the Correct Letter Sounds (NWF-CLS) & Retell Score columns will display in SPA. However, note that these values are not used to calculate a composite score. Middle/End Testing: If ORF-WRC is below 40 and Retell is not administered, use 0 for the Retell value only. This ensures an accurate Acadience Reading Composite Score can be calculated. A score recorded in the Retell Quality of Response column will display in SPA. However, note that this value is not used to calculate a composite score.
H3: complete all columns or leave blank | P3: complete all columns or leave blank | W3: complete all columns or leave blank
A4: Required | B4: Required | C4: Required | D4: Required | E4: Optional | F4: Required | G4: Optional | H4: Required | I4: Optional | J4: Required | K4: Required | L4: Optional | M4: Required | N4: Optional | P4: Required | Q4: Required | R4: Optional | S4: Required | T4: Required | U4: Optional | W4: Required | X4: Required | Y4: Optional | Z4: Required | AA4: Required | AB4: Optional
H5: Beginning | P5: Middle | W5: End
I6: Nonsense Word Fluency (NWF) | K6: Oral Reading Fluency (ORF) | Q6: Oral Reading Fluency (ORF) | X6: Oral Reading Fluency (ORF) | AF6: Beginning | AG6: Middle | AH6: End
A7: Year Level | B7: Surname | C7: First Name | D7: Student ID | E7: Gender | F7: DOB (dd/mm/yy) | G7: Class | H7: Test Date (dd/mm/yy) | I7: Correct Letter Sounds (NWF-CLS) Score | J7: Whole Words Read (NWF-WWR) Score | K7: Words Read Correctly (ORF-WRC) Score | L7: ORF-Errors | M7: Accuracy Percent (ORF-AP) | N7: Retell | O7: Composite Score | P7: Test Date (dd/mm/yy) | Q7: Words Read Correctly (ORF-WRC) Score | R7: ORF-Errors | S7: Accuracy Percent (ORF-AP) | T7: Retell | U7: Retell Quality of Response | V7: Composite Score | W7: Test Date (dd/mm/yy) | X7: Words Read Correctly (ORF-WRC) Score | Y7: ORF-Errors | Z7: Accuracy Percent (ORF-AP) | AA7: Retell | AB7: Retell Quality of Response | AC7: Composite Score | AF7: Accuracy Value (ORF-AV) | AG7: Accuracy Value (ORF-AV) | AH7: Accuracy Value (ORF-AV)
A8: 3 | B8: Lname1 | C8: Fname1 | D8: XXXXX1 | E8: Female | F8: 40959 | G8: 3A | H8: 45376 | I8: 2 | J8: 0 | K8: 1 | L8: 1 | M8: 0.5 | N8: 0 | O8: 1 | P8: 45441 | Q8: 1 | R8: 1 | S8: 0.5 | T8: 0 | U8: 2 | V8: 1 | W8: 45580 | X8: 1 | Y8: 1 | Z8: 0.5 | AA8: 0 | AB8: 2 | AC8: 1 | AF8: =IF($M8="","",VLOOKUP($M8,'ORF Accuracy Value LookUp'!$D$4:$E$104,2,TRUE)) -> 0 | AG8: =IF($S8="","",VLOOKUP($S8,'ORF Accuracy Value LookUp'!$G$4:$H$104,2,TRUE)) -> 0 | AH8: =IF($Z8="","",VLOOKUP($Z8,'ORF Accuracy Value LookUp'!$G$4:$H$104,2,TRUE)) -> 0
A9: 3 | B9: Lname2 | C9: Fname2 | D9: XXXXX2 | E9: Male | F9: 40960 | G9: 3A | H9: 45376 | I9: 19 | J9: 1 | K9: 7 | L9: 3 | M9: 0.7 | N9: 2 | O9: 24 | P9: 45441 | Q9: 5 | R9: 3 | S9: 0.625 | T9: 1 | U9: 2 | V9: 7 | W9: 45580 | X9: 8 | Y9: 3 | Z9: 0.72727273 | AA9: 1 | AB9: 2 | AC9: 10 | AF9: =IF($M9="","",VLOOKUP($M9,'ORF Accuracy Value LookUp'!$D$4:$E$104,2,TRUE)) -> 15 | AG9: =IF($S9="","",VLOOKUP($S9,'ORF Accuracy Value LookUp'!$G$4:$H$104,2,TRUE)) -> 0 | AH9: =IF($Z9="","",VLOOKUP($Z9,'ORF Accuracy Value LookUp'!$G$4:$H$104,2,TRUE)) -> 0
A10: 3 | B10: Lname3 | C10: Fname3 | D10: XXXXX3 | E10: Female | F10: 40961 | G10: 3A | H10: 45376 | I10: 26 | J10: 2 | K10: 15 | L10: 3 | M10: 0.83333333 | N10: 7 | O10: 76 | P10: 45441 | Q10: 8 | R10: 3 | S10: 0.72727273 | T10: 2 | U10: 2 | V10: 12 | W10: 45580 | X10: 14 | Y10: 3 | Z10: 0.82352941 | AA10: 5 | AB10: 2 | AC10: 24 | AF10: =IF($M10="","",VLOOKUP($M10,'ORF Accuracy Value LookUp'!$D$4:$E$104,2,TRUE)) -> 57 | AG10: =IF($S10="","",VLOOKUP($S10,'ORF Accuracy Value LookUp'!$G$4:$H$104,2,TRUE)) -> 0 | AH10: =IF($Z10="","",VLOOKUP($Z10,'ORF Accuracy Value LookUp'!$G$4:$H$104,2,TRUE)) -> 0
A11: 3 | B11: Lname4 | C11: Fname4 | D11: XXXXX4 | E11: Female | F11: 40962 | G11: 3A | H11: 45376 | I11: 32 | J11: 5 | K11: 24 | L11: 4 | M11: 0.85714286 | N11: 10 | O11: 97 | P11: 45441 | Q11: 11 | R11: 4 | S11: 0.73333333 | T11: 5 | U11: 1 | V11: 21 | W11: 45580 | X11: 20 | Y11: 4 | Z11: 0.83333333 | AA11: 9 | AB11: 1 | AC11: 38 | AF11: =IF($M11="","",VLOOKUP($M11,'ORF Accuracy Value LookUp'!$D$4:$E$104,2,TRUE)) -> 63 | AG11: =IF($S11="","",VLOOKUP($S11,'ORF Accuracy Value LookUp'!$G$4:$H$104,2,TRUE)) -> 0 | AH11: =IF($Z11="","",VLOOKUP($Z11,'ORF Accuracy Value LookUp'!$G$4:$H$104,2,TRUE)) -> 0
A12: 3 | B12: ULname13 | C12: UFname13 | D12: UNLISTED | E12: Male | F12: 40970 | G12: 3B | H12: 45376 | I12: 37 | J12: 7 | K12: 30 | L12: 3 | M12: 0.90909091 | N12: 12 | O12: 119 | P12: 45441 | Q12: 13 | R12: 3 | S12: 0.8125 | T12: 6 | U12: 0 | V12: 25 | W12: 45580 | X12: 26 | Y12: 3 | Z12: 0.89655172 | AA12: 11 | AB12: 0 | AC12: 80 | AF12: =IF($M12="","",VLOOKUP($M12,'ORF Accuracy Value LookUp'!$D$4:$E$104,2,TRUE)) -> 75 | AG12: =IF($S12="","",VLOOKUP($S12,'ORF Accuracy Value LookUp'!$G$4:$H$104,2,TRUE)) -> 0 | AH12: =IF($Z12="","",VLOOKUP($Z12,'ORF Accuracy Value LookUp'!$G$4:$H$104,2,TRUE)) -> 32
A13: 3 | B13: Lname5 | C13: Fname5 | D13: XXXXX5 | E13: Male | F13: 40963 | G13: 3A | H13: 45376 | I13: 41 | J13: 9 | K13: 36 | L13: 4 | M13: 0.9 | N13: 14 | O13: 129 | P13: 45441 | Q13: 16 | R13: 4 | S13: 0.8 | T13: 8 | U13: 0 | V13: 32 | W13: 45580 | X13: 31 | Y13: 4 | Z13: 0.88571429 | AA13: 13 | AB13: 0 | AC13: 81 | AF13: =IF($M13="","",VLOOKUP($M13,'ORF Accuracy Value LookUp'!$D$4:$E$104,2,TRUE)) -> 75 | AG13: =IF($S13="","",VLOOKUP($S13,'ORF Accuracy Value LookUp'!$G$4:$H$104,2,TRUE)) -> 0 | AH13: =IF($Z13="","",VLOOKUP($Z13,'ORF Accuracy Value LookUp'!$G$4:$H$104,2,TRUE)) -> 24
A14: 3 | B14: Lname6 | C14: Fname6 | D14: XXXXX6 | E14: Female | F14: 40964 | G14: 3B | H14: 45376 | I14: 46 | J14: 11 | K14: 41 | L14: 1 | M14: 0.97619048 | N14: 16 | O14: 162 | P14: 45441 | Q14: 18 | R14: 1 | S14: 0.94736842 | T14: 10 | U14: 2 | V14: 110 | W14: 45580 | X14: 36 | Y14: 1 | Z14: 0.97297297 | AA14: 15 | AB14: 2 | AC14: 162 | AF14: =IF($M14="","",VLOOKUP($M14,'ORF Accuracy Value LookUp'!$D$4:$E$104,2,TRUE)) -> 99 | AG14: =IF($S14="","",VLOOKUP($S14,'ORF Accuracy Value LookUp'!$G$4:$H$104,2,TRUE)) -> 72 | AH14: =IF($Z14="","",VLOOKUP($Z14,'ORF Accuracy Value LookUp'!$G$4:$H$104,2,TRUE)) -> 96
A15: 3 | B15: Lname7 | C15: Fname7 | D15: XXXXX7 | E15: Male | F15: 40965 | G15: 3B | H15: 45376 | I15: 51 | J15: 13 | K15: 46 | L15: 2 | M15: 0.95833333 | N15: 18 | O15: 165 | P15: 45441 | Q15: 20 | R15: 2 | S15: 0.90909091 | T15: 11 | U15: 1 | V15: 82 | W15: 45580 | X15: 42 | Y15: 2 | Z15: 0.95454545 | AA15: 17 | AB15: 1 | AC15: 156 | AF15: =IF($M15="","",VLOOKUP($M15,'ORF Accuracy Value LookUp'!$D$4:$E$104,2,TRUE)) -> 93 | AG15: =IF($S15="","",VLOOKUP($S15,'ORF Accuracy Value LookUp'!$G$4:$H$104,2,TRUE)) -> 40 | AH15: =IF($Z15="","",VLOOKUP($Z15,'ORF Accuracy Value LookUp'!$G$4:$H$104,2,TRUE)) -> 80
A16: 3 | B16: Lname8 | C16: Fname8 | D16: XXXXX8 | E16: Female | F16: 40966 | G16: 3B | H16: 45376 | I16: 56 | J16: 15 | K16: 51 | L16: 5 | M16: 0.91071429 | N16: 19 | O16: 162 | P16: 45441 | Q16: 23 | R16: 5 | S16: 0.82142857 | T16: 12 | U16: 2 | V16: 47 | W16: 45580 | X16: 48 | Y16: 5 | Z16: 0.90566038 | AA16: 18 | AB16: 2 | AC16: 124 | AF16: =IF($M16="","",VLOOKUP($M16,'ORF Accuracy Value LookUp'!$D$4:$E$104,2,TRUE)) -> 81 | AG16: =IF($S16="","",VLOOKUP($S16,'ORF Accuracy Value LookUp'!$G$4:$H$104,2,TRUE)) -> 0 | AH16: =IF($Z16="","",VLOOKUP($Z16,'ORF Accuracy Value LookUp'!$G$4:$H$104,2,TRUE)) -> 40
A17: 3 | B17: Lname9 | C17: Fname9 | D17: XXXXX9 | E17: Female | F17: 40967 | G17: 3B | H17: 45376 | I17: 61 | J17: 17 | K17: 56 | L17: 7 | M17: 0.88888889 | N17: 21 | O17: 159 | P17: 45441 | Q17: 25 | R17: 7 | S17: 0.78125 | T17: 14 | U17: 1 | V17: 53 | W17: 45580 | X17: 54 | Y17: 7 | Z17: 0.8852459 | AA17: 20 | AB17: 1 | AC17: 118 | AF17: =IF($M17="","",VLOOKUP($M17,'ORF Accuracy Value LookUp'!$D$4:$E$104,2,TRUE)) -> 69 | AG17: =IF($S17="","",VLOOKUP($S17,'ORF Accuracy Value LookUp'!$G$4:$H$104,2,TRUE)) -> 0 | AH17: =IF($Z17="","",VLOOKUP($Z17,'ORF Accuracy Value LookUp'!$G$4:$H$104,2,TRUE)) -> 24
A18: 3 | B18: Lname10 | C18: Fname10 | D18: XXXXX10 | E18: Female | F18: 40968 | G18: 3B | H18: 45376 | I18: 67 | J18: 19 | K18: 60 | L18: 9 | M18: 0.86956522 | N18: 23 | O18: 161 | P18: 45441 | Q18: 28 | R18: 9 | S18: 0.75675676 | T18: 15 | U18: 1 | V18: 58 | W18: 45580 | X18: 59 | Y18: 9 | Z18: 0.86764706 | AA18: 21 | AB18: 1 | AC18: 109 | AF18: =IF($M18="","",VLOOKUP($M18,'ORF Accuracy Value LookUp'!$D$4:$E$104,2,TRUE)) -> 63 | AG18: =IF($S18="","",VLOOKUP($S18,'ORF Accuracy Value LookUp'!$G$4:$H$104,2,TRUE)) -> 0 | AH18: =IF($Z18="","",VLOOKUP($Z18,'ORF Accuracy Value LookUp'!$G$4:$H$104,2,TRUE)) -> 8
M19: =IF($K19="","",SUM($K19/($K19+$L19))) | O19: =IF($B19="","",SUM(($J19*2)+$K19+$AF19)) | S19: =IF($Q19="","",SUM($Q19/($Q19+$R19))) | V19: =IF($P19="","",SUM($Q19+$AG19+($T19*2))) | Z19: =IF($X19="","",SUM($X19/($X19+$Y19))) | AC19: =IF($W19="","",SUM($X19+$AH19+($AA19*2))) | AF19: =IF($M19="","",VLOOKUP($M19,'ORF Accuracy Value LookUp'!$D$4:$E$104,2,TRUE)) | AG19: =IF($S19="","",VLOOKUP($S19,'ORF Accuracy Value LookUp'!$G$4:$H$104,2,TRUE)) | AH19: =IF($Z19="","",VLOOKUP($Z19,'ORF Accuracy Value LookUp'!$G$4:$H$104,2,TRUE))
M20: =IF($K20="","",SUM($K20/($K20+$L20))) | O20: =IF($B20="","",SUM(($J20*2)+$K20+$AF20)) | S20: =IF($Q20="","",SUM($Q20/($Q20+$R20))) | V20: =IF($P20="","",SUM($Q20+$AG20+($T20*2))) | Z20: =IF($X20="","",SUM($X20/($X20+$Y20))) | AC20: =IF($W20="","",SUM($X20+$AH20+($AA20*2))) | AF20: =IF($M20="","",VLOOKUP($M20,'ORF Accuracy Value LookUp'!$D$4:$E$104,2,TRUE)) | AG20: =IF($S20="","",VLOOKUP($S20,'ORF Accuracy Value LookUp'!$G$4:$H$104,2,TRUE)) | AH20: =IF($Z20="","",VLOOKUP($Z20,'ORF Accuracy Value LookUp'!$G$4:$H$104,2,TRUE))
M21: =IF($K21="","",SUM($K21/($K21+$L21))) | O21: =IF($B21="","",SUM(($J21*2)+$K21+$AF21)) | S21: =IF($Q21="","",SUM($Q21/($Q21+$R21))) | V21: =IF($P21="","",SUM($Q21+$AG21+($T21*2))) | Z21: =IF($X21="","",SUM($X21/($X21+$Y21))) | AC21: =IF($W21="","",SUM($X21+$AH21+($AA21*2))) | AF21: =IF($M21="","",VLOOKUP($M21,'ORF Accuracy Value LookUp'!$D$4:$E$104,2,TRUE)) | AG21: =IF($S21="","",VLOOKUP($S21,'ORF Accuracy Value LookUp'!$G$4:$H$104,2,TRUE)) | AH21: =IF($Z21="","",VLOOKUP($Z21,'ORF Accuracy Value LookUp'!$G$4:$H$104,2,TRUE))
M22: =IF($K22="","",SUM($K22/($K22+$L22))) | O22: =IF($B22="","",SUM(($J22*2)+$K22+$AF22)) | S22: =IF($Q22="","",SUM($Q22/($Q22+$R22))) | V22: =IF($P22="","",SUM($Q22+$AG22+($T22*2))) | Z22: =IF($X22="","",SUM($X22/($X22+$Y22))) | AC22: =IF($W22="","",SUM($X22+$AH22+($AA22*2))) | AF22: =IF($M22="","",VLOOKUP($M22,'ORF Accuracy Value LookUp'!$D$4:$E$104,2,TRUE)) | AG22: =IF($S22="","",VLOOKUP($S22,'ORF Accuracy Value LookUp'!$G$4:$H$104,2,TRUE)) | AH22: =IF($Z22="","",VLOOKUP($Z22,'ORF Accuracy Value LookUp'!$G$4:$H$104,2,TRUE))
M23: =IF($K23="","",SUM($K23/($K23+$L23))) | O23: =IF($B23="","",SUM(($J23*2)+$K23+$AF23)) | S23: =IF($Q23="","",SUM($Q23/($Q23+$R23))) | V23: =IF($P23="","",SUM($Q23+$AG23+($T23*2))) | Z23: =IF($X23="","",SUM($X23/($X23+$Y23))) | AC23: =IF($W23="","",SUM($X23+$AH23+($AA23*2))) | AF23: =IF($M23="","",VLOOKUP($M23,'ORF Accuracy Value LookUp'!$D$4:$E$104,2,TRUE)) | AG23: =IF($S23="","",VLOOKUP($S23,'ORF Accuracy Value LookUp'!$G$4:$H$104,2,TRUE)) | AH23: =IF($Z23="","",VLOOKUP($Z23,'ORF Accuracy Value LookUp'!$G$4:$H$104,2,TRUE))
M24: =IF($K24="","",SUM($K24/($K24+$L24))) | O24: =IF($B24="","",SUM(($J24*2)+$K24+$AF24)) | S24: =IF($Q24="","",SUM($Q24/($Q24+$R24))) | V24: =IF($P24="","",SUM($Q24+$AG24+($T24*2))) | Z24: =IF($X24="","",SUM($X24/($X24+$Y24))) | AC24: =IF($W24="","",SUM($X24+$AH24+($AA24*2))) | AF24: =IF($M24="","",VLOOKUP($M24,'ORF Accuracy Value LookUp'!$D$4:$E$104,2,TRUE)) | AG24: =IF($S24="","",VLOOKUP($S24,'ORF Accuracy Value LookUp'!$G$4:$H$104,2,TRUE)) | AH24: =IF($Z24="","",VLOOKUP($Z24,'ORF Accuracy Value LookUp'!$G$4:$H$104,2,TRUE))
M25: =IF($K25="","",SUM($K25/($K25+$L25))) | O25: =IF($B25="","",SUM(($J25*2)+$K25+$AF25)) | S25: =IF($Q25="","",SUM($Q25/($Q25+$R25))) | V25: =IF($P25="","",SUM($Q25+$AG25+($T25*2))) | Z25: =IF($X25="","",SUM($X25/($X25+$Y25))) | AC25: =IF($W25="","",SUM($X25+$AH25+($AA25*2))) | AF25: =IF($M25="","",VLOOKUP($M25,'ORF Accuracy Value LookUp'!$D$4:$E$104,2,TRUE)) | AG25: =IF($S25="","",VLOOKUP($S25,'ORF Accuracy Value LookUp'!$G$4:$H$104,2,TRUE)) | AH25: =IF($Z25="","",VLOOKUP($Z25,'ORF Accuracy Value LookUp'!$G$4:$H$104,2,TRUE))
M26: =IF($K26="","",SUM($K26/($K26+$L26))) | O26: =IF($B26="","",SUM(($J26*2)+$K26+$AF26)) | S26: =IF($Q26="","",SUM($Q26/($Q26+$R26))) | V26: =IF($P26="","",SUM($Q26+$AG26+($T26*2))) | Z26: =IF($X26="","",SUM($X26/($X26+$Y26))) | AC26: =IF($W26="","",SUM($X26+$AH26+($AA26*2))) | AF26: =IF($M26="","",VLOOKUP($M26,'ORF Accuracy Value LookUp'!$D$4:$E$104,2,TRUE)) | AG26: =IF($S26="","",VLOOKUP($S26,'ORF Accuracy Value LookUp'!$G$4:$H$104,2,TRUE)) | AH26: =IF($Z26="","",VLOOKUP($Z26,'ORF Accuracy Value LookUp'!$G$4:$H$104,2,TRUE))
M27: =IF($K27="","",SUM($K27/($K27+$L27))) | O27: =IF($B27="","",SUM(($J27*2)+$K27+$AF27)) | S27: =IF($Q27="","",SUM($Q27/($Q27+$R27))) | V27: =IF($P27="","",SUM($Q27+$AG27+($T27*2))) | Z27: =IF($X27="","",SUM($X27/($X27+$Y27))) | AC27: =IF($W27="","",SUM($X27+$AH27+($AA27*2))) | AF27: =IF($M27="","",VLOOKUP($M27,'ORF Accuracy Value LookUp'!$D$4:$E$104,2,TRUE)) | AG27: =IF($S27="","",VLOOKUP($S27,'ORF Accuracy Value LookUp'!$G$4:$H$104,2,TRUE)) | AH27: =IF($Z27="","",VLOOKUP($Z27,'ORF Accuracy Value LookUp'!$G$4:$H$104,2,TRUE))
M28: =IF($K28="","",SUM($K28/($K28+$L28))) | O28: =IF($B28="","",SUM(($J28*2)+$K28+$AF28)) | S28: =IF($Q28="","",SUM($Q28/($Q28+$R28))) | V28: =IF($P28="","",SUM($Q28+$AG28+($T28*2))) | Z28: =IF($X28="","",SUM($X28/($X28+$Y28))) | AC28: =IF($W28="","",SUM($X28+$AH28+($AA28*2))) | AF28: =IF($M28="","",VLOOKUP($M28,'ORF Accuracy Value LookUp'!$D$4:$E$104,2,TRUE)) | AG28: =IF($S28="","",VLOOKUP($S28,'ORF Accuracy Value LookUp'!$G$4:$H$104,2,TRUE)) | AH28: =IF($Z28="","",VLOOKUP($Z28,'ORF Accuracy Value LookUp'!$G$4:$H$104,2,TRUE))
M29: =IF($K29="","",SUM($K29/($K29+$L29))) | O29: =IF($B29="","",SUM(($J29*2)+$K29+$AF29)) | S29: =IF($Q29="","",SUM($Q29/($Q29+$R29))) | V29: =IF($P29="","",SUM($Q29+$AG29+($T29*2))) | Z29: =IF($X29="","",SUM($X29/($X29+$Y29))) | AC29: =IF($W29="","",SUM($X29+$AH29+($AA29*2))) | AF29: =IF($M29="","",VLOOKUP($M29,'ORF Accuracy Value LookUp'!$D$4:$E$104,2,TRUE)) | AG29: =IF($S29="","",VLOOKUP($S29,'ORF Accuracy Value LookUp'!$G$4:$H$104,2,TRUE)) | AH29: =IF($Z29="","",VLOOKUP($Z29,'ORF Accuracy Value LookUp'!$G$4:$H$104,2,TRUE))
M30: =IF($K30="","",SUM($K30/($K30+$L30))) | O30: =IF($B30="","",SUM(($J30*2)+$K30+$AF30)) | S30: =IF($Q30="","",SUM($Q30/($Q30+$R30))) | V30: =IF($P30="","",SUM($Q30+$AG30+($T30*2))) | Z30: =IF($X30="","",SUM($X30/($X30+$Y30))) | AC30: =IF($W30="","",SUM($X30+$AH30+($AA30*2))) | AF30: =IF($M30="","",VLOOKUP($M30,'ORF Accuracy Value LookUp'!$D$4:$E$104,2,TRUE)) | AG30: =IF($S30="","",VLOOKUP($S30,'ORF Accuracy Value LookUp'!$G$4:$H$104,2,TRUE)) | AH30: =IF($Z30="","",VLOOKUP($Z30,'ORF Accuracy Value LookUp'!$G$4:$H$104,2,TRUE))
... M399: =IF($K399="","",SUM($K399/($K399+$L399))) | O399: =IF($B399="","",SUM(($J399*2)+$K399+$AF399)) | S399: =IF($Q399="","",SUM($Q399/($Q399+$R399))) | V399: =IF($P399="","",SUM($Q399+$AG399+($T399*2))) | Z399: =IF($X399="","",SUM($X399/($X399+$Y399))) | AC399: =IF($W399="","",SUM($X399+$AH399+($AA399*2))) | AF399: =IF($M399="","",VLOOKUP($M399,'ORF Accuracy Value LookUp'!$D$4:$E$104,2,TRUE)) | AG399: =IF($S399="","",VLOOKUP($S399,'ORF Accuracy Value LookUp'!$G$4:$H$104,2,TRUE)) | AH399: =IF($Z399="","",VLOOKUP($Z399,'ORF Accuracy Value LookUp'!$G$4:$H$104,2,TRUE))

Sheet Year 3
A1: Acadience Reading (2021) K-6 Assessment | I1: NOTE: If ORF-WRC is below 40 and Retell is not administered, use 0 for the Retell value only. This ensures an accurate Acadience Reading Composite Score can be calculated. A score recorded in the Retell Quality of Response column will display in SPA. However, note that this value is not used to calculate a composite score.
H3: complete all columns or leave blank | R3: complete all columns or leave blank | AB3: complete all columns or leave blank
A4: Required | B4: Required | C4: Required | D4: Required | E4: Optional | F4: Required | G4: Optional | H4: Required | I4: Required | J4: Optional | K4: Required | L4: Required | M4: Optional | N4: Optional | O4: Optional | P4: Required | R4: Required | S4: Required | T4: Optional | U4: Required | V4: Required | W4: Optional | X4: Optional | Y4: Optional | Z4: Required | AB4: Required | AC4: Required | AD4: Optional | AE4: Required | AF4: Required | AG4: Optional | AH4: Optional | AI4: Optional | AJ4: Required
H5: Beginning | R5: Middle | AB5: End
I6: Oral Reading Fluency (ORF) | N6: MAZE | S6: Oral Reading Fluency (ORF) | X6: MAZE | AC6: Oral Reading Fluency (ORF) | AH6: MAZE | AN6: Beginning | AP6: Middle | AR6: End
A7: Year Level | B7: Surname | C7: First Name | D7: Student ID | E7: Gender | F7: DOB (dd/mm/yy) | G7: Class | H7: Test Date (dd/mm/yy) | I7: Words Read Correctly (ORF-WRC) Score | J7: ORF-Errors | K7: Accuracy Percent (ORF-AP) | L7: Retell | M7: Retell Quality of Response | N7: Maze Correct | O7: Maze Errors | P7: Maze Adjusted Score | Q7: Composite Score | R7: Test Date (dd/mm/yy) | S7: Words Read Correctly (ORF-WRC) Score | T7: ORF-Errors | U7: Accuracy Percent (ORF-AP) | V7: Retell | W7: Retell Quality of Response | X7: Maze Correct | Y7: Maze Errors | Z7: Maze Adjusted Score | AA7: Composite Score | AB7: Test Date (dd/mm/yy) | AC7: Words Read Correctly (ORF-WRC) Score | AD7: ORF-Errors | AE7: Accuracy Percent (ORF-AP) | AF7: Retell | AG7: Retell Quality of Response | AH7: Maze Correct | AI7: Maze Errors | AJ7: Maze Adjusted Score | AK7: Composite Score | AN7: Accuracy Value (ORF-AV) | AO7: Maze Adjusted Score calculation | AP7: Accuracy Value (ORF-AV) | AQ7: Maze Adjusted Score calculation | AR7: Accuracy Value (ORF-AV) | AS7: Maze Adjusted Score calculation
A8: 3 | B8: Lname1 | C8: Fname1 | D8: XXXXX1 | E8: Female | F8: 40959 | G8: 3A | H8: 45376 | I8: 2 | J8: 1 | K8: 0.66666667 | L8: 0 | M8: 2 | N8: 0 | O8: 1 | P8: 0 | Q8: 2 | R8: 45441 | S8: 5 | T8: 1 | U8: 0.83333333 | V8: 0 | W8: 2 | X8: 0 | Y8: 1 | Z8: 0 | AA8: 5 | AB8: 45580 | AC8: 8 | AD8: 1 | AE8: 0.88888889 | AF8: 0 | AG8: 2 | AH8: 0 | AI8: 1 | AJ8: 0 | AK8: 32 | AN8: =IF($K8="","",VLOOKUP($K8,'ORF Accuracy Value LookUp'!$G$4:$H$104,2,TRUE)) -> 0 | AO8: =IF($N8="","",($N8-($O8/2))) -> -0.5 | AP8: =IF($U8="","",VLOOKUP($U8,'ORF Accuracy Value LookUp'!$G$4:$H$104,2,TRUE)) -> 0 | AQ8: =IF($X8="","",$X8-($Y8/2)) -> -0.5 | AR8: =IF($AE8="","",VLOOKUP($AE8,'ORF Accuracy Value LookUp'!$G$4:$H$104,2,TRUE)) -> 24 | AS8: =IF($AH8="","",$AH8-($AI8/2)) -> -0.5
A9: 3 | B9: Lname2 | C9: Fname2 | D9: XXXXX2 | E9: Male | F9: 40960 | G9: 3A | H9: 45376 | I9: 15 | J9: 3 | K9: 0.83333333 | L9: 5 | M9: 2 | N9: 1 | O9: 3 | P9: 0 | Q9: 25 | R9: 45441 | S9: 28 | T9: 3 | U9: 0.90322581 | V9: 9 | W9: 2 | X9: 1 | Y9: 3 | Z9: 0 | AA9: 86 | AB9: 45580 | AC9: 33 | AD9: 3 | AE9: 0.91666667 | AF9: 11 | AG9: 2 | AH9: 1 | AI9: 3 | AJ9: 0 | AK9: 103 | AN9: =IF($K9="","",VLOOKUP($K9,'ORF Accuracy Value LookUp'!$G$4:$H$104,2,TRUE)) -> 0 | AO9: =IF($N9="","",($N9-($O9/2))) -> -0.5 | AP9: =IF($U9="","",VLOOKUP($U9,'ORF Accuracy Value LookUp'!$G$4:$H$104,2,TRUE)) -> 40 | AQ9: =IF($X9="","",$X9-($Y9/2)) -> -0.5 | AR9: =IF($AE9="","",VLOOKUP($AE9,'ORF Accuracy Value LookUp'!$G$4:$H$104,2,TRUE)) -> 48 | AS9: =IF($AH9="","",$AH9-($AI9/2)) -> -0.5
A10: 3 | B10: Lname3 | C10: Fname3 | D10: XXXXX3 | E10: Female | F10: 40961 | G10: 3A | H10: 45376 | I10: 29 | J10: 3 | K10: 0.90625 | L10: 11 | M10: 2 | N10: 1 | O10: 3 | P10: 0 | Q10: 91 | R10: 45441 | S10: 43 | T10: 3 | U10: 0.93478261 | V10: 14 | W10: 2 | X10: 1 | Y10: 3 | Z10: 0 | AA10: 135 | AB10: 45580 | AC10: 55 | AD10: 3 | AE10: 0.94827586 | AF10: 17 | AG10: 2 | AH10: 1 | AI10: 3 | AJ10: 0 | AK10: 161 | AN10: =IF($K10="","",VLOOKUP($K10,'ORF Accuracy Value LookUp'!$G$4:$H$104,2,TRUE)) -> 40 | AO10: =IF($N10="","",($N10-($O10/2))) -> -0.5 | AP10: =IF($U10="","",VLOOKUP($U10,'ORF Accuracy Value LookUp'!$G$4:$H$104,2,TRUE)) -> 64 | AQ10: =IF($X10="","",$X10-($Y10/2)) -> -0.5 | AR10: =IF($AE10="","",VLOOKUP($AE10,'ORF Accuracy Value LookUp'!$G$4:$H$104,2,TRUE)) -> 72 | AS10: =IF($AH10="","",$AH10-($AI10/2)) -> -0.5
A11: 3 | B11: Lname4 | C11: Fname4 | D11: XXXXX4 | E11: Female | F11: 40962 | G11: 3A | H11: 45376 | I11: 40 | J11: 4 | K11: 0.90909091 | L11: 14 | M11: 1 | N11: 3 | O11: 4 | P11: 1 | Q11: 110 | R11: 45441 | S11: 54 | T11: 4 | U11: 0.93103448 | V11: 18 | W11: 1 | X11: 3 | Y11: 4 | Z11: 1 | AA11: 158 | AB11: 45580 | AC11: 67 | AD11: 4 | AE11: 0.94366197 | AF11: 21 | AG11: 1 | AH11: 3 | AI11: 4 | AJ11: 1 | AK11: 185 | AN11: =IF($K11="","",VLOOKUP($K11,'ORF Accuracy Value LookUp'!$G$4:$H$104,2,TRUE)) -> 40 | AO11: =IF($N11="","",($N11-($O11/2))) -> 1 | AP11: =IF($U11="","",VLOOKUP($U11,'ORF Accuracy Value LookUp'!$G$4:$H$104,2,TRUE)) -> 64 | AQ11: =IF($X11="","",$X11-($Y11/2)) -> 1 | AR11: =IF($AE11="","",VLOOKUP($AE11,'ORF Accuracy Value LookUp'!$G$4:$H$104,2,TRUE)) -> 72 | AS11: =IF($AH11="","",$AH11-($AI11/2)) -> 1
A12: 3 | B12: ULname13 | C12: UFname13 | D12: UNLISTED | E12: Male | F12: 40970 | G12: 3B | H12: 45376 | I12: 49 | J12: 3 | K12: 0.94230769 | L12: 17 | M12: 0 | N12: 4 | O12: 3 | P12: 2.5 | Q12: 160 | R12: 45441 | S12: 63 | T12: 3 | U12: 0.95454545 | V12: 21 | W12: 0 | X12: 4 | Y12: 3 | Z12: 2.5 | AA12: 195 | AB12: 45580 | AC12: 75 | AD12: 3 | AE12: 0.96153846 | AF12: 25 | AG12: 0 | AH12: 4 | AI12: 3 | AJ12: 2.5 | AK12: 223 | AN12: =IF($K12="","",VLOOKUP($K12,'ORF Accuracy Value LookUp'!$G$4:$H$104,2,TRUE)) -> 72 | AO12: =IF($N12="","",($N12-($O12/2))) -> 2.5 | AP12: =IF($U12="","",VLOOKUP($U12,'ORF Accuracy Value LookUp'!$G$4:$H$104,2,TRUE)) -> 80 | AQ12: =IF($X12="","",$X12-($Y12/2)) -> 2.5 | AR12: =IF($AE12="","",VLOOKUP($AE12,'ORF Accuracy Value LookUp'!$G$4:$H$104,2,TRUE)) -> 88 | AS12: =IF($AH12="","",$AH12-($AI12/2)) -> 2.5
A13: 3 | B13: Lname5 | C13: Fname5 | D13: XXXXX5 | E13: Male | F13: 40963 | G13: 3A | H13: 45376 | I13: 55 | J13: 4 | K13: 0.93220339 | L13: 19 | M13: 0 | N13: 5 | O13: 4 | P13: 3 | Q13: 163 | R13: 45441 | S13: 71 | T13: 4 | U13: 0.94666667 | V13: 24 | W13: 0 | X13: 5 | Y13: 4 | Z13: 3 | AA13: 203 | AB13: 45580 | AC13: 82 | AD13: 4 | AE13: 0.95348837 | AF13: 28 | AG13: 0 | AH13: 5 | AI13: 4 | AJ13: 3 | AK13: 230 | AN13: =IF($K13="","",VLOOKUP($K13,'ORF Accuracy Value LookUp'!$G$4:$H$104,2,TRUE)) -> 64 | AO13: =IF($N13="","",($N13-($O13/2))) -> 3 | AP13: =IF($U13="","",VLOOKUP($U13,'ORF Accuracy Value LookUp'!$G$4:$H$104,2,TRUE)) -> 72 | AQ13: =IF($X13="","",$X13-($Y13/2)) -> 3 | AR13: =IF($AE13="","",VLOOKUP($AE13,'ORF Accuracy Value LookUp'!$G$4:$H$104,2,TRUE)) -> 80 | AS13: =IF($AH13="","",$AH13-($AI13/2)) -> 3
A14: 3 | B14: Lname6 | C14: Fname6 | D14: XXXXX6 | E14: Female | F14: 40964 | G14: 3B | H14: 45376 | I14: 61 | J14: 1 | K14: 0.98387097 | L14: 21 | M14: 2 | N14: 5 | O14: 1 | P14: 4.5 | Q14: 216 | R14: 45441 | S14: 78 | T14: 1 | U14: 0.98734177 | V14: 26 | W14: 2 | X14: 5 | Y14: 1 | Z14: 4.5 | AA14: 252 | AB14: 45580 | AC14: 89 | AD14: 1 | AE14: 0.98888889 | AF14: 31 | AG14: 2 | AH14: 5 | AI14: 1 | AJ14: 4.5 | AK14: 273 | AN14: =IF($K14="","",VLOOKUP($K14,'ORF Accuracy Value LookUp'!$G$4:$H$104,2,TRUE)) -> 104 | AO14: =IF($N14="","",($N14-($O14/2))) -> 4.5 | AP14: =IF($U14="","",VLOOKUP($U14,'ORF Accuracy Value LookUp'!$G$4:$H$104,2,TRUE)) -> 104 | AQ14: =IF($X14="","",$X14-($Y14/2)) -> 4.5 | AR14: =IF($AE14="","",VLOOKUP($AE14,'ORF Accuracy Value LookUp'!$G$4:$H$104,2,TRUE)) -> 104 | AS14: =IF($AH14="","",$AH14-($AI14/2)) -> 4.5
A15: 3 | B15: Lname7 | C15: Fname7 | D15: XXXXX7 | E15: Male | F15: 40965 | G15: 3B | H15: 45376 | I15: 67 | J15: 2 | K15: 0.97101449 | L15: 23 | M15: 1 | N15: 6 | O15: 2 | P15: 5 | Q15: 219 | R15: 45441 | S15: 84 | T15: 2 | U15: 0.97674419 | V15: 28 | W15: 1 | X15: 6 | Y15: 2 | Z15: 5 | AA15: 256 | AB15: 45580 | AC15: 95 | AD15: 2 | AE15: 0.97938144 | AF15: 34 | AG15: 1 | AH15: 6 | AI15: 2 | AJ15: 5 | AK15: 279 | AN15: =IF($K15="","",VLOOKUP($K15,'ORF Accuracy Value LookUp'!$G$4:$H$104,2,TRUE)) -> 96 | AO15: =IF($N15="","",($N15-($O15/2))) -> 5 | AP15: =IF($U15="","",VLOOKUP($U15,'ORF Accuracy Value LookUp'!$G$4:$H$104,2,TRUE)) -> 96 | AQ15: =IF($X15="","",$X15-($Y15/2)) -> 5 | AR15: =IF($AE15="","",VLOOKUP($AE15,'ORF Accuracy Value LookUp'!$G$4:$H$104,2,TRUE)) -> 96 | AS15: =IF($AH15="","",$AH15-($AI15/2)) -> 5
A16: 3 | B16: Lname8 | C16: Fname8 | D16: XXXXX8 | E16: Female | F16: 40966 | G16: 3B | H16: 45376 | I16: 73 | J16: 5 | K16: 0.93589744 | L16: 25 | M16: 2 | N16: 7 | O16: 2 | P16: 6 | Q16: 199 | R16: 45441 | S16: 88 | T16: 5 | U16: 0.94623656 | V16: 31 | W16: 2 | X16: 7 | Y16: 2 | Z16: 6 | AA16: 246 | AB16: 45580 | AC16: 100 | AD16: 5 | AE16: 0.95238095 | AF16: 36 | AG16: 2 | AH16: 7 | AI16: 2 | AJ16: 6 | AK16: 276 | AN16: =IF($K16="","",VLOOKUP($K16,'ORF Accuracy Value LookUp'!$G$4:$H$104,2,TRUE)) -> 64 | AO16: =IF($N16="","",($N16-($O16/2))) -> 6 | AP16: =IF($U16="","",VLOOKUP($U16,'ORF Accuracy Value LookUp'!$G$4:$H$104,2,TRUE)) -> 72 | AQ16: =IF($X16="","",$X16-($Y16/2)) -> 6 | AR16: =IF($AE16="","",VLOOKUP($AE16,'ORF Accuracy Value LookUp'!$G$4:$H$104,2,TRUE)) -> 80 | AS16: =IF($AH16="","",$AH16-($AI16/2)) -> 6
A17: 3 | B17: Lname9 | C17: Fname9 | D17: XXXXX9 | E17: Female | F17: 40967 | G17: 3B | H17: 45376 | I17: 77 | J17: 7 | K17: 0.91666667 | L17: 27 | M17: 1 | N17: 8 | O17: 1 | P17: 7.5 | Q17: 194 | R17: 45441 | S17: 92 | T17: 7 | U17: 0.92929293 | V17: 33 | W17: 1 | X17: 8 | Y17: 1 | Z17: 7.5 | AA17: 244 | AB17: 45580 | AC17: 105 | AD17: 7 | AE17: 0.9375 | AF17: 39 | AG17: 1 | AH17: 8 | AI17: 1 | AJ17: 7.5 | AK17: 277 | AN17: =IF($K17="","",VLOOKUP($K17,'ORF Accuracy Value LookUp'!$G$4:$H$104,2,TRUE)) -> 48 | AO17: =IF($N17="","",($N17-($O17/2))) -> 7.5 | AP17: =IF($U17="","",VLOOKUP($U17,'ORF Accuracy Value LookUp'!$G$4:$H$104,2,TRUE)) -> 56 | AQ17: =IF($X17="","",$X17-($Y17/2)) -> 7.5 | AR17: =IF($AE17="","",VLOOKUP($AE17,'ORF Accuracy Value LookUp'!$G$4:$H$104,2,TRUE)) -> 64 | AS17: =IF($AH17="","",$AH17-($AI17/2)) -> 7.5
A18: 3 | B18: Lname10 | C18: Fname10 | D18: XXXXX10 | E18: Female | F18: 40968 | G18: 3B | H18: 45376 | I18: 81 | J18: 9 | K18: 0.9 | L18: 29 | M18: 1 | N18: 9 | O18: 1 | P18: 8.5 | Q18: 196 | R18: 45441 | S18: 96 | T18: 9 | U18: 0.91428571 | V18: 35 | W18: 1 | X18: 9 | Y18: 1 | Z18: 8.5 | AA18: 248 | AB18: 45580 | AC18: 110 | AD18: 9 | AE18: 0.92436975 | AF18: 41 | AG18: 1 | AH18: 9 | AI18: 1 | AJ18: 8.5 | AK18: 282 | AN18: =IF($K18="","",VLOOKUP($K18,'ORF Accuracy Value LookUp'!$G$4:$H$104,2,TRUE)) -> 40 | AO18: =IF($N18="","",($N18-($O18/2))) -> 8.5 | AP18: =IF($U18="","",VLOOKUP($U18,'ORF Accuracy Value LookUp'!$G$4:$H$104,2,TRUE)) -> 48 | AQ18: =IF($X18="","",$X18-($Y18/2)) -> 8.5 | AR18: =IF($AE18="","",VLOOKUP($AE18,'ORF Accuracy Value LookUp'!$G$4:$H$104,2,TRUE)) -> 56 | AS18: =IF($AH18="","",$AH18-($AI18/2)) -> 8.5
K19: =IF($I19="","",SUM($I19/($I19+$J19))) | P19: =IF($AO19>0,$AO19,0) | Q19: =IF($B19="","",SUM($I19+$AN19+($L19*2)+($P19*2))) | U19: =IF($S19="","",SUM($S19/($S19+$T19))) | Z19: =IF($AQ19>0,$AQ19,0) | AA19: =IF($R19="","",SUM($S19+$AP19+($V19*2)+($Z19*4))) | AE19: =IF($AC19="","",SUM($AC19/($AC19+$AD19))) | AJ19: =IF($AS19>0,$AS19,0) | AK19: =IF($AB19="","",SUM($AC19+$AR19+($AF19*2)+($AJ19*4))) | AN19: =IF($K19="","",VLOOKUP($K19,'ORF Accuracy Value LookUp'!$G$4:$H$104,2,TRUE)) | AO19: =IF($N19="","",($N19-($O19/2))) | AP19: =IF($U19="","",VLOOKUP($U19,'ORF Accuracy Value LookUp'!$G$4:$H$104,2,TRUE)) | AQ19: =IF($X19="","",$X19-($Y19/2)) | AR19: =IF($AE19="","",VLOOKUP($AE19,'ORF Accuracy Value LookUp'!$G$4:$H$104,2,TRUE)) | AS19: =IF($AH19="","",$AH19-($AI19/2))
K20: =IF($I20="","",SUM($I20/($I20+$J20))) | P20: =IF($AO20>0,$AO20,0) | Q20: =IF($B20="","",SUM($I20+$AN20+($L20*2)+($P20*2))) | U20: =IF($S20="","",SUM($S20/($S20+$T20))) | Z20: =IF($AQ20>0,$AQ20,0) | AA20: =IF($R20="","",SUM($S20+$AP20+($V20*2)+($Z20*4))) | AE20: =IF($AC20="","",SUM($AC20/($AC20+$AD20))) | AJ20: =IF($AS20>0,$AS20,0) | AK20: =IF($AB20="","",SUM($AC20+$AR20+($AF20*2)+($AJ20*4))) | AN20: =IF($K20="","",VLOOKUP($K20,'ORF Accuracy Value LookUp'!$G$4:$H$104,2,TRUE)) | AO20: =IF($N20="","",($N20-($O20/2))) | AP20: =IF($U20="","",VLOOKUP($U20,'ORF Accuracy Value LookUp'!$G$4:$H$104,2,TRUE)) | AQ20: =IF($X20="","",$X20-($Y20/2)) | AR20: =IF($AE20="","",VLOOKUP($AE20,'ORF Accuracy Value LookUp'!$G$4:$H$104,2,TRUE)) | AS20: =IF($AH20="","",$AH20-($AI20/2))
K21: =IF($I21="","",SUM($I21/($I21+$J21))) | P21: =IF($AO21>0,$AO21,0) | Q21: =IF($B21="","",SUM($I21+$AN21+($L21*2)+($P21*2))) | U21: =IF($S21="","",SUM($S21/($S21+$T21))) | Z21: =IF($AQ21>0,$AQ21,0) | AA21: =IF($R21="","",SUM($S21+$AP21+($V21*2)+($Z21*4))) | AE21: =IF($AC21="","",SUM($AC21/($AC21+$AD21))) | AJ21: =IF($AS21>0,$AS21,0) | AK21: =IF($AB21="","",SUM($AC21+$AR21+($AF21*2)+($AJ21*4))) | AN21: =IF($K21="","",VLOOKUP($K21,'ORF Accuracy Value LookUp'!$G$4:$H$104,2,TRUE)) | AO21: =IF($N21="","",($N21-($O21/2))) | AP21: =IF($U21="","",VLOOKUP($U21,'ORF Accuracy Value LookUp'!$G$4:$H$104,2,TRUE)) | AQ21: =IF($X21="","",$X21-($Y21/2)) | AR21: =IF($AE21="","",VLOOKUP($AE21,'ORF Accuracy Value LookUp'!$G$4:$H$104,2,TRUE)) | AS21: =IF($AH21="","",$AH21-($AI21/2))
K22: =IF($I22="","",SUM($I22/($I22+$J22))) | P22: =IF($AO22>0,$AO22,0) | Q22: =IF($B22="","",SUM($I22+$AN22+($L22*2)+($P22*2))) | U22: =IF($S22="","",SUM($S22/($S22+$T22))) | Z22: =IF($AQ22>0,$AQ22,0) | AA22: =IF($R22="","",SUM($S22+$AP22+($V22*2)+($Z22*4))) | AE22: =IF($AC22="","",SUM($AC22/($AC22+$AD22))) | AJ22: =IF($AS22>0,$AS22,0) | AK22: =IF($AB22="","",SUM($AC22+$AR22+($AF22*2)+($AJ22*4))) | AN22: =IF($K22="","",VLOOKUP($K22,'ORF Accuracy Value LookUp'!$G$4:$H$104,2,TRUE)) | AO22: =IF($N22="","",($N22-($O22/2))) | AP22: =IF($U22="","",VLOOKUP($U22,'ORF Accuracy Value LookUp'!$G$4:$H$104,2,TRUE)) | AQ22: =IF($X22="","",$X22-($Y22/2)) | AR22: =IF($AE22="","",VLOOKUP($AE22,'ORF Accuracy Value LookUp'!$G$4:$H$104,2,TRUE)) | AS22: =IF($AH22="","",$AH22-($AI22/2))
K23: =IF($I23="","",SUM($I23/($I23+$J23))) | P23: =IF($AO23>0,$AO23,0) | Q23: =IF($B23="","",SUM($I23+$AN23+($L23*2)+($P23*2))) | U23: =IF($S23="","",SUM($S23/($S23+$T23))) | Z23: =IF($AQ23>0,$AQ23,0) | AA23: =IF($R23="","",SUM($S23+$AP23+($V23*2)+($Z23*4))) | AE23: =IF($AC23="","",SUM($AC23/($AC23+$AD23))) | AJ23: =IF($AS23>0,$AS23,0) | AK23: =IF($AB23="","",SUM($AC23+$AR23+($AF23*2)+($AJ23*4))) | AN23: =IF($K23="","",VLOOKUP($K23,'ORF Accuracy Value LookUp'!$G$4:$H$104,2,TRUE)) | AO23: =IF($N23="","",($N23-($O23/2))) | AP23: =IF($U23="","",VLOOKUP($U23,'ORF Accuracy Value LookUp'!$G$4:$H$104,2,TRUE)) | AQ23: =IF($X23="","",$X23-($Y23/2)) | AR23: =IF($AE23="","",VLOOKUP($AE23,'ORF Accuracy Value LookUp'!$G$4:$H$104,2,TRUE)) | AS23: =IF($AH23="","",$AH23-($AI23/2))
K24: =IF($I24="","",SUM($I24/($I24+$J24))) | P24: =IF($AO24>0,$AO24,0) | Q24: =IF($B24="","",SUM($I24+$AN24+($L24*2)+($P24*2))) | U24: =IF($S24="","",SUM($S24/($S24+$T24))) | Z24: =IF($AQ24>0,$AQ24,0) | AA24: =IF($R24="","",SUM($S24+$AP24+($V24*2)+($Z24*4))) | AE24: =IF($AC24="","",SUM($AC24/($AC24+$AD24))) | AJ24: =IF($AS24>0,$AS24,0) | AK24: =IF($AB24="","",SUM($AC24+$AR24+($AF24*2)+($AJ24*4))) | AN24: =IF($K24="","",VLOOKUP($K24,'ORF Accuracy Value LookUp'!$G$4:$H$104,2,TRUE)) | AO24: =IF($N24="","",($N24-($O24/2))) | AP24: =IF($U24="","",VLOOKUP($U24,'ORF Accuracy Value LookUp'!$G$4:$H$104,2,TRUE)) | AQ24: =IF($X24="","",$X24-($Y24/2)) | AR24: =IF($AE24="","",VLOOKUP($AE24,'ORF Accuracy Value LookUp'!$G$4:$H$104,2,TRUE)) | AS24: =IF($AH24="","",$AH24-($AI24/2))
K25: =IF($I25="","",SUM($I25/($I25+$J25))) | P25: =IF($AO25>0,$AO25,0) | Q25: =IF($B25="","",SUM($I25+$AN25+($L25*2)+($P25*2))) | U25: =IF($S25="","",SUM($S25/($S25+$T25))) | Z25: =IF($AQ25>0,$AQ25,0) | AA25: =IF($R25="","",SUM($S25+$AP25+($V25*2)+($Z25*4))) | AE25: =IF($AC25="","",SUM($AC25/($AC25+$AD25))) | AJ25: =IF($AS25>0,$AS25,0) | AK25: =IF($AB25="","",SUM($AC25+$AR25+($AF25*2)+($AJ25*4))) | AN25: =IF($K25="","",VLOOKUP($K25,'ORF Accuracy Value LookUp'!$G$4:$H$104,2,TRUE)) | AO25: =IF($N25="","",($N25-($O25/2))) | AP25: =IF($U25="","",VLOOKUP($U25,'ORF Accuracy Value LookUp'!$G$4:$H$104,2,TRUE)) | AQ25: =IF($X25="","",$X25-($Y25/2)) | AR25: =IF($AE25="","",VLOOKUP($AE25,'ORF Accuracy Value LookUp'!$G$4:$H$104,2,TRUE)) | AS25: =IF($AH25="","",$AH25-($AI25/2))
K26: =IF($I26="","",SUM($I26/($I26+$J26))) | P26: =IF($AO26>0,$AO26,0) | Q26: =IF($B26="","",SUM($I26+$AN26+($L26*2)+($P26*2))) | U26: =IF($S26="","",SUM($S26/($S26+$T26))) | Z26: =IF($AQ26>0,$AQ26,0) | AA26: =IF($R26="","",SUM($S26+$AP26+($V26*2)+($Z26*4))) | AE26: =IF($AC26="","",SUM($AC26/($AC26+$AD26))) | AJ26: =IF($AS26>0,$AS26,0) | AK26: =IF($AB26="","",SUM($AC26+$AR26+($AF26*2)+($AJ26*4))) | AN26: =IF($K26="","",VLOOKUP($K26,'ORF Accuracy Value LookUp'!$G$4:$H$104,2,TRUE)) | AO26: =IF($N26="","",($N26-($O26/2))) | AP26: =IF($U26="","",VLOOKUP($U26,'ORF Accuracy Value LookUp'!$G$4:$H$104,2,TRUE)) | AQ26: =IF($X26="","",$X26-($Y26/2)) | AR26: =IF($AE26="","",VLOOKUP($AE26,'ORF Accuracy Value LookUp'!$G$4:$H$104,2,TRUE)) | AS26: =IF($AH26="","",$AH26-($AI26/2))
K27: =IF($I27="","",SUM($I27/($I27+$J27))) | P27: =IF($AO27>0,$AO27,0) | Q27: =IF($B27="","",SUM($I27+$AN27+($L27*2)+($P27*2))) | U27: =IF($S27="","",SUM($S27/($S27+$T27))) | Z27: =IF($AQ27>0,$AQ27,0) | AA27: =IF($R27="","",SUM($S27+$AP27+($V27*2)+($Z27*4))) | AE27: =IF($AC27="","",SUM($AC27/($AC27+$AD27))) | AJ27: =IF($AS27>0,$AS27,0) | AK27: =IF($AB27="","",SUM($AC27+$AR27+($AF27*2)+($AJ27*4))) | AN27: =IF($K27="","",VLOOKUP($K27,'ORF Accuracy Value LookUp'!$G$4:$H$104,2,TRUE)) | AO27: =IF($N27="","",($N27-($O27/2))) | AP27: =IF($U27="","",VLOOKUP($U27,'ORF Accuracy Value LookUp'!$G$4:$H$104,2,TRUE)) | AQ27: =IF($X27="","",$X27-($Y27/2)) | AR27: =IF($AE27="","",VLOOKUP($AE27,'ORF Accuracy Value LookUp'!$G$4:$H$104,2,TRUE)) | AS27: =IF($AH27="","",$AH27-($AI27/2))
K28: =IF($I28="","",SUM($I28/($I28+$J28))) | P28: =IF($AO28>0,$AO28,0) | Q28: =IF($B28="","",SUM($I28+$AN28+($L28*2)+($P28*2))) | U28: =IF($S28="","",SUM($S28/($S28+$T28))) | Z28: =IF($AQ28>0,$AQ28,0) | AA28: =IF($R28="","",SUM($S28+$AP28+($V28*2)+($Z28*4))) | AE28: =IF($AC28="","",SUM($AC28/($AC28+$AD28))) | AJ28: =IF($AS28>0,$AS28,0) | AK28: =IF($AB28="","",SUM($AC28+$AR28+($AF28*2)+($AJ28*4))) | AN28: =IF($K28="","",VLOOKUP($K28,'ORF Accuracy Value LookUp'!$G$4:$H$104,2,TRUE)) | AO28: =IF($N28="","",($N28-($O28/2))) | AP28: =IF($U28="","",VLOOKUP($U28,'ORF Accuracy Value LookUp'!$G$4:$H$104,2,TRUE)) | AQ28: =IF($X28="","",$X28-($Y28/2)) | AR28: =IF($AE28="","",VLOOKUP($AE28,'ORF Accuracy Value LookUp'!$G$4:$H$104,2,TRUE)) | AS28: =IF($AH28="","",$AH28-($AI28/2))
K29: =IF($I29="","",SUM($I29/($I29+$J29))) | P29: =IF($AO29>0,$AO29,0) | Q29: =IF($B29="","",SUM($I29+$AN29+($L29*2)+($P29*2))) | U29: =IF($S29="","",SUM($S29/($S29+$T29))) | Z29: =IF($AQ29>0,$AQ29,0) | AA29: =IF($R29="","",SUM($S29+$AP29+($V29*2)+($Z29*4))) | AE29: =IF($AC29="","",SUM($AC29/($AC29+$AD29))) | AJ29: =IF($AS29>0,$AS29,0) | AK29: =IF($AB29="","",SUM($AC29+$AR29+($AF29*2)+($AJ29*4))) | AN29: =IF($K29="","",VLOOKUP($K29,'ORF Accuracy Value LookUp'!$G$4:$H$104,2,TRUE)) | AO29: =IF($N29="","",($N29-($O29/2))) | AP29: =IF($U29="","",VLOOKUP($U29,'ORF Accuracy Value LookUp'!$G$4:$H$104,2,TRUE)) | AQ29: =IF($X29="","",$X29-($Y29/2)) | AR29: =IF($AE29="","",VLOOKUP($AE29,'ORF Accuracy Value LookUp'!$G$4:$H$104,2,TRUE)) | AS29: =IF($AH29="","",$AH29-($AI29/2))
K30: =IF($I30="","",SUM($I30/($I30+$J30))) | P30: =IF($AO30>0,$AO30,0) | Q30: =IF($B30="","",SUM($I30+$AN30+($L30*2)+($P30*2))) | U30: =IF($S30="","",SUM($S30/($S30+$T30))) | Z30: =IF($AQ30>0,$AQ30,0) | AA30: =IF($R30="","",SUM($S30+$AP30+($V30*2)+($Z30*4))) | AE30: =IF($AC30="","",SUM($AC30/($AC30+$AD30))) | AJ30: =IF($AS30>0,$AS30,0) | AK30: =IF($AB30="","",SUM($AC30+$AR30+($AF30*2)+($AJ30*4))) | AN30: =IF($K30="","",VLOOKUP($K30,'ORF Accuracy Value LookUp'!$G$4:$H$104,2,TRUE)) | AO30: =IF($N30="","",($N30-($O30/2))) | AP30: =IF($U30="","",VLOOKUP($U30,'ORF Accuracy Value LookUp'!$G$4:$H$104,2,TRUE)) | AQ30: =IF($X30="","",$X30-($Y30/2)) | AR30: =IF($AE30="","",VLOOKUP($AE30,'ORF Accuracy Value LookUp'!$G$4:$H$104,2,TRUE)) | AS30: =IF($AH30="","",$AH30-($AI30/2))
... K397: =IF($I397="","",SUM($I397/($I397+$J397))) | P397: =IF($AO397>0,$AO397,0) | Q397: =IF($B397="","",SUM($I397+$AN397+($L397*2)+($P397*2))) | U397: =IF($S397="","",SUM($S397/($S397+$T397))) | Z397: =IF($AQ397>0,$AQ397,0) | AA397: =IF($R397="","",SUM($S397+$AP397+($V397*2)+($Z397*4))) | AE397: =IF($AC397="","",SUM($AC397/($AC397+$AD397))) | AJ397: =IF($AS397>0,$AS397,0) | AK397: =IF($AB397="","",SUM($AC397+$AR397+($AF397*2)+($AJ397*4))) | AN397: =IF($K397="","",VLOOKUP($K397,'ORF Accuracy Value LookUp'!$G$4:$H$104,2,TRUE)) | AO397: =IF($N397="","",($N397-($O397/2))) | AP397: =IF($U397="","",VLOOKUP($U397,'ORF Accuracy Value LookUp'!$G$4:$H$104,2,TRUE)) | AQ397: =IF($X397="","",$X397-($Y397/2)) | AR397: =IF($AE397="","",VLOOKUP($AE397,'ORF Accuracy Value LookUp'!$G$4:$H$104,2,TRUE)) | AS397: =IF($AH397="","",$AH397-($AI397/2))

Sheet Year 4
A1: Acadience Reading (2021) K-6 Assessment | I1: NOTE: If ORF-WRC is below 40 and Retell is not administered, use 0 for the Retell value only. This ensures an accurate Acadience Reading Composite Score can be calculated. A score recorded in the Retell Quality of Response column will display in SPA. However, note that this value is not used to calculate a composite score.
H3: complete all columns or leave blank | R3: complete all columns or leave blank | AB3: complete all columns or leave blank
A4: Required | B4: Required | C4: Required | D4: Required | E4: Optional | F4: Required | G4: Optional | H4: Required | I4: Required | J4: Optional | K4: Required | L4: Required | M4: Optional | N4: Optional | O4: Optional | P4: Required | R4: Required | S4: Required | T4: Optional | U4: Required | V4: Required | W4: Optional | X4: Optional | Y4: Optional | Z4: Required | AB4: Required | AC4: Required | AD4: Optional | AE4: Required | AF4: Required | AG4: Optional | AH4: Optional | AI4: Optional | AJ4: Required
H5: Beginning | R5: Middle | AB5: End
I6: Oral Reading Fluency (ORF) | N6: MAZE | S6: Oral Reading Fluency (ORF) | X6: MAZE | AC6: Oral Reading Fluency (ORF) | AH6: MAZE | AN6: Beginning | AP6: Middle | AR6: End
A7: Year Level | B7: Surname | C7: First Name | D7: Student ID | E7: Gender | F7: DOB (dd/mm/yy) | G7: Class | H7: Test Date (dd/mm/yy) | I7: Words Read Correctly (ORF-WRC) Score | J7: ORF-Errors | K7: Accuracy Percent (ORF-AP) | L7: Retell | M7: Retell Quality of Response | N7: Maze Correct | O7: Maze Errors | P7: Maze Adjusted Score | Q7: Composite Score | R7: Test Date (dd/mm/yy) | S7: Words Read Correctly (ORF-WRC) Score | T7: ORF-Errors | U7: Accuracy Percent (ORF-AP) | V7: Retell | W7: Retell Quality of Response | X7: Maze Correct | Y7: Maze Errors | Z7: Maze Adjusted Score | AA7: Composite Score | AB7: Test Date (dd/mm/yy) | AC7: Words Read Correctly (ORF-WRC) Score | AD7: ORF-Errors | AE7: Accuracy Percent (ORF-AP) | AF7: Retell | AG7: Retell Quality of Response | AH7: Maze Correct | AI7: Maze Errors | AJ7: Maze Adjusted Score | AK7: Composite Score | AN7: Accuracy Value (ORF-AV) | AO7: Maze Adjusted Score calculation | AP7: Accuracy Value (ORF-AV) | AQ7: Maze Adjusted Score calculation | AR7: Accuracy Value (ORF-AV) | AS7: Maze Adjusted Score calculation
A8: 3 | B8: Lname1 | C8: Fname1 | D8: XXXXX1 | E8: Female | F8: 40959 | G8: 3A | K8: =IF($I8="","",SUM($I8/($I8+$J8))) | P8: =IF($AO8>0,$AO8,0) | Q8: =IF($B8="","",SUM($I8+$AN8+($L8*2)+($P8*2))) -> #VALUE! | U8: =IF($S8="","",SUM($S8/($S8+$T8))) | Z8: =IF($AQ8>0,$AQ8,0) | AA8: =IF($R8="","",SUM($S8+$AP8+($V8*2)+($Z8*4))) | AE8: =IF($AC8="","",SUM($AC8/($AC8+$AD8))) | AJ8: =IF($AS8>0,$AS8,0) | AK8: =IF($AB8="","",SUM($AC8+$AR8+($AF8*2)+($AJ8*4))) | AN8: =IF($K8="","",VLOOKUP($K8,'ORF Accuracy Value LookUp'!$G$4:$H$104,2,TRUE)) | AO8: =IF($N8="","",($N8-($O8/2))) | AP8: =IF($U8="","",VLOOKUP($U8,'ORF Accuracy Value LookUp'!$G$4:$H$104,2,TRUE)) | AQ8: =IF($X8="","",$X8-($Y8/2)) | AR8: =IF($AE8="","",VLOOKUP($AE8,'ORF Accuracy Value LookUp'!$G$4:$H$104,2,TRUE)) | AS8: =IF($AH8="","",$AH8-($AI8/2))
