Workbook

Sheet Main Menu
B2: PAT-R Comprehesion Fourth Edition Scoring Templates
B4: This series of spreadsheets provide the templates required to enter ACER's PAT-R (Comprehension) results into the Student Performance Analyser (SPA). Click on the appropriate button (at right) to select the correct Test Booklet proforma to complete. Follow the instructions opposite. | H4: Step 1: Click on the appropriate button (at left) to select the correct Test Booklet proforma to complete. Step 2: For each student, enter the Date (when test was sat), Year Level, Home Group, Name, and Student ID (CASES No. or Student No.). Step 3: For each question, enter their response (their score will be calculated) OR enter their Raw Score OR enter their PAT Score. Step 4: Save and upload into SPA.
B29: Click here to find out more about other tests available from ACER | H29: Click here to find out more about the Student Performance Analyser

Sheet PAT-R Comp P
A1: PAT-R Comprehesion - Test Booklet P
G3: QUESTION No. and ANSWER KEY (Enter the student's response - "Y" if correct, "N" if incorrect)
E4: Question Number | G4: 1 | H4: 2 | I4: 3 | J4: 4 | K4: 5 | L4: 6 | M4: 7 | N4: 8 | O4: 9 | P4: 10 | Q4: 11 | R4: 12 | S4: 13 | T4: 14 | U4: 15 | V4: 16 | W4: 17 | X4: 18 | Y4: 19 | Z4: 20 | AA4: 21 | AB4: 22 | AC4: 23
E5: Item Difficulty | G5: 51.43 | H5: 58.54 | I5: 66.06 | J5: 49.72 | K5: 93.78 | L5: 73.61 | M5: 103.28 | N5: 59.42 | O5: 49.72 | P5: 55.48 | Q5: 97.12 | R5: 71.05 | S5: 63.76 | T5: 47.71 | U5: 49.72 | V5: 61.02 | W5: 80.81 | X5: 71.05 | Y5: 74.28 | Z5: 63.76 | AA5: 68.97 | AB5: 64.37 | AC5: 73.95
E6: Skill Assessed | G6: PR | H6: PR | I6: PR | J6: PR | K6: PR | L6: PR | M6: PR | N6: PR | O6: PR | P6: PR | Q6: PR | R6: PR | S6: PR | T6: PR | U6: PR | V6: PR | W6: PR | X6: PR | Y6: PR | Z6: PR | AA6: PR | AB6: PR | AC6: PR
A7: required | B7: required | C7: optional | D7: required | E7: required | F7: required
A8: Date (dd/mm/yy) | B8: Yr_Lev | C8: HG | D8: Surname | E8: First_Name | F8: Student_ID | G8: Y | H8: Y | I8: Y | J8: Y | K8: Y | L8: Y | M8: Y | N8: Y | O8: Y | P8: Y | Q8: Y | R8: Y | S8: Y | T8: Y | U8: Y | V8: Y | W8: Y | X8: Y | Y8: Y | Z8: Y | AA8: Y | AB8: Y | AC8: Y | AD8: Raw Score | AE8: PAT Score
A9: 45356 | B9: 3 | C9: 3A | D9: Lname1 | E9: Fname1 | F9: XXXXX1 | AD9: =IF(D9="",0,(IF(G9=$G$8,1,0)+IF(H9=$H$8,1,0)+IF(I9=$I$8,1,0)+IF(J9=$J$8,1,0)+IF(K9=$K$8,1,0)+IF(L9=$L$8,1,0)+IF(M9=$M$8,1,0)+IF(N9=$N$8,1,0)+IF(O9=$O$8,1,0)+IF(P9=$P$8,1,0)+IF(Q9=$Q$8,1,0)+IF(R9=$R$8,1,0)+IF(S9=$S$8,1,0)+IF(T9=$T$8,1,0)+IF(U9=$U$8,1,0)+IF(V9=$V$8,1,0)+IF(W9=$W$8,1,0)+IF(X9=$X$8,1,0)+IF(Y9=$Y$8,1,0)+IF(Z9=$Z$8,1,0)+IF(AA9=$AA$8,1,0)+IF(AB9=$AB$8,1,0)+IF(AC9=$AC$8,1,0))) -> 0 | AE9: =IF(D9="","",VLOOKUP(AD9,'PAT-C_Tables'!$A$3:$B$40,2,FALSE)) -> 18.9
A10: 45356 | B10: 3 | C10: 3A | D10: Lname2 | E10: Fname2 | F10: XXXXX2 | AD10: =IF(D10="",0,(IF(G10=$G$8,1,0)+IF(H10=$H$8,1,0)+IF(I10=$I$8,1,0)+IF(J10=$J$8,1,0)+IF(K10=$K$8,1,0)+IF(L10=$L$8,1,0)+IF(M10=$M$8,1,0)+IF(N10=$N$8,1,0)+IF(O10=$O$8,1,0)+IF(P10=$P$8,1,0)+IF(Q10=$Q$8,1,0)+IF(R10=$R$8,1,0)+IF(S10=$S$8,1,0)+IF(T10=$T$8,1,0)+IF(U10=$U$8,1,0)+IF(V10=$V$8,1,0)+IF(W10=$W$8,1,0)+IF(X10=$X$8,1,0)+IF(Y10=$Y$8,1,0)+IF(Z10=$Z$8,1,0)+IF(AA10=$AA$8,1,0)+IF(AB10=$AB$8,1,0)+IF(AC10=$AC$8,1,0))) -> 0 | AE10: =IF(D10="","",VLOOKUP(AD10,'PAT-C_Tables'!$A$3:$B$40,2,FALSE)) -> 18.9
A11: 45356 | B11: 3 | C11: 3A | D11: Lname3 | E11: Fname3 | F11: XXXXX3 | AD11: =IF(D11="",0,(IF(G11=$G$8,1,0)+IF(H11=$H$8,1,0)+IF(I11=$I$8,1,0)+IF(J11=$J$8,1,0)+IF(K11=$K$8,1,0)+IF(L11=$L$8,1,0)+IF(M11=$M$8,1,0)+IF(N11=$N$8,1,0)+IF(O11=$O$8,1,0)+IF(P11=$P$8,1,0)+IF(Q11=$Q$8,1,0)+IF(R11=$R$8,1,0)+IF(S11=$S$8,1,0)+IF(T11=$T$8,1,0)+IF(U11=$U$8,1,0)+IF(V11=$V$8,1,0)+IF(W11=$W$8,1,0)+IF(X11=$X$8,1,0)+IF(Y11=$Y$8,1,0)+IF(Z11=$Z$8,1,0)+IF(AA11=$AA$8,1,0)+IF(AB11=$AB$8,1,0)+IF(AC11=$AC$8,1,0))) -> 0 | AE11: =IF(D11="","",VLOOKUP(AD11,'PAT-C_Tables'!$A$3:$B$40,2,FALSE)) -> 18.9
A12: 45356 | B12: 3 | C12: 3A | D12: Lname4 | E12: Fname4 | F12: XXXXX4 | AD12: =IF(D12="",0,(IF(G12=$G$8,1,0)+IF(H12=$H$8,1,0)+IF(I12=$I$8,1,0)+IF(J12=$J$8,1,0)+IF(K12=$K$8,1,0)+IF(L12=$L$8,1,0)+IF(M12=$M$8,1,0)+IF(N12=$N$8,1,0)+IF(O12=$O$8,1,0)+IF(P12=$P$8,1,0)+IF(Q12=$Q$8,1,0)+IF(R12=$R$8,1,0)+IF(S12=$S$8,1,0)+IF(T12=$T$8,1,0)+IF(U12=$U$8,1,0)+IF(V12=$V$8,1,0)+IF(W12=$W$8,1,0)+IF(X12=$X$8,1,0)+IF(Y12=$Y$8,1,0)+IF(Z12=$Z$8,1,0)+IF(AA12=$AA$8,1,0)+IF(AB12=$AB$8,1,0)+IF(AC12=$AC$8,1,0))) -> 0 | AE12: =IF(D12="","",VLOOKUP(AD12,'PAT-C_Tables'!$A$3:$B$40,2,FALSE)) -> 18.9
A13: 45356 | B13: 3 | C13: 3B | D13: ULname13 | E13: UFname13 | F13: UNLISTED | AD13: =IF(D13="",0,(IF(G13=$G$8,1,0)+IF(H13=$H$8,1,0)+IF(I13=$I$8,1,0)+IF(J13=$J$8,1,0)+IF(K13=$K$8,1,0)+IF(L13=$L$8,1,0)+IF(M13=$M$8,1,0)+IF(N13=$N$8,1,0)+IF(O13=$O$8,1,0)+IF(P13=$P$8,1,0)+IF(Q13=$Q$8,1,0)+IF(R13=$R$8,1,0)+IF(S13=$S$8,1,0)+IF(T13=$T$8,1,0)+IF(U13=$U$8,1,0)+IF(V13=$V$8,1,0)+IF(W13=$W$8,1,0)+IF(X13=$X$8,1,0)+IF(Y13=$Y$8,1,0)+IF(Z13=$Z$8,1,0)+IF(AA13=$AA$8,1,0)+IF(AB13=$AB$8,1,0)+IF(AC13=$AC$8,1,0))) -> 0 | AE13: =IF(D13="","",VLOOKUP(AD13,'PAT-C_Tables'!$A$3:$B$40,2,FALSE)) -> 18.9
A14: 45356 | B14: 3 | C14: 3A | D14: Lname5 | E14: Fname5 | F14: XXXXX5 | AD14: =IF(D14="",0,(IF(G14=$G$8,1,0)+IF(H14=$H$8,1,0)+IF(I14=$I$8,1,0)+IF(J14=$J$8,1,0)+IF(K14=$K$8,1,0)+IF(L14=$L$8,1,0)+IF(M14=$M$8,1,0)+IF(N14=$N$8,1,0)+IF(O14=$O$8,1,0)+IF(P14=$P$8,1,0)+IF(Q14=$Q$8,1,0)+IF(R14=$R$8,1,0)+IF(S14=$S$8,1,0)+IF(T14=$T$8,1,0)+IF(U14=$U$8,1,0)+IF(V14=$V$8,1,0)+IF(W14=$W$8,1,0)+IF(X14=$X$8,1,0)+IF(Y14=$Y$8,1,0)+IF(Z14=$Z$8,1,0)+IF(AA14=$AA$8,1,0)+IF(AB14=$AB$8,1,0)+IF(AC14=$AC$8,1,0))) -> 0 | AE14: =IF(D14="","",VLOOKUP(AD14,'PAT-C_Tables'!$A$3:$B$40,2,FALSE)) -> 18.9
A15: 45356 | B15: 3 | C15: 3B | D15: Lname6 | E15: Fname6 | F15: XXXXX6 | AD15: =IF(D15="",0,(IF(G15=$G$8,1,0)+IF(H15=$H$8,1,0)+IF(I15=$I$8,1,0)+IF(J15=$J$8,1,0)+IF(K15=$K$8,1,0)+IF(L15=$L$8,1,0)+IF(M15=$M$8,1,0)+IF(N15=$N$8,1,0)+IF(O15=$O$8,1,0)+IF(P15=$P$8,1,0)+IF(Q15=$Q$8,1,0)+IF(R15=$R$8,1,0)+IF(S15=$S$8,1,0)+IF(T15=$T$8,1,0)+IF(U15=$U$8,1,0)+IF(V15=$V$8,1,0)+IF(W15=$W$8,1,0)+IF(X15=$X$8,1,0)+IF(Y15=$Y$8,1,0)+IF(Z15=$Z$8,1,0)+IF(AA15=$AA$8,1,0)+IF(AB15=$AB$8,1,0)+IF(AC15=$AC$8,1,0))) -> 0 | AE15: =IF(D15="","",VLOOKUP(AD15,'PAT-C_Tables'!$A$3:$B$40,2,FALSE)) -> 18.9
A16: 45356 | B16: 3 | C16: 3B | D16: Lname7 | E16: Fname7 | F16: XXXXX7 | AD16: =IF(D16="",0,(IF(G16=$G$8,1,0)+IF(H16=$H$8,1,0)+IF(I16=$I$8,1,0)+IF(J16=$J$8,1,0)+IF(K16=$K$8,1,0)+IF(L16=$L$8,1,0)+IF(M16=$M$8,1,0)+IF(N16=$N$8,1,0)+IF(O16=$O$8,1,0)+IF(P16=$P$8,1,0)+IF(Q16=$Q$8,1,0)+IF(R16=$R$8,1,0)+IF(S16=$S$8,1,0)+IF(T16=$T$8,1,0)+IF(U16=$U$8,1,0)+IF(V16=$V$8,1,0)+IF(W16=$W$8,1,0)+IF(X16=$X$8,1,0)+IF(Y16=$Y$8,1,0)+IF(Z16=$Z$8,1,0)+IF(AA16=$AA$8,1,0)+IF(AB16=$AB$8,1,0)+IF(AC16=$AC$8,1,0))) -> 0 | AE16: =IF(D16="","",VLOOKUP(AD16,'PAT-C_Tables'!$A$3:$B$40,2,FALSE)) -> 18.9
A17: 45356 | B17: 3 | C17: 3B | D17: Lname8 | E17: Fname8 | F17: XXXXX8 | AD17: =IF(D17="",0,(IF(G17=$G$8,1,0)+IF(H17=$H$8,1,0)+IF(I17=$I$8,1,0)+IF(J17=$J$8,1,0)+IF(K17=$K$8,1,0)+IF(L17=$L$8,1,0)+IF(M17=$M$8,1,0)+IF(N17=$N$8,1,0)+IF(O17=$O$8,1,0)+IF(P17=$P$8,1,0)+IF(Q17=$Q$8,1,0)+IF(R17=$R$8,1,0)+IF(S17=$S$8,1,0)+IF(T17=$T$8,1,0)+IF(U17=$U$8,1,0)+IF(V17=$V$8,1,0)+IF(W17=$W$8,1,0)+IF(X17=$X$8,1,0)+IF(Y17=$Y$8,1,0)+IF(Z17=$Z$8,1,0)+IF(AA17=$AA$8,1,0)+IF(AB17=$AB$8,1,0)+IF(AC17=$AC$8,1,0))) -> 0 | AE17: =IF(D17="","",VLOOKUP(AD17,'PAT-C_Tables'!$A$3:$B$40,2,FALSE)) -> 18.9
A18: 45356 | B18: 3 | C18: 3B | D18: Lname9 | E18: Fname9 | F18: XXXXX9 | AD18: =IF(D18="",0,(IF(G18=$G$8,1,0)+IF(H18=$H$8,1,0)+IF(I18=$I$8,1,0)+IF(J18=$J$8,1,0)+IF(K18=$K$8,1,0)+IF(L18=$L$8,1,0)+IF(M18=$M$8,1,0)+IF(N18=$N$8,1,0)+IF(O18=$O$8,1,0)+IF(P18=$P$8,1,0)+IF(Q18=$Q$8,1,0)+IF(R18=$R$8,1,0)+IF(S18=$S$8,1,0)+IF(T18=$T$8,1,0)+IF(U18=$U$8,1,0)+IF(V18=$V$8,1,0)+IF(W18=$W$8,1,0)+IF(X18=$X$8,1,0)+IF(Y18=$Y$8,1,0)+IF(Z18=$Z$8,1,0)+IF(AA18=$AA$8,1,0)+IF(AB18=$AB$8,1,0)+IF(AC18=$AC$8,1,0))) -> 0 | AE18: =IF(D18="","",VLOOKUP(AD18,'PAT-C_Tables'!$A$3:$B$40,2,FALSE)) -> 18.9
A19: 45356 | B19: 3 | C19: 3B | D19: Lname10 | E19: Fname10 | F19: XXXXX10 | AD19: =IF(D19="",0,(IF(G19=$G$8,1,0)+IF(H19=$H$8,1,0)+IF(I19=$I$8,1,0)+IF(J19=$J$8,1,0)+IF(K19=$K$8,1,0)+IF(L19=$L$8,1,0)+IF(M19=$M$8,1,0)+IF(N19=$N$8,1,0)+IF(O19=$O$8,1,0)+IF(P19=$P$8,1,0)+IF(Q19=$Q$8,1,0)+IF(R19=$R$8,1,0)+IF(S19=$S$8,1,0)+IF(T19=$T$8,1,0)+IF(U19=$U$8,1,0)+IF(V19=$V$8,1,0)+IF(W19=$W$8,1,0)+IF(X19=$X$8,1,0)+IF(Y19=$Y$8,1,0)+IF(Z19=$Z$8,1,0)+IF(AA19=$AA$8,1,0)+IF(AB19=$AB$8,1,0)+IF(AC19=$AC$8,1,0))) -> 0 | AE19: =IF(D19="","",VLOOKUP(AD19,'PAT-C_Tables'!$A$3:$B$40,2,FALSE)) -> 18.9
AD20: =IF(D20="",0,(IF(G20=$G$8,1,0)+IF(H20=$H$8,1,0)+IF(I20=$I$8,1,0)+IF(J20=$J$8,1,0)+IF(K20=$K$8,1,0)+IF(L20=$L$8,1,0)+IF(M20=$M$8,1,0)+IF(N20=$N$8,1,0)+IF(O20=$O$8,1,0)+IF(P20=$P$8,1,0)+IF(Q20=$Q$8,1,0)+IF(R20=$R$8,1,0)+IF(S20=$S$8,1,0)+IF(T20=$T$8,1,0)+IF(U20=$U$8,1,0)+IF(V20=$V$8,1,0)+IF(W20=$W$8,1,0)+IF(X20=$X$8,1,0)+IF(Y20=$Y$8,1,0)+IF(Z20=$Z$8,1,0)+IF(AA20=$AA$8,1,0)+IF(AB20=$AB$8,1,0)+IF(AC20=$AC$8,1,0))) -> 0 | AE20: =IF(D20="","",VLOOKUP(AD20,'PAT-C_Tables'!$A$3:$B$40,2,FALSE))
AD21: =IF(D21="",0,(IF(G21=$G$8,1,0)+IF(H21=$H$8,1,0)+IF(I21=$I$8,1,0)+IF(J21=$J$8,1,0)+IF(K21=$K$8,1,0)+IF(L21=$L$8,1,0)+IF(M21=$M$8,1,0)+IF(N21=$N$8,1,0)+IF(O21=$O$8,1,0)+IF(P21=$P$8,1,0)+IF(Q21=$Q$8,1,0)+IF(R21=$R$8,1,0)+IF(S21=$S$8,1,0)+IF(T21=$T$8,1,0)+IF(U21=$U$8,1,0)+IF(V21=$V$8,1,0)+IF(W21=$W$8,1,0)+IF(X21=$X$8,1,0)+IF(Y21=$Y$8,1,0)+IF(Z21=$Z$8,1,0)+IF(AA21=$AA$8,1,0)+IF(AB21=$AB$8,1,0)+IF(AC21=$AC$8,1,0))) -> 0 | AE21: =IF(D21="","",VLOOKUP(AD21,'PAT-C_Tables'!$A$3:$B$40,2,FALSE))
AD22: =IF(D22="",0,(IF(G22=$G$8,1,0)+IF(H22=$H$8,1,0)+IF(I22=$I$8,1,0)+IF(J22=$J$8,1,0)+IF(K22=$K$8,1,0)+IF(L22=$L$8,1,0)+IF(M22=$M$8,1,0)+IF(N22=$N$8,1,0)+IF(O22=$O$8,1,0)+IF(P22=$P$8,1,0)+IF(Q22=$Q$8,1,0)+IF(R22=$R$8,1,0)+IF(S22=$S$8,1,0)+IF(T22=$T$8,1,0)+IF(U22=$U$8,1,0)+IF(V22=$V$8,1,0)+IF(W22=$W$8,1,0)+IF(X22=$X$8,1,0)+IF(Y22=$Y$8,1,0)+IF(Z22=$Z$8,1,0)+IF(AA22=$AA$8,1,0)+IF(AB22=$AB$8,1,0)+IF(AC22=$AC$8,1,0))) -> 0 | AE22: =IF(D22="","",VLOOKUP(AD22,'PAT-C_Tables'!$A$3:$B$40,2,FALSE))
AD23: =IF(D23="",0,(IF(G23=$G$8,1,0)+IF(H23=$H$8,1,0)+IF(I23=$I$8,1,0)+IF(J23=$J$8,1,0)+IF(K23=$K$8,1,0)+IF(L23=$L$8,1,0)+IF(M23=$M$8,1,0)+IF(N23=$N$8,1,0)+IF(O23=$O$8,1,0)+IF(P23=$P$8,1,0)+IF(Q23=$Q$8,1,0)+IF(R23=$R$8,1,0)+IF(S23=$S$8,1,0)+IF(T23=$T$8,1,0)+IF(U23=$U$8,1,0)+IF(V23=$V$8,1,0)+IF(W23=$W$8,1,0)+IF(X23=$X$8,1,0)+IF(Y23=$Y$8,1,0)+IF(Z23=$Z$8,1,0)+IF(AA23=$AA$8,1,0)+IF(AB23=$AB$8,1,0)+IF(AC23=$AC$8,1,0))) -> 0 | AE23: =IF(D23="","",VLOOKUP(AD23,'PAT-C_Tables'!$A$3:$B$40,2,FALSE))
AD24: =IF(D24="",0,(IF(G24=$G$8,1,0)+IF(H24=$H$8,1,0)+IF(I24=$I$8,1,0)+IF(J24=$J$8,1,0)+IF(K24=$K$8,1,0)+IF(L24=$L$8,1,0)+IF(M24=$M$8,1,0)+IF(N24=$N$8,1,0)+IF(O24=$O$8,1,0)+IF(P24=$P$8,1,0)+IF(Q24=$Q$8,1,0)+IF(R24=$R$8,1,0)+IF(S24=$S$8,1,0)+IF(T24=$T$8,1,0)+IF(U24=$U$8,1,0)+IF(V24=$V$8,1,0)+IF(W24=$W$8,1,0)+IF(X24=$X$8,1,0)+IF(Y24=$Y$8,1,0)+IF(Z24=$Z$8,1,0)+IF(AA24=$AA$8,1,0)+IF(AB24=$AB$8,1,0)+IF(AC24=$AC$8,1,0))) -> 0 | AE24: =IF(D24="","",VLOOKUP(AD24,'PAT-C_Tables'!$A$3:$B$40,2,FALSE))
AD25: =IF(D25="",0,(IF(G25=$G$8,1,0)+IF(H25=$H$8,1,0)+IF(I25=$I$8,1,0)+IF(J25=$J$8,1,0)+IF(K25=$K$8,1,0)+IF(L25=$L$8,1,0)+IF(M25=$M$8,1,0)+IF(N25=$N$8,1,0)+IF(O25=$O$8,1,0)+IF(P25=$P$8,1,0)+IF(Q25=$Q$8,1,0)+IF(R25=$R$8,1,0)+IF(S25=$S$8,1,0)+IF(T25=$T$8,1,0)+IF(U25=$U$8,1,0)+IF(V25=$V$8,1,0)+IF(W25=$W$8,1,0)+IF(X25=$X$8,1,0)+IF(Y25=$Y$8,1,0)+IF(Z25=$Z$8,1,0)+IF(AA25=$AA$8,1,0)+IF(AB25=$AB$8,1,0)+IF(AC25=$AC$8,1,0))) -> 0 | AE25: =IF(D25="","",VLOOKUP(AD25,'PAT-C_Tables'!$A$3:$B$40,2,FALSE))
AD26: =IF(D26="",0,(IF(G26=$G$8,1,0)+IF(H26=$H$8,1,0)+IF(I26=$I$8,1,0)+IF(J26=$J$8,1,0)+IF(K26=$K$8,1,0)+IF(L26=$L$8,1,0)+IF(M26=$M$8,1,0)+IF(N26=$N$8,1,0)+IF(O26=$O$8,1,0)+IF(P26=$P$8,1,0)+IF(Q26=$Q$8,1,0)+IF(R26=$R$8,1,0)+IF(S26=$S$8,1,0)+IF(T26=$T$8,1,0)+IF(U26=$U$8,1,0)+IF(V26=$V$8,1,0)+IF(W26=$W$8,1,0)+IF(X26=$X$8,1,0)+IF(Y26=$Y$8,1,0)+IF(Z26=$Z$8,1,0)+IF(AA26=$AA$8,1,0)+IF(AB26=$AB$8,1,0)+IF(AC26=$AC$8,1,0))) -> 0 | AE26: =IF(D26="","",VLOOKUP(AD26,'PAT-C_Tables'!$A$3:$B$40,2,FALSE))
AD27: =IF(D27="",0,(IF(G27=$G$8,1,0)+IF(H27=$H$8,1,0)+IF(I27=$I$8,1,0)+IF(J27=$J$8,1,0)+IF(K27=$K$8,1,0)+IF(L27=$L$8,1,0)+IF(M27=$M$8,1,0)+IF(N27=$N$8,1,0)+IF(O27=$O$8,1,0)+IF(P27=$P$8,1,0)+IF(Q27=$Q$8,1,0)+IF(R27=$R$8,1,0)+IF(S27=$S$8,1,0)+IF(T27=$T$8,1,0)+IF(U27=$U$8,1,0)+IF(V27=$V$8,1,0)+IF(W27=$W$8,1,0)+IF(X27=$X$8,1,0)+IF(Y27=$Y$8,1,0)+IF(Z27=$Z$8,1,0)+IF(AA27=$AA$8,1,0)+IF(AB27=$AB$8,1,0)+IF(AC27=$AC$8,1,0))) -> 0 | AE27: =IF(D27="","",VLOOKUP(AD27,'PAT-C_Tables'!$A$3:$B$40,2,FALSE))
AD28: =IF(D28="",0,(IF(G28=$G$8,1,0)+IF(H28=$H$8,1,0)+IF(I28=$I$8,1,0)+IF(J28=$J$8,1,0)+IF(K28=$K$8,1,0)+IF(L28=$L$8,1,0)+IF(M28=$M$8,1,0)+IF(N28=$N$8,1,0)+IF(O28=$O$8,1,0)+IF(P28=$P$8,1,0)+IF(Q28=$Q$8,1,0)+IF(R28=$R$8,1,0)+IF(S28=$S$8,1,0)+IF(T28=$T$8,1,0)+IF(U28=$U$8,1,0)+IF(V28=$V$8,1,0)+IF(W28=$W$8,1,0)+IF(X28=$X$8,1,0)+IF(Y28=$Y$8,1,0)+IF(Z28=$Z$8,1,0)+IF(AA28=$AA$8,1,0)+IF(AB28=$AB$8,1,0)+IF(AC28=$AC$8,1,0))) -> 0 | AE28: =IF(D28="","",VLOOKUP(AD28,'PAT-C_Tables'!$A$3:$B$40,2,FALSE))
AD29: =IF(D29="",0,(IF(G29=$G$8,1,0)+IF(H29=$H$8,1,0)+IF(I29=$I$8,1,0)+IF(J29=$J$8,1,0)+IF(K29=$K$8,1,0)+IF(L29=$L$8,1,0)+IF(M29=$M$8,1,0)+IF(N29=$N$8,1,0)+IF(O29=$O$8,1,0)+IF(P29=$P$8,1,0)+IF(Q29=$Q$8,1,0)+IF(R29=$R$8,1,0)+IF(S29=$S$8,1,0)+IF(T29=$T$8,1,0)+IF(U29=$U$8,1,0)+IF(V29=$V$8,1,0)+IF(W29=$W$8,1,0)+IF(X29=$X$8,1,0)+IF(Y29=$Y$8,1,0)+IF(Z29=$Z$8,1,0)+IF(AA29=$AA$8,1,0)+IF(AB29=$AB$8,1,0)+IF(AC29=$AC$8,1,0))) -> 0 | AE29: =IF(D29="","",VLOOKUP(AD29,'PAT-C_Tables'!$A$3:$B$40,2,FALSE))
AD30: =IF(D30="",0,(IF(G30=$G$8,1,0)+IF(H30=$H$8,1,0)+IF(I30=$I$8,1,0)+IF(J30=$J$8,1,0)+IF(K30=$K$8,1,0)+IF(L30=$L$8,1,0)+IF(M30=$M$8,1,0)+IF(N30=$N$8,1,0)+IF(O30=$O$8,1,0)+IF(P30=$P$8,1,0)+IF(Q30=$Q$8,1,0)+IF(R30=$R$8,1,0)+IF(S30=$S$8,1,0)+IF(T30=$T$8,1,0)+IF(U30=$U$8,1,0)+IF(V30=$V$8,1,0)+IF(W30=$W$8,1,0)+IF(X30=$X$8,1,0)+IF(Y30=$Y$8,1,0)+IF(Z30=$Z$8,1,0)+IF(AA30=$AA$8,1,0)+IF(AB30=$AB$8,1,0)+IF(AC30=$AC$8,1,0))) -> 0 | AE30: =IF(D30="","",VLOOKUP(AD30,'PAT-C_Tables'!$A$3:$B$40,2,FALSE))
AD31: =IF(D31="",0,(IF(G31=$G$8,1,0)+IF(H31=$H$8,1,0)+IF(I31=$I$8,1,0)+IF(J31=$J$8,1,0)+IF(K31=$K$8,1,0)+IF(L31=$L$8,1,0)+IF(M31=$M$8,1,0)+IF(N31=$N$8,1,0)+IF(O31=$O$8,1,0)+IF(P31=$P$8,1,0)+IF(Q31=$Q$8,1,0)+IF(R31=$R$8,1,0)+IF(S31=$S$8,1,0)+IF(T31=$T$8,1,0)+IF(U31=$U$8,1,0)+IF(V31=$V$8,1,0)+IF(W31=$W$8,1,0)+IF(X31=$X$8,1,0)+IF(Y31=$Y$8,1,0)+IF(Z31=$Z$8,1,0)+IF(AA31=$AA$8,1,0)+IF(AB31=$AB$8,1,0)+IF(AC31=$AC$8,1,0))) -> 0 | AE31: =IF(D31="","",VLOOKUP(AD31,'PAT-C_Tables'!$A$3:$B$40,2,FALSE))
... AD503: =IF(D503="",0,(IF(G503=$G$8,1,0)+IF(H503=$H$8,1,0)+IF(I503=$I$8,1,0)+IF(J503=$J$8,1,0)+IF(K503=$K$8,1,0)+IF(L503=$L$8,1,0)+IF(M503=$M$8,1,0)+IF(N503=$N$8,1,0)+IF(O503=$O$8,1,0)+IF(P503=$P$8,1,0)+IF(Q503=$Q$8,1,0)+IF(R503=$R$8,1,0)+IF(S503=$S$8,1,0)+IF(T503=$T$8,1,0)+IF(U503=$U$8,1,0)+IF(V503=$V$8,1,0)+IF(W503=$W$8,1,0)+IF(X503=$X$8,1,0)+IF(Y503=$Y$8,1,0)+IF(Z503=$Z$8,1,0)+IF(AA503=$AA$8,1,0)+IF(AB503=$AB$8,1,0)+IF(AC503=$AC$8,1,0))) -> 0 | AE503: =IF(D503="","",VLOOKUP(AD503,'PAT-C_Tables'!$A$3:$B$40,2,FALSE))

Sheet PAT-R Comp 1
A1: PAT-R Comprehesion - Test Booklet 1
G3: QUESTION No. and ANSWER KEY (Enter the student's response - "Y" if correct, "N" if incorrect)
E4: Question Number | G4: 1 | H4: 2 | I4: 3 | J4: 4 | K4: 5 | L4: 6 | M4: 7 | N4: 8 | O4: 9 | P4: 10 | Q4: 11 | R4: 12 | S4: 13 | T4: 14 | U4: 15 | V4: 16 | W4: 17 | X4: 18
E5: Item Difficulty | G5: 45.07 | H5: 64.52 | I5: 57.29 | J5: 55.79 | K5: 67.12 | L5: 71.05 | M5: 73.42 | N5: 87.42 | O5: 88.95 | P5: 74.76 | Q5: 73.53 | R5: 79.53 | S5: 96.06 | T5: 75.56 | U5: 90.69 | V5: 91.14 | W5: 82.23 | X5: 91.8
E6: Skill Assessed | G6: RI | H6: RI | I6: RI | J6: IE | K6: RI | L6: IE | M6: PR | N6: PR | O6: PR | P6: PR | Q6: CL | R6: CL | S6: CL | T6: CL | U6: CL | V6: CL | W6: CL | X6: CL
A7: required | B7: required | C7: optional | D7: required | E7: required | F7: required
A8: Date (dd/mm/yy) | B8: Yr_Lev | C8: HG | D8: Surname | E8: First_Name | F8: Student_ID | G8: Y | H8: Y | I8: Y | J8: Y | K8: Y | L8: Y | M8: Y | N8: Y | O8: Y | P8: Y | Q8: Y | R8: Y | S8: Y | T8: Y | U8: Y | V8: Y | W8: Y | X8: Y | Y8: Raw Score | Z8: PAT Score
A9: 45356 | B9: 3 | C9: 3A | D9: Lname1 | E9: Fname1 | F9: XXXXX1 | Y9: =IF(D9="",0,(IF(G9=$G$8,1,0)+IF(H9=$H$8,1,0)+IF(I9=$I$8,1,0)+IF(J9=$J$8,1,0)+IF(K9=$K$8,1,0)+IF(L9=$L$8,1,0)+IF(M9=$M$8,1,0)+IF(N9=$N$8,1,0)+IF(O9=$O$8,1,0)+IF(P9=$P$8,1,0)+IF(Q9=$Q$8,1,0)+IF(R9=$R$8,1,0)+IF(S9=$S$8,1,0)+IF(T9=$T$8,1,0)+IF(U9=$U$8,1,0)+IF(V9=$V$8,1,0)+IF(W9=$W$8,1,0)+IF(X9=$X$8,1,0))) -> 0 | Z9: =IF(D9="","",VLOOKUP(Y9,'PAT-C_Tables'!$C$3:$D$40,2,FALSE)) -> 27
A10: 45356 | B10: 3 | C10: 3A | D10: Lname2 | E10: Fname2 | F10: XXXXX2 | Y10: =IF(D10="",0,(IF(G10=$G$8,1,0)+IF(H10=$H$8,1,0)+IF(I10=$I$8,1,0)+IF(J10=$J$8,1,0)+IF(K10=$K$8,1,0)+IF(L10=$L$8,1,0)+IF(M10=$M$8,1,0)+IF(N10=$N$8,1,0)+IF(O10=$O$8,1,0)+IF(P10=$P$8,1,0)+IF(Q10=$Q$8,1,0)+IF(R10=$R$8,1,0)+IF(S10=$S$8,1,0)+IF(T10=$T$8,1,0)+IF(U10=$U$8,1,0)+IF(V10=$V$8,1,0)+IF(W10=$W$8,1,0)+IF(X10=$X$8,1,0))) -> 0 | Z10: =IF(D10="","",VLOOKUP(Y10,'PAT-C_Tables'!$C$3:$D$40,2,FALSE)) -> 27
A11: 45356 | B11: 3 | C11: 3A | D11: Lname3 | E11: Fname3 | F11: XXXXX3 | Y11: =IF(D11="",0,(IF(G11=$G$8,1,0)+IF(H11=$H$8,1,0)+IF(I11=$I$8,1,0)+IF(J11=$J$8,1,0)+IF(K11=$K$8,1,0)+IF(L11=$L$8,1,0)+IF(M11=$M$8,1,0)+IF(N11=$N$8,1,0)+IF(O11=$O$8,1,0)+IF(P11=$P$8,1,0)+IF(Q11=$Q$8,1,0)+IF(R11=$R$8,1,0)+IF(S11=$S$8,1,0)+IF(T11=$T$8,1,0)+IF(U11=$U$8,1,0)+IF(V11=$V$8,1,0)+IF(W11=$W$8,1,0)+IF(X11=$X$8,1,0))) -> 0 | Z11: =IF(D11="","",VLOOKUP(Y11,'PAT-C_Tables'!$C$3:$D$40,2,FALSE)) -> 27
A12: 45356 | B12: 3 | C12: 3A | D12: Lname4 | E12: Fname4 | F12: XXXXX4 | Y12: =IF(D12="",0,(IF(G12=$G$8,1,0)+IF(H12=$H$8,1,0)+IF(I12=$I$8,1,0)+IF(J12=$J$8,1,0)+IF(K12=$K$8,1,0)+IF(L12=$L$8,1,0)+IF(M12=$M$8,1,0)+IF(N12=$N$8,1,0)+IF(O12=$O$8,1,0)+IF(P12=$P$8,1,0)+IF(Q12=$Q$8,1,0)+IF(R12=$R$8,1,0)+IF(S12=$S$8,1,0)+IF(T12=$T$8,1,0)+IF(U12=$U$8,1,0)+IF(V12=$V$8,1,0)+IF(W12=$W$8,1,0)+IF(X12=$X$8,1,0))) -> 0 | Z12: =IF(D12="","",VLOOKUP(Y12,'PAT-C_Tables'!$C$3:$D$40,2,FALSE)) -> 27
A13: 45356 | B13: 3 | C13: 3B | D13: ULname13 | E13: UFname13 | F13: UNLISTED | Y13: =IF(D13="",0,(IF(G13=$G$8,1,0)+IF(H13=$H$8,1,0)+IF(I13=$I$8,1,0)+IF(J13=$J$8,1,0)+IF(K13=$K$8,1,0)+IF(L13=$L$8,1,0)+IF(M13=$M$8,1,0)+IF(N13=$N$8,1,0)+IF(O13=$O$8,1,0)+IF(P13=$P$8,1,0)+IF(Q13=$Q$8,1,0)+IF(R13=$R$8,1,0)+IF(S13=$S$8,1,0)+IF(T13=$T$8,1,0)+IF(U13=$U$8,1,0)+IF(V13=$V$8,1,0)+IF(W13=$W$8,1,0)+IF(X13=$X$8,1,0))) -> 0 | Z13: =IF(D13="","",VLOOKUP(Y13,'PAT-C_Tables'!$C$3:$D$40,2,FALSE)) -> 27
A14: 45356 | B14: 3 | C14: 3A | D14: Lname5 | E14: Fname5 | F14: XXXXX5 | Y14: =IF(D14="",0,(IF(G14=$G$8,1,0)+IF(H14=$H$8,1,0)+IF(I14=$I$8,1,0)+IF(J14=$J$8,1,0)+IF(K14=$K$8,1,0)+IF(L14=$L$8,1,0)+IF(M14=$M$8,1,0)+IF(N14=$N$8,1,0)+IF(O14=$O$8,1,0)+IF(P14=$P$8,1,0)+IF(Q14=$Q$8,1,0)+IF(R14=$R$8,1,0)+IF(S14=$S$8,1,0)+IF(T14=$T$8,1,0)+IF(U14=$U$8,1,0)+IF(V14=$V$8,1,0)+IF(W14=$W$8,1,0)+IF(X14=$X$8,1,0))) -> 0 | Z14: =IF(D14="","",VLOOKUP(Y14,'PAT-C_Tables'!$C$3:$D$40,2,FALSE)) -> 27
A15: 45356 | B15: 3 | C15: 3B | D15: Lname6 | E15: Fname6 | F15: XXXXX6 | Y15: =IF(D15="",0,(IF(G15=$G$8,1,0)+IF(H15=$H$8,1,0)+IF(I15=$I$8,1,0)+IF(J15=$J$8,1,0)+IF(K15=$K$8,1,0)+IF(L15=$L$8,1,0)+IF(M15=$M$8,1,0)+IF(N15=$N$8,1,0)+IF(O15=$O$8,1,0)+IF(P15=$P$8,1,0)+IF(Q15=$Q$8,1,0)+IF(R15=$R$8,1,0)+IF(S15=$S$8,1,0)+IF(T15=$T$8,1,0)+IF(U15=$U$8,1,0)+IF(V15=$V$8,1,0)+IF(W15=$W$8,1,0)+IF(X15=$X$8,1,0))) -> 0 | Z15: =IF(D15="","",VLOOKUP(Y15,'PAT-C_Tables'!$C$3:$D$40,2,FALSE)) -> 27
A16: 45356 | B16: 3 | C16: 3B | D16: Lname7 | E16: Fname7 | F16: XXXXX7 | Y16: =IF(D16="",0,(IF(G16=$G$8,1,0)+IF(H16=$H$8,1,0)+IF(I16=$I$8,1,0)+IF(J16=$J$8,1,0)+IF(K16=$K$8,1,0)+IF(L16=$L$8,1,0)+IF(M16=$M$8,1,0)+IF(N16=$N$8,1,0)+IF(O16=$O$8,1,0)+IF(P16=$P$8,1,0)+IF(Q16=$Q$8,1,0)+IF(R16=$R$8,1,0)+IF(S16=$S$8,1,0)+IF(T16=$T$8,1,0)+IF(U16=$U$8,1,0)+IF(V16=$V$8,1,0)+IF(W16=$W$8,1,0)+IF(X16=$X$8,1,0))) -> 0 | Z16: =IF(D16="","",VLOOKUP(Y16,'PAT-C_Tables'!$C$3:$D$40,2,FALSE)) -> 27
A17: 45356 | B17: 3 | C17: 3B | D17: Lname8 | E17: Fname8 | F17: XXXXX8 | Y17: =IF(D17="",0,(IF(G17=$G$8,1,0)+IF(H17=$H$8,1,0)+IF(I17=$I$8,1,0)+IF(J17=$J$8,1,0)+IF(K17=$K$8,1,0)+IF(L17=$L$8,1,0)+IF(M17=$M$8,1,0)+IF(N17=$N$8,1,0)+IF(O17=$O$8,1,0)+IF(P17=$P$8,1,0)+IF(Q17=$Q$8,1,0)+IF(R17=$R$8,1,0)+IF(S17=$S$8,1,0)+IF(T17=$T$8,1,0)+IF(U17=$U$8,1,0)+IF(V17=$V$8,1,0)+IF(W17=$W$8,1,0)+IF(X17=$X$8,1,0))) -> 0 | Z17: =IF(D17="","",VLOOKUP(Y17,'PAT-C_Tables'!$C$3:$D$40,2,FALSE)) -> 27
A18: 45356 | B18: 3 | C18: 3B | D18: Lname9 | E18: Fname9 | F18: XXXXX9 | Y18: =IF(D18="",0,(IF(G18=$G$8,1,0)+IF(H18=$H$8,1,0)+IF(I18=$I$8,1,0)+IF(J18=$J$8,1,0)+IF(K18=$K$8,1,0)+IF(L18=$L$8,1,0)+IF(M18=$M$8,1,0)+IF(N18=$N$8,1,0)+IF(O18=$O$8,1,0)+IF(P18=$P$8,1,0)+IF(Q18=$Q$8,1,0)+IF(R18=$R$8,1,0)+IF(S18=$S$8,1,0)+IF(T18=$T$8,1,0)+IF(U18=$U$8,1,0)+IF(V18=$V$8,1,0)+IF(W18=$W$8,1,0)+IF(X18=$X$8,1,0))) -> 0 | Z18: =IF(D18="","",VLOOKUP(Y18,'PAT-C_Tables'!$C$3:$D$40,2,FALSE)) -> 27
A19: 45356 | B19: 3 | C19: 3B | D19: Lname10 | E19: Fname10 | F19: XXXXX10 | Y19: =IF(D19="",0,(IF(G19=$G$8,1,0)+IF(H19=$H$8,1,0)+IF(I19=$I$8,1,0)+IF(J19=$J$8,1,0)+IF(K19=$K$8,1,0)+IF(L19=$L$8,1,0)+IF(M19=$M$8,1,0)+IF(N19=$N$8,1,0)+IF(O19=$O$8,1,0)+IF(P19=$P$8,1,0)+IF(Q19=$Q$8,1,0)+IF(R19=$R$8,1,0)+IF(S19=$S$8,1,0)+IF(T19=$T$8,1,0)+IF(U19=$U$8,1,0)+IF(V19=$V$8,1,0)+IF(W19=$W$8,1,0)+IF(X19=$X$8,1,0))) -> 0 | Z19: =IF(D19="","",VLOOKUP(Y19,'PAT-C_Tables'!$C$3:$D$40,2,FALSE)) -> 27
Y20: =IF(D20="",0,(IF(G20=$G$8,1,0)+IF(H20=$H$8,1,0)+IF(I20=$I$8,1,0)+IF(J20=$J$8,1,0)+IF(K20=$K$8,1,0)+IF(L20=$L$8,1,0)+IF(M20=$M$8,1,0)+IF(N20=$N$8,1,0)+IF(O20=$O$8,1,0)+IF(P20=$P$8,1,0)+IF(Q20=$Q$8,1,0)+IF(R20=$R$8,1,0)+IF(S20=$S$8,1,0)+IF(T20=$T$8,1,0)+IF(U20=$U$8,1,0)+IF(V20=$V$8,1,0)+IF(W20=$W$8,1,0)+IF(X20=$X$8,1,0))) -> 0 | Z20: =IF(D20="","",VLOOKUP(Y20,'PAT-C_Tables'!$C$3:$D$40,2,FALSE))
Y21: =IF(D21="",0,(IF(G21=$G$8,1,0)+IF(H21=$H$8,1,0)+IF(I21=$I$8,1,0)+IF(J21=$J$8,1,0)+IF(K21=$K$8,1,0)+IF(L21=$L$8,1,0)+IF(M21=$M$8,1,0)+IF(N21=$N$8,1,0)+IF(O21=$O$8,1,0)+IF(P21=$P$8,1,0)+IF(Q21=$Q$8,1,0)+IF(R21=$R$8,1,0)+IF(S21=$S$8,1,0)+IF(T21=$T$8,1,0)+IF(U21=$U$8,1,0)+IF(V21=$V$8,1,0)+IF(W21=$W$8,1,0)+IF(X21=$X$8,1,0))) -> 0 | Z21: =IF(D21="","",VLOOKUP(Y21,'PAT-C_Tables'!$C$3:$D$40,2,FALSE))
Y22: =IF(D22="",0,(IF(G22=$G$8,1,0)+IF(H22=$H$8,1,0)+IF(I22=$I$8,1,0)+IF(J22=$J$8,1,0)+IF(K22=$K$8,1,0)+IF(L22=$L$8,1,0)+IF(M22=$M$8,1,0)+IF(N22=$N$8,1,0)+IF(O22=$O$8,1,0)+IF(P22=$P$8,1,0)+IF(Q22=$Q$8,1,0)+IF(R22=$R$8,1,0)+IF(S22=$S$8,1,0)+IF(T22=$T$8,1,0)+IF(U22=$U$8,1,0)+IF(V22=$V$8,1,0)+IF(W22=$W$8,1,0)+IF(X22=$X$8,1,0))) -> 0 | Z22: =IF(D22="","",VLOOKUP(Y22,'PAT-C_Tables'!$C$3:$D$40,2,FALSE))
Y23: =IF(D23="",0,(IF(G23=$G$8,1,0)+IF(H23=$H$8,1,0)+IF(I23=$I$8,1,0)+IF(J23=$J$8,1,0)+IF(K23=$K$8,1,0)+IF(L23=$L$8,1,0)+IF(M23=$M$8,1,0)+IF(N23=$N$8,1,0)+IF(O23=$O$8,1,0)+IF(P23=$P$8,1,0)+IF(Q23=$Q$8,1,0)+IF(R23=$R$8,1,0)+IF(S23=$S$8,1,0)+IF(T23=$T$8,1,0)+IF(U23=$U$8,1,0)+IF(V23=$V$8,1,0)+IF(W23=$W$8,1,0)+IF(X23=$X$8,1,0))) -> 0 | Z23: =IF(D23="","",VLOOKUP(Y23,'PAT-C_Tables'!$C$3:$D$40,2,FALSE))
Y24: =IF(D24="",0,(IF(G24=$G$8,1,0)+IF(H24=$H$8,1,0)+IF(I24=$I$8,1,0)+IF(J24=$J$8,1,0)+IF(K24=$K$8,1,0)+IF(L24=$L$8,1,0)+IF(M24=$M$8,1,0)+IF(N24=$N$8,1,0)+IF(O24=$O$8,1,0)+IF(P24=$P$8,1,0)+IF(Q24=$Q$8,1,0)+IF(R24=$R$8,1,0)+IF(S24=$S$8,1,0)+IF(T24=$T$8,1,0)+IF(U24=$U$8,1,0)+IF(V24=$V$8,1,0)+IF(W24=$W$8,1,0)+IF(X24=$X$8,1,0))) -> 0 | Z24: =IF(D24="","",VLOOKUP(Y24,'PAT-C_Tables'!$C$3:$D$40,2,FALSE))
Y25: =IF(D25="",0,(IF(G25=$G$8,1,0)+IF(H25=$H$8,1,0)+IF(I25=$I$8,1,0)+IF(J25=$J$8,1,0)+IF(K25=$K$8,1,0)+IF(L25=$L$8,1,0)+IF(M25=$M$8,1,0)+IF(N25=$N$8,1,0)+IF(O25=$O$8,1,0)+IF(P25=$P$8,1,0)+IF(Q25=$Q$8,1,0)+IF(R25=$R$8,1,0)+IF(S25=$S$8,1,0)+IF(T25=$T$8,1,0)+IF(U25=$U$8,1,0)+IF(V25=$V$8,1,0)+IF(W25=$W$8,1,0)+IF(X25=$X$8,1,0))) -> 0 | Z25: =IF(D25="","",VLOOKUP(Y25,'PAT-C_Tables'!$C$3:$D$40,2,FALSE))
Y26: =IF(D26="",0,(IF(G26=$G$8,1,0)+IF(H26=$H$8,1,0)+IF(I26=$I$8,1,0)+IF(J26=$J$8,1,0)+IF(K26=$K$8,1,0)+IF(L26=$L$8,1,0)+IF(M26=$M$8,1,0)+IF(N26=$N$8,1,0)+IF(O26=$O$8,1,0)+IF(P26=$P$8,1,0)+IF(Q26=$Q$8,1,0)+IF(R26=$R$8,1,0)+IF(S26=$S$8,1,0)+IF(T26=$T$8,1,0)+IF(U26=$U$8,1,0)+IF(V26=$V$8,1,0)+IF(W26=$W$8,1,0)+IF(X26=$X$8,1,0))) -> 0 | Z26: =IF(D26="","",VLOOKUP(Y26,'PAT-C_Tables'!$C$3:$D$40,2,FALSE))
Y27: =IF(D27="",0,(IF(G27=$G$8,1,0)+IF(H27=$H$8,1,0)+IF(I27=$I$8,1,0)+IF(J27=$J$8,1,0)+IF(K27=$K$8,1,0)+IF(L27=$L$8,1,0)+IF(M27=$M$8,1,0)+IF(N27=$N$8,1,0)+IF(O27=$O$8,1,0)+IF(P27=$P$8,1,0)+IF(Q27=$Q$8,1,0)+IF(R27=$R$8,1,0)+IF(S27=$S$8,1,0)+IF(T27=$T$8,1,0)+IF(U27=$U$8,1,0)+IF(V27=$V$8,1,0)+IF(W27=$W$8,1,0)+IF(X27=$X$8,1,0))) -> 0 | Z27: =IF(D27="","",VLOOKUP(Y27,'PAT-C_Tables'!$C$3:$D$40,2,FALSE))
Y28: =IF(D28="",0,(IF(G28=$G$8,1,0)+IF(H28=$H$8,1,0)+IF(I28=$I$8,1,0)+IF(J28=$J$8,1,0)+IF(K28=$K$8,1,0)+IF(L28=$L$8,1,0)+IF(M28=$M$8,1,0)+IF(N28=$N$8,1,0)+IF(O28=$O$8,1,0)+IF(P28=$P$8,1,0)+IF(Q28=$Q$8,1,0)+IF(R28=$R$8,1,0)+IF(S28=$S$8,1,0)+IF(T28=$T$8,1,0)+IF(U28=$U$8,1,0)+IF(V28=$V$8,1,0)+IF(W28=$W$8,1,0)+IF(X28=$X$8,1,0))) -> 0 | Z28: =IF(D28="","",VLOOKUP(Y28,'PAT-C_Tables'!$C$3:$D$40,2,FALSE))
Y29: =IF(D29="",0,(IF(G29=$G$8,1,0)+IF(H29=$H$8,1,0)+IF(I29=$I$8,1,0)+IF(J29=$J$8,1,0)+IF(K29=$K$8,1,0)+IF(L29=$L$8,1,0)+IF(M29=$M$8,1,0)+IF(N29=$N$8,1,0)+IF(O29=$O$8,1,0)+IF(P29=$P$8,1,0)+IF(Q29=$Q$8,1,0)+IF(R29=$R$8,1,0)+IF(S29=$S$8,1,0)+IF(T29=$T$8,1,0)+IF(U29=$U$8,1,0)+IF(V29=$V$8,1,0)+IF(W29=$W$8,1,0)+IF(X29=$X$8,1,0))) -> 0 | Z29: =IF(D29="","",VLOOKUP(Y29,'PAT-C_Tables'!$C$3:$D$40,2,FALSE))
Y30: =IF(D30="",0,(IF(G30=$G$8,1,0)+IF(H30=$H$8,1,0)+IF(I30=$I$8,1,0)+IF(J30=$J$8,1,0)+IF(K30=$K$8,1,0)+IF(L30=$L$8,1,0)+IF(M30=$M$8,1,0)+IF(N30=$N$8,1,0)+IF(O30=$O$8,1,0)+IF(P30=$P$8,1,0)+IF(Q30=$Q$8,1,0)+IF(R30=$R$8,1,0)+IF(S30=$S$8,1,0)+IF(T30=$T$8,1,0)+IF(U30=$U$8,1,0)+IF(V30=$V$8,1,0)+IF(W30=$W$8,1,0)+IF(X30=$X$8,1,0))) -> 0 | Z30: =IF(D30="","",VLOOKUP(Y30,'PAT-C_Tables'!$C$3:$D$40,2,FALSE))
Y31: =IF(D31="",0,(IF(G31=$G$8,1,0)+IF(H31=$H$8,1,0)+IF(I31=$I$8,1,0)+IF(J31=$J$8,1,0)+IF(K31=$K$8,1,0)+IF(L31=$L$8,1,0)+IF(M31=$M$8,1,0)+IF(N31=$N$8,1,0)+IF(O31=$O$8,1,0)+IF(P31=$P$8,1,0)+IF(Q31=$Q$8,1,0)+IF(R31=$R$8,1,0)+IF(S31=$S$8,1,0)+IF(T31=$T$8,1,0)+IF(U31=$U$8,1,0)+IF(V31=$V$8,1,0)+IF(W31=$W$8,1,0)+IF(X31=$X$8,1,0))) -> 0 | Z31: =IF(D31="","",VLOOKUP(Y31,'PAT-C_Tables'!$C$3:$D$40,2,FALSE))
... Y501: =IF(D501="",0,(IF(G501=$G$8,1,0)+IF(H501=$H$8,1,0)+IF(I501=$I$8,1,0)+IF(J501=$J$8,1,0)+IF(K501=$K$8,1,0)+IF(L501=$L$8,1,0)+IF(M501=$M$8,1,0)+IF(N501=$N$8,1,0)+IF(O501=$O$8,1,0)+IF(P501=$P$8,1,0)+IF(Q501=$Q$8,1,0)+IF(R501=$R$8,1,0)+IF(S501=$S$8,1,0)+IF(T501=$T$8,1,0)+IF(U501=$U$8,1,0)+IF(V501=$V$8,1,0)+IF(W501=$W$8,1,0)+IF(X501=$X$8,1,0))) -> 0 | Z501: =IF(D501="","",VLOOKUP(Y501,'PAT-C_Tables'!$C$3:$D$40,2,FALSE))

Sheet PAT-R Comp 2
A1: PAT-R Comprehesion - Test Booklet 2
G3: QUESTION No. and ANSWER KEY (Enter the student's response - "A" or "B" or "C" or "D")
E4: Question Number | G4: 1 | H4: 2 | I4: 3 | J4: 4 | K4: 5 | L4: 6 | M4: 7 | N4: 8 | O4: 9 | P4: 10 | Q4: 11 | R4: 12 | S4: 13 | T4: 14 | U4: 15 | V4: 16 | W4: 17 | X4: 18 | Y4: 19 | Z4: 20 | AA4: 21 | AB4: 22 | AC4: 23 | AD4: 24 | AE4: 25
E5: Item Difficulty | G5: 74.29 | H5: 82.41 | I5: 84.46 | J5: 95.22 | K5: 87.6 | L5: 89.26 | M5: 86.36 | N5: 94.06 | O5: 96.37 | P5: 95.49 | Q5: 77.82 | R5: 87.88 | S5: 103.06 | T5: 87.25 | U5: 97.12 | V5: 96.21 | W5: 100.58 | X5: 111.97 | Y5: 93.8 | Z5: 88.2 | AA5: 103.11 | AB5: 106.29 | AC5: 95.46 | AD5: 103.19 | AE5: 109.93
E6: Skill Assessed | G6: RI | H6: IE | I6: IE | J6: IE | K6: IE | L6: RI | M6: RI | N6: IE | O6: IE | P6: IE | Q6: RI | R6: IE | S6: RI | T6: IE | U6: RI | V6: IE | W6: IE | X6: RI | Y6: RI | Z6: RI | AA6: II | AB6: IE | AC6: RI | AD6: IE | AE6: RF
A7: required | B7: required | C7: optional | D7: required | E7: required | F7: required
A8: Date (dd/mm/yy) | B8: Yr_Lev | C8: HG | D8: Surname | E8: First_Name | F8: Student_ID | G8: A | H8: A | I8: A | J8: C | K8: D | L8: A | M8: C | N8: C | O8: C | P8: D | Q8: A | R8: B | S8: A | T8: D | U8: D | V8: C | W8: A | X8: A | Y8: C | Z8: B | AA8: D | AB8: D | AC8: C | AD8: C | AE8: B | AF8: Raw Score | AG8: PAT Score
A9: 45356 | B9: 3 | C9: 3A | D9: Lname1 | E9: Fname1 | F9: XXXXX1 | AF9: =IF(D9="",0,(IF(G9=$G$8,1,0)+IF(H9=$H$8,1,0)+IF(I9=$I$8,1,0)+IF(J9=$J$8,1,0)+IF(K9=$K$8,1,0)+IF(L9=$L$8,1,0)+IF(M9=$M$8,1,0)+IF(N9=$N$8,1,0)+IF(O9=$O$8,1,0)+IF(P9=$P$8,1,0)+IF(Q9=$Q$8,1,0)+IF(R9=$R$8,1,0)+IF(S9=$S$8,1,0)+IF(T9=$T$8,1,0)+IF(U9=$U$8,1,0)+IF(V9=$V$8,1,0)+IF(W9=$W$8,1,0)+IF(X9=$X$8,1,0)+IF(Y9=$Y$8,1,0)+IF(Z9=$Z$8,1,0)+IF(AA9=$AA$8,1,0)+IF(AB9=$AB$8,1,0)+IF(AC9=$AC$8,1,0)+IF(AD9=$AD$8,1,0)+IF(AE9=$AE$8,1,0))) -> 0 | AG9: =IF(D9="","",VLOOKUP(AF9,'PAT-C_Tables'!$E$3:$F$40,2,FALSE)) -> 47.8
A10: 45356 | B10: 3 | C10: 3A | D10: Lname2 | E10: Fname2 | F10: XXXXX2 | AF10: =IF(D10="",0,(IF(G10=$G$8,1,0)+IF(H10=$H$8,1,0)+IF(I10=$I$8,1,0)+IF(J10=$J$8,1,0)+IF(K10=$K$8,1,0)+IF(L10=$L$8,1,0)+IF(M10=$M$8,1,0)+IF(N10=$N$8,1,0)+IF(O10=$O$8,1,0)+IF(P10=$P$8,1,0)+IF(Q10=$Q$8,1,0)+IF(R10=$R$8,1,0)+IF(S10=$S$8,1,0)+IF(T10=$T$8,1,0)+IF(U10=$U$8,1,0)+IF(V10=$V$8,1,0)+IF(W10=$W$8,1,0)+IF(X10=$X$8,1,0)+IF(Y10=$Y$8,1,0)+IF(Z10=$Z$8,1,0)+IF(AA10=$AA$8,1,0)+IF(AB10=$AB$8,1,0)+IF(AC10=$AC$8,1,0)+IF(AD10=$AD$8,1,0)+IF(AE10=$AE$8,1,0))) -> 0 | AG10: =IF(D10="","",VLOOKUP(AF10,'PAT-C_Tables'!$E$3:$F$40,2,FALSE)) -> 47.8
A11: 45356 | B11: 3 | C11: 3A | D11: Lname3 | E11: Fname3 | F11: XXXXX3 | AF11: =IF(D11="",0,(IF(G11=$G$8,1,0)+IF(H11=$H$8,1,0)+IF(I11=$I$8,1,0)+IF(J11=$J$8,1,0)+IF(K11=$K$8,1,0)+IF(L11=$L$8,1,0)+IF(M11=$M$8,1,0)+IF(N11=$N$8,1,0)+IF(O11=$O$8,1,0)+IF(P11=$P$8,1,0)+IF(Q11=$Q$8,1,0)+IF(R11=$R$8,1,0)+IF(S11=$S$8,1,0)+IF(T11=$T$8,1,0)+IF(U11=$U$8,1,0)+IF(V11=$V$8,1,0)+IF(W11=$W$8,1,0)+IF(X11=$X$8,1,0)+IF(Y11=$Y$8,1,0)+IF(Z11=$Z$8,1,0)+IF(AA11=$AA$8,1,0)+IF(AB11=$AB$8,1,0)+IF(AC11=$AC$8,1,0)+IF(AD11=$AD$8,1,0)+IF(AE11=$AE$8,1,0))) -> 0 | AG11: =IF(D11="","",VLOOKUP(AF11,'PAT-C_Tables'!$E$3:$F$40,2,FALSE)) -> 47.8
A12: 45356 | B12: 3 | C12: 3A | D12: Lname4 | E12: Fname4 | F12: XXXXX4 | AF12: =IF(D12="",0,(IF(G12=$G$8,1,0)+IF(H12=$H$8,1,0)+IF(I12=$I$8,1,0)+IF(J12=$J$8,1,0)+IF(K12=$K$8,1,0)+IF(L12=$L$8,1,0)+IF(M12=$M$8,1,0)+IF(N12=$N$8,1,0)+IF(O12=$O$8,1,0)+IF(P12=$P$8,1,0)+IF(Q12=$Q$8,1,0)+IF(R12=$R$8,1,0)+IF(S12=$S$8,1,0)+IF(T12=$T$8,1,0)+IF(U12=$U$8,1,0)+IF(V12=$V$8,1,0)+IF(W12=$W$8,1,0)+IF(X12=$X$8,1,0)+IF(Y12=$Y$8,1,0)+IF(Z12=$Z$8,1,0)+IF(AA12=$AA$8,1,0)+IF(AB12=$AB$8,1,0)+IF(AC12=$AC$8,1,0)+IF(AD12=$AD$8,1,0)+IF(AE12=$AE$8,1,0))) -> 0 | AG12: =IF(D12="","",VLOOKUP(AF12,'PAT-C_Tables'!$E$3:$F$40,2,FALSE)) -> 47.8
A13: 45356 | B13: 3 | C13: 3B | D13: ULname13 | E13: UFname13 | F13: UNLISTED | AF13: =IF(D13="",0,(IF(G13=$G$8,1,0)+IF(H13=$H$8,1,0)+IF(I13=$I$8,1,0)+IF(J13=$J$8,1,0)+IF(K13=$K$8,1,0)+IF(L13=$L$8,1,0)+IF(M13=$M$8,1,0)+IF(N13=$N$8,1,0)+IF(O13=$O$8,1,0)+IF(P13=$P$8,1,0)+IF(Q13=$Q$8,1,0)+IF(R13=$R$8,1,0)+IF(S13=$S$8,1,0)+IF(T13=$T$8,1,0)+IF(U13=$U$8,1,0)+IF(V13=$V$8,1,0)+IF(W13=$W$8,1,0)+IF(X13=$X$8,1,0)+IF(Y13=$Y$8,1,0)+IF(Z13=$Z$8,1,0)+IF(AA13=$AA$8,1,0)+IF(AB13=$AB$8,1,0)+IF(AC13=$AC$8,1,0)+IF(AD13=$AD$8,1,0)+IF(AE13=$AE$8,1,0))) -> 0 | AG13: =IF(D13="","",VLOOKUP(AF13,'PAT-C_Tables'!$E$3:$F$40,2,FALSE)) -> 47.8
A14: 45356 | B14: 3 | C14: 3A | D14: Lname5 | E14: Fname5 | F14: XXXXX5 | AF14: =IF(D14="",0,(IF(G14=$G$8,1,0)+IF(H14=$H$8,1,0)+IF(I14=$I$8,1,0)+IF(J14=$J$8,1,0)+IF(K14=$K$8,1,0)+IF(L14=$L$8,1,0)+IF(M14=$M$8,1,0)+IF(N14=$N$8,1,0)+IF(O14=$O$8,1,0)+IF(P14=$P$8,1,0)+IF(Q14=$Q$8,1,0)+IF(R14=$R$8,1,0)+IF(S14=$S$8,1,0)+IF(T14=$T$8,1,0)+IF(U14=$U$8,1,0)+IF(V14=$V$8,1,0)+IF(W14=$W$8,1,0)+IF(X14=$X$8,1,0)+IF(Y14=$Y$8,1,0)+IF(Z14=$Z$8,1,0)+IF(AA14=$AA$8,1,0)+IF(AB14=$AB$8,1,0)+IF(AC14=$AC$8,1,0)+IF(AD14=$AD$8,1,0)+IF(AE14=$AE$8,1,0))) -> 0 | AG14: =IF(D14="","",VLOOKUP(AF14,'PAT-C_Tables'!$E$3:$F$40,2,FALSE)) -> 47.8
A15: 45356 | B15: 3 | C15: 3B | D15: Lname6 | E15: Fname6 | F15: XXXXX6 | AF15: =IF(D15="",0,(IF(G15=$G$8,1,0)+IF(H15=$H$8,1,0)+IF(I15=$I$8,1,0)+IF(J15=$J$8,1,0)+IF(K15=$K$8,1,0)+IF(L15=$L$8,1,0)+IF(M15=$M$8,1,0)+IF(N15=$N$8,1,0)+IF(O15=$O$8,1,0)+IF(P15=$P$8,1,0)+IF(Q15=$Q$8,1,0)+IF(R15=$R$8,1,0)+IF(S15=$S$8,1,0)+IF(T15=$T$8,1,0)+IF(U15=$U$8,1,0)+IF(V15=$V$8,1,0)+IF(W15=$W$8,1,0)+IF(X15=$X$8,1,0)+IF(Y15=$Y$8,1,0)+IF(Z15=$Z$8,1,0)+IF(AA15=$AA$8,1,0)+IF(AB15=$AB$8,1,0)+IF(AC15=$AC$8,1,0)+IF(AD15=$AD$8,1,0)+IF(AE15=$AE$8,1,0))) -> 0 | AG15: =IF(D15="","",VLOOKUP(AF15,'PAT-C_Tables'!$E$3:$F$40,2,FALSE)) -> 47.8
A16: 45356 | B16: 3 | C16: 3B | D16: Lname7 | E16: Fname7 | F16: XXXXX7 | AF16: =IF(D16="",0,(IF(G16=$G$8,1,0)+IF(H16=$H$8,1,0)+IF(I16=$I$8,1,0)+IF(J16=$J$8,1,0)+IF(K16=$K$8,1,0)+IF(L16=$L$8,1,0)+IF(M16=$M$8,1,0)+IF(N16=$N$8,1,0)+IF(O16=$O$8,1,0)+IF(P16=$P$8,1,0)+IF(Q16=$Q$8,1,0)+IF(R16=$R$8,1,0)+IF(S16=$S$8,1,0)+IF(T16=$T$8,1,0)+IF(U16=$U$8,1,0)+IF(V16=$V$8,1,0)+IF(W16=$W$8,1,0)+IF(X16=$X$8,1,0)+IF(Y16=$Y$8,1,0)+IF(Z16=$Z$8,1,0)+IF(AA16=$AA$8,1,0)+IF(AB16=$AB$8,1,0)+IF(AC16=$AC$8,1,0)+IF(AD16=$AD$8,1,0)+IF(AE16=$AE$8,1,0))) -> 0 | AG16: =IF(D16="","",VLOOKUP(AF16,'PAT-C_Tables'!$E$3:$F$40,2,FALSE)) -> 47.8
A17: 45356 | B17: 3 | C17: 3B | D17: Lname8 | E17: Fname8 | F17: XXXXX8 | AF17: =IF(D17="",0,(IF(G17=$G$8,1,0)+IF(H17=$H$8,1,0)+IF(I17=$I$8,1,0)+IF(J17=$J$8,1,0)+IF(K17=$K$8,1,0)+IF(L17=$L$8,1,0)+IF(M17=$M$8,1,0)+IF(N17=$N$8,1,0)+IF(O17=$O$8,1,0)+IF(P17=$P$8,1,0)+IF(Q17=$Q$8,1,0)+IF(R17=$R$8,1,0)+IF(S17=$S$8,1,0)+IF(T17=$T$8,1,0)+IF(U17=$U$8,1,0)+IF(V17=$V$8,1,0)+IF(W17=$W$8,1,0)+IF(X17=$X$8,1,0)+IF(Y17=$Y$8,1,0)+IF(Z17=$Z$8,1,0)+IF(AA17=$AA$8,1,0)+IF(AB17=$AB$8,1,0)+IF(AC17=$AC$8,1,0)+IF(AD17=$AD$8,1,0)+IF(AE17=$AE$8,1,0))) -> 0 | AG17: =IF(D17="","",VLOOKUP(AF17,'PAT-C_Tables'!$E$3:$F$40,2,FALSE)) -> 47.8
A18: 45356 | B18: 3 | C18: 3B | D18: Lname9 | E18: Fname9 | F18: XXXXX9 | AF18: =IF(D18="",0,(IF(G18=$G$8,1,0)+IF(H18=$H$8,1,0)+IF(I18=$I$8,1,0)+IF(J18=$J$8,1,0)+IF(K18=$K$8,1,0)+IF(L18=$L$8,1,0)+IF(M18=$M$8,1,0)+IF(N18=$N$8,1,0)+IF(O18=$O$8,1,0)+IF(P18=$P$8,1,0)+IF(Q18=$Q$8,1,0)+IF(R18=$R$8,1,0)+IF(S18=$S$8,1,0)+IF(T18=$T$8,1,0)+IF(U18=$U$8,1,0)+IF(V18=$V$8,1,0)+IF(W18=$W$8,1,0)+IF(X18=$X$8,1,0)+IF(Y18=$Y$8,1,0)+IF(Z18=$Z$8,1,0)+IF(AA18=$AA$8,1,0)+IF(AB18=$AB$8,1,0)+IF(AC18=$AC$8,1,0)+IF(AD18=$AD$8,1,0)+IF(AE18=$AE$8,1,0))) -> 0 | AG18: =IF(D18="","",VLOOKUP(AF18,'PAT-C_Tables'!$E$3:$F$40,2,FALSE)) -> 47.8
A19: 45356 | B19: 3 | C19: 3B | D19: Lname10 | E19: Fname10 | F19: XXXXX10 | AF19: =IF(D19="",0,(IF(G19=$G$8,1,0)+IF(H19=$H$8,1,0)+IF(I19=$I$8,1,0)+IF(J19=$J$8,1,0)+IF(K19=$K$8,1,0)+IF(L19=$L$8,1,0)+IF(M19=$M$8,1,0)+IF(N19=$N$8,1,0)+IF(O19=$O$8,1,0)+IF(P19=$P$8,1,0)+IF(Q19=$Q$8,1,0)+IF(R19=$R$8,1,0)+IF(S19=$S$8,1,0)+IF(T19=$T$8,1,0)+IF(U19=$U$8,1,0)+IF(V19=$V$8,1,0)+IF(W19=$W$8,1,0)+IF(X19=$X$8,1,0)+IF(Y19=$Y$8,1,0)+IF(Z19=$Z$8,1,0)+IF(AA19=$AA$8,1,0)+IF(AB19=$AB$8,1,0)+IF(AC19=$AC$8,1,0)+IF(AD19=$AD$8,1,0)+IF(AE19=$AE$8,1,0))) -> 0 | AG19: =IF(D19="","",VLOOKUP(AF19,'PAT-C_Tables'!$E$3:$F$40,2,FALSE)) -> 47.8
AF20: =IF(D20="",0,(IF(G20=$G$8,1,0)+IF(H20=$H$8,1,0)+IF(I20=$I$8,1,0)+IF(J20=$J$8,1,0)+IF(K20=$K$8,1,0)+IF(L20=$L$8,1,0)+IF(M20=$M$8,1,0)+IF(N20=$N$8,1,0)+IF(O20=$O$8,1,0)+IF(P20=$P$8,1,0)+IF(Q20=$Q$8,1,0)+IF(R20=$R$8,1,0)+IF(S20=$S$8,1,0)+IF(T20=$T$8,1,0)+IF(U20=$U$8,1,0)+IF(V20=$V$8,1,0)+IF(W20=$W$8,1,0)+IF(X20=$X$8,1,0)+IF(Y20=$Y$8,1,0)+IF(Z20=$Z$8,1,0)+IF(AA20=$AA$8,1,0)+IF(AB20=$AB$8,1,0)+IF(AC20=$AC$8,1,0)+IF(AD20=$AD$8,1,0)+IF(AE20=$AE$8,1,0))) -> 0 | AG20: =IF(D20="","",VLOOKUP(AF20,'PAT-C_Tables'!$E$3:$F$40,2,FALSE))
AF21: =IF(D21="",0,(IF(G21=$G$8,1,0)+IF(H21=$H$8,1,0)+IF(I21=$I$8,1,0)+IF(J21=$J$8,1,0)+IF(K21=$K$8,1,0)+IF(L21=$L$8,1,0)+IF(M21=$M$8,1,0)+IF(N21=$N$8,1,0)+IF(O21=$O$8,1,0)+IF(P21=$P$8,1,0)+IF(Q21=$Q$8,1,0)+IF(R21=$R$8,1,0)+IF(S21=$S$8,1,0)+IF(T21=$T$8,1,0)+IF(U21=$U$8,1,0)+IF(V21=$V$8,1,0)+IF(W21=$W$8,1,0)+IF(X21=$X$8,1,0)+IF(Y21=$Y$8,1,0)+IF(Z21=$Z$8,1,0)+IF(AA21=$AA$8,1,0)+IF(AB21=$AB$8,1,0)+IF(AC21=$AC$8,1,0)+IF(AD21=$AD$8,1,0)+IF(AE21=$AE$8,1,0))) -> 0 | AG21: =IF(D21="","",VLOOKUP(AF21,'PAT-C_Tables'!$E$3:$F$40,2,FALSE))
AF22: =IF(D22="",0,(IF(G22=$G$8,1,0)+IF(H22=$H$8,1,0)+IF(I22=$I$8,1,0)+IF(J22=$J$8,1,0)+IF(K22=$K$8,1,0)+IF(L22=$L$8,1,0)+IF(M22=$M$8,1,0)+IF(N22=$N$8,1,0)+IF(O22=$O$8,1,0)+IF(P22=$P$8,1,0)+IF(Q22=$Q$8,1,0)+IF(R22=$R$8,1,0)+IF(S22=$S$8,1,0)+IF(T22=$T$8,1,0)+IF(U22=$U$8,1,0)+IF(V22=$V$8,1,0)+IF(W22=$W$8,1,0)+IF(X22=$X$8,1,0)+IF(Y22=$Y$8,1,0)+IF(Z22=$Z$8,1,0)+IF(AA22=$AA$8,1,0)+IF(AB22=$AB$8,1,0)+IF(AC22=$AC$8,1,0)+IF(AD22=$AD$8,1,0)+IF(AE22=$AE$8,1,0))) -> 0 | AG22: =IF(D22="","",VLOOKUP(AF22,'PAT-C_Tables'!$E$3:$F$40,2,FALSE))
AF23: =IF(D23="",0,(IF(G23=$G$8,1,0)+IF(H23=$H$8,1,0)+IF(I23=$I$8,1,0)+IF(J23=$J$8,1,0)+IF(K23=$K$8,1,0)+IF(L23=$L$8,1,0)+IF(M23=$M$8,1,0)+IF(N23=$N$8,1,0)+IF(O23=$O$8,1,0)+IF(P23=$P$8,1,0)+IF(Q23=$Q$8,1,0)+IF(R23=$R$8,1,0)+IF(S23=$S$8,1,0)+IF(T23=$T$8,1,0)+IF(U23=$U$8,1,0)+IF(V23=$V$8,1,0)+IF(W23=$W$8,1,0)+IF(X23=$X$8,1,0)+IF(Y23=$Y$8,1,0)+IF(Z23=$Z$8,1,0)+IF(AA23=$AA$8,1,0)+IF(AB23=$AB$8,1,0)+IF(AC23=$AC$8,1,0)+IF(AD23=$AD$8,1,0)+IF(AE23=$AE$8,1,0))) -> 0 | AG23: =IF(D23="","",VLOOKUP(AF23,'PAT-C_Tables'!$E$3:$F$40,2,FALSE))
AF24: =IF(D24="",0,(IF(G24=$G$8,1,0)+IF(H24=$H$8,1,0)+IF(I24=$I$8,1,0)+IF(J24=$J$8,1,0)+IF(K24=$K$8,1,0)+IF(L24=$L$8,1,0)+IF(M24=$M$8,1,0)+IF(N24=$N$8,1,0)+IF(O24=$O$8,1,0)+IF(P24=$P$8,1,0)+IF(Q24=$Q$8,1,0)+IF(R24=$R$8,1,0)+IF(S24=$S$8,1,0)+IF(T24=$T$8,1,0)+IF(U24=$U$8,1,0)+IF(V24=$V$8,1,0)+IF(W24=$W$8,1,0)+IF(X24=$X$8,1,0)+IF(Y24=$Y$8,1,0)+IF(Z24=$Z$8,1,0)+IF(AA24=$AA$8,1,0)+IF(AB24=$AB$8,1,0)+IF(AC24=$AC$8,1,0)+IF(AD24=$AD$8,1,0)+IF(AE24=$AE$8,1,0))) -> 0 | AG24: =IF(D24="","",VLOOKUP(AF24,'PAT-C_Tables'!$E$3:$F$40,2,FALSE))
AF25: =IF(D25="",0,(IF(G25=$G$8,1,0)+IF(H25=$H$8,1,0)+IF(I25=$I$8,1,0)+IF(J25=$J$8,1,0)+IF(K25=$K$8,1,0)+IF(L25=$L$8,1,0)+IF(M25=$M$8,1,0)+IF(N25=$N$8,1,0)+IF(O25=$O$8,1,0)+IF(P25=$P$8,1,0)+IF(Q25=$Q$8,1,0)+IF(R25=$R$8,1,0)+IF(S25=$S$8,1,0)+IF(T25=$T$8,1,0)+IF(U25=$U$8,1,0)+IF(V25=$V$8,1,0)+IF(W25=$W$8,1,0)+IF(X25=$X$8,1,0)+IF(Y25=$Y$8,1,0)+IF(Z25=$Z$8,1,0)+IF(AA25=$AA$8,1,0)+IF(AB25=$AB$8,1,0)+IF(AC25=$AC$8,1,0)+IF(AD25=$AD$8,1,0)+IF(AE25=$AE$8,1,0))) -> 0 | AG25: =IF(D25="","",VLOOKUP(AF25,'PAT-C_Tables'!$E$3:$F$40,2,FALSE))
AF26: =IF(D26="",0,(IF(G26=$G$8,1,0)+IF(H26=$H$8,1,0)+IF(I26=$I$8,1,0)+IF(J26=$J$8,1,0)+IF(K26=$K$8,1,0)+IF(L26=$L$8,1,0)+IF(M26=$M$8,1,0)+IF(N26=$N$8,1,0)+IF(O26=$O$8,1,0)+IF(P26=$P$8,1,0)+IF(Q26=$Q$8,1,0)+IF(R26=$R$8,1,0)+IF(S26=$S$8,1,0)+IF(T26=$T$8,1,0)+IF(U26=$U$8,1,0)+IF(V26=$V$8,1,0)+IF(W26=$W$8,1,0)+IF(X26=$X$8,1,0)+IF(Y26=$Y$8,1,0)+IF(Z26=$Z$8,1,0)+IF(AA26=$AA$8,1,0)+IF(AB26=$AB$8,1,0)+IF(AC26=$AC$8,1,0)+IF(AD26=$AD$8,1,0)+IF(AE26=$AE$8,1,0))) -> 0 | AG26: =IF(D26="","",VLOOKUP(AF26,'PAT-C_Tables'!$E$3:$F$40,2,FALSE))
AF27: =IF(D27="",0,(IF(G27=$G$8,1,0)+IF(H27=$H$8,1,0)+IF(I27=$I$8,1,0)+IF(J27=$J$8,1,0)+IF(K27=$K$8,1,0)+IF(L27=$L$8,1,0)+IF(M27=$M$8,1,0)+IF(N27=$N$8,1,0)+IF(O27=$O$8,1,0)+IF(P27=$P$8,1,0)+IF(Q27=$Q$8,1,0)+IF(R27=$R$8,1,0)+IF(S27=$S$8,1,0)+IF(T27=$T$8,1,0)+IF(U27=$U$8,1,0)+IF(V27=$V$8,1,0)+IF(W27=$W$8,1,0)+IF(X27=$X$8,1,0)+IF(Y27=$Y$8,1,0)+IF(Z27=$Z$8,1,0)+IF(AA27=$AA$8,1,0)+IF(AB27=$AB$8,1,0)+IF(AC27=$AC$8,1,0)+IF(AD27=$AD$8,1,0)+IF(AE27=$AE$8,1,0))) -> 0 | AG27: =IF(D27="","",VLOOKUP(AF27,'PAT-C_Tables'!$E$3:$F$40,2,FALSE))
AF28: =IF(D28="",0,(IF(G28=$G$8,1,0)+IF(H28=$H$8,1,0)+IF(I28=$I$8,1,0)+IF(J28=$J$8,1,0)+IF(K28=$K$8,1,0)+IF(L28=$L$8,1,0)+IF(M28=$M$8,1,0)+IF(N28=$N$8,1,0)+IF(O28=$O$8,1,0)+IF(P28=$P$8,1,0)+IF(Q28=$Q$8,1,0)+IF(R28=$R$8,1,0)+IF(S28=$S$8,1,0)+IF(T28=$T$8,1,0)+IF(U28=$U$8,1,0)+IF(V28=$V$8,1,0)+IF(W28=$W$8,1,0)+IF(X28=$X$8,1,0)+IF(Y28=$Y$8,1,0)+IF(Z28=$Z$8,1,0)+IF(AA28=$AA$8,1,0)+IF(AB28=$AB$8,1,0)+IF(AC28=$AC$8,1,0)+IF(AD28=$AD$8,1,0)+IF(AE28=$AE$8,1,0))) -> 0 | AG28: =IF(D28="","",VLOOKUP(AF28,'PAT-C_Tables'!$E$3:$F$40,2,FALSE))
AF29: =IF(D29="",0,(IF(G29=$G$8,1,0)+IF(H29=$H$8,1,0)+IF(I29=$I$8,1,0)+IF(J29=$J$8,1,0)+IF(K29=$K$8,1,0)+IF(L29=$L$8,1,0)+IF(M29=$M$8,1,0)+IF(N29=$N$8,1,0)+IF(O29=$O$8,1,0)+IF(P29=$P$8,1,0)+IF(Q29=$Q$8,1,0)+IF(R29=$R$8,1,0)+IF(S29=$S$8,1,0)+IF(T29=$T$8,1,0)+IF(U29=$U$8,1,0)+IF(V29=$V$8,1,0)+IF(W29=$W$8,1,0)+IF(X29=$X$8,1,0)+IF(Y29=$Y$8,1,0)+IF(Z29=$Z$8,1,0)+IF(AA29=$AA$8,1,0)+IF(AB29=$AB$8,1,0)+IF(AC29=$AC$8,1,0)+IF(AD29=$AD$8,1,0)+IF(AE29=$AE$8,1,0))) -> 0 | AG29: =IF(D29="","",VLOOKUP(AF29,'PAT-C_Tables'!$E$3:$F$40,2,FALSE))
AF30: =IF(D30="",0,(IF(G30=$G$8,1,0)+IF(H30=$H$8,1,0)+IF(I30=$I$8,1,0)+IF(J30=$J$8,1,0)+IF(K30=$K$8,1,0)+IF(L30=$L$8,1,0)+IF(M30=$M$8,1,0)+IF(N30=$N$8,1,0)+IF(O30=$O$8,1,0)+IF(P30=$P$8,1,0)+IF(Q30=$Q$8,1,0)+IF(R30=$R$8,1,0)+IF(S30=$S$8,1,0)+IF(T30=$T$8,1,0)+IF(U30=$U$8,1,0)+IF(V30=$V$8,1,0)+IF(W30=$W$8,1,0)+IF(X30=$X$8,1,0)+IF(Y30=$Y$8,1,0)+IF(Z30=$Z$8,1,0)+IF(AA30=$AA$8,1,0)+IF(AB30=$AB$8,1,0)+IF(AC30=$AC$8,1,0)+IF(AD30=$AD$8,1,0)+IF(AE30=$AE$8,1,0))) -> 0 | AG30: =IF(D30="","",VLOOKUP(AF30,'PAT-C_Tables'!$E$3:$F$40,2,FALSE))
AF31: =IF(D31="",0,(IF(G31=$G$8,1,0)+IF(H31=$H$8,1,0)+IF(I31=$I$8,1,0)+IF(J31=$J$8,1,0)+IF(K31=$K$8,1,0)+IF(L31=$L$8,1,0)+IF(M31=$M$8,1,0)+IF(N31=$N$8,1,0)+IF(O31=$O$8,1,0)+IF(P31=$P$8,1,0)+IF(Q31=$Q$8,1,0)+IF(R31=$R$8,1,0)+IF(S31=$S$8,1,0)+IF(T31=$T$8,1,0)+IF(U31=$U$8,1,0)+IF(V31=$V$8,1,0)+IF(W31=$W$8,1,0)+IF(X31=$X$8,1,0)+IF(Y31=$Y$8,1,0)+IF(Z31=$Z$8,1,0)+IF(AA31=$AA$8,1,0)+IF(AB31=$AB$8,1,0)+IF(AC31=$AC$8,1,0)+IF(AD31=$AD$8,1,0)+IF(AE31=$AE$8,1,0))) -> 0 | AG31: =IF(D31="","",VLOOKUP(AF31,'PAT-C_Tables'!$E$3:$F$40,2,FALSE))
... AF486: =IF(D486="",0,(IF(G486=$G$8,1,0)+IF(H486=$H$8,1,0)+IF(I486=$I$8,1,0)+IF(J486=$J$8,1,0)+IF(K486=$K$8,1,0)+IF(L486=$L$8,1,0)+IF(M486=$M$8,1,0)+IF(N486=$N$8,1,0)+IF(O486=$O$8,1,0)+IF(P486=$P$8,1,0)+IF(Q486=$Q$8,1,0)+IF(R486=$R$8,1,0)+IF(S486=$S$8,1,0)+IF(T486=$T$8,1,0)+IF(U486=$U$8,1,0)+IF(V486=$V$8,1,0)+IF(W486=$W$8,1,0)+IF(X486=$X$8,1,0)+IF(Y486=$Y$8,1,0)+IF(Z486=$Z$8,1,0)+IF(AA486=$AA$8,1,0)+IF(AB486=$AB$8,1,0)+IF(AC486=$AC$8,1,0)+IF(AD486=$AD$8,1,0)+IF(AE486=$AE$8,1,0))) -> 0 | AG486: =IF(D486="","",VLOOKUP(AF486,'PAT-C_Tables'!$E$3:$F$40,2,FALSE))

Sheet PAT-R Comp 3
A1: PAT-R Comprehesion - Test Booklet 3
G3: QUESTION No. and ANSWER KEY (Enter the student's response - "A" or "B" or "C" or "D")
E4: Question Number | G4: 1 | H4: 2 | I4: 3 | J4: 4 | K4: 5 | L4: 6 | M4: 7 | N4: 8 | O4: 9 | P4: 10 | Q4: 11 | R4: 12 | S4: 13 | T4: 14 | U4: 15 | V4: 16 | W4: 17 | X4: 18 | Y4: 19 | Z4: 20 | AA4: 21 | AB4: 22 | AC4: 23 | AD4: 24 | AE4: 25 | AF4: 26 | AG4: 27 | AH4: 28
E5: Item Difficulty | G5: 80.08 | H5: 92.73 | I5: 86.33 | J5: 85.57 | K5: 88.36 | L5: 86.05 | M5: 93.16 | N5: 95.61 | O5: 95.73 | P5: 104.17 | Q5: 101.99 | R5: 101.57 | S5: 115.71 | T5: 103.4 | U5: 115.61 | V5: 101.05 | W5: 104.6 | X5: 108.73 | Y5: 105.77 | Z5: 99.35 | AA5: 97.46 | AB5: 105.73 | AC5: 98.61 | AD5: 108.67 | AE5: 112.83 | AF5: 123.86 | AG5: 112.36 | AH5: 108.55
E6: Skill Assessed | G6: IE | H6: RI | I6: RI | J6: II | K6: II | L6: RI | M6: RI | N6: RI | O6: II | P6: IE | Q6: IE | R6: IE | S6: II | T6: IE | U6: II | V6: II | W6: II | X6: RI | Y6: II | Z6: IE | AA6: II | AB6: IE | AC6: RF | AD6: II | AE6: IE | AF6: RF | AG6: RI | AH6: II
A7: required | B7: required | C7: optional | D7: required | E7: required | F7: required
A8: Date (dd/mm/yy) | B8: Yr_Lev | C8: HG | D8: Surname | E8: First_Name | F8: Student_ID | G8: D | H8: D | I8: B | J8: D | K8: D | L8: A | M8: C | N8: C | O8: B | P8: C | Q8: C | R8: A | S8: B | T8: D | U8: C | V8: B | W8: D | X8: C | Y8: A | Z8: B | AA8: B | AB8: C | AC8: B | AD8: D | AE8: D | AF8: D | AG8: B | AH8: B | AI8: Raw Score | AJ8: PAT Score
A9: 45356 | B9: 3 | C9: 3A | D9: Lname1 | E9: Fname1 | F9: XXXXX1 | AI9: =IF(D9="",0,(IF(G9=$G$8,1,0)+IF(H9=$H$8,1,0)+IF(I9=$I$8,1,0)+IF(J9=$J$8,1,0)+IF(K9=$K$8,1,0)+IF(L9=$L$8,1,0)+IF(M9=$M$8,1,0)+IF(N9=$N$8,1,0)+IF(O9=$O$8,1,0)+IF(P9=$P$8,1,0)+IF(Q9=$Q$8,1,0)+IF(R9=$R$8,1,0)+IF(S9=$S$8,1,0)+IF(T9=$T$8,1,0)+IF(U9=$U$8,1,0)+IF(V9=$V$8,1,0)+IF(W9=$W$8,1,0)+IF(X9=$X$8,1,0)+IF(Y9=$Y$8,1,0)+IF(Z9=$Z$8,1,0)+IF(AA9=$AA$8,1,0)+IF(AB9=$AB$8,1,0)+IF(AC9=$AC$8,1,0)+IF(AD9=$AD$8,1,0)+IF(AE9=$AE$8,1,0)+IF(AF9=$AF$8,1,0)+IF(AG9=$AG$8,1,0)+IF(AH9=$AH$8,1,0))) -> 0 | AJ9: =IF(D9="","",VLOOKUP(AI9,'PAT-C_Tables'!$G$3:$H$40,2,FALSE)) -> 53
A10: 45356 | B10: 3 | C10: 3A | D10: Lname2 | E10: Fname2 | F10: XXXXX2 | AI10: =IF(D10="",0,(IF(G10=$G$8,1,0)+IF(H10=$H$8,1,0)+IF(I10=$I$8,1,0)+IF(J10=$J$8,1,0)+IF(K10=$K$8,1,0)+IF(L10=$L$8,1,0)+IF(M10=$M$8,1,0)+IF(N10=$N$8,1,0)+IF(O10=$O$8,1,0)+IF(P10=$P$8,1,0)+IF(Q10=$Q$8,1,0)+IF(R10=$R$8,1,0)+IF(S10=$S$8,1,0)+IF(T10=$T$8,1,0)+IF(U10=$U$8,1,0)+IF(V10=$V$8,1,0)+IF(W10=$W$8,1,0)+IF(X10=$X$8,1,0)+IF(Y10=$Y$8,1,0)+IF(Z10=$Z$8,1,0)+IF(AA10=$AA$8,1,0)+IF(AB10=$AB$8,1,0)+IF(AC10=$AC$8,1,0)+IF(AD10=$AD$8,1,0)+IF(AE10=$AE$8,1,0)+IF(AF10=$AF$8,1,0)+IF(AG10=$AG$8,1,0)+IF(AH10=$AH$8,1,0))) -> 0 | AJ10: =IF(D10="","",VLOOKUP(AI10,'PAT-C_Tables'!$G$3:$H$40,2,FALSE)) -> 53
A11: 45356 | B11: 3 | C11: 3A | D11: Lname3 | E11: Fname3 | F11: XXXXX3 | AI11: =IF(D11="",0,(IF(G11=$G$8,1,0)+IF(H11=$H$8,1,0)+IF(I11=$I$8,1,0)+IF(J11=$J$8,1,0)+IF(K11=$K$8,1,0)+IF(L11=$L$8,1,0)+IF(M11=$M$8,1,0)+IF(N11=$N$8,1,0)+IF(O11=$O$8,1,0)+IF(P11=$P$8,1,0)+IF(Q11=$Q$8,1,0)+IF(R11=$R$8,1,0)+IF(S11=$S$8,1,0)+IF(T11=$T$8,1,0)+IF(U11=$U$8,1,0)+IF(V11=$V$8,1,0)+IF(W11=$W$8,1,0)+IF(X11=$X$8,1,0)+IF(Y11=$Y$8,1,0)+IF(Z11=$Z$8,1,0)+IF(AA11=$AA$8,1,0)+IF(AB11=$AB$8,1,0)+IF(AC11=$AC$8,1,0)+IF(AD11=$AD$8,1,0)+IF(AE11=$AE$8,1,0)+IF(AF11=$AF$8,1,0)+IF(AG11=$AG$8,1,0)+IF(AH11=$AH$8,1,0))) -> 0 | AJ11: =IF(D11="","",VLOOKUP(AI11,'PAT-C_Tables'!$G$3:$H$40,2,FALSE)) -> 53
A12: 45356 | B12: 3 | C12: 3A | D12: Lname4 | E12: Fname4 | F12: XXXXX4 | AI12: =IF(D12="",0,(IF(G12=$G$8,1,0)+IF(H12=$H$8,1,0)+IF(I12=$I$8,1,0)+IF(J12=$J$8,1,0)+IF(K12=$K$8,1,0)+IF(L12=$L$8,1,0)+IF(M12=$M$8,1,0)+IF(N12=$N$8,1,0)+IF(O12=$O$8,1,0)+IF(P12=$P$8,1,0)+IF(Q12=$Q$8,1,0)+IF(R12=$R$8,1,0)+IF(S12=$S$8,1,0)+IF(T12=$T$8,1,0)+IF(U12=$U$8,1,0)+IF(V12=$V$8,1,0)+IF(W12=$W$8,1,0)+IF(X12=$X$8,1,0)+IF(Y12=$Y$8,1,0)+IF(Z12=$Z$8,1,0)+IF(AA12=$AA$8,1,0)+IF(AB12=$AB$8,1,0)+IF(AC12=$AC$8,1,0)+IF(AD12=$AD$8,1,0)+IF(AE12=$AE$8,1,0)+IF(AF12=$AF$8,1,0)+IF(AG12=$AG$8,1,0)+IF(AH12=$AH$8,1,0))) -> 0 | AJ12: =IF(D12="","",VLOOKUP(AI12,'PAT-C_Tables'!$G$3:$H$40,2,FALSE)) -> 53
A13: 45356 | B13: 3 | C13: 3B | D13: ULname13 | E13: UFname13 | F13: UNLISTED | AI13: =IF(D13="",0,(IF(G13=$G$8,1,0)+IF(H13=$H$8,1,0)+IF(I13=$I$8,1,0)+IF(J13=$J$8,1,0)+IF(K13=$K$8,1,0)+IF(L13=$L$8,1,0)+IF(M13=$M$8,1,0)+IF(N13=$N$8,1,0)+IF(O13=$O$8,1,0)+IF(P13=$P$8,1,0)+IF(Q13=$Q$8,1,0)+IF(R13=$R$8,1,0)+IF(S13=$S$8,1,0)+IF(T13=$T$8,1,0)+IF(U13=$U$8,1,0)+IF(V13=$V$8,1,0)+IF(W13=$W$8,1,0)+IF(X13=$X$8,1,0)+IF(Y13=$Y$8,1,0)+IF(Z13=$Z$8,1,0)+IF(AA13=$AA$8,1,0)+IF(AB13=$AB$8,1,0)+IF(AC13=$AC$8,1,0)+IF(AD13=$AD$8,1,0)+IF(AE13=$AE$8,1,0)+IF(AF13=$AF$8,1,0)+IF(AG13=$AG$8,1,0)+IF(AH13=$AH$8,1,0))) -> 0 | AJ13: =IF(D13="","",VLOOKUP(AI13,'PAT-C_Tables'!$G$3:$H$40,2,FALSE)) -> 53
A14: 45356 | B14: 3 | C14: 3A | D14: Lname5 | E14: Fname5 | F14: XXXXX5 | AI14: =IF(D14="",0,(IF(G14=$G$8,1,0)+IF(H14=$H$8,1,0)+IF(I14=$I$8,1,0)+IF(J14=$J$8,1,0)+IF(K14=$K$8,1,0)+IF(L14=$L$8,1,0)+IF(M14=$M$8,1,0)+IF(N14=$N$8,1,0)+IF(O14=$O$8,1,0)+IF(P14=$P$8,1,0)+IF(Q14=$Q$8,1,0)+IF(R14=$R$8,1,0)+IF(S14=$S$8,1,0)+IF(T14=$T$8,1,0)+IF(U14=$U$8,1,0)+IF(V14=$V$8,1,0)+IF(W14=$W$8,1,0)+IF(X14=$X$8,1,0)+IF(Y14=$Y$8,1,0)+IF(Z14=$Z$8,1,0)+IF(AA14=$AA$8,1,0)+IF(AB14=$AB$8,1,0)+IF(AC14=$AC$8,1,0)+IF(AD14=$AD$8,1,0)+IF(AE14=$AE$8,1,0)+IF(AF14=$AF$8,1,0)+IF(AG14=$AG$8,1,0)+IF(AH14=$AH$8,1,0))) -> 0 | AJ14: =IF(D14="","",VLOOKUP(AI14,'PAT-C_Tables'!$G$3:$H$40,2,FALSE)) -> 53
A15: 45356 | B15: 3 | C15: 3B | D15: Lname6 | E15: Fname6 | F15: XXXXX6 | AI15: =IF(D15="",0,(IF(G15=$G$8,1,0)+IF(H15=$H$8,1,0)+IF(I15=$I$8,1,0)+IF(J15=$J$8,1,0)+IF(K15=$K$8,1,0)+IF(L15=$L$8,1,0)+IF(M15=$M$8,1,0)+IF(N15=$N$8,1,0)+IF(O15=$O$8,1,0)+IF(P15=$P$8,1,0)+IF(Q15=$Q$8,1,0)+IF(R15=$R$8,1,0)+IF(S15=$S$8,1,0)+IF(T15=$T$8,1,0)+IF(U15=$U$8,1,0)+IF(V15=$V$8,1,0)+IF(W15=$W$8,1,0)+IF(X15=$X$8,1,0)+IF(Y15=$Y$8,1,0)+IF(Z15=$Z$8,1,0)+IF(AA15=$AA$8,1,0)+IF(AB15=$AB$8,1,0)+IF(AC15=$AC$8,1,0)+IF(AD15=$AD$8,1,0)+IF(AE15=$AE$8,1,0)+IF(AF15=$AF$8,1,0)+IF(AG15=$AG$8,1,0)+IF(AH15=$AH$8,1,0))) -> 0 | AJ15: =IF(D15="","",VLOOKUP(AI15,'PAT-C_Tables'!$G$3:$H$40,2,FALSE)) -> 53
A16: 45356 | B16: 3 | C16: 3B | D16: Lname7 | E16: Fname7 | F16: XXXXX7 | AI16: =IF(D16="",0,(IF(G16=$G$8,1,0)+IF(H16=$H$8,1,0)+IF(I16=$I$8,1,0)+IF(J16=$J$8,1,0)+IF(K16=$K$8,1,0)+IF(L16=$L$8,1,0)+IF(M16=$M$8,1,0)+IF(N16=$N$8,1,0)+IF(O16=$O$8,1,0)+IF(P16=$P$8,1,0)+IF(Q16=$Q$8,1,0)+IF(R16=$R$8,1,0)+IF(S16=$S$8,1,0)+IF(T16=$T$8,1,0)+IF(U16=$U$8,1,0)+IF(V16=$V$8,1,0)+IF(W16=$W$8,1,0)+IF(X16=$X$8,1,0)+IF(Y16=$Y$8,1,0)+IF(Z16=$Z$8,1,0)+IF(AA16=$AA$8,1,0)+IF(AB16=$AB$8,1,0)+IF(AC16=$AC$8,1,0)+IF(AD16=$AD$8,1,0)+IF(AE16=$AE$8,1,0)+IF(AF16=$AF$8,1,0)+IF(AG16=$AG$8,1,0)+IF(AH16=$AH$8,1,0))) -> 0 | AJ16: =IF(D16="","",VLOOKUP(AI16,'PAT-C_Tables'!$G$3:$H$40,2,FALSE)) -> 53
A17: 45356 | B17: 3 | C17: 3B | D17: Lname8 | E17: Fname8 | F17: XXXXX8 | AI17: =IF(D17="",0,(IF(G17=$G$8,1,0)+IF(H17=$H$8,1,0)+IF(I17=$I$8,1,0)+IF(J17=$J$8,1,0)+IF(K17=$K$8,1,0)+IF(L17=$L$8,1,0)+IF(M17=$M$8,1,0)+IF(N17=$N$8,1,0)+IF(O17=$O$8,1,0)+IF(P17=$P$8,1,0)+IF(Q17=$Q$8,1,0)+IF(R17=$R$8,1,0)+IF(S17=$S$8,1,0)+IF(T17=$T$8,1,0)+IF(U17=$U$8,1,0)+IF(V17=$V$8,1,0)+IF(W17=$W$8,1,0)+IF(X17=$X$8,1,0)+IF(Y17=$Y$8,1,0)+IF(Z17=$Z$8,1,0)+IF(AA17=$AA$8,1,0)+IF(AB17=$AB$8,1,0)+IF(AC17=$AC$8,1,0)+IF(AD17=$AD$8,1,0)+IF(AE17=$AE$8,1,0)+IF(AF17=$AF$8,1,0)+IF(AG17=$AG$8,1,0)+IF(AH17=$AH$8,1,0))) -> 0 | AJ17: =IF(D17="","",VLOOKUP(AI17,'PAT-C_Tables'!$G$3:$H$40,2,FALSE)) -> 53
A18: 45356 | B18: 3 | C18: 3B | D18: Lname9 | E18: Fname9 | F18: XXXXX9 | AI18: =IF(D18="",0,(IF(G18=$G$8,1,0)+IF(H18=$H$8,1,0)+IF(I18=$I$8,1,0)+IF(J18=$J$8,1,0)+IF(K18=$K$8,1,0)+IF(L18=$L$8,1,0)+IF(M18=$M$8,1,0)+IF(N18=$N$8,1,0)+IF(O18=$O$8,1,0)+IF(P18=$P$8,1,0)+IF(Q18=$Q$8,1,0)+IF(R18=$R$8,1,0)+IF(S18=$S$8,1,0)+IF(T18=$T$8,1,0)+IF(U18=$U$8,1,0)+IF(V18=$V$8,1,0)+IF(W18=$W$8,1,0)+IF(X18=$X$8,1,0)+IF(Y18=$Y$8,1,0)+IF(Z18=$Z$8,1,0)+IF(AA18=$AA$8,1,0)+IF(AB18=$AB$8,1,0)+IF(AC18=$AC$8,1,0)+IF(AD18=$AD$8,1,0)+IF(AE18=$AE$8,1,0)+IF(AF18=$AF$8,1,0)+IF(AG18=$AG$8,1,0)+IF(AH18=$AH$8,1,0))) -> 0 | AJ18: =IF(D18="","",VLOOKUP(AI18,'PAT-C_Tables'!$G$3:$H$40,2,FALSE)) -> 53
A19: 45356 | B19: 3 | C19: 3B | D19: Lname10 | E19: Fname10 | F19: XXXXX10 | AI19: =IF(D19="",0,(IF(G19=$G$8,1,0)+IF(H19=$H$8,1,0)+IF(I19=$I$8,1,0)+IF(J19=$J$8,1,0)+IF(K19=$K$8,1,0)+IF(L19=$L$8,1,0)+IF(M19=$M$8,1,0)+IF(N19=$N$8,1,0)+IF(O19=$O$8,1,0)+IF(P19=$P$8,1,0)+IF(Q19=$Q$8,1,0)+IF(R19=$R$8,1,0)+IF(S19=$S$8,1,0)+IF(T19=$T$8,1,0)+IF(U19=$U$8,1,0)+IF(V19=$V$8,1,0)+IF(W19=$W$8,1,0)+IF(X19=$X$8,1,0)+IF(Y19=$Y$8,1,0)+IF(Z19=$Z$8,1,0)+IF(AA19=$AA$8,1,0)+IF(AB19=$AB$8,1,0)+IF(AC19=$AC$8,1,0)+IF(AD19=$AD$8,1,0)+IF(AE19=$AE$8,1,0)+IF(AF19=$AF$8,1,0)+IF(AG19=$AG$8,1,0)+IF(AH19=$AH$8,1,0))) -> 0 | AJ19: =IF(D19="","",VLOOKUP(AI19,'PAT-C_Tables'!$G$3:$H$40,2,FALSE)) -> 53
AI20: =IF(D20="",0,(IF(G20=$G$8,1,0)+IF(H20=$H$8,1,0)+IF(I20=$I$8,1,0)+IF(J20=$J$8,1,0)+IF(K20=$K$8,1,0)+IF(L20=$L$8,1,0)+IF(M20=$M$8,1,0)+IF(N20=$N$8,1,0)+IF(O20=$O$8,1,0)+IF(P20=$P$8,1,0)+IF(Q20=$Q$8,1,0)+IF(R20=$R$8,1,0)+IF(S20=$S$8,1,0)+IF(T20=$T$8,1,0)+IF(U20=$U$8,1,0)+IF(V20=$V$8,1,0)+IF(W20=$W$8,1,0)+IF(X20=$X$8,1,0)+IF(Y20=$Y$8,1,0)+IF(Z20=$Z$8,1,0)+IF(AA20=$AA$8,1,0)+IF(AB20=$AB$8,1,0)+IF(AC20=$AC$8,1,0)+IF(AD20=$AD$8,1,0)+IF(AE20=$AE$8,1,0)+IF(AF20=$AF$8,1,0)+IF(AG20=$AG$8,1,0)+IF(AH20=$AH$8,1,0))) -> 0 | AJ20: =IF(D20="","",VLOOKUP(AI20,'PAT-C_Tables'!$G$3:$H$40,2,FALSE))
AI21: =IF(D21="",0,(IF(G21=$G$8,1,0)+IF(H21=$H$8,1,0)+IF(I21=$I$8,1,0)+IF(J21=$J$8,1,0)+IF(K21=$K$8,1,0)+IF(L21=$L$8,1,0)+IF(M21=$M$8,1,0)+IF(N21=$N$8,1,0)+IF(O21=$O$8,1,0)+IF(P21=$P$8,1,0)+IF(Q21=$Q$8,1,0)+IF(R21=$R$8,1,0)+IF(S21=$S$8,1,0)+IF(T21=$T$8,1,0)+IF(U21=$U$8,1,0)+IF(V21=$V$8,1,0)+IF(W21=$W$8,1,0)+IF(X21=$X$8,1,0)+IF(Y21=$Y$8,1,0)+IF(Z21=$Z$8,1,0)+IF(AA21=$AA$8,1,0)+IF(AB21=$AB$8,1,0)+IF(AC21=$AC$8,1,0)+IF(AD21=$AD$8,1,0)+IF(AE21=$AE$8,1,0)+IF(AF21=$AF$8,1,0)+IF(AG21=$AG$8,1,0)+IF(AH21=$AH$8,1,0))) -> 0 | AJ21: =IF(D21="","",VLOOKUP(AI21,'PAT-C_Tables'!$G$3:$H$40,2,FALSE))
AI22: =IF(D22="",0,(IF(G22=$G$8,1,0)+IF(H22=$H$8,1,0)+IF(I22=$I$8,1,0)+IF(J22=$J$8,1,0)+IF(K22=$K$8,1,0)+IF(L22=$L$8,1,0)+IF(M22=$M$8,1,0)+IF(N22=$N$8,1,0)+IF(O22=$O$8,1,0)+IF(P22=$P$8,1,0)+IF(Q22=$Q$8,1,0)+IF(R22=$R$8,1,0)+IF(S22=$S$8,1,0)+IF(T22=$T$8,1,0)+IF(U22=$U$8,1,0)+IF(V22=$V$8,1,0)+IF(W22=$W$8,1,0)+IF(X22=$X$8,1,0)+IF(Y22=$Y$8,1,0)+IF(Z22=$Z$8,1,0)+IF(AA22=$AA$8,1,0)+IF(AB22=$AB$8,1,0)+IF(AC22=$AC$8,1,0)+IF(AD22=$AD$8,1,0)+IF(AE22=$AE$8,1,0)+IF(AF22=$AF$8,1,0)+IF(AG22=$AG$8,1,0)+IF(AH22=$AH$8,1,0))) -> 0 | AJ22: =IF(D22="","",VLOOKUP(AI22,'PAT-C_Tables'!$G$3:$H$40,2,FALSE))
AI23: =IF(D23="",0,(IF(G23=$G$8,1,0)+IF(H23=$H$8,1,0)+IF(I23=$I$8,1,0)+IF(J23=$J$8,1,0)+IF(K23=$K$8,1,0)+IF(L23=$L$8,1,0)+IF(M23=$M$8,1,0)+IF(N23=$N$8,1,0)+IF(O23=$O$8,1,0)+IF(P23=$P$8,1,0)+IF(Q23=$Q$8,1,0)+IF(R23=$R$8,1,0)+IF(S23=$S$8,1,0)+IF(T23=$T$8,1,0)+IF(U23=$U$8,1,0)+IF(V23=$V$8,1,0)+IF(W23=$W$8,1,0)+IF(X23=$X$8,1,0)+IF(Y23=$Y$8,1,0)+IF(Z23=$Z$8,1,0)+IF(AA23=$AA$8,1,0)+IF(AB23=$AB$8,1,0)+IF(AC23=$AC$8,1,0)+IF(AD23=$AD$8,1,0)+IF(AE23=$AE$8,1,0)+IF(AF23=$AF$8,1,0)+IF(AG23=$AG$8,1,0)+IF(AH23=$AH$8,1,0))) -> 0 | AJ23: =IF(D23="","",VLOOKUP(AI23,'PAT-C_Tables'!$G$3:$H$40,2,FALSE))
AI24: =IF(D24="",0,(IF(G24=$G$8,1,0)+IF(H24=$H$8,1,0)+IF(I24=$I$8,1,0)+IF(J24=$J$8,1,0)+IF(K24=$K$8,1,0)+IF(L24=$L$8,1,0)+IF(M24=$M$8,1,0)+IF(N24=$N$8,1,0)+IF(O24=$O$8,1,0)+IF(P24=$P$8,1,0)+IF(Q24=$Q$8,1,0)+IF(R24=$R$8,1,0)+IF(S24=$S$8,1,0)+IF(T24=$T$8,1,0)+IF(U24=$U$8,1,0)+IF(V24=$V$8,1,0)+IF(W24=$W$8,1,0)+IF(X24=$X$8,1,0)+IF(Y24=$Y$8,1,0)+IF(Z24=$Z$8,1,0)+IF(AA24=$AA$8,1,0)+IF(AB24=$AB$8,1,0)+IF(AC24=$AC$8,1,0)+IF(AD24=$AD$8,1,0)+IF(AE24=$AE$8,1,0)+IF(AF24=$AF$8,1,0)+IF(AG24=$AG$8,1,0)+IF(AH24=$AH$8,1,0))) -> 0 | AJ24: =IF(D24="","",VLOOKUP(AI24,'PAT-C_Tables'!$G$3:$H$40,2,FALSE))
AI25: =IF(D25="",0,(IF(G25=$G$8,1,0)+IF(H25=$H$8,1,0)+IF(I25=$I$8,1,0)+IF(J25=$J$8,1,0)+IF(K25=$K$8,1,0)+IF(L25=$L$8,1,0)+IF(M25=$M$8,1,0)+IF(N25=$N$8,1,0)+IF(O25=$O$8,1,0)+IF(P25=$P$8,1,0)+IF(Q25=$Q$8,1,0)+IF(R25=$R$8,1,0)+IF(S25=$S$8,1,0)+IF(T25=$T$8,1,0)+IF(U25=$U$8,1,0)+IF(V25=$V$8,1,0)+IF(W25=$W$8,1,0)+IF(X25=$X$8,1,0)+IF(Y25=$Y$8,1,0)+IF(Z25=$Z$8,1,0)+IF(AA25=$AA$8,1,0)+IF(AB25=$AB$8,1,0)+IF(AC25=$AC$8,1,0)+IF(AD25=$AD$8,1,0)+IF(AE25=$AE$8,1,0)+IF(AF25=$AF$8,1,0)+IF(AG25=$AG$8,1,0)+IF(AH25=$AH$8,1,0))) -> 0 | AJ25: =IF(D25="","",VLOOKUP(AI25,'PAT-C_Tables'!$G$3:$H$40,2,FALSE))
AI26: =IF(D26="",0,(IF(G26=$G$8,1,0)+IF(H26=$H$8,1,0)+IF(I26=$I$8,1,0)+IF(J26=$J$8,1,0)+IF(K26=$K$8,1,0)+IF(L26=$L$8,1,0)+IF(M26=$M$8,1,0)+IF(N26=$N$8,1,0)+IF(O26=$O$8,1,0)+IF(P26=$P$8,1,0)+IF(Q26=$Q$8,1,0)+IF(R26=$R$8,1,0)+IF(S26=$S$8,1,0)+IF(T26=$T$8,1,0)+IF(U26=$U$8,1,0)+IF(V26=$V$8,1,0)+IF(W26=$W$8,1,0)+IF(X26=$X$8,1,0)+IF(Y26=$Y$8,1,0)+IF(Z26=$Z$8,1,0)+IF(AA26=$AA$8,1,0)+IF(AB26=$AB$8,1,0)+IF(AC26=$AC$8,1,0)+IF(AD26=$AD$8,1,0)+IF(AE26=$AE$8,1,0)+IF(AF26=$AF$8,1,0)+IF(AG26=$AG$8,1,0)+IF(AH26=$AH$8,1,0))) -> 0 | AJ26: =IF(D26="","",VLOOKUP(AI26,'PAT-C_Tables'!$G$3:$H$40,2,FALSE))
AI27: =IF(D27="",0,(IF(G27=$G$8,1,0)+IF(H27=$H$8,1,0)+IF(I27=$I$8,1,0)+IF(J27=$J$8,1,0)+IF(K27=$K$8,1,0)+IF(L27=$L$8,1,0)+IF(M27=$M$8,1,0)+IF(N27=$N$8,1,0)+IF(O27=$O$8,1,0)+IF(P27=$P$8,1,0)+IF(Q27=$Q$8,1,0)+IF(R27=$R$8,1,0)+IF(S27=$S$8,1,0)+IF(T27=$T$8,1,0)+IF(U27=$U$8,1,0)+IF(V27=$V$8,1,0)+IF(W27=$W$8,1,0)+IF(X27=$X$8,1,0)+IF(Y27=$Y$8,1,0)+IF(Z27=$Z$8,1,0)+IF(AA27=$AA$8,1,0)+IF(AB27=$AB$8,1,0)+IF(AC27=$AC$8,1,0)+IF(AD27=$AD$8,1,0)+IF(AE27=$AE$8,1,0)+IF(AF27=$AF$8,1,0)+IF(AG27=$AG$8,1,0)+IF(AH27=$AH$8,1,0))) -> 0 | AJ27: =IF(D27="","",VLOOKUP(AI27,'PAT-C_Tables'!$G$3:$H$40,2,FALSE))
AI28: =IF(D28="",0,(IF(G28=$G$8,1,0)+IF(H28=$H$8,1,0)+IF(I28=$I$8,1,0)+IF(J28=$J$8,1,0)+IF(K28=$K$8,1,0)+IF(L28=$L$8,1,0)+IF(M28=$M$8,1,0)+IF(N28=$N$8,1,0)+IF(O28=$O$8,1,0)+IF(P28=$P$8,1,0)+IF(Q28=$Q$8,1,0)+IF(R28=$R$8,1,0)+IF(S28=$S$8,1,0)+IF(T28=$T$8,1,0)+IF(U28=$U$8,1,0)+IF(V28=$V$8,1,0)+IF(W28=$W$8,1,0)+IF(X28=$X$8,1,0)+IF(Y28=$Y$8,1,0)+IF(Z28=$Z$8,1,0)+IF(AA28=$AA$8,1,0)+IF(AB28=$AB$8,1,0)+IF(AC28=$AC$8,1,0)+IF(AD28=$AD$8,1,0)+IF(AE28=$AE$8,1,0)+IF(AF28=$AF$8,1,0)+IF(AG28=$AG$8,1,0)+IF(AH28=$AH$8,1,0))) -> 0 | AJ28: =IF(D28="","",VLOOKUP(AI28,'PAT-C_Tables'!$G$3:$H$40,2,FALSE))
AI29: =IF(D29="",0,(IF(G29=$G$8,1,0)+IF(H29=$H$8,1,0)+IF(I29=$I$8,1,0)+IF(J29=$J$8,1,0)+IF(K29=$K$8,1,0)+IF(L29=$L$8,1,0)+IF(M29=$M$8,1,0)+IF(N29=$N$8,1,0)+IF(O29=$O$8,1,0)+IF(P29=$P$8,1,0)+IF(Q29=$Q$8,1,0)+IF(R29=$R$8,1,0)+IF(S29=$S$8,1,0)+IF(T29=$T$8,1,0)+IF(U29=$U$8,1,0)+IF(V29=$V$8,1,0)+IF(W29=$W$8,1,0)+IF(X29=$X$8,1,0)+IF(Y29=$Y$8,1,0)+IF(Z29=$Z$8,1,0)+IF(AA29=$AA$8,1,0)+IF(AB29=$AB$8,1,0)+IF(AC29=$AC$8,1,0)+IF(AD29=$AD$8,1,0)+IF(AE29=$AE$8,1,0)+IF(AF29=$AF$8,1,0)+IF(AG29=$AG$8,1,0)+IF(AH29=$AH$8,1,0))) -> 0 | AJ29: =IF(D29="","",VLOOKUP(AI29,'PAT-C_Tables'!$G$3:$H$40,2,FALSE))
AI30: =IF(D30="",0,(IF(G30=$G$8,1,0)+IF(H30=$H$8,1,0)+IF(I30=$I$8,1,0)+IF(J30=$J$8,1,0)+IF(K30=$K$8,1,0)+IF(L30=$L$8,1,0)+IF(M30=$M$8,1,0)+IF(N30=$N$8,1,0)+IF(O30=$O$8,1,0)+IF(P30=$P$8,1,0)+IF(Q30=$Q$8,1,0)+IF(R30=$R$8,1,0)+IF(S30=$S$8,1,0)+IF(T30=$T$8,1,0)+IF(U30=$U$8,1,0)+IF(V30=$V$8,1,0)+IF(W30=$W$8,1,0)+IF(X30=$X$8,1,0)+IF(Y30=$Y$8,1,0)+IF(Z30=$Z$8,1,0)+IF(AA30=$AA$8,1,0)+IF(AB30=$AB$8,1,0)+IF(AC30=$AC$8,1,0)+IF(AD30=$AD$8,1,0)+IF(AE30=$AE$8,1,0)+IF(AF30=$AF$8,1,0)+IF(AG30=$AG$8,1,0)+IF(AH30=$AH$8,1,0))) -> 0 | AJ30: =IF(D30="","",VLOOKUP(AI30,'PAT-C_Tables'!$G$3:$H$40,2,FALSE))
AI31: =IF(D31="",0,(IF(G31=$G$8,1,0)+IF(H31=$H$8,1,0)+IF(I31=$I$8,1,0)+IF(J31=$J$8,1,0)+IF(K31=$K$8,1,0)+IF(L31=$L$8,1,0)+IF(M31=$M$8,1,0)+IF(N31=$N$8,1,0)+IF(O31=$O$8,1,0)+IF(P31=$P$8,1,0)+IF(Q31=$Q$8,1,0)+IF(R31=$R$8,1,0)+IF(S31=$S$8,1,0)+IF(T31=$T$8,1,0)+IF(U31=$U$8,1,0)+IF(V31=$V$8,1,0)+IF(W31=$W$8,1,0)+IF(X31=$X$8,1,0)+IF(Y31=$Y$8,1,0)+IF(Z31=$Z$8,1,0)+IF(AA31=$AA$8,1,0)+IF(AB31=$AB$8,1,0)+IF(AC31=$AC$8,1,0)+IF(AD31=$AD$8,1,0)+IF(AE31=$AE$8,1,0)+IF(AF31=$AF$8,1,0)+IF(AG31=$AG$8,1,0)+IF(AH31=$AH$8,1,0))) -> 0 | AJ31: =IF(D31="","",VLOOKUP(AI31,'PAT-C_Tables'!$G$3:$H$40,2,FALSE))
... AI484: =IF(D484="",0,(IF(G484=$G$8,1,0)+IF(H484=$H$8,1,0)+IF(I484=$I$8,1,0)+IF(J484=$J$8,1,0)+IF(K484=$K$8,1,0)+IF(L484=$L$8,1,0)+IF(M484=$M$8,1,0)+IF(N484=$N$8,1,0)+IF(O484=$O$8,1,0)+IF(P484=$P$8,1,0)+IF(Q484=$Q$8,1,0)+IF(R484=$R$8,1,0)+IF(S484=$S$8,1,0)+IF(T484=$T$8,1,0)+IF(U484=$U$8,1,0)+IF(V484=$V$8,1,0)+IF(W484=$W$8,1,0)+IF(X484=$X$8,1,0)+IF(Y484=$Y$8,1,0)+IF(Z484=$Z$8,1,0)+IF(AA484=$AA$8,1,0)+IF(AB484=$AB$8,1,0)+IF(AC484=$AC$8,1,0)+IF(AD484=$AD$8,1,0)+IF(AE484=$AE$8,1,0)+IF(AF484=$AF$8,1,0)+IF(AG484=$AG$8,1,0)+IF(AH484=$AH$8,1,0))) -> 0 | AJ484: =IF(D484="","",VLOOKUP(AI484,'PAT-C_Tables'!$G$3:$H$40,2,FALSE))

Sheet PAT-R Comp 4
A1: PAT-R Comprehesion - Test Booklet 4
G3: QUESTION No. and ANSWER KEY (Enter the student's response - "A" or "B" or "C" or "D")
E4: Question Number | G4: 1 | H4: 2 | I4: 3 | J4: 4 | K4: 5 | L4: 6 | M4: 7 | N4: 8 | O4: 9 | P4: 10 | Q4: 11 | R4: 12 | S4: 13 | T4: 14 | U4: 15 | V4: 16 | W4: 17 | X4: 18 | Y4: 19 | Z4: 20 | AA4: 21 | AB4: 22 | AC4: 23 | AD4: 24 | AE4: 25 | AF4: 26 | AG4: 27 | AH4: 28 | AI4: 29 | AJ4: 30
E5: Item Difficulty | G5: 94.54 | H5: 90.53 | I5: 91.14 | J5: 87.4 | K5: 92.53 | L5: 90.64 | M5: 99.98 | N5: 93.7 | O5: 105.62 | P5: 110.94 | Q5: 99 | R5: 117.71 | S5: 106.91 | T5: 115.24 | U5: 102.36 | V5: 106.41 | W5: 116.37 | X5: 114.71 | Y5: 123.53 | Z5: 114.12 | AA5: 104.39 | AB5: 113.9 | AC5: 108.77 | AD5: 115.62 | AE5: 106.34 | AF5: 114.8 | AG5: 123.63 | AH5: 132.15 | AI5: 117.84 | AJ5: 119.07
E6: Skill Assessed | G6: RI | H6: RI | I6: II | J6: RI | K6: IE | L6: RF | M6: IE | N6: RF | O6: IE | P6: RI | Q6: RI | R6: IE | S6: IE | T6: II | U6: RI | V6: IE | W6: RF | X6: IE | Y6: II | Z6: IE | AA6: IE | AB6: II | AC6: IE | AD6: II | AE6: II | AF6: IE | AG6: II | AH6: IE | AI6: II | AJ6: II
A7: required | B7: required | C7: optional | D7: required | E7: required | F7: required
A8: Date (dd/mm/yy) | B8: Yr_Lev | C8: HG | D8: Surname | E8: First_Name | F8: Student_ID | G8: A | H8: D | I8: B | J8: A | K8: C | L8: A | M8: D | N8: D | O8: A | P8: B | Q8: D | R8: B | S8: D | T8: D | U8: B | V8: C | W8: B | X8: C | Y8: B | Z8: A | AA8: B | AB8: D | AC8: A | AD8: B | AE8: C | AF8: C | AG8: A | AH8: C | AI8: D | AJ8: D | AK8: Raw Score | AL8: PAT Score
