Workbook

Sheet Main Menu
B2: South Australian Spelling Test Second Edition Scoring Templates
B4: This series of spreadsheets provide the templates required to enter ACER's South Australian Spelling Test (SAST) results into the Student Performance Analyser (SPA). Click on the appropriate button (at right) to select the correct Test Form proforma to complete. Follow the instructions opposite. | H4: Step 1: Click on the appropriate button (at left) to select the correct Test Form proforma to complete. Step 2: For each student, enter the Date (when test was sat), Year Level, Home Group, Name, and Student ID (CASES No. or Student No.). Step 3: For each question, enter their response (their score will be calculated) OR enter their Raw Score OR enter their PAT Score. Step 4: Save and upload into SPA.
B29: Click here to find out more about other tests available from ACER | H29: Click here to find out more about the Student Performance Analyser

Sheet Form A
A1: SAST - Form A
H3: QUESTION No. and ANSWER KEY (Enter the student's response - "Y" if correct; "N" if incorrect )
F4: Question Number | H4: 1 | I4: 2 | J4: 3 | K4: 4 | L4: 5 | M4: 6 | N4: 7 | O4: 8 | P4: 9 | Q4: 10 | R4: 11 | S4: 12 | T4: 13 | U4: 14 | V4: 15 | W4: 16 | X4: 17 | Y4: 18 | Z4: 19 | AA4: 20 | AB4: 21 | AC4: 22 | AD4: 23 | AE4: 24 | AF4: 25 | AG4: 26 | AH4: 27 | AI4: 28 | AJ4: 29 | AK4: 30 | AL4: 31 | AM4: 32 | AN4: 33 | AO4: 34 | AP4: 35 | AQ4: 36 | AR4: 37 | AS4: 38 | AT4: 39 | AU4: 40 | AV4: 41 | AW4: 42 | AX4: 43 | AY4: 44 | AZ4: 45 | BA4: 46 | BB4: 47 | BC4: 48 | BD4: 49 | BE4: 50 | BF4: 51 | BG4: 52 | BH4: 53 | BI4: 54 | BJ4: 55 | BK4: 56 | BL4: 57 | BM4: 58 | BN4: 59 | BO4: 60 | BP4: 61 | BQ4: 62 | BR4: 63 | BS4: 64 | BT4: 65 | BU4: 66 | BV4: 67 | BW4: 68 | BX4: 69 | BY4: 70
F5: Word | H5: On | I5: Hot | J5: Cup | K5: Van | L5: Jam | M5: Mud | N5: Sit | O5: Beg | P5: Me | Q5: Go | R5: Do | S5: Of | T5: The | U5: So | V5: Plan | W5: Ship | X5: Chop | Y5: From | Z5: Thin | AA5: Lost | AB5: Dart | AC5: Seem | AD5: Food | AE5: For | AF5: Are | AG5: Who | AH5: Here | AI5: Fire | AJ5: Date | AK5: Loud | AL5: Eye | AM5: Fight | AN5: Friend | AO5: Done | AP5: Any | AQ5: Great | AR5: Sure | AS5: Women | AT5: Answer | AU5: Beautiful | AV5: Orchestra | AW5: Equally | AX5: Appreciate | AY5: Familiar | AZ5: Enthusiastic | BA5: Signature | BB5: Breathe | BC5: Permanent | BD5: Sufficient | BE5: Surplus | BF5: Customary | BG5: Especially | BH5: Materially | BI5: Cemetery | BJ5: Leisure | BK5: Fraternally | BL5: Successful | BM5: Definite | BN5: Exhibition | BO5: Apparatus | BP5: Mortgage | BQ5: Equipped | BR5: Subterranean | BS5: Politician | BT5: Miscellaneous | BU5: Exaggerate | BV5: Guarantee | BW5: Embarrassing | BX5: Conscientious | BY5: Seismograph
A7: required | B7: required | C7: required | D7: optional | E7: required | F7: required | G7: required
A8: Date (dd/mm/yy) | B8: Date of Birth (dd/mm/yy) | C8: Yr_Lev | D8: Grp | E8: Surname | F8: First_Name | G8: Student_ID | H8: Y | I8: Y | J8: Y | K8: Y | L8: Y | M8: Y | N8: Y | O8: Y | P8: Y | Q8: Y | R8: Y | S8: Y | T8: Y | U8: Y | V8: Y | W8: Y | X8: Y | Y8: Y | Z8: Y | AA8: Y | AB8: Y | AC8: Y | AD8: Y | AE8: Y | AF8: Y | AG8: Y | AH8: Y | AI8: Y | AJ8: Y | AK8: Y | AL8: Y | AM8: Y | AN8: Y | AO8: Y | AP8: Y | AQ8: Y | AR8: Y | AS8: Y | AT8: Y | AU8: Y | AV8: Y | AW8: Y | AX8: Y | AY8: Y | AZ8: Y | BA8: Y | BB8: Y | BC8: Y | BD8: Y | BE8: Y | BF8: Y | BG8: Y | BH8: Y | BI8: Y | BJ8: Y | BK8: Y | BL8: Y | BM8: Y | BN8: Y | BO8: Y | BP8: Y | BQ8: Y | BR8: Y | BS8: Y | BT8: Y | BU8: Y | BV8: Y | BW8: Y | BX8: Y | BY8: Y | BZ8: Raw Score | CA8: Spelling Age Yrs:mths
A9: 45356 | B9: 40959 | C9: 3 | D9: 3A | E9: Lname1 | F9: Fname1 | G9: XXXXX1 | BZ9: =IF(E9="",0,COUNTIF(H9:BY9,"=Y")) -> 0 | CA9: =IF(E9="","",VLOOKUP(BZ9,LookUp!$A$3:$B$73,2,FALSE)) -> 6
A10: 45356 | B10: 40960 | C10: 3 | D10: 3A | E10: Lname2 | F10: Fname2 | G10: XXXXX2 | BZ10: =IF(E10="",0,COUNTIF(H10:BY10,"=Y")) -> 0 | CA10: =IF(E10="","",VLOOKUP(BZ10,LookUp!$A$3:$B$73,2,FALSE)) -> 6
A11: 45356 | B11: 40961 | C11: 3 | D11: 3A | E11: Lname3 | F11: Fname3 | G11: XXXXX3 | BZ11: =IF(E11="",0,COUNTIF(H11:BY11,"=Y")) -> 0 | CA11: =IF(E11="","",VLOOKUP(BZ11,LookUp!$A$3:$B$73,2,FALSE)) -> 6
A12: 45356 | B12: 40962 | C12: 3 | D12: 3A | E12: Lname4 | F12: Fname4 | G12: XXXXX4 | BZ12: =IF(E12="",0,COUNTIF(H12:BY12,"=Y")) -> 0 | CA12: =IF(E12="","",VLOOKUP(BZ12,LookUp!$A$3:$B$73,2,FALSE)) -> 6
A13: 45356 | B13: 40970 | C13: 3 | D13: 3B | E13: ULname13 | F13: UFname13 | G13: UNLISTED | BZ13: =IF(E13="",0,COUNTIF(H13:BY13,"=Y")) -> 0 | CA13: =IF(E13="","",VLOOKUP(BZ13,LookUp!$A$3:$B$73,2,FALSE)) -> 6
A14: 45356 | B14: 40963 | C14: 3 | D14: 3A | E14: Lname5 | F14: Fname5 | G14: XXXXX5 | BZ14: =IF(E14="",0,COUNTIF(H14:BY14,"=Y")) -> 0 | CA14: =IF(E14="","",VLOOKUP(BZ14,LookUp!$A$3:$B$73,2,FALSE)) -> 6
A15: 45356 | B15: 40964 | C15: 3 | D15: 3B | E15: Lname6 | F15: Fname6 | G15: XXXXX6 | BZ15: =IF(E15="",0,COUNTIF(H15:BY15,"=Y")) -> 0 | CA15: =IF(E15="","",VLOOKUP(BZ15,LookUp!$A$3:$B$73,2,FALSE)) -> 6
A16: 45356 | B16: 40965 | C16: 3 | D16: 3B | E16: Lname7 | F16: Fname7 | G16: XXXXX7 | BZ16: =IF(E16="",0,COUNTIF(H16:BY16,"=Y")) -> 0 | CA16: =IF(E16="","",VLOOKUP(BZ16,LookUp!$A$3:$B$73,2,FALSE)) -> 6
A17: 45356 | B17: 40966 | C17: 3 | D17: 3B | E17: Lname8 | F17: Fname8 | G17: XXXXX8 | BZ17: =IF(E17="",0,COUNTIF(H17:BY17,"=Y")) -> 0 | CA17: =IF(E17="","",VLOOKUP(BZ17,LookUp!$A$3:$B$73,2,FALSE)) -> 6
A18: 45356 | B18: 40967 | C18: 3 | D18: 3B | E18: Lname9 | F18: Fname9 | G18: XXXXX9 | BZ18: =IF(E18="",0,COUNTIF(H18:BY18,"=Y")) -> 0 | CA18: =IF(E18="","",VLOOKUP(BZ18,LookUp!$A$3:$B$73,2,FALSE)) -> 6
A19: 45356 | B19: 40968 | C19: 3 | D19: 3B | E19: Lname10 | F19: Fname10 | G19: XXXXX10 | BZ19: =IF(E19="",0,COUNTIF(H19:BY19,"=Y")) -> 0 | CA19: =IF(E19="","",VLOOKUP(BZ19,LookUp!$A$3:$B$73,2,FALSE)) -> 6
BZ20: =IF(E20="",0,COUNTIF(H20:BY20,"=Y")) -> 0 | CA20: =IF(E20="","",VLOOKUP(BZ20,LookUp!$A$3:$B$73,2,FALSE))
BZ21: =IF(E21="",0,COUNTIF(H21:BY21,"=Y")) -> 0 | CA21: =IF(E21="","",VLOOKUP(BZ21,LookUp!$A$3:$B$73,2,FALSE))
BZ22: =IF(E22="",0,COUNTIF(H22:BY22,"=Y")) -> 0 | CA22: =IF(E22="","",VLOOKUP(BZ22,LookUp!$A$3:$B$73,2,FALSE))
BZ23: =IF(E23="",0,COUNTIF(H23:BY23,"=Y")) -> 0 | CA23: =IF(E23="","",VLOOKUP(BZ23,LookUp!$A$3:$B$73,2,FALSE))
BZ24: =IF(E24="",0,COUNTIF(H24:BY24,"=Y")) -> 0 | CA24: =IF(E24="","",VLOOKUP(BZ24,LookUp!$A$3:$B$73,2,FALSE))
BZ25: =IF(E25="",0,COUNTIF(H25:BY25,"=Y")) -> 0 | CA25: =IF(E25="","",VLOOKUP(BZ25,LookUp!$A$3:$B$73,2,FALSE))
BZ26: =IF(E26="",0,COUNTIF(H26:BY26,"=Y")) -> 0 | CA26: =IF(E26="","",VLOOKUP(BZ26,LookUp!$A$3:$B$73,2,FALSE))
BZ27: =IF(E27="",0,COUNTIF(H27:BY27,"=Y")) -> 0 | CA27: =IF(E27="","",VLOOKUP(BZ27,LookUp!$A$3:$B$73,2,FALSE))
BZ28: =IF(E28="",0,COUNTIF(H28:BY28,"=Y")) -> 0 | CA28: =IF(E28="","",VLOOKUP(BZ28,LookUp!$A$3:$B$73,2,FALSE))
BZ29: =IF(E29="",0,COUNTIF(H29:BY29,"=Y")) -> 0 | CA29: =IF(E29="","",VLOOKUP(BZ29,LookUp!$A$3:$B$73,2,FALSE))
BZ30: =IF(E30="",0,COUNTIF(H30:BY30,"=Y")) -> 0 | CA30: =IF(E30="","",VLOOKUP(BZ30,LookUp!$A$3:$B$73,2,FALSE))
BZ31: =IF(E31="",0,COUNTIF(H31:BY31,"=Y")) -> 0 | CA31: =IF(E31="","",VLOOKUP(BZ31,LookUp!$A$3:$B$73,2,FALSE))
... BZ502: =IF(E502="",0,COUNTIF(H502:BY502,"=Y")) -> 0 | CA502: =IF(E502="","",VLOOKUP(BZ502,LookUp!$A$3:$B$73,2,FALSE))

Sheet Form B
A1: SAST - Form B
H3: QUESTION No. and ANSWER KEY (Enter the student's response - "Y" if correct; "N" if incorrect )
F4: Question Number | H4: 1 | I4: 2 | J4: 3 | K4: 4 | L4: 5 | M4: 6 | N4: 7 | O4: 8 | P4: 9 | Q4: 10 | R4: 11 | S4: 12 | T4: 13 | U4: 14 | V4: 15 | W4: 16 | X4: 17 | Y4: 18 | Z4: 19 | AA4: 20 | AB4: 21 | AC4: 22 | AD4: 23 | AE4: 24 | AF4: 25 | AG4: 26 | AH4: 27 | AI4: 28 | AJ4: 29 | AK4: 30 | AL4: 31 | AM4: 32 | AN4: 33 | AO4: 34 | AP4: 35 | AQ4: 36 | AR4: 37 | AS4: 38 | AT4: 39 | AU4: 40 | AV4: 41 | AW4: 42 | AX4: 43 | AY4: 44 | AZ4: 45 | BA4: 46 | BB4: 47 | BC4: 48 | BD4: 49 | BE4: 50 | BF4: 51 | BG4: 52 | BH4: 53 | BI4: 54 | BJ4: 55 | BK4: 56 | BL4: 57 | BM4: 58 | BN4: 59 | BO4: 60 | BP4: 61 | BQ4: 62 | BR4: 63 | BS4: 64 | BT4: 65 | BU4: 66 | BV4: 67 | BW4: 68 | BX4: 69 | BY4: 70
F5: Word | H5: In | I5: Top | J5: Can | K5: Pet | L5: Bus | M5: Dig | N5: Fed | O5: Men | P5: Be | Q5: To | R5: By | S5: No | T5: Was | U5: Son | V5: Flag | W5: Trip | X5: Stop | Y5: Skin | Z5: Cost | AA5: Thank | AB5: Need | AC5: Hook | AD5: Part | AE5: Four | AF5: Our | AG5: They | AH5: Hear | AI5: Fare | AJ5: Gate | AK5: Cloud | AL5: Air | AM5: Tight | AN5: Cried | AO5: None | AP5: Ask | AQ5: Treat | AR5: Surf | AS5: world | AT5: Dancer | AU5: Unusual | AV5: Quality | AW5: Furniture | AX5: Reliable | AY5: Fashion | AZ5: Laughter | BA5: Thoughtful | BB5: Encourage | BC5: Efficient | BD5: Purpose | BE5: Curious | BF5: Acceptable | BG5: Equipment | BH5: Choir | BI5: Chemically | BJ5: Neighbour | BK5: Nocturnal | BL5: Assessment | BM5: Adolescence | BN5: Casualty | BO5: Catalogue | BP5: Boulder | BQ5: Exemplary | BR5: Magnificent | BS5: Substitute | BT5: Maintenance | BU5: Disguise | BV5: Proprietor | BW5: Vaccination | BX5: Excruciating | BY5: Kaleidoscope
A7: required | B7: required | C7: required | D7: optional | E7: required | F7: required | G7: required
A8: Date (dd/mm/yy) | B8: Date of Birth (dd/mm/yy) | C8: Yr_Lev | D8: Grp | E8: Surname | F8: First_Name | G8: Student_ID | H8: Y | I8: Y | J8: Y | K8: Y | L8: Y | M8: Y | N8: Y | O8: Y | P8: Y | Q8: Y | R8: Y | S8: Y | T8: Y | U8: Y | V8: Y | W8: Y | X8: Y | Y8: Y | Z8: Y | AA8: Y | AB8: Y | AC8: Y | AD8: Y | AE8: Y | AF8: Y | AG8: Y | AH8: Y | AI8: Y | AJ8: Y | AK8: Y | AL8: Y | AM8: Y | AN8: Y | AO8: Y | AP8: Y | AQ8: Y | AR8: Y | AS8: Y | AT8: Y | AU8: Y | AV8: Y | AW8: Y | AX8: Y | AY8: Y | AZ8: Y | BA8: Y | BB8: Y | BC8: Y | BD8: Y | BE8: Y | BF8: Y | BG8: Y | BH8: Y | BI8: Y | BJ8: Y | BK8: Y | BL8: Y | BM8: Y | BN8: Y | BO8: Y | BP8: Y | BQ8: Y | BR8: Y | BS8: Y | BT8: Y | BU8: Y | BV8: Y | BW8: Y | BX8: Y | BY8: Y | BZ8: Raw Score | CA8: Spelling Age Yrs:mths
A9: 45356 | B9: 40959 | C9: 3 | D9: 3A | E9: Lname1 | F9: Fname1 | G9: XXXXX1 | BZ9: =IF(E9="",0,COUNTIF(H9:BY9,"=Y")) -> 0 | CA9: =IF(E9="","",VLOOKUP(BZ9,LookUp!$D$3:$E$73,2,FALSE)) -> 6
A10: 45356 | B10: 40960 | C10: 3 | D10: 3A | E10: Lname2 | F10: Fname2 | G10: XXXXX2 | BZ10: =IF(E10="",0,COUNTIF(H10:BY10,"=Y")) -> 0 | CA10: =IF(E10="","",VLOOKUP(BZ10,LookUp!$D$3:$E$73,2,FALSE)) -> 6
A11: 45356 | B11: 40961 | C11: 3 | D11: 3A | E11: Lname3 | F11: Fname3 | G11: XXXXX3 | BZ11: =IF(E11="",0,COUNTIF(H11:BY11,"=Y")) -> 0 | CA11: =IF(E11="","",VLOOKUP(BZ11,LookUp!$D$3:$E$73,2,FALSE)) -> 6
A12: 45356 | B12: 40962 | C12: 3 | D12: 3A | E12: Lname4 | F12: Fname4 | G12: XXXXX4 | BZ12: =IF(E12="",0,COUNTIF(H12:BY12,"=Y")) -> 0 | CA12: =IF(E12="","",VLOOKUP(BZ12,LookUp!$D$3:$E$73,2,FALSE)) -> 6
A13: 45356 | B13: 40970 | C13: 3 | D13: 3B | E13: ULname13 | F13: UFname13 | G13: UNLISTED | BZ13: =IF(E13="",0,COUNTIF(H13:BY13,"=Y")) -> 0 | CA13: =IF(E13="","",VLOOKUP(BZ13,LookUp!$D$3:$E$73,2,FALSE)) -> 6
A14: 45356 | B14: 40963 | C14: 3 | D14: 3A | E14: Lname5 | F14: Fname5 | G14: XXXXX5 | BZ14: =IF(E14="",0,COUNTIF(H14:BY14,"=Y")) -> 0 | CA14: =IF(E14="","",VLOOKUP(BZ14,LookUp!$D$3:$E$73,2,FALSE)) -> 6
A15: 45356 | B15: 40964 | C15: 3 | D15: 3B | E15: Lname6 | F15: Fname6 | G15: XXXXX6 | BZ15: =IF(E15="",0,COUNTIF(H15:BY15,"=Y")) -> 0 | CA15: =IF(E15="","",VLOOKUP(BZ15,LookUp!$D$3:$E$73,2,FALSE)) -> 6
A16: 45356 | B16: 40965 | C16: 3 | D16: 3B | E16: Lname7 | F16: Fname7 | G16: XXXXX7 | BZ16: =IF(E16="",0,COUNTIF(H16:BY16,"=Y")) -> 0 | CA16: =IF(E16="","",VLOOKUP(BZ16,LookUp!$D$3:$E$73,2,FALSE)) -> 6
A17: 45356 | B17: 40966 | C17: 3 | D17: 3B | E17: Lname8 | F17: Fname8 | G17: XXXXX8 | BZ17: =IF(E17="",0,COUNTIF(H17:BY17,"=Y")) -> 0 | CA17: =IF(E17="","",VLOOKUP(BZ17,LookUp!$D$3:$E$73,2,FALSE)) -> 6
A18: 45356 | B18: 40967 | C18: 3 | D18: 3B | E18: Lname9 | F18: Fname9 | G18: XXXXX9 | BZ18: =IF(E18="",0,COUNTIF(H18:BY18,"=Y")) -> 0 | CA18: =IF(E18="","",VLOOKUP(BZ18,LookUp!$D$3:$E$73,2,FALSE)) -> 6
A19: 45356 | B19: 40968 | C19: 3 | D19: 3B | E19: Lname10 | F19: Fname10 | G19: XXXXX10 | BZ19: =IF(E19="",0,COUNTIF(H19:BY19,"=Y")) -> 0 | CA19: =IF(E19="","",VLOOKUP(BZ19,LookUp!$D$3:$E$73,2,FALSE)) -> 6
BZ20: =IF(E20="",0,COUNTIF(H20:BY20,"=Y")) -> 0 | CA20: =IF(E20="","",VLOOKUP(BZ20,LookUp!$D$3:$E$73,2,FALSE))
BZ21: =IF(E21="",0,COUNTIF(H21:BY21,"=Y")) -> 0 | CA21: =IF(E21="","",VLOOKUP(BZ21,LookUp!$D$3:$E$73,2,FALSE))
BZ22: =IF(E22="",0,COUNTIF(H22:BY22,"=Y")) -> 0 | CA22: =IF(E22="","",VLOOKUP(BZ22,LookUp!$D$3:$E$73,2,FALSE))
BZ23: =IF(E23="",0,COUNTIF(H23:BY23,"=Y")) -> 0 | CA23: =IF(E23="","",VLOOKUP(BZ23,LookUp!$D$3:$E$73,2,FALSE))
BZ24: =IF(E24="",0,COUNTIF(H24:BY24,"=Y")) -> 0 | CA24: =IF(E24="","",VLOOKUP(BZ24,LookUp!$D$3:$E$73,2,FALSE))
BZ25: =IF(E25="",0,COUNTIF(H25:BY25,"=Y")) -> 0 | CA25: =IF(E25="","",VLOOKUP(BZ25,LookUp!$D$3:$E$73,2,FALSE))
BZ26: =IF(E26="",0,COUNTIF(H26:BY26,"=Y")) -> 0 | CA26: =IF(E26="","",VLOOKUP(BZ26,LookUp!$D$3:$E$73,2,FALSE))
BZ27: =IF(E27="",0,COUNTIF(H27:BY27,"=Y")) -> 0 | CA27: =IF(E27="","",VLOOKUP(BZ27,LookUp!$D$3:$E$73,2,FALSE))
BZ28: =IF(E28="",0,COUNTIF(H28:BY28,"=Y")) -> 0 | CA28: =IF(E28="","",VLOOKUP(BZ28,LookUp!$D$3:$E$73,2,FALSE))
BZ29: =IF(E29="",0,COUNTIF(H29:BY29,"=Y")) -> 0 | CA29: =IF(E29="","",VLOOKUP(BZ29,LookUp!$D$3:$E$73,2,FALSE))
BZ30: =IF(E30="",0,COUNTIF(H30:BY30,"=Y")) -> 0 | CA30: =IF(E30="","",VLOOKUP(BZ30,LookUp!$D$3:$E$73,2,FALSE))
BZ31: =IF(E31="",0,COUNTIF(H31:BY31,"=Y")) -> 0 | CA31: =IF(E31="","",VLOOKUP(BZ31,LookUp!$D$3:$E$73,2,FALSE))
... BZ502: =IF(E502="",0,COUNTIF(H502:BY502,"=Y")) -> 0 | CA502: =IF(E502="","",VLOOKUP(BZ502,LookUp!$D$3:$E$73,2,FALSE))
CA503: =IF(E503="","",VLOOKUP(BZ503,LookUp!$D$3:$E$73,2,FALSE))
CA504: =IF(E504="","",VLOOKUP(BZ504,LookUp!$D$3:$E$73,2,FALSE))
CA505: =IF(E505="","",VLOOKUP(BZ505,LookUp!$D$3:$E$73,2,FALSE))
CA506: =IF(E506="","",VLOOKUP(BZ506,LookUp!$D$3:$E$73,2,FALSE))
CA507: =IF(E507="","",VLOOKUP(BZ507,LookUp!$D$3:$E$73,2,FALSE))
CA508: =IF(E508="","",VLOOKUP(BZ508,LookUp!$D$3:$E$73,2,FALSE))
CA509: =IF(E509="","",VLOOKUP(BZ509,LookUp!$D$3:$E$73,2,FALSE))
CA510: =IF(E510="","",VLOOKUP(BZ510,LookUp!$D$3:$E$73,2,FALSE))
CA511: =IF(E511="","",VLOOKUP(BZ511,LookUp!$D$3:$E$73,2,FALSE))
CA512: =IF(E512="","",VLOOKUP(BZ512,LookUp!$D$3:$E$73,2,FALSE))
...

Sheet LookUp
A1: FORM A | D1: FORM B
A2: Score | B2: Approx Spelling Age (Yrs.Mths) | D2: Score | E2: Approx Spelling Age (Yrs.Mths)
A3: 0 | B3: 6 | D3: 0 | E3: 6
A4: 1 | B4: 6 | D4: 1 | E4: 6
A5: 2 | B5: 6 | D5: 2 | E5: 6
A6: 3 | B6: 6 | D6: 3 | E6: 6
A7: 4 | B7: 6 | D7: 4 | E7: 6
A8: 5 | B8: 6 | D8: 5 | E8: 6
A9: 6 | B9: 6 | D9: 6 | E9: 6
A10: 7 | B10: 6 | D10: 7 | E10: 6
A11: 8 | B11: 6 | D11: 8 | E11: 6
A12: 9 | B12: 6 | D12: 9 | E12: 6
A13: 10 | B13: 6 | D13: 10 | E13: 6
A14: 11 | B14: 6 | D14: 11 | E14: 6
... A60: 57 | B60: 16 | D60: 57 | E60: 15.09
A61: 58 | B61: 16 | D61: 58 | E61: 16 or higher
A62: 59 | B62: 16 | D62: 59 | E62: 16 or higher
A63: 60 | B63: 16 | D63: 60 | E63: 16 or higher
A64: 61 | B64: 16 | D64: 61 | E64: 16 or higher
A65: 62 | B65: 16 | D65: 62 | E65: 16 or higher
A66: 63 | B66: 16 | D66: 63 | E66: 16 or higher
A67: 64 | B67: 16 | D67: 64 | E67: 16 or higher
A68: 65 | B68: 16 | D68: 65 | E68: 16 or higher
A69: 66 | B69: 16 | D69: 66 | E69: 16 or higher
A70: 67 | B70: 16 | D70: 67 | E70: 16 or higher
A71: 68 | B71: 16 | D71: 68 | E71: 16 or higher
A72: 69 | B72: 16 | D72: 69 | E72: 16 or higher
A73: 70 | B73: 16 | D73: 70 | E73: 16 or higher
